File: Lab 4 Data/G1CF_DRY.csv
Text Inputs : Specimen label,"G1CF_DRY"
Test : Rate 1,"0.70000",mm/min
Dimension : Support span,"25.60000",mm
Dimension : Thickness,"1.42100",mm
Dimension : Width,"12.30000",mm

Time,Extension,Load
(sec),(mm),(N)
"0.00000","0.00000","0.06604"
"0.30000","-0.00344","-0.38541"
"0.60000","-0.00688","-0.91825"
"0.90000","-0.01047","-1.32827"
"1.20000","-0.01391","-1.75827"
"1.50000","-0.01734","-2.22500"
"1.80000","-0.02078","-2.62956"
"2.10000","-0.02453","-3.12153"
"2.40000","-0.02781","-3.59137"
"2.70000","-0.03156","-4.02286"
"3.00000","-0.03516","-4.49537"
"3.30000","-0.03859","-4.88699"
"3.60000","-0.04203","-5.36894"
"3.90000","-0.04563","-5.81644"
"4.20000","-0.04906","-6.24744"
"4.50000","-0.05250","-6.69256"
"4.80000","-0.05578","-7.07743"
"5.10000","-0.05938","-7.48132"
"5.40000","-0.06297","-7.96136"
"5.70000","-0.06641","-8.43318"
"6.00000","-0.07000","-8.94040"
"6.30000","-0.07344","-9.52822"
"6.60000","-0.07703","-10.12380"
"6.90000","-0.08047","-10.62975"
"7.20000","-0.08406","-11.25357"
"7.50000","-0.08750","-11.80898"
"7.80000","-0.09094","-12.36894"
"8.10000","-0.09437","-12.97559"
"8.40000","-0.09797","-13.55443"
"8.70000","-0.10141","-14.19231"
"9.00000","-0.10500","-14.79104"
"9.30000","-0.10859","-15.40404"
"9.60000","-0.11203","-15.99066"
"9.90000","-0.11563","-16.60281"
"10.20000","-0.11906","-17.22353"
"10.50000","-0.12250","-17.79679"
"10.80000","-0.12594","-18.35045"
"11.10000","-0.12938","-18.97282"
"11.40000","-0.13281","-19.58708"
"11.70000","-0.13656","-20.24794"
"12.00000","-0.14000","-20.83696"
"12.30000","-0.14359","-21.46191"
"12.60000","-0.14703","-22.10047"
"12.90000","-0.15062","-22.67496"
"13.20000","-0.15406","-23.29496"
"13.50000","-0.15750","-23.88760"
"13.80000","-0.16078","-24.47327"
"14.10000","-0.16438","-25.11239"
"14.40000","-0.16797","-25.77248"
"14.70000","-0.17141","-26.42418"
"15.00000","-0.17500","-27.16724"
"15.30000","-0.17859","-27.91576"
"15.60000","-0.18219","-28.65031"
"15.90000","-0.18563","-29.37337"
"16.20000","-0.18906","-30.06715"
"16.50000","-0.19234","-30.80429"
"16.80000","-0.19594","-31.54537"
"17.10000","-0.19938","-32.30211"
"17.40000","-0.20297","-33.08357"
"17.70000","-0.20656","-33.82750"
"18.00000","-0.21016","-34.62953"
"18.30000","-0.21359","-35.31508"
"18.60000","-0.21703","-36.05028"
"18.90000","-0.22063","-36.83634"
"19.20000","-0.22406","-37.44567"
"19.50000","-0.22734","-38.17655"
"19.80000","-0.23094","-38.90413"
"20.10000","-0.23437","-39.67986"
"20.40000","-0.23797","-40.38558"
"20.70000","-0.24156","-41.16984"
"21.00000","-0.24516","-41.95270"
"21.30000","-0.24859","-42.66871"
"21.60000","-0.25203","-43.35840"
"21.90000","-0.25562","-44.14035"
"22.20000","-0.25891","-44.86031"
"22.50000","-0.26234","-45.61524"
"22.80000","-0.26578","-46.36482"
"23.10000","-0.26953","-47.11512"
"23.40000","-0.27297","-47.83531"
"23.70000","-0.27656","-48.62105"
"24.00000","-0.28016","-49.36513"
"24.30000","-0.28359","-50.17282"
"24.60000","-0.28719","-50.92965"
"24.90000","-0.29063","-51.69487"
"25.20000","-0.29406","-52.43247"
"25.50000","-0.29734","-53.16467"
"25.80000","-0.30094","-53.94193"
"26.10000","-0.30438","-54.71673"
"26.40000","-0.30797","-55.49031"
"26.70000","-0.31141","-56.25426"
"27.00000","-0.31516","-57.05599"
"27.30000","-0.31844","-57.75944"
"27.60000","-0.32219","-58.55252"
"27.90000","-0.32547","-59.27853"
"28.20000","-0.32906","-60.07288"
"28.50000","-0.33234","-60.72085"
"28.80000","-0.33594","-61.55733"
"29.10000","-0.33937","-62.32075"
"29.40000","-0.34297","-63.12242"
"29.70000","-0.34656","-63.91671"
"30.00000","-0.35000","-64.67124"
"30.30000","-0.35359","-65.47119"
"30.60000","-0.35719","-66.19151"
"30.90000","-0.36063","-66.94591"
"31.20000","-0.36391","-67.67272"
"31.50000","-0.36734","-68.41685"
"31.80000","-0.37078","-69.12931"
"32.10000","-0.37437","-69.96070"
"32.40000","-0.37781","-70.75488"
"32.70000","-0.38156","-71.53627"
"33.00000","-0.38500","-72.29700"
"33.30000","-0.38859","-73.01664"
"33.60000","-0.39203","-73.80805"
"33.90000","-0.39563","-74.56199"
"34.20000","-0.39906","-75.32376"
"34.50000","-0.40234","-76.01287"
"34.80000","-0.40578","-76.81124"
"35.10000","-0.40938","-77.53026"
"35.40000","-0.41297","-78.36294"
"35.70000","-0.41641","-79.07879"
"36.00000","-0.42016","-79.93636"
"36.30000","-0.42359","-80.57394"
"36.60000","-0.42703","-81.36975"
"36.90000","-0.43062","-82.09515"
"37.20000","-0.43391","-82.84928"
"37.50000","-0.43734","-83.57519"
"37.80000","-0.44094","-84.39331"
"38.10000","-0.44438","-85.08687"
"38.40000","-0.44813","-85.92553"
"38.70000","-0.45156","-86.67498"
"39.00000","-0.45516","-87.40907"
"39.30000","-0.45859","-88.16630"
"39.60000","-0.46219","-88.88433"
"39.90000","-0.46562","-89.59674"
"40.20000","-0.46875","-90.28328"
"40.50000","-0.47234","-91.04162"
"40.80000","-0.47594","-91.85689"
"41.10000","-0.47953","-92.62098"
"41.40000","-0.48313","-93.39344"
"41.70000","-0.48656","-94.16470"
"42.00000","-0.49000","-94.90266"
"42.30000","-0.49359","-95.63547"
"42.60000","-0.49703","-96.39456"
"42.90000","-0.50062","-97.14613"
"43.20000","-0.50391","-97.82203"
"43.50000","-0.50734","-98.63247"
"43.80000","-0.51094","-99.38011"
"44.10000","-0.51437","-100.13839"
"44.40000","-0.51797","-100.94649"
"44.70000","-0.52156","-101.68860"
"45.00000","-0.52516","-102.50057"
"45.30000","-0.52859","-103.22995"
"45.60000","-0.53203","-104.01291"
"45.90000","-0.53563","-104.73778"
"46.20000","-0.53891","-105.47441"
"46.50000","-0.54234","-106.21326"
"46.80000","-0.54594","-107.04088"
"47.10000","-0.54938","-107.78636"
"47.40000","-0.55297","-108.63537"
"47.70000","-0.55656","-109.39722"
"48.00000","-0.56016","-110.17187"
"48.30000","-0.56344","-110.92372"
"48.60000","-0.56719","-111.71155"
"48.90000","-0.57063","-112.45871"
"49.20000","-0.57391","-113.11245"
"49.50000","-0.57734","-113.92606"
"49.80000","-0.58094","-114.72012"
"50.10000","-0.58437","-115.51044"
"50.40000","-0.58797","-116.29077"
"50.70000","-0.59156","-117.10080"
"51.00000","-0.59516","-117.82906"
"51.30000","-0.59859","-118.62513"
"51.60000","-0.60219","-119.39473"
"51.90000","-0.60563","-120.12710"
"52.20000","-0.60891","-120.79935"
"52.50000","-0.61234","-121.58195"
"52.80000","-0.61578","-122.34001"
"53.10000","-0.61953","-123.17776"
"53.40000","-0.62297","-123.96176"
"53.70000","-0.62656","-124.72427"
"54.00000","-0.63016","-125.48562"
"54.30000","-0.63359","-126.22986"
"54.60000","-0.63703","-126.95878"
"54.90000","-0.64047","-127.75025"
"55.20000","-0.64391","-128.42171"
"55.50000","-0.64734","-129.20729"
"55.80000","-0.65094","-130.00448"
"56.10000","-0.65438","-130.77009"
"56.40000","-0.65813","-131.56441"
"56.70000","-0.66156","-132.29218"
"57.00000","-0.66516","-133.02870"
"57.30000","-0.66859","-133.79971"
"57.60000","-0.67219","-134.55218"
"57.90000","-0.67547","-135.32197"
"58.20000","-0.67891","-136.06288"
"58.50000","-0.68234","-136.78465"
"58.80000","-0.68594","-137.58941"
"59.10000","-0.68953","-138.37055"
"59.40000","-0.69297","-139.10051"
"59.70000","-0.69656","-139.90020"
"60.00000","-0.70016","-140.62835"
"60.30000","-0.70359","-141.46020"
"60.60000","-0.70703","-142.09522"
"60.90000","-0.71047","-142.93691"
"61.20000","-0.71391","-143.59742"
"61.50000","-0.71734","-144.32659"
"61.80000","-0.72094","-145.09930"
"62.10000","-0.72438","-145.90458"
"62.40000","-0.72781","-146.63987"
"62.70000","-0.73156","-147.40869"
"63.00000","-0.73500","-148.17456"
"63.30000","-0.73859","-148.92312"
"63.60000","-0.74203","-149.62136"
"63.90000","-0.74563","-150.41822"
"64.20000","-0.74891","-151.11394"
"64.50000","-0.75234","-151.87229"
"64.80000","-0.75594","-152.63640"
"65.10001","-0.75937","-153.36270"
"65.40000","-0.76313","-154.14298"
"65.70001","-0.76656","-154.87030"
"66.00000","-0.77016","-155.62187"
"66.30000","-0.77359","-156.36738"
"66.60001","-0.77703","-157.10682"
"66.90000","-0.78047","-157.80116"
"67.20001","-0.78391","-158.48028"
"67.50000","-0.78734","-159.21749"
"67.80000","-0.79094","-160.00008"
"68.10001","-0.79438","-160.74914"
"68.40000","-0.79797","-161.46228"
"68.70001","-0.80156","-162.18603"
"69.00000","-0.80516","-162.92650"
"69.30000","-0.80859","-163.64612"
"69.60001","-0.81203","-164.35524"
"69.90000","-0.81547","-165.06735"
"70.20001","-0.81891","-165.70807"
"70.50000","-0.82234","-166.45340"
"70.80000","-0.82578","-167.15355"
"71.10001","-0.82953","-167.94469"
"71.40000","-0.83297","-168.65591"
"71.70001","-0.83656","-169.33709"
"72.00000","-0.84016","-170.01633"
"72.30000","-0.84359","-170.72732"
"72.60001","-0.84703","-171.43987"
"72.90000","-0.85047","-172.13283"
"73.20001","-0.85375","-172.73532"
"73.50000","-0.85734","-173.48405"
"73.80000","-0.86078","-174.11079"
"74.10001","-0.86453","-174.81687"
"74.40000","-0.86813","-175.50338"
"74.70001","-0.87156","-176.02036"
"75.00000","-0.87516","-173.29117"
"75.30000","-0.87859","-172.64225"
"75.60001","-0.88203","-163.49986"
"75.90000","-0.88531","-162.78056"
"76.20001","-0.88891","-154.04057"
"76.50000","-0.89234","-146.17651"
"76.80000","-0.89594","-145.98568"
"77.10001","-0.89953","-146.18131"
"77.40000","-0.90312","-146.44893"
"77.70001","-0.90656","-146.79650"
"78.00000","-0.91016","-147.17595"
"78.30000","-0.91344","-147.52065"
"78.60001","-0.91703","-147.92886"
"78.90000","-0.92047","-148.33190"
"79.20001","-0.92391","-148.69971"
"79.50000","-0.92734","-128.07231"
"79.80000","-0.93094","-125.70579"
"80.10001","-0.93453","-125.30821"
"80.40000","-0.93813","-125.29912"
"80.70001","-0.94156","-125.43170"
"81.00001","-0.94500","-125.57007"
"81.30000","-0.94859","-125.74705"
"81.60001","-0.95203","-125.93636"
"81.90000","-0.95547","-126.15236"
"82.20001","-0.95875","-126.36595"
"82.50001","-0.96234","-126.66774"
"82.80000","-0.96578","-126.94100"
"83.10001","-0.96953","-127.26993"
"83.40000","-0.97297","-127.54295"
"83.70001","-0.97656","-127.79165"
"84.00001","-0.98000","-123.15790"
"84.30000","-0.98359","-121.57739"
"84.60001","-0.98703","-120.45496"
"84.90000","-0.99047","-120.11533"
"85.20001","-0.99391","-120.08555"
"85.50001","-0.99734","-120.17624"
"85.80000","-1.00094","-120.33682"
"86.10001","-1.00438","-120.48609"
"86.40000","-1.00813","-120.71207"
"86.70001","-1.01156","-120.92528"
"87.00001","-1.01516","-121.17667"
"87.30000","-1.01859","-121.24517"
"87.60001","-1.02203","-121.19565"
"87.90000","-1.02547","-121.26544"
"88.20001","-1.02891","-121.43747"
"88.50001","-1.03234","-121.64020"
"88.80000","-1.03594","-121.99018"
"89.10001","-1.03938","-122.19344"
"89.40000","-1.04297","-122.52741"
"89.70001","-1.04656","-122.80965"
"90.00001","-1.05016","-123.08856"
"90.30000","-1.05359","-123.35425"
"90.60001","-1.05703","-123.70891"
"90.90000","-1.06047","-123.99593"
"91.20001","-1.06375","-124.26784"
"91.50001","-1.06750","-124.58386"
"91.80000","-1.07094","-124.79214"
"92.10001","-1.07453","-125.04356"
"92.40000","-1.07812","-125.26125"
"92.70001","-1.08156","-125.52352"
"93.00001","-1.08500","-125.73111"
"93.30000","-1.08859","-125.97326"
"93.60001","-1.09203","-126.22252"
"93.90000","-1.09531","-126.50179"
"94.20001","-1.09875","-126.76008"
"94.50001","-1.10250","-127.05531"
"94.80000","-1.10594","-127.36547"
"95.10001","-1.10953","-127.64566"
"95.40000","-1.11313","-127.91629"
"95.70001","-1.11656","-128.21573"
"96.00001","-1.12016","-128.49695"
"96.30000","-1.12344","-128.70817"
"96.60001","-1.12703","-129.08730"
"96.90000","-1.13031","-129.29446"
"97.20001","-1.13391","-129.62672"
"97.50001","-1.13750","-129.92843"
"97.80000","-1.14094","-130.24027"
"98.10001","-1.14438","-130.52428"
"98.40000","-1.14797","-130.88451"
"98.70001","-1.15156","-131.18939"
"99.00001","-1.15516","-131.49968"
"99.30000","-1.15844","-131.70594"
"99.60001","-1.16203","-132.04704"
"99.90000","-1.16531","-132.29188"
"100.20001","-1.16891","-132.59404"
"100.50001","-1.17234","-132.86995"
"100.80000","-1.17594","-133.19305"
"101.10001","-1.17953","-133.51307"
"101.40000","-1.18297","-133.81671"
"101.70001","-1.18656","-134.16792"
"102.00001","-1.19000","-134.18347"
"102.30000","-1.19359","-134.07636"
"102.60001","-1.19703","-134.32839"
"102.90000","-1.20031","-134.50121"
"103.20001","-1.20391","-134.80873"
"103.50001","-1.20734","-135.10042"
"103.80000","-1.21094","-135.36845"
"104.10001","-1.21453","-135.67151"
"104.40000","-1.21797","-135.95138"
"104.70001","-1.22172","-136.17733"
"105.00001","-1.22516","-136.37616"
"105.30000","-1.22859","-136.58283"
"105.60001","-1.23203","-136.89524"
"105.90000","-1.23531","-137.08841"
"106.20001","-1.23891","-136.64293"
"106.50001","-1.24234","-135.89624"
"106.80000","-1.24609","-135.91934"
"107.10001","-1.24953","-135.90298"
"107.40000","-1.25313","-136.08165"
"107.70001","-1.25656","-136.29443"
"108.00001","-1.26016","-136.49347"
"108.30000","-1.26359","-136.75611"
"108.60001","-1.26688","-137.02134"
"108.90000","-1.27031","-137.25608"
"109.20001","-1.27391","-137.61193"
"109.50001","-1.27734","-137.86349"
"109.80000","-1.28109","-138.22387"
"110.10001","-1.28469","-138.55045"
"110.40000","-1.28813","-138.81422"
"110.70001","-1.29156","-139.12709"
"111.00001","-1.29516","-139.40301"
"111.30000","-1.29859","-139.63700"
"111.60001","-1.30187","-139.84374"
"111.90000","-1.30531","-140.10842"
"112.20001","-1.30891","-140.35193"
"112.50001","-1.31250","-139.20295"
"112.80000","-1.31594","-138.99853"
"113.10001","-1.31953","-138.99502"
"113.40001","-1.32312","-139.06654"
"113.70001","-1.32656","-139.23870"
"114.00001","-1.33000","-139.43144"
"114.30000","-1.33359","-139.64392"
"114.60001","-1.33688","-139.90921"
"114.90001","-1.34031","-140.13024"
"115.20001","-1.34391","-140.42151"
"115.50001","-1.34734","-140.65601"
"115.80000","-1.35094","-138.61815"
"116.10001","-1.35438","-138.35551"
"116.40001","-1.35813","-138.39314"
"116.70001","-1.36156","-138.50842"
"117.00001","-1.36516","-138.66468"
"117.30000","-1.36859","-137.72478"
"117.60001","-1.37203","-137.71557"
"117.90001","-1.37547","-137.90206"
"118.20001","-1.37891","-138.05408"
"118.50001","-1.38234","-138.30512"
"118.80000","-1.38594","-138.56337"
"119.10001","-1.38953","-138.82950"
"119.40001","-1.39313","-139.07330"
"119.70001","-1.39656","-139.34916"
"120.00001","-1.40016","-139.59306"
"120.30000","-1.40359","-139.79882"
"120.60001","-1.40687","-138.13399"
"120.90001","-1.41031","-138.08182"
"121.20001","-1.41391","-138.16217"
"121.50001","-1.41750","-138.34131"
"121.80000","-1.42078","-138.46240"
"122.10001","-1.42453","-138.72690"
"122.40001","-1.42813","-138.92189"
"122.70001","-1.43172","-139.19345"
"123.00001","-1.43516","-139.35985"
"123.30000","-1.43859","-139.59162"
"123.60001","-1.44188","-139.76802"
"123.90001","-1.44531","-140.01959"
"124.20001","-1.44891","-140.29404"
"124.50001","-1.45250","-140.58511"
"124.80000","-1.45594","-140.81677"
"125.10001","-1.45969","-141.04160"
"125.40001","-1.46312","-141.31095"
"125.70001","-1.46656","-141.57107"
"126.00001","-1.47016","-141.79573"
"126.30000","-1.47344","-142.02026"
"126.60001","-1.47688","-142.22461"
"126.90001","-1.48031","-142.46826"
"127.20001","-1.48391","-142.79155"
"127.50001","-1.48750","-143.04121"
"127.80000","-1.49109","-143.34061"
"128.10001","-1.49453","-143.53395"
"128.40001","-1.49813","-143.76235"
"128.70002","-1.50156","-143.98398"
"129.00000","-1.50516","-144.17172"
"129.30000","-1.50844","-144.43682"
"129.60001","-1.51188","-144.63874"
"129.90001","-1.51531","-144.85742"
"130.20002","-1.51891","-145.15073"
"130.50000","-1.52250","-145.43819"
"130.80000","-1.52609","-145.67266"
"131.10000","-1.52969","-145.90040"
"131.40002","-1.53313","-146.11589"
"131.70002","-1.53656","-146.35896"
"132.00000","-1.54000","-146.57584"
"132.30000","-1.54359","-146.65694"
"132.60000","-1.54687","-146.65530"
"132.90002","-1.55031","-147.13256"
"133.20002","-1.55391","-147.30059"
"133.50000","-1.55750","-147.52477"
"133.80000","-1.56109","-147.76754"
"134.10000","-1.56469","-147.95553"
"134.40002","-1.56797","-148.15300"
"134.70002","-1.57156","-148.31757"
"135.00000","-1.57500","-148.51439"
"135.30000","-1.57844","-148.73912"
"135.60000","-1.58188","-145.38527"
"135.90002","-1.58531","-145.01874"
"136.20002","-1.58891","-144.91435"
"136.50000","-1.59234","-144.87414"
"136.80000","-1.59609","-144.89904"
"137.10000","-1.59953","-144.94973"
"137.40002","-1.60313","-145.08384"
"137.70002","-1.60656","-145.17378"
"138.00000","-1.61016","-145.25185"
"138.30000","-1.61344","-145.38442"
"138.60000","-1.61688","-144.39011"
"138.90002","-1.62031","-143.92335"
"139.20002","-1.62391","-143.81800"
"139.50000","-1.62734","-143.56015"
"139.80000","-1.63094","-143.61683"
"140.10000","-1.63453","-143.55419"
"140.40002","-1.63813","-143.65525"
"140.70002","-1.64156","-143.66763"
"141.00000","-1.64516","-143.83262"
"141.30000","-1.64844","-143.83429"
"141.60000","-1.65187","-143.99434"
"141.90002","-1.65531","-144.05589"
"142.20002","-1.65891","-144.17567"
"142.50000","-1.66250","-144.36148"
"142.80000","-1.66594","-144.45832"
"143.10000","-1.66969","-144.58442"
"143.40002","-1.67312","-144.76016"
"143.70002","-1.67656","-144.82355"
"144.00000","-1.68000","-144.98336"
"144.30000","-1.68344","-145.09286"
"144.60000","-1.68688","-145.20348"
"144.90002","-1.69047","-145.40358"
"145.20002","-1.69391","-145.48736"
"145.50000","-1.69750","-145.68841"
"145.80000","-1.70109","-145.82829"
"146.10000","-1.70453","-145.93949"
"146.40002","-1.70812","-146.00462"
"146.70002","-1.71156","-146.10818"
"147.00000","-1.71516","-146.10558"
"147.30000","-1.71828","-146.01816"
"147.60000","-1.72188","-145.99365"
"147.90002","-1.72547","-145.92527"
"148.20002","-1.72906","-145.90730"
"148.50000","-1.73250","-145.93013"
"148.80000","-1.73609","-145.93259"
"149.10000","-1.73953","-145.73545"
"149.40002","-1.74313","-145.64074"
"149.70002","-1.74656","-145.67052"
"150.00000","-1.75000","-145.66658"
"150.30000","-1.75328","-145.66805"
"150.60000","-1.75687","-145.65969"
"150.90002","-1.76031","-145.72781"
"151.20002","-1.76391","-145.79174"
"151.50000","-1.76750","-145.82312"
"151.80000","-1.77094","-145.92831"
"152.10000","-1.77453","-145.97462"
"152.40002","-1.77797","-146.04907"
"152.70002","-1.78156","-146.13932"
"153.00000","-1.78500","-146.24946"
"153.30000","-1.78859","-146.32531"
"153.60000","-1.79187","-146.37381"
"153.90002","-1.79531","-146.49135"
"154.20002","-1.79891","-146.58974"
"154.50000","-1.80250","-146.73700"
"154.80000","-1.80609","-146.82766"
"155.10000","-1.80953","-146.84550"
"155.40002","-1.81297","-146.81409"
"155.70002","-1.81656","-146.98195"
"156.00000","-1.82016","-147.03413"
"156.30000","-1.82344","-147.07373"
"156.60000","-1.82688","-147.12795"
"156.90002","-1.83031","-147.23684"
"157.20002","-1.83391","-147.34152"
"157.50000","-1.83734","-147.47394"
"157.80000","-1.84109","-147.55188"
"158.10000","-1.84453","-147.58880"
"158.40002","-1.84813","-147.67572"
"158.70002","-1.85156","-147.79338"
"159.00000","-1.85516","-147.86565"
"159.30000","-1.85844","-147.84981"
"159.60000","-1.86188","-147.92781"
"159.90002","-1.86531","-148.01901"
"160.20002","-1.86906","-148.08229"
"160.50000","-1.87250","-148.14096"
"160.80000","-1.87609","-148.21122"
"161.10000","-1.87953","-148.22972"
"161.40002","-1.88313","-148.24211"
"161.70002","-1.88656","-148.28114"
"162.00002","-1.89000","-148.24308"
"162.30000","-1.89344","-148.23406"
"162.60000","-1.89687","-148.25561"
"162.90002","-1.90047","-148.32935"
"163.20002","-1.90391","-148.32220"
"163.50002","-1.90750","-148.32508"
"163.80000","-1.91109","-148.36137"
"164.10000","-1.91453","-148.38387"
"164.40002","-1.91812","-148.03987"
"164.70002","-1.92156","-147.86068"
"165.00002","-1.92500","-147.75916"
"165.30000","-1.92844","-147.50121"
"165.60000","-1.93172","-147.29500"
"165.90002","-1.93547","-147.23405"
"166.20002","-1.93891","-147.16376"
"166.50002","-1.94250","-147.07149"
"166.80000","-1.94609","-147.05043"
"167.10000","-1.94953","-146.96874"
"167.40002","-1.95312","-146.95899"
"167.70002","-1.95641","-146.87001"
"168.00002","-1.96016","-146.86725"
"168.30000","-1.96328","-146.75876"
"168.60000","-1.96688","-146.76249"
"168.90002","-1.97031","-146.75976"
"169.20002","-1.97391","-146.76600"
"169.50002","-1.97734","-146.63410"
"169.80000","-1.98094","-146.54648"
"170.10000","-1.98453","-146.53264"
"170.40002","-1.98813","-146.30375"
"170.70002","-1.99156","-146.06489"
"171.00002","-1.99516","-146.00967"
"171.30000","-1.99844","-145.85227"
"171.60000","-2.00188","-145.81337"
"171.90002","-2.00547","-145.74533"
"172.20002","-2.00891","-145.72788"
"172.50002","-2.01250","-145.71701"
"172.80000","-2.01594","-145.66178"
"173.10000","-2.01969","-145.70443"
"173.40002","-2.02313","-145.66338"
"173.70002","-2.02656","-145.70687"
"174.00002","-2.03000","-145.76487"
"174.30000","-2.03344","-145.75674"
"174.60000","-2.03688","-145.81973"
"174.90002","-2.04047","-145.87327"
"175.20002","-2.04391","-145.96103"
"175.50002","-2.04750","-145.94777"
"175.80000","-2.05094","-146.05787"
"176.10000","-2.05469","-146.12900"
"176.40002","-2.05813","-146.18121"
"176.70002","-2.06156","-146.19685"
"177.00002","-2.06500","-146.25281"
"177.30000","-2.06844","-146.26421"
"177.60000","-2.07188","-146.37545"
"177.90002","-2.07531","-146.41468"
"178.20002","-2.07906","-146.62228"
"178.50002","-2.08250","-146.68423"
"178.80000","-2.08609","-146.78045"
"179.10000","-2.08953","-146.81876"
"179.40002","-2.09313","-146.90771"
"179.70002","-2.09656","-147.01379"
"180.00002","-2.10000","-147.10492"
"180.30000","-2.10328","-147.12219"
"180.60000","-2.10687","-147.27733"
"180.90002","-2.11031","-147.35893"
"181.20002","-2.11406","-147.52136"
"181.50002","-2.11766","-147.66812"
"181.80000","-2.12109","-147.74750"
"182.10000","-2.12453","-147.85670"
"182.40002","-2.12813","-147.99204"
"182.70002","-2.13156","-148.10967"
"183.00002","-2.13484","-148.18454"
"183.30000","-2.13844","-148.31712"
"183.60000","-2.14187","-148.45907"
"183.90002","-2.14547","-148.60551"
"184.20002","-2.14906","-148.69073"
"184.50002","-2.15266","-148.82992"
"184.80000","-2.15609","-148.96319"
"185.10000","-2.15969","-149.01175"
"185.40002","-2.16312","-149.11207"
"185.70002","-2.16656","-149.19893"
"186.00002","-2.16984","-149.22234"
"186.30000","-2.17344","-149.29989"
"186.60000","-2.17688","-149.40952"
"186.90002","-2.18047","-149.51881"
"187.20002","-2.18406","-149.67222"
"187.50002","-2.18750","-149.70080"
"187.80000","-2.19109","-149.77010"
"188.10000","-2.19453","-149.79684"
"188.40002","-2.19813","-149.91480"
"188.70002","-2.20156","-149.92877"
"189.00002","-2.20500","-149.97993"
"189.30000","-2.20828","-149.99421"
"189.60000","-2.21188","-150.11367"
"189.90002","-2.21531","-150.19031"
"190.20002","-2.21891","-150.27423"
"190.50002","-2.22250","-150.28734"
"190.80000","-2.22609","-150.39925"
"191.10000","-2.22953","-150.43768"
"191.40002","-2.23313","-150.51382"
"191.70002","-2.23656","-150.56688"
"192.00002","-2.24000","-150.61785"
"192.30000","-2.24328","-150.64976"
"192.60000","-2.24688","-150.73036"
"192.90002","-2.25047","-150.81881"
"193.20002","-2.25391","-150.88178"
"193.50002","-2.25750","-150.97204"
"193.80000","-2.26109","-151.00792"
"194.10000","-2.26469","-151.07507"
"194.40002","-2.26813","-151.11002"
"194.70002","-2.27156","-151.15638"
"195.00002","-2.27500","-151.15329"
"195.30000","-2.27844","-151.13282"
"195.60000","-2.28188","-151.19287"
"195.90002","-2.28547","-150.78299"
"196.20002","-2.28891","-150.06065"
"196.50002","-2.29250","-149.61975"
"196.80000","-2.29609","-149.29217"
"197.10000","-2.29953","-148.95105"
"197.40002","-2.30313","-148.50311"
"197.70002","-2.30656","-148.09778"
"198.00002","-2.31000","-147.77717"
"198.30000","-2.31328","-147.44630"
"198.60000","-2.31703","-147.25029"
"198.90002","-2.32047","-147.07454"
"199.20002","-2.32406","-146.92041"
"199.50002","-2.32766","-146.70974"
"199.80000","-2.33109","-146.47636"
"200.10000","-2.33453","-146.33649"
"200.40002","-2.33813","-146.18661"
"200.70002","-2.34156","-146.08880"
"201.00002","-2.34484","-146.03540"
"201.30000","-2.34828","-145.89157"
"201.60000","-2.35187","-145.85942"
"201.90002","-2.35547","-145.79567"
"202.20002","-2.35906","-145.78467"
"202.50002","-2.36266","-145.73627"
"202.80000","-2.36609","-145.80601"
"203.10000","-2.36953","-145.79857"
"203.40002","-2.37297","-145.76418"
"203.70002","-2.37656","-145.85119"
"204.00002","-2.37984","-145.86172"
"204.30000","-2.38344","-145.90735"
"204.60000","-2.38687","-145.98748"
"204.90002","-2.39047","-146.08506"
"205.20002","-2.39391","-146.12950"
"205.50002","-2.39750","-146.11457"
"205.80000","-2.40109","-146.24495"
"206.10000","-2.40453","-146.30576"
"206.40002","-2.40797","-146.35106"
"206.70002","-2.41156","-146.43159"
"207.00002","-2.41500","-146.50344"
"207.30000","-2.41828","-146.54517"
"207.60000","-2.42188","-146.65117"
"207.90002","-2.42547","-146.75190"
"208.20002","-2.42906","-146.88968"
"208.50002","-2.43250","-146.96984"
"208.80000","-2.43609","-147.06210"
"209.10000","-2.43953","-147.14757"
"209.40002","-2.44313","-147.29976"
"209.70002","-2.44656","-147.39053"
"210.00002","-2.45000","-147.46099"
"210.30000","-2.45328","-147.53667"
"210.60000","-2.45688","-147.65637"
"210.90002","-2.46047","-147.74407"
"211.20002","-2.46391","-147.82663"
"211.50002","-2.46750","-147.89748"
"211.80000","-2.47109","-148.02010"
"212.10000","-2.47469","-148.09910"
"212.40002","-2.47813","-148.16548"
"212.70002","-2.48156","-148.30349"
"213.00002","-2.48484","-148.35327"
"213.30000","-2.48844","-148.44209"
"213.60000","-2.49188","-148.55850"
"213.90002","-2.49563","-148.73303"
"214.20002","-2.49906","-148.84747"
"214.50002","-2.50266","-148.96904"
"214.80000","-2.50609","-149.10039"
"215.10000","-2.50953","-149.19797"
"215.40002","-2.51313","-149.31100"
"215.70002","-2.51656","-149.46234"
"216.00002","-2.51984","-149.53984"
"216.30000","-2.52344","-149.65742"
"216.60000","-2.52688","-149.69168"
"216.90002","-2.53047","-149.84685"
"217.20002","-2.53406","-149.98363"
"217.50002","-2.53766","-150.05440"
"217.80000","-2.54109","-150.19856"
"218.10000","-2.54453","-150.28699"
"218.40002","-2.54813","-150.40303"
"218.70002","-2.55141","-150.46355"
"219.00002","-2.55484","-150.56964"
"219.30000","-2.55828","-150.62877"
"219.60000","-2.56203","-150.83067"
"219.90002","-2.56563","-150.97177"
"220.20002","-2.56906","-151.06998"
"220.50002","-2.57250","-151.15412"
"220.80000","-2.57609","-151.28700"
"221.10000","-2.57953","-151.32811"
"221.40002","-2.58313","-151.47237"
"221.70002","-2.58656","-151.53990"
"222.00002","-2.58984","-151.64608"
"222.30000","-2.59328","-151.73009"
"222.60000","-2.59687","-151.86755"
"222.90002","-2.60047","-151.95559"
"223.20002","-2.60391","-152.08043"
"223.50002","-2.60750","-152.19240"
"223.80000","-2.61094","-152.29945"
"224.10000","-2.61469","-152.41810"
"224.40002","-2.61812","-152.53962"
"224.70002","-2.62156","-152.65420"
"225.00002","-2.62484","-152.69325"
"225.30002","-2.62844","-152.78917"
"225.60000","-2.63187","-152.91196"
"225.90002","-2.63547","-153.00146"
"226.20002","-2.63906","-153.15364"
"226.50002","-2.64250","-153.24151"
"226.80002","-2.64609","-153.36015"
"227.10000","-2.64969","-153.54563"
"227.40002","-2.65312","-153.59085"
"227.70002","-2.65656","-153.66457"
"228.00002","-2.65984","-153.84765"
"228.30002","-2.66328","-153.89532"
"228.60000","-2.66688","-154.08721"
"228.90002","-2.67031","-154.17526"
"229.20002","-2.67406","-154.33847"
"229.50002","-2.67750","-154.46262"
"229.80002","-2.68109","-154.60442"
"230.10000","-2.68453","-154.71778"
"230.40002","-2.68813","-154.86753"
"230.70002","-2.69141","-154.98106"
"231.00002","-2.69484","-155.09534"
"231.30002","-2.69844","-155.24274"
"231.60000","-2.70188","-155.37396"
"231.90002","-2.70547","-155.47357"
"232.20002","-2.70906","-155.58439"
"232.50002","-2.71266","-155.68435"
"232.80002","-2.71609","-155.79010"
"233.10000","-2.71953","-155.87452"
"233.40002","-2.72313","-155.99863"
"233.70002","-2.72656","-156.11660"
"234.00002","-2.72969","-155.85020"
"234.30002","-2.73344","-155.60780"
"234.60000","-2.73688","-155.47977"
"234.90002","-2.74063","-155.42503"
"235.20002","-2.74406","-155.48031"
"235.50002","-2.74766","-155.28094"
"235.80002","-2.75109","-155.16519"
"236.10000","-2.75453","-155.07531"
"236.40002","-2.75813","-154.99601"
"236.70002","-2.76141","-154.87683"
"237.00002","-2.76484","-154.88450"
"237.30002","-2.76844","-154.86902"
"237.60000","-2.77203","-154.86578"
"237.90002","-2.77563","-154.88859"
"238.20002","-2.77906","-154.89930"
"238.50002","-2.78250","-154.90536"
"238.80002","-2.78609","-155.00052"
"239.10000","-2.78953","-154.87224"
"239.40002","-2.79313","-154.86787"
"239.70002","-2.79641","-154.73850"
"240.00002","-2.79984","-154.54086"
"240.30002","-2.80344","-154.24657"
"240.60000","-2.80688","-154.20966"
"240.90002","-2.81047","-154.09029"
"241.20002","-2.81406","-154.01420"
"241.50002","-2.81766","-154.19554"
"241.80002","-2.82109","-154.08708"
"242.10000","-2.82453","-154.19659"
"242.40002","-2.82813","-154.19121"
"242.70002","-2.83156","-154.11927"
"243.00002","-2.83484","-154.19615"
"243.30002","-2.83844","-154.17300"
"243.60000","-2.84187","-154.16108"
"243.90002","-2.84547","-154.21093"
"244.20002","-2.84891","-153.32353"
"244.50002","-2.85266","-152.73384"
"244.80002","-2.85609","-152.33940"
"245.10000","-2.85969","-152.06838"
"245.40002","-2.86312","-151.81832"
"245.70002","-2.86641","-151.62563"
"246.00002","-2.86984","-151.51525"
"246.30002","-2.87344","-151.43505"
"246.60000","-2.87703","-151.40747"
"246.90002","-2.88047","-151.38703"
"247.20002","-2.88406","-151.43081"
"247.50002","-2.88766","-151.42524"
"247.80002","-2.89109","-151.47367"
"248.10000","-2.89453","-151.42492"
"248.40002","-2.89812","-151.51705"
"248.70002","-2.90141","-151.49064"
"249.00002","-2.90484","-151.59082"
"249.30002","-2.90828","-151.63655"
"249.60000","-2.91203","-151.55566"
"249.90002","-2.91547","-151.57850"
"250.20002","-2.91906","-151.68861"
"250.50002","-2.92266","-151.77743"
"250.80002","-2.92609","-151.87860"
"251.10000","-2.92953","-151.98287"
"251.40002","-2.93313","-152.05793"
"251.70002","-2.93656","-152.13950"
"252.00002","-2.93984","-152.27620"
"252.30002","-2.94344","-152.40522"
"252.60000","-2.94703","-152.46504"
"252.90002","-2.95063","-152.65684"
"253.20002","-2.95406","-152.75457"
"253.50002","-2.95766","-152.87527"
"253.80002","-2.96109","-153.02164"
"254.10000","-2.96469","-153.16500"
"254.40002","-2.96797","-153.22489"
"254.70002","-2.97141","-153.36828"
"255.00002","-2.97484","-153.50563"
"255.30002","-2.97844","-153.67539"
"255.60000","-2.98203","-153.75586"
"255.90002","-2.98563","-153.94312"
"256.20002","-2.98906","-154.09421"
"256.50000","-2.99266","-154.13942"
"256.80002","-2.99609","-154.25561"
"257.10000","-2.99953","-154.32042"
"257.40003","-3.00297","-154.45588"
"257.70002","-3.00641","-154.50637"
"258.00000","-3.00984","-154.64632"
"258.30002","-3.01344","-154.78513"
"258.60000","-3.01703","-154.83364"
"258.90003","-3.02047","-155.01535"
"259.20002","-3.02406","-155.07573"
"259.50000","-3.02750","-155.09676"
"259.80002","-3.03109","-155.16833"
"260.10000","-3.03453","-155.26743"
"260.40003","-3.03813","-155.36028"
"260.70002","-3.04141","-155.40013"
"261.00000","-3.04484","-155.47457"
"261.30002","-3.04844","-155.56918"
"261.60000","-3.05203","-155.67585"
"261.90003","-3.05563","-155.78201"
"262.20000","-3.05906","-155.80534"
"262.50000","-3.06250","-155.89796"
"262.80003","-3.06609","-155.97513"
"263.10000","-3.06953","-156.04175"
"263.40003","-3.07313","-156.14172"
"263.70000","-3.07641","-156.21713"
"264.00000","-3.07984","-156.30113"
"264.30003","-3.08344","-156.42006"
"264.60000","-3.08687","-156.42738"
"264.90003","-3.09047","-156.57647"
"265.20000","-3.09406","-156.54661"
"265.50000","-3.09766","-156.63434"
"265.80003","-3.10109","-156.67662"
"266.10000","-3.10469","-156.71382"
"266.40003","-3.10797","-156.76942"
"266.70000","-3.11141","-156.78065"
"267.00000","-3.11484","-156.88352"
"267.30003","-3.11844","-156.93635"
"267.60000","-3.12203","-156.99776"
"267.90003","-3.12547","-157.06435"
"268.20000","-3.12906","-157.14169"
"268.50000","-3.13266","-157.18980"
"268.80003","-3.13609","-157.24484"
"269.10000","-3.13953","-157.23757"
"269.40003","-3.14312","-157.23897"
"269.70000","-3.14625","-157.22485"
"270.00000","-3.15000","-157.30347"
"270.30003","-3.15344","-157.29757"
"270.60000","-3.15703","-157.38288"
"270.90003","-3.16062","-157.39426"
"271.20000","-3.16406","-157.43507"
"271.50000","-3.16766","-157.47333"
"271.80003","-3.17109","-157.52371"
"272.10000","-3.17453","-157.54702"
"272.40003","-3.17797","-157.59245"
"272.70000","-3.18125","-157.63097"
"273.00000","-3.18500","-157.69614"
"273.30003","-3.18844","-157.71737"
"273.60000","-3.19203","-157.77590"
"273.90003","-3.19563","-157.85001"
"274.20000","-3.19906","-157.84957"
"274.50000","-3.20266","-157.90721"
"274.80003","-3.20594","-157.86074"
"275.10000","-3.20953","-157.96537"
"275.40003","-3.21281","-157.96276"
"275.70000","-3.21641","-158.01976"
"276.00000","-3.21984","-158.06951"
"276.30003","-3.22344","-158.14049"
"276.60000","-3.22688","-158.17717"
"276.90003","-3.23047","-158.25599"
"277.20000","-3.23406","-158.29867"
"277.50000","-3.23750","-158.25177"
"277.80003","-3.24109","-158.26032"
"278.10000","-3.24469","-158.32551"
"278.40003","-3.24797","-158.32189"
"278.70000","-3.25141","-158.35527"
"279.00000","-3.25484","-158.42322"
"279.30003","-3.25844","-158.41536"
"279.60000","-3.26203","-158.41335"
"279.90003","-3.26547","-158.42423"
"280.20000","-3.26906","-158.48953"
"280.50000","-3.27250","-158.38666"
"280.80003","-3.27609","-158.24411"
"281.10000","-3.27969","-158.12872"
"281.40003","-3.28297","-157.95166"
"281.70000","-3.28641","-157.88225"
"282.00000","-3.29000","-157.81639"
"282.30003","-3.29344","-157.70886"
"282.60000","-3.29687","-157.09801"
"282.90003","-3.30047","-155.64052"
"283.20000","-3.30406","-154.24866"
"283.50000","-3.30766","-152.74442"
"283.80003","-3.31109","-151.23336"
"284.10000","-3.31453","-149.88072"
"284.40003","-3.31797","-148.80384"
"284.70000","-3.32141","-147.87844"
"285.00000","-3.32484","-147.15234"
"285.30003","-3.32844","-146.48099"
"285.60000","-3.33203","-145.99738"
"285.90003","-3.33562","-145.60052"
"286.20000","-3.33906","-145.31693"
"286.50000","-3.34266","-145.09308"
"286.80003","-3.34609","-144.93650"
"287.10000","-3.34953","-144.66794"
"287.40003","-3.35297","-144.50386"
"287.70000","-3.35641","-144.43463"
"288.00000","-3.35984","-144.39018"
"288.30003","-3.36344","-144.31767"
"288.60000","-3.36703","-144.29406"
"288.90003","-3.37062","-144.22012"
"289.20000","-3.37406","-144.14024"
"289.50000","-3.37750","-144.04812"
"289.80003","-3.38109","-143.83929"
"290.10000","-3.38438","-143.50938"
"290.40003","-3.38781","-143.46329"
"290.70000","-3.39141","-143.31982"
"291.00000","-3.39500","-143.34582"
"291.30003","-3.39859","-143.27508"
"291.60000","-3.40203","-143.30492"
"291.90003","-3.40563","-143.31147"
"292.20000","-3.40906","-143.35341"
"292.50000","-3.41266","-143.39091"
"292.80003","-3.41609","-143.56536"
"293.10000","-3.41953","-143.61132"
"293.40003","-3.42281","-143.65940"
"293.70000","-3.42641","-143.74342"
"294.00000","-3.43000","-143.89144"
"294.30003","-3.43359","-144.01956"
"294.60000","-3.43703","-144.10906"
"294.90003","-3.44063","-144.24611"
"295.20000","-3.44391","-144.27338"
"295.50000","-3.44750","-144.31837"
"295.80003","-3.45109","-144.39901"
"296.10000","-3.45453","-144.45107"
"296.40003","-3.45797","-144.46869"
"296.70000","-3.46141","-144.46347"
"297.00000","-3.46484","-144.62826"
"297.30003","-3.46844","-144.75183"
"297.60000","-3.47203","-144.89499"
"297.90003","-3.47547","-145.01438"
"298.20000","-3.47906","-145.17393"
"298.50000","-3.48266","-145.29372"
"298.80003","-3.48609","-145.40728"
"299.10000","-3.48953","-145.49760"
"299.40003","-3.49281","-145.46505"
"299.70000","-3.49641","-145.55237"
"300.00000","-3.50000","-145.77898"
"300.30003","-3.50344","-145.86033"
"300.60000","-3.50703","-146.02125"
"300.90003","-3.51047","-146.17010"
"301.20000","-3.51406","-146.33899"
"301.50000","-3.51766","-146.48450"
"301.80003","-3.52109","-146.63781"
"302.10000","-3.52453","-146.79667"
"302.40003","-3.52781","-146.89422"
"302.70000","-3.53141","-147.05461"
"303.00000","-3.53500","-147.29518"
"303.30003","-3.53844","-147.45145"
"303.60000","-3.54203","-147.59996"
"303.90003","-3.54563","-147.71534"
"304.20000","-3.54906","-147.90149"
"304.50000","-3.55266","-148.00920"
"304.80003","-3.55609","-148.15589"
"305.10000","-3.55953","-148.32812"
"305.40003","-3.56281","-148.38033"
"305.70000","-3.56641","-148.62124"
"306.00000","-3.56984","-148.76658"
"306.30003","-3.57359","-149.01981"
"306.60000","-3.57703","-149.17229"
"306.90003","-3.58062","-149.36054"
"307.20000","-3.58406","-149.53640"
"307.50000","-3.58766","-149.67156"
"307.80003","-3.59109","-149.84591"
"308.10000","-3.59437","-149.93617"
"308.40003","-3.59781","-150.01745"
"308.70000","-3.60141","-150.00785"
"309.00000","-3.60500","-150.22974"
"309.30003","-3.60859","-150.34331"
"309.60000","-3.61203","-150.44940"
"309.90003","-3.61562","-150.55417"
"310.20000","-3.61906","-150.62911"
"310.50000","-3.62250","-150.61776"
"310.80003","-3.62609","-150.81786"
"311.10000","-3.62938","-150.81891"
"311.40003","-3.63297","-151.04333"
"311.70000","-3.63641","-151.09116"
"312.00000","-3.64000","-151.29313"
"312.30003","-3.64344","-151.42634"
"312.60000","-3.64703","-151.50483"
"312.90003","-3.65063","-151.67954"
"313.20000","-3.65406","-151.82073"
"313.50000","-3.65750","-151.89814"
"313.80003","-3.66109","-152.06393"
"314.10000","-3.66453","-152.18779"
"314.40003","-3.66781","-152.31798"
"314.70000","-3.67141","-152.54663"
"315.00000","-3.67484","-152.65708"
"315.30003","-3.67859","-152.91112"
"315.60000","-3.68203","-153.04488"
"315.90003","-3.68563","-153.26144"
"316.20000","-3.68906","-153.39947"
"316.50000","-3.69266","-153.56454"
"316.80003","-3.69609","-153.71045"
"317.10000","-3.69938","-153.81414"
"317.40003","-3.70281","-153.96778"
"317.70000","-3.70641","-154.13120"
"318.00000","-3.71000","-154.22978"
"318.30003","-3.71344","-154.33918"
"318.60000","-3.71703","-154.48536"
"318.90003","-3.72063","-154.66472"
"319.20000","-3.72406","-154.81755"
"319.50000","-3.72766","-154.90402"
"319.80003","-3.73109","-155.05528"
"320.10000","-3.73438","-154.99014"
"320.40003","-3.73781","-155.12013"
"320.70000","-3.74125","-155.18191"
"321.00000","-3.74500","-155.37417"
"321.30003","-3.74859","-155.41223"
"321.60000","-3.75219","-155.51253"
"321.90003","-3.75563","-155.52997"
"322.20000","-3.75906","-155.66142"
"322.50003","-3.76250","-155.60106"
"322.80003","-3.76609","-155.75830"
"323.10000","-3.76937","-155.62164"
"323.40003","-3.77281","-155.73506"
"323.70000","-3.77641","-155.77668"
"324.00003","-3.78000","-155.84381"
"324.30003","-3.78359","-155.88314"
"324.60000","-3.78703","-155.81544"
"324.90003","-3.79062","-155.85624"
"325.20000","-3.79406","-155.84524"
"325.50003","-3.79766","-155.91846"
"325.80003","-3.80094","-155.83863"
"326.10000","-3.80437","-155.92553"
"326.40003","-3.80781","-155.97696"
"326.70000","-3.81141","-156.11897"
"327.00003","-3.81500","-156.20685"
"327.30003","-3.81859","-156.24617"
"327.60000","-3.82203","-156.35418"
"327.90003","-3.82562","-156.46201"
"328.20000","-3.82906","-156.55749"
"328.50003","-3.83250","-156.64313"
"328.80003","-3.83594","-156.70396"
"329.10000","-3.83937","-156.58118"
"329.40003","-3.84281","-156.62037"
"329.70000","-3.84641","-156.68849"
"330.00003","-3.84984","-156.77955"
"330.30003","-3.85344","-156.82282"
"330.60000","-3.85703","-156.97818"
"330.90003","-3.86047","-157.10058"
"331.20000","-3.86406","-157.28611"
"331.50003","-3.86750","-157.33015"
"331.80003","-3.87109","-157.52040"
"332.10000","-3.87453","-157.64972"
"332.40003","-3.87781","-157.81378"
"332.70000","-3.88141","-157.85770"
"333.00003","-3.88500","-158.03717"
"333.30003","-3.88859","-158.11611"
"333.60000","-3.89203","-158.12036"
"333.90003","-3.89547","-158.18411"
"334.20000","-3.89922","-158.30047"
"334.50003","-3.90266","-158.29042"
"334.80003","-3.90609","-158.37016"
"335.10000","-3.90938","-158.37964"
"335.40003","-3.91281","-158.44561"
"335.70000","-3.91641","-158.60362"
"336.00003","-3.91984","-158.60636"
"336.30003","-3.92344","-158.61873"
"336.60000","-3.92703","-158.50842"
"336.90003","-3.93063","-158.49881"
"337.20000","-3.93406","-158.43008"
"337.50003","-3.93766","-158.39681"
"337.80003","-3.94094","-158.29513"
"338.10000","-3.94438","-158.31647"
"338.40003","-3.94797","-157.68129"
"338.70000","-3.95141","-157.13625"
"339.00003","-3.95500","-157.09870"
"339.30003","-3.95859","-157.04321"
"339.60000","-3.96219","-157.05859"
"339.90003","-3.96563","-156.77260"
"340.20000","-3.96906","-156.68856"
"340.50003","-3.97250","-156.59746"
"340.80003","-3.97594","-156.60517"
"341.10000","-3.97922","-156.52852"
"341.40003","-3.98297","-156.59332"
"341.70000","-3.98641","-156.54052"
"342.00003","-3.99000","-156.63153"
"342.30003","-3.99359","-156.69897"
"342.60000","-3.99719","-156.70117"
"342.90003","-4.00063","-156.60724"
"343.20000","-4.00406","-154.82837"
"343.50003","-4.00766","-154.03832"
"343.80003","-4.01094","-150.20546"
"344.10000","-4.01438","-149.80960"
"344.40003","-4.01797","-149.79146"
"344.70000","-4.02156","-149.68739"
"345.00003","-4.02516","-146.78707"
"345.30003","-4.02859","-146.71100"
"345.60000","-4.03203","-146.75486"
"345.90003","-4.03563","-146.86581"
"346.20000","-4.03891","-146.80626"
"346.50003","-4.04266","-146.89134"
"346.80003","-4.04594","-146.85854"
"347.10000","-4.04938","-146.97784"
"347.40003","-4.05297","-147.14473"
"347.70000","-4.05641","-142.65263"
"348.00003","-4.06016","-142.33558"
"348.30003","-4.06359","-142.06955"
"348.60000","-4.06703","-142.08378"
"348.90003","-4.07047","-142.08447"
"349.20000","-4.07406","-142.06072"
"349.50003","-4.07750","-142.16601"
"349.80003","-4.08109","-141.76640"
"350.10000","-4.08438","-141.62918"
"350.40003","-4.08797","-141.70512"
"350.70000","-4.09141","-141.56442"
"351.00003","-4.09500","-141.60169"
"351.30003","-4.09844","-141.58045"
"351.60000","-4.10203","-141.72019"
"351.90003","-4.10547","-141.67729"
"352.20000","-4.10906","-141.35798"
"352.50003","-4.11266","-141.39364"
"352.80003","-4.11594","-133.73687"
"353.10000","-4.11938","-133.87408"
"353.40003","-4.12297","-133.92751"
"353.70000","-4.12641","-134.05034"
"354.00003","-4.12984","-134.09429"
"354.30003","-4.13359","-134.22669"
"354.60000","-4.13703","-134.37824"
"354.90003","-4.14063","-134.46221"
"355.20000","-4.14406","-134.61936"
"355.50003","-4.14766","-134.68680"
"355.80003","-4.15094","-134.73050"
"356.10000","-4.15438","-134.34541"
"356.40003","-4.15781","-134.32383"
"356.70000","-4.16141","-134.42914"
"357.00003","-4.16484","-134.49878"
"357.30003","-4.16859","-134.58321"
"357.60000","-4.17219","-132.62974"
"357.90003","-4.17563","-132.49770"
"358.20000","-4.17906","-132.50243"
"358.50003","-4.18250","-132.44801"
"358.80003","-4.18594","-132.27697"
"359.10000","-4.18938","-132.36375"
"359.40003","-4.19297","-132.46414"
"359.70000","-4.19641","-132.56235"
"360.00003","-4.20016","-132.66680"
"360.30003","-4.20359","-132.68063"
"360.60000","-4.20703","-132.78922"
"360.90003","-4.21063","-132.95188"
"361.20000","-4.21406","-133.09252"
"361.50003","-4.21750","-133.24155"
"361.80003","-4.22094","-133.41066"
"362.10000","-4.22438","-133.52804"
"362.40003","-4.22797","-133.41297"
"362.70000","-4.23156","-131.95873"
"363.00003","-4.23516","-114.42882"
"363.30003","-4.23859","-114.92101"
"363.60000","-4.24203","-115.45002"
"363.90003","-4.24563","-115.91339"
"364.20000","-4.24906","-116.42304"
"364.50003","-4.25250","-116.63451"
"364.80003","-4.25594","-117.03499"
"365.10000","-4.25937","-117.29592"
"365.40003","-4.26297","-117.62920"
"365.70000","-4.26641","-117.95514"
"366.00003","-4.26984","-118.22308"
"366.30003","-4.27344","-118.51631"
"366.60000","-4.27687","-118.76364"
"366.90003","-4.28047","-119.14672"
"367.20000","-4.28391","-119.41842"
"367.50003","-4.28750","-119.73936"
"367.80003","-4.29094","-119.90488"
"368.10000","-4.29437","-120.31396"
"368.40003","-4.29797","-120.57846"
"368.70000","-4.30141","-120.83580"
"369.00003","-4.30500","-121.21256"
"369.30003","-4.30844","-121.41252"
"369.60000","-4.31203","-121.73656"
"369.90003","-4.31547","-122.04659"
"370.20000","-4.31906","-122.28631"
"370.50003","-4.32250","-122.56382"
"370.80003","-4.32594","-122.85212"
"371.10000","-4.32937","-123.11057"
"371.40003","-4.33297","-123.42713"
"371.70000","-4.33641","-123.65281"
"372.00003","-4.34000","-124.00793"
"372.30003","-4.34359","-124.23901"
"372.60000","-4.34719","-124.52471"
"372.90003","-4.35062","-124.77105"
"373.20000","-4.35406","-125.05101"
"373.50003","-4.35750","-125.29360"
"373.80003","-4.36094","-125.50789"
"373.94403","-4.36250","-125.60336"