File: Lab 4 Data/G1NC_1_DRY.csv
Text Inputs : Specimen label,"G1NC_1_DRY"
Test : Rate 1,"15.04212",mm/min
Dimension : Support span,"50.00000",mm
Dimension : Thickness,"2.77000",mm
Dimension : Width,"12.51000",mm

Time,Extension,Load
(sec),(mm),(N)
"0.00000","0.00000","0.07322"
"0.05000","-0.00594","-0.02472"
"0.10000","-0.02063","-0.29780"
"0.15000","-0.03563","-0.69920"
"0.20000","-0.04906","-1.01587"
"0.25000","-0.06250","-1.28251"
"0.30000","-0.07484","-1.60188"
"0.35000","-0.08766","-1.87633"
"0.40000","-0.10031","-2.12856"
"0.45000","-0.11266","-2.42268"
"0.50000","-0.12531","-2.70168"
"0.55000","-0.13813","-2.99030"
"0.60000","-0.15062","-3.24026"
"0.65000","-0.16328","-3.54627"
"0.70000","-0.17578","-3.83432"
"0.75000","-0.18813","-4.06427"
"0.80000","-0.20078","-4.36173"
"0.85000","-0.21328","-4.65065"
"0.90000","-0.22563","-4.93306"
"0.95000","-0.23844","-5.22768"
"1.00000","-0.25063","-5.52456"
"1.05000","-0.26328","-5.84225"
"1.10000","-0.27609","-6.10563"
"1.15000","-0.28844","-6.35633"
"1.20000","-0.30109","-6.64932"
"1.25000","-0.31359","-6.91075"
"1.30000","-0.32609","-7.18093"
"1.35000","-0.33875","-7.43284"
"1.40000","-0.35109","-7.74000"
"1.45000","-0.36375","-8.02840"
"1.50000","-0.37625","-8.29288"
"1.55000","-0.38859","-8.60185"
"1.60000","-0.40109","-8.84861"
"1.65000","-0.41375","-9.12364"
"1.70000","-0.42609","-9.39488"
"1.75000","-0.43875","-9.64365"
"1.80000","-0.45156","-9.97482"
"1.85000","-0.46391","-10.21910"
"1.90000","-0.47656","-10.49505"
"1.95000","-0.48891","-10.78636"
"2.00000","-0.50141","-11.05940"
"2.05000","-0.51422","-11.37902"
"2.10000","-0.52656","-11.64525"
"2.15000","-0.53906","-11.89877"
"2.20000","-0.55172","-12.19382"
"2.25000","-0.56406","-12.44826"
"2.30000","-0.57656","-12.73312"
"2.35000","-0.58922","-13.03746"
"2.40000","-0.60172","-13.33477"
"2.45000","-0.61437","-13.59519"
"2.50000","-0.62703","-13.89493"
"2.55000","-0.63922","-14.19413"
"2.60000","-0.65187","-14.45127"
"2.65000","-0.66438","-14.73514"
"2.70000","-0.67703","-15.04348"
"2.75000","-0.68969","-15.32319"
"2.80000","-0.70188","-15.60187"
"2.85000","-0.71453","-15.91402"
"2.90000","-0.72719","-16.20614"
"2.95000","-0.73953","-16.47250"
"3.00000","-0.75234","-16.75934"
"3.05000","-0.76484","-17.04977"
"3.10000","-0.77734","-17.32982"
"3.15000","-0.79000","-17.61513"
"3.20000","-0.80234","-17.94718"
"3.25000","-0.81484","-18.20277"
"3.30000","-0.82766","-18.47695"
"3.35000","-0.84000","-18.79324"
"3.40000","-0.85250","-19.04196"
"3.45000","-0.86531","-19.33702"
"3.50000","-0.87750","-19.63775"
"3.55000","-0.89016","-19.91954"
"3.60000","-0.90266","-20.16517"
"3.65000","-0.91516","-20.47241"
"3.70000","-0.92797","-20.72640"
"3.75000","-0.94016","-21.05850"
"3.80000","-0.95266","-21.31816"
"3.85000","-0.96547","-21.62343"
"3.90000","-0.97781","-21.88440"
"3.95000","-0.99047","-22.18554"
"4.00000","-1.00312","-22.49425"
"4.05000","-1.01531","-22.77588"
"4.10000","-1.02781","-23.03197"
"4.15000","-1.04047","-23.31381"
"4.20000","-1.05281","-23.59733"
"4.25000","-1.06562","-23.89470"
"4.30000","-1.07828","-24.18173"
"4.35000","-1.09063","-24.42965"
"4.40000","-1.10344","-24.74442"
"4.45000","-1.11563","-25.04910"
"4.50000","-1.12813","-25.32702"
"4.55000","-1.14094","-25.64626"
"4.60000","-1.15328","-25.89760"
"4.65000","-1.16594","-26.18524"
"4.70000","-1.17844","-26.49950"
"4.75000","-1.19078","-26.74612"
"4.80000","-1.20344","-27.06177"
"4.85000","-1.21609","-27.33570"
"4.90000","-1.22844","-27.64221"
"4.95000","-1.24125","-27.93612"
"5.00000","-1.25359","-28.22129"
"5.05000","-1.26594","-28.52027"
"5.10000","-1.27875","-28.80199"
"5.15000","-1.29109","-29.09740"
"5.20000","-1.30375","-29.37766"
"5.25000","-1.31656","-29.66160"
"5.30000","-1.32859","-29.98166"
"5.35000","-1.34141","-30.22345"
"5.40000","-1.35391","-30.51398"
"5.45000","-1.36625","-30.82419"
"5.50000","-1.37906","-31.07992"
"5.55000","-1.39156","-31.41420"
"5.60000","-1.40406","-31.67668"
"5.65000","-1.41672","-31.98901"
"5.70000","-1.42922","-32.27218"
"5.75000","-1.44156","-32.55734"
"5.80000","-1.45437","-32.87385"
"5.85000","-1.46672","-33.16113"
"5.90000","-1.47922","-33.42987"
"5.95000","-1.49188","-33.74083"
"6.00000","-1.50406","-34.02959"
"6.05000","-1.51687","-34.29121"
"6.10000","-1.52937","-34.60051"
"6.15000","-1.54188","-34.90501"
"6.20000","-1.55469","-35.17095"
"6.25000","-1.56688","-35.50442"
"6.30000","-1.57953","-35.77921"
"6.35000","-1.59219","-36.06359"
"6.40000","-1.60437","-36.35749"
"6.45000","-1.61719","-36.63169"
"6.50000","-1.62969","-36.95200"
"6.55000","-1.64203","-37.24306"
"6.60000","-1.65453","-37.49297"
"6.65000","-1.66734","-37.79026"
"6.70000","-1.67953","-38.10575"
"6.75000","-1.69250","-38.41524"
"6.80000","-1.70484","-38.70076"
"6.85000","-1.71734","-39.00388"
"6.90000","-1.73016","-39.31825"
"6.95000","-1.74234","-39.58189"
"7.00000","-1.75500","-39.86905"
"7.05000","-1.76766","-40.17046"
"7.10000","-1.78000","-40.47836"
"7.15000","-1.79266","-40.78240"
"7.20000","-1.80516","-41.02227"
"7.25000","-1.81766","-41.32119"
"7.30000","-1.83016","-41.59950"
"7.35000","-1.84281","-41.91900"
"7.40000","-1.85531","-42.21629"
"7.45000","-1.86813","-42.50886"
"7.50000","-1.88031","-42.82751"
"7.55000","-1.89266","-43.11167"
"7.60000","-1.90562","-43.40871"
"7.65000","-1.91781","-43.68698"
"7.70000","-1.93047","-43.94540"
"7.75000","-1.94328","-44.27093"
"7.80000","-1.95531","-44.54534"
"7.85000","-1.96813","-44.85247"
"7.90000","-1.98047","-45.12977"
"7.95000","-1.99313","-45.43742"
"8.00000","-2.00594","-45.71831"
"8.05000","-2.01828","-46.01443"
"8.10000","-2.03078","-46.28628"
"8.15000","-2.04359","-46.60488"
"8.20000","-2.05578","-46.91242"
"8.25000","-2.06844","-47.18331"
"8.30000","-2.08109","-47.45769"
"8.35000","-2.09328","-47.77221"
"8.40000","-2.10609","-48.08176"
"8.45000","-2.11875","-48.33738"
"8.50000","-2.13078","-48.59933"
"8.55000","-2.14375","-48.91303"
"8.60000","-2.15609","-49.19368"
"8.65000","-2.16875","-49.49221"
"8.70000","-2.18156","-49.74910"
"8.75000","-2.19375","-50.06989"
"8.80000","-2.20625","-50.35153"
"8.85000","-2.21891","-50.61435"
"8.90000","-2.23109","-50.91072"
"8.95000","-2.24391","-51.23739"
"9.00000","-2.25656","-51.52682"
"9.05000","-2.26891","-51.80395"
"9.10000","-2.28156","-52.06965"
"9.15000","-2.29406","-52.36626"
"9.20000","-2.30641","-52.62901"
"9.25000","-2.31938","-52.89367"
"9.30000","-2.33156","-53.19677"
"9.35000","-2.34422","-53.50660"
"9.40000","-2.35703","-53.76319"
"9.45000","-2.36891","-54.05303"
"9.50000","-2.38172","-54.33689"
"9.55000","-2.39438","-54.66069"
"9.60000","-2.40656","-54.86173"
"9.65000","-2.41938","-55.17896"
"9.70000","-2.43188","-55.47469"
"9.75000","-2.44422","-55.75668"
"9.80000","-2.45703","-56.00742"
"9.85000","-2.46953","-56.33996"
"9.90000","-2.48188","-56.60674"
"9.95000","-2.49484","-56.87529"
"10.00000","-2.50719","-57.20121"
"10.05000","-2.51953","-57.49255"
"10.10000","-2.53250","-57.75027"
"10.15000","-2.54469","-58.04352"
"10.20000","-2.55734","-58.28489"
"10.25000","-2.57000","-58.59513"
"10.30000","-2.58203","-58.84518"
"10.35000","-2.59500","-59.10447"
"10.40000","-2.60719","-59.42472"
"10.45000","-2.61984","-59.63153"
"10.50000","-2.63266","-59.95155"
"10.55000","-2.64500","-60.26005"
"10.60000","-2.65766","-60.51139"
"10.65000","-2.67031","-60.75112"
"10.70000","-2.68234","-61.04991"
"10.75000","-2.69516","-61.32753"
"10.80000","-2.70781","-61.60188"
"10.85000","-2.72000","-61.85857"
"10.90000","-2.73281","-62.15449"
"10.95000","-2.74531","-62.41340"
"11.00000","-2.75750","-62.69686"
"11.05000","-2.77047","-62.98882"
"11.10000","-2.78281","-63.23132"
"11.15000","-2.79547","-63.49624"
"11.20000","-2.80828","-63.78112"
"11.25000","-2.82047","-64.06282"
"11.30000","-2.83312","-64.33633"
"11.35000","-2.84563","-64.60186"
"11.40000","-2.85813","-64.85471"
"11.45000","-2.87078","-65.15314"
"11.50000","-2.88313","-65.43008"
"11.55000","-2.89547","-65.65654"
"11.60000","-2.90828","-65.89768"
"11.65000","-2.92063","-66.18960"
"11.70000","-2.93313","-66.42270"
"11.75000","-2.94625","-66.72060"
"11.80000","-2.95844","-67.00466"
"11.85000","-2.97094","-67.28011"
"11.90000","-2.98375","-67.52636"
"11.95000","-2.99578","-67.80853"
"12.00000","-3.00859","-68.04041"
"12.05000","-3.02125","-68.35284"
"12.10000","-3.03359","-68.60877"
"12.15000","-3.04625","-68.88952"
"12.20000","-3.05859","-69.11484"
"12.25000","-3.07109","-69.37309"
"12.30000","-3.08391","-69.64942"
"12.35000","-3.09641","-69.91707"
"12.40000","-3.10891","-70.17769"
"12.45000","-3.12172","-70.46774"
"12.50000","-3.13391","-70.70566"
"12.55000","-3.14641","-70.98597"
"12.60000","-3.15906","-71.22362"
"12.65000","-3.17125","-71.48583"
"12.70000","-3.18422","-71.70637"
"12.75000","-3.19656","-72.00254"
"12.80000","-3.20891","-72.27067"
"12.85000","-3.22172","-72.53796"
"12.90000","-3.23391","-72.79848"
"12.95000","-3.24672","-73.06127"
"13.00000","-3.25953","-73.35545"
"13.05000","-3.27172","-73.61509"
"13.10000","-3.28453","-73.84056"
"13.15000","-3.29703","-74.10978"
"13.20000","-3.30906","-74.37408"
"13.25000","-3.32188","-74.60295"
"13.30000","-3.33453","-74.91495"
"13.35000","-3.34672","-75.13615"
"13.40000","-3.35969","-75.41908"
"13.45000","-3.37203","-75.70877"
"13.50000","-3.38438","-75.92588"
"13.55000","-3.39734","-76.23664"
"13.60000","-3.40953","-76.51378"
"13.65000","-3.42219","-76.76320"
"13.70000","-3.43500","-77.01929"
"13.75000","-3.44719","-77.29373"
"13.80000","-3.46000","-77.55655"
"13.85000","-3.47234","-77.84421"
"13.90000","-3.48484","-78.08846"
"13.95000","-3.49750","-78.35360"
"14.00000","-3.50984","-78.63937"
"14.05000","-3.52219","-78.91568"
"14.10000","-3.53500","-79.13651"
"14.15000","-3.54734","-79.40756"
"14.20000","-3.55984","-79.65395"
"14.25000","-3.57297","-79.92952"
"14.30000","-3.58516","-80.19374"
"14.35000","-3.59781","-80.49170"
"14.40000","-3.61031","-80.72763"
"14.45000","-3.62234","-81.00897"
"14.50000","-3.63547","-81.26152"
"14.55000","-3.64781","-81.54071"
"14.60000","-3.66031","-81.78287"
"14.65000","-3.67281","-82.06425"
"14.70000","-3.68516","-82.29542"
"14.75000","-3.69781","-82.59014"
"14.80000","-3.71062","-82.87758"
"14.85000","-3.72297","-83.13430"
"14.90000","-3.73562","-83.40085"
"14.95000","-3.74859","-83.64157"
"15.00000","-3.76062","-83.91004"
"15.05000","-3.77328","-84.22526"
"15.10000","-3.78578","-84.45145"
"15.15000","-3.79813","-84.73094"
"15.20000","-3.81109","-84.98848"
"15.25000","-3.82328","-85.25060"
"15.30000","-3.83563","-85.47477"
"15.35000","-3.84844","-85.76623"
"15.40000","-3.86062","-86.02059"
"15.45000","-3.87344","-86.27576"
"15.50000","-3.88625","-86.55075"
"15.55000","-3.89859","-86.80569"
"15.60000","-3.91125","-87.07904"
"15.65000","-3.92375","-87.31052"
"15.70000","-3.93609","-87.54516"
"15.75000","-3.94875","-87.81835"
"15.80000","-3.96125","-88.10327"
"15.85000","-3.97359","-88.33965"
"15.90000","-3.98656","-88.58815"
"15.95000","-3.99859","-88.86775"
"16.00000","-4.01109","-89.06208"
"16.05000","-4.02406","-89.35641"
"16.10000","-4.03625","-89.58506"
"16.15000","-4.04906","-89.83875"
"16.20000","-4.06172","-90.09273"
"16.25000","-4.07391","-90.33457"
"16.30000","-4.08672","-90.57092"
"16.35000","-4.09906","-90.84356"
"16.40000","-4.11156","-91.05287"
"16.45000","-4.12422","-91.31109"
"16.50000","-4.13672","-91.55590"
"16.55000","-4.14906","-91.83314"
"16.60000","-4.16188","-92.06273"
"16.65000","-4.17406","-92.31390"
"16.70000","-4.18672","-92.53314"
"16.75000","-4.19969","-92.78796"
"16.80000","-4.21188","-93.06265"
"16.85000","-4.22453","-93.28421"
"16.90000","-4.23703","-93.55867"
"16.95000","-4.24938","-93.76686"
"17.00000","-4.26219","-94.05770"
"17.05000","-4.27438","-94.30596"
"17.10000","-4.28703","-94.53828"
"17.15000","-4.29969","-94.80436"
"17.20000","-4.31203","-95.04573"
"17.25000","-4.32453","-95.26322"
"17.30000","-4.33734","-95.53626"
"17.35000","-4.34969","-95.78746"
"17.40000","-4.36219","-96.01429"
"17.45000","-4.37500","-96.27200"
"17.50000","-4.38719","-96.52886"
"17.55000","-4.40000","-96.76838"
"17.60000","-4.41234","-97.01109"
"17.65000","-4.42484","-97.22563"
"17.70000","-4.43766","-97.46642"
"17.75000","-4.45000","-97.71510"
"17.80000","-4.46250","-97.92795"
"17.85000","-4.47516","-98.19369"
"17.90000","-4.48734","-98.39780"
"17.95000","-4.50031","-98.65024"
"18.00000","-4.51297","-98.86375"
"18.05000","-4.52531","-99.10415"
"18.10000","-4.53797","-99.34890"
"18.15000","-4.55031","-99.54690"
"18.20000","-4.56281","-99.76853"
"18.25000","-4.57547","-100.06690"
"18.30000","-4.58797","-100.28659"
"18.35000","-4.60031","-100.50229"
"18.40000","-4.61313","-100.76982"
"18.45000","-4.62547","-100.97068"
"18.50000","-4.63797","-101.20902"
"18.55000","-4.65078","-101.47289"
"18.60000","-4.66313","-101.69305"
"18.65000","-4.67594","-101.91428"
"18.70000","-4.68844","-102.10707"
"18.75000","-4.70063","-102.38965"
"18.80000","-4.71328","-102.61677"
"18.85000","-4.72578","-102.82839"
"18.90000","-4.73828","-103.08284"
"18.95000","-4.75094","-103.33481"
"19.00000","-4.76344","-103.57697"
"19.05000","-4.77578","-103.79359"
"19.10000","-4.78859","-104.00996"
"19.15000","-4.80094","-104.24848"
"19.20000","-4.81359","-104.47954"
"19.25000","-4.82625","-104.71048"
"19.30000","-4.83859","-104.90875"
"19.35000","-4.85141","-105.14921"
"19.40000","-4.86375","-105.35849"
"19.45000","-4.87609","-105.59251"
"19.50000","-4.88891","-105.83228"
"19.55000","-4.90125","-106.05072"
"19.60000","-4.91391","-106.24603"
"19.65000","-4.92641","-106.50391"
"19.70000","-4.93875","-106.67283"
"19.75000","-4.95141","-106.94188"
"19.80000","-4.96406","-107.17576"
"19.85000","-4.97641","-107.38922"
"19.90000","-4.98906","-107.62061"
"19.95000","-5.00188","-107.87139"
"20.00000","-5.01406","-108.07676"
"20.05000","-5.02672","-108.29337"
"20.10000","-5.03922","-108.47651"
"20.15000","-5.05172","-108.70687"
"20.20000","-5.06438","-108.95361"
"20.25000","-5.07656","-109.13945"
"20.30000","-5.08938","-109.37648"
"20.35000","-5.10187","-109.62675"
"20.40000","-5.11422","-109.79805"
"20.45000","-5.12703","-110.03974"
"20.50000","-5.13969","-110.25657"
"20.55000","-5.15203","-110.50644"
"20.60000","-5.16469","-110.66784"
"20.65000","-5.17719","-110.88677"
"20.70000","-5.18953","-111.06548"
"20.75000","-5.20234","-111.30652"
"20.80000","-5.21469","-111.54220"
"20.85000","-5.22703","-111.71592"
"20.90000","-5.24000","-111.94176"
"20.95000","-5.25219","-112.16425"
"21.00000","-5.26484","-112.35719"
"21.05000","-5.27750","-112.57694"
"21.10000","-5.28984","-112.77006"
"21.15000","-5.30266","-112.97027"
"21.20000","-5.31516","-113.15724"
"21.25000","-5.32766","-113.40297"
"21.30000","-5.34016","-113.59367"
"21.35000","-5.35250","-113.80798"
"21.40000","-5.36531","-114.02927"
"21.45000","-5.37781","-114.23360"
"21.50000","-5.39016","-114.37380"
"21.55000","-5.40266","-114.62972"
"21.60000","-5.41531","-114.82432"
"21.65000","-5.42766","-115.01003"
"21.70000","-5.44047","-115.19917"
"21.75000","-5.45297","-115.42688"
"21.80000","-5.46531","-115.60018"
"21.85000","-5.47813","-115.83856"
"21.90000","-5.49047","-116.03856"
"21.95000","-5.50297","-116.19896"
"22.00000","-5.51578","-116.42043"
"22.05000","-5.52797","-116.61189"
"22.10000","-5.54063","-116.80270"
"22.15000","-5.55312","-117.03120"
"22.20000","-5.56547","-117.17293"
"22.25000","-5.57812","-117.42107"
"22.30000","-5.59078","-117.61853"
"22.35000","-5.60328","-117.81424"
"22.40000","-5.61594","-117.98654"
"22.45000","-5.62844","-118.18457"
"22.50000","-5.64078","-118.37459"
"22.55000","-5.65359","-118.58432"
"22.60000","-5.66578","-118.77368"
"22.65000","-5.67844","-118.97786"
"22.70000","-5.69125","-119.17994"
"22.75000","-5.70328","-119.36652"
"22.80000","-5.71609","-119.61029"
"22.85000","-5.72859","-119.80362"
"22.90000","-5.74109","-119.97393"
"22.95000","-5.75391","-120.20260"
"23.00000","-5.76625","-120.39609"
"23.05000","-5.77891","-120.60312"
"23.10000","-5.79156","-120.81589"
"23.15000","-5.80391","-121.00546"
"23.20000","-5.81703","-38.14097"
"23.25000","-5.82953","7.91847"
"23.30000","-5.84172","3.14049"
"23.35000","-5.85406","3.35762"
"23.40000","-5.86672","3.35820"
"23.45000","-5.87891","3.36237"
"23.50000","-5.89156","3.35534"
"23.55000","-5.90422","3.34196"
"23.60000","-5.91656","3.36514"
"23.65000","-5.92953","3.35721"
"23.70000","-5.94172","3.35530"
"23.75000","-5.95422","3.35403"
"23.80000","-5.96688","3.35649"
"23.85000","-5.97937","3.36197"
"23.90000","-5.99188","3.33889"
"23.95000","-6.00453","3.33846"
"24.00000","-6.01688","3.33744"
"24.05000","-6.02937","3.33961"
"24.10000","-6.04203","3.35748"
"24.15000","-6.05437","3.36916"
"24.20000","-6.06719","3.38200"
"24.25000","-6.07984","3.35866"
"24.30000","-6.09219","3.36394"
"24.35000","-6.10500","3.35324"
"24.40000","-6.11703","3.35935"
"24.45000","-6.12969","3.36376"
"24.50000","-6.14234","3.39682"
"24.55000","-6.15469","3.34525"
"24.60000","-6.16750","3.36093"
"24.65000","-6.18000","3.36090"
"24.70000","-6.19234","3.36486"
"24.75000","-6.20484","3.35880"
"24.80000","-6.21750","3.33543"
"24.85000","-6.23000","3.36581"
"24.90000","-6.24266","3.36123"
"24.95000","-6.25516","3.34763"
"25.00000","-6.26750","3.31689"
"25.05000","-6.28031","3.35834"
"25.10000","-6.29250","3.33266"
"25.15000","-6.30516","3.35250"
"25.20000","-6.31797","3.36971"
"25.25000","-6.33016","3.38527"
"25.30000","-6.34281","3.38502"
"25.35000","-6.35531","3.37386"
"25.40000","-6.36781","3.38296"
"25.45000","-6.38063","3.40182"
"25.50000","-6.39297","3.37136"
"25.55000","-6.40563","3.36737"
"25.60000","-6.41828","3.37532"
"25.65000","-6.43062","3.36470"
"25.70000","-6.44313","3.37127"
"25.75000","-6.45594","3.38240"
"25.80000","-6.46828","3.35072"
"25.85000","-6.48078","3.39849"
"25.90000","-6.49328","3.40897"
"25.95000","-6.50547","3.36296"
"26.00000","-6.51844","3.36303"
"26.05000","-6.53094","3.37232"
"26.10000","-6.54344","3.37359"
"26.15000","-6.55641","3.35740"
"26.20000","-6.56844","3.38427"
"26.25000","-6.58094","3.39706"
"26.30000","-6.59375","3.39262"
"26.35000","-6.60609","3.35778"
"26.40000","-6.61875","3.36753"
"26.45000","-6.63125","3.35028"
"26.50000","-6.64359","3.37209"
"26.55000","-6.65625","3.37320"
"26.60000","-6.66875","3.39436"
"26.65000","-6.68109","3.39599"
"26.70000","-6.69406","3.37949"
"26.75000","-6.70641","3.37657"
"26.80000","-6.71891","3.41029"
"26.85000","-6.73172","3.39037"
"26.90000","-6.74359","3.37986"
"26.95000","-6.75656","3.38877"
"27.00000","-6.76922","3.38593"
"27.05000","-6.78141","3.33756"
"27.10000","-6.79422","3.38124"
"27.15000","-6.80672","3.36572"
"27.20000","-6.81906","3.38644"
"27.25000","-6.83172","3.39544"
"27.30000","-6.84422","3.39519"
"27.35000","-6.85672","3.38924"
"27.40000","-6.86953","3.39615"
"27.45000","-6.88187","3.39592"
"27.50000","-6.89422","3.37751"
"27.55000","-6.90703","3.35114"
"27.60000","-6.91922","3.34154"
"27.65000","-6.93203","3.36252"
"27.70000","-6.94469","3.38587"
"27.75000","-6.95687","3.38333"
"27.80000","-6.96969","3.39286"
"27.85000","-6.98203","3.40023"
"27.90000","-6.99469","3.39504"
"27.95000","-7.00750","3.38643"
"28.00000","-7.01984","3.38986"
"28.05000","-7.03250","3.37158"
"28.10000","-7.04516","3.38732"
"28.15000","-7.05734","3.37867"
"28.20000","-7.06984","3.37230"
"28.25000","-7.08266","3.37380"
"28.30000","-7.09484","3.38501"
"28.35000","-7.10750","3.41387"
"28.40000","-7.12016","3.37145"
"28.45000","-7.13219","3.34714"
"28.50000","-7.14531","3.34145"
"28.55000","-7.15766","3.32513"
"28.60000","-7.17016","3.34171"
"28.65000","-7.18313","3.34132"
"28.70000","-7.19516","3.32664"
"28.75000","-7.20781","3.34369"
"28.80000","-7.22047","3.35904"
"28.85000","-7.23281","3.33281"
"28.90000","-7.24547","3.33351"
"28.95000","-7.25797","3.34721"
"29.00000","-7.27031","3.35934"
"29.05000","-7.28297","3.34128"
"29.10000","-7.29547","3.34880"
"29.15000","-7.30781","3.38037"
"29.20000","-7.32094","3.35128"
"29.25000","-7.33312","3.33622"
"29.30000","-7.34578","3.35691"
"29.35000","-7.35844","3.35219"
"29.40000","-7.37047","3.37567"
"29.45000","-7.38328","3.35564"
"29.50000","-7.39594","3.31562"
"29.55000","-7.40828","3.31167"
"29.59800","-7.42047","3.36101"