File: Lab 4 Data/G1NE_DRY.csv
Text Inputs : Specimen label,"G1NE_DRY"
Test : Rate 1,"1.30000",mm/min
Dimension : Support span,"50.00000",mm
Dimension : Thickness,"2.90200",mm
Dimension : Width,"13.30000",mm

Time,Extension,Load
(sec),(mm),(N)
"0.00000","0.00000","0.00790"
"0.45000","-0.00938","-0.30856"
"0.90000","-0.01938","-0.57796"
"1.35000","-0.02906","-0.86706"
"1.80000","-0.03906","-1.08641"
"2.25000","-0.04875","-1.36853"
"2.70000","-0.05828","-1.60312"
"3.15000","-0.06828","-1.86268"
"3.60000","-0.07797","-2.13527"
"4.05000","-0.08750","-2.35665"
"4.50000","-0.09750","-2.62894"
"4.95000","-0.10734","-2.91225"
"5.40000","-0.11703","-3.16526"
"5.85000","-0.12656","-3.36551"
"6.30000","-0.13656","-3.63955"
"6.75000","-0.14625","-3.90192"
"7.20000","-0.15578","-4.12764"
"7.65000","-0.16563","-4.39984"
"8.10000","-0.17547","-4.66892"
"8.55000","-0.18531","-4.89717"
"9.00000","-0.19484","-5.20076"
"9.45000","-0.20469","-5.43852"
"9.90000","-0.21453","-5.69166"
"10.35000","-0.22422","-5.93975"
"10.80000","-0.23391","-6.14335"
"11.25000","-0.24391","-6.41895"
"11.70000","-0.25359","-6.69719"
"12.15000","-0.26312","-6.92224"
"12.60000","-0.27313","-7.19195"
"13.05000","-0.28281","-7.45359"
"13.50000","-0.29234","-7.71132"
"13.95000","-0.30219","-7.95886"
"14.40000","-0.31203","-8.08557"
"14.85000","-0.32172","-8.38075"
"15.30000","-0.33141","-8.69541"
"15.75000","-0.34125","-8.98135"
"16.20000","-0.35094","-9.14989"
"16.65000","-0.36078","-9.49135"
"17.10000","-0.37031","-9.76934"
"17.55000","-0.38000","-10.00280"
"18.00000","-0.39000","-10.24419"
"18.45000","-0.39969","-10.49614"
"18.90000","-0.40922","-10.76499"
"19.35000","-0.41937","-10.98936"
"19.80000","-0.42906","-11.26483"
"20.25000","-0.43844","-11.46264"
"20.70000","-0.44859","-11.77036"
"21.15000","-0.45828","-12.04984"
"21.60000","-0.46781","-12.30729"
"22.05000","-0.47766","-12.55456"
"22.50000","-0.48766","-12.79421"
"22.95000","-0.49734","-13.09514"
"23.40000","-0.50687","-13.31651"
"23.85000","-0.51672","-13.55182"
"24.30000","-0.52656","-13.83440"
"24.75000","-0.53609","-14.09326"
"25.20000","-0.54594","-14.32511"
"25.65000","-0.55563","-14.66711"
"26.10000","-0.56547","-14.96516"
"26.55000","-0.57516","-15.21109"
"27.00000","-0.58500","-15.45697"
"27.45000","-0.59484","-15.71044"
"27.90000","-0.60453","-15.98072"
"28.35000","-0.61406","-16.24560"
"28.80000","-0.62391","-16.55788"
"29.25000","-0.63391","-16.76519"
"29.70000","-0.64328","-17.09347"
"30.15000","-0.65312","-17.38941"
"30.60000","-0.66313","-17.64382"
"31.05000","-0.67281","-17.89250"
"31.50000","-0.68234","-18.13409"
"31.95000","-0.69234","-18.48325"
"32.40000","-0.70203","-18.67605"
"32.85000","-0.71156","-18.94494"
"33.30000","-0.72141","-19.25759"
"33.75000","-0.73141","-19.45623"
"34.20000","-0.74109","-19.78948"
"34.65000","-0.75062","-20.06177"
"35.10000","-0.76047","-20.34132"
"35.55000","-0.77031","-20.61549"
"36.00000","-0.77984","-20.88940"
"36.45000","-0.78969","-21.15092"
"36.90000","-0.79953","-21.42019"
"37.35000","-0.80938","-21.69967"
"37.80000","-0.81891","-21.97269"
"38.25000","-0.82859","-22.20483"
"38.70000","-0.83859","-22.50948"
"39.15000","-0.84813","-22.80963"
"39.60000","-0.85797","-23.08726"
"40.05000","-0.86781","-23.34746"
"40.50000","-0.87750","-23.59422"
"40.95000","-0.88703","-23.85024"
"41.40000","-0.89703","-24.16231"
"41.85000","-0.90688","-24.40155"
"42.30000","-0.91641","-24.73213"
"42.75000","-0.92625","-24.95985"
"43.20000","-0.93609","-25.26678"
"43.65000","-0.94578","-25.50786"
"44.10000","-0.95531","-25.78959"
"44.55000","-0.96516","-26.02165"
"45.00000","-0.97500","-26.32928"
"45.45000","-0.98484","-26.59303"
"45.90000","-0.99437","-26.84877"
"46.35000","-1.00406","-27.16814"
"46.80000","-1.01406","-27.45775"
"47.25000","-1.02359","-27.65964"
"47.70000","-1.03328","-27.98731"
"48.15000","-1.04328","-28.14856"
"48.60000","-1.05313","-28.49313"
"49.05000","-1.06266","-28.76895"
"49.50000","-1.07250","-29.01901"
"49.95000","-1.08234","-29.22724"
"50.40000","-1.09188","-29.53192"
"50.85000","-1.10156","-29.80051"
"51.30000","-1.11156","-30.14178"
"51.75000","-1.12141","-30.44311"
"52.20000","-1.13078","-30.70136"
"52.65000","-1.14078","-30.95212"
"53.10000","-1.15063","-31.23967"
"53.55000","-1.16016","-31.46801"
"54.00000","-1.16984","-31.75984"
"54.45000","-1.17969","-32.05139"
"54.90000","-1.18953","-32.34104"
"55.35000","-1.19906","-32.58737"
"55.80000","-1.20891","-32.88320"
"56.25000","-1.21875","-33.13911"
"56.70000","-1.22859","-33.42519"
"57.15000","-1.23813","-33.70695"
"57.60000","-1.24781","-33.98725"
"58.05000","-1.25781","-34.24573"
"58.50000","-1.26734","-34.48391"
"58.95000","-1.27719","-34.80110"
"59.40000","-1.28703","-35.05115"
"59.85000","-1.29688","-35.36533"
"60.30000","-1.30625","-35.63884"
"60.75000","-1.31625","-35.91413"
"61.20000","-1.32594","-36.13730"
"61.65000","-1.33563","-36.42810"
"62.10000","-1.34547","-36.71822"
"62.55000","-1.35531","-36.97462"
"63.00000","-1.36516","-37.24691"
"63.45000","-1.37453","-37.50411"
"63.90000","-1.38453","-37.83856"
"64.35001","-1.39437","-38.10686"
"64.80000","-1.40391","-38.40056"
"65.25000","-1.41359","-38.61061"
"65.70001","-1.42359","-38.87702"
"66.15000","-1.43328","-39.16598"
"66.60001","-1.44281","-39.42679"
"67.05000","-1.45266","-39.74624"
"67.50000","-1.46266","-40.01398"
"67.95001","-1.47219","-40.28622"
"68.40000","-1.48188","-40.58111"
"68.85001","-1.49188","-40.87135"
"69.30000","-1.50156","-41.10012"
"69.75000","-1.51094","-41.33143"
"70.20001","-1.52109","-41.59953"
"70.65000","-1.53078","-41.91193"
"71.10001","-1.54031","-42.17704"
"71.55000","-1.55016","-42.50788"
"72.00000","-1.56000","-42.72509"
"72.45001","-1.56969","-42.96418"
"72.90000","-1.57938","-43.29624"
"73.35001","-1.58922","-43.56707"
"73.80000","-1.59906","-43.83238"
"74.25000","-1.60891","-44.12434"
"74.70001","-1.61828","-44.37986"
"75.15000","-1.62828","-44.63430"
"75.60001","-1.63797","-44.93352"
"76.05000","-1.64766","-45.19706"
"76.50000","-1.65734","-45.47739"
"76.95001","-1.66734","-45.74421"
"77.40000","-1.67703","-46.06050"
"77.85001","-1.68656","-46.31945"
"78.30000","-1.69641","-46.54867"
"78.75000","-1.70641","-46.84269"
"79.20001","-1.71594","-47.11641"
"79.65000","-1.72563","-47.39278"
"80.10001","-1.73562","-47.67360"
"80.55000","-1.74531","-47.89642"
"81.00001","-1.75469","-48.22900"
"81.45001","-1.76469","-48.50172"
"81.90000","-1.77453","-48.77866"
"82.35001","-1.78406","-49.03288"
"82.80000","-1.79391","-49.32195"
"83.25001","-1.80375","-49.55759"
"83.70001","-1.81344","-49.81084"
"84.15000","-1.82313","-50.16249"
"84.60001","-1.83297","-50.46623"
"85.05000","-1.84281","-50.71626"
"85.50001","-1.85250","-51.03196"
"85.95001","-1.86203","-51.23648"
"86.40000","-1.87188","-51.54245"
"86.85001","-1.88187","-51.80468"
"87.30000","-1.89125","-52.03075"
"87.75001","-1.90125","-52.36927"
"88.20001","-1.91109","-52.62297"
"88.65000","-1.92078","-52.89765"
"89.10001","-1.93031","-53.15826"
"89.55000","-1.94031","-53.42850"
"90.00001","-1.95000","-53.74599"
"90.45001","-1.95953","-53.98579"
"90.90000","-1.96938","-54.27061"
"91.35001","-1.97922","-54.47948"
"91.80000","-1.98906","-54.78341"
"92.25001","-1.99859","-55.05207"
"92.70001","-2.00844","-55.35718"
"93.15000","-2.01828","-55.62215"
"93.60001","-2.02797","-55.92188"
"94.05000","-2.03766","-56.15726"
"94.50001","-2.04750","-56.44758"
"94.95001","-2.05734","-56.76907"
"95.40000","-2.06672","-56.96804"
"95.85001","-2.07656","-57.23319"
"96.30000","-2.08656","-57.55357"
"96.75001","-2.09625","-57.77668"
"97.20001","-2.10563","-58.08803"
"97.65000","-2.11578","-58.37189"
"98.10001","-2.12563","-58.62544"
"98.55000","-2.13484","-58.88345"
"99.00001","-2.14500","-59.19390"
"99.45001","-2.15484","-59.42813"
"99.90000","-2.16438","-59.70405"
"100.35001","-2.17406","-59.93845"
"100.80000","-2.18406","-60.25977"
"101.25001","-2.19375","-60.49545"
"101.70001","-2.20328","-60.77776"
"102.15000","-2.21313","-61.08867"
"102.60001","-2.22312","-61.37907"
"103.05000","-2.23281","-61.63375"
"103.50001","-2.24234","-61.89116"
"103.95001","-2.25219","-62.19719"
"104.40000","-2.26203","-62.45268"
"104.85001","-2.27156","-62.72150"
"105.30000","-2.28141","-63.02000"
"105.75001","-2.29125","-63.25302"
"106.20001","-2.30109","-63.51023"
"106.65000","-2.31063","-63.79769"
"107.10001","-2.32047","-64.11283"
"107.55000","-2.33031","-64.37358"
"108.00001","-2.34000","-64.65890"
"108.45001","-2.34953","-64.86264"
"108.90000","-2.35953","-65.19338"
"109.35001","-2.36937","-65.46258"
"109.80000","-2.37875","-65.70731"
"110.25001","-2.38859","-66.01700"
"110.70001","-2.39859","-66.26629"
"111.15000","-2.40828","-66.54470"
"111.60001","-2.41781","-66.82846"
"112.05000","-2.42766","-67.09066"
"112.50001","-2.43766","-67.38032"
"112.95001","-2.44719","-67.65095"
"113.40001","-2.45688","-67.87571"
"113.85001","-2.46688","-68.19971"
"114.30000","-2.47656","-68.45175"
"114.75001","-2.48609","-68.75890"
"115.20001","-2.49594","-69.04599"
"115.65001","-2.50578","-69.32390"
"116.10001","-2.51531","-69.58564"
"116.55000","-2.52516","-69.88722"
"117.00001","-2.53516","-70.15048"
"117.45001","-2.54469","-70.39091"
"117.90001","-2.55422","-70.71704"
"118.35001","-2.56438","-70.98757"
"118.80000","-2.57406","-71.29937"
"119.25001","-2.58359","-71.54445"
"119.70001","-2.59344","-71.86414"
"120.15001","-2.60328","-72.13103"
"120.60001","-2.61297","-72.41053"
"121.05000","-2.62266","-72.65471"
"121.50001","-2.63250","-72.98681"
"121.95001","-2.64219","-73.22229"
"122.40001","-2.65203","-73.47681"
"122.85001","-2.66156","-73.76686"
"123.30000","-2.67141","-74.09588"
"123.75001","-2.68141","-74.34739"
"124.20001","-2.69078","-74.63510"
"124.65001","-2.70047","-74.92643"
"125.10001","-2.71063","-75.17739"
"125.55000","-2.72031","-75.43566"
"126.00001","-2.72969","-75.75832"
"126.45001","-2.73969","-76.00404"
"126.90001","-2.74969","-76.29688"
"127.35001","-2.75906","-76.54590"
"127.80000","-2.76891","-76.86653"
"128.25000","-2.77891","-77.13466"
"128.70002","-2.78859","-77.42655"
"129.15001","-2.79813","-77.66994"
"129.60001","-2.80797","-77.96788"
"130.05000","-2.81781","-78.26249"
"130.50000","-2.82734","-78.52565"
"130.95002","-2.83719","-78.77840"
"131.40002","-2.84703","-79.07064"
"131.85000","-2.85672","-79.33783"
"132.30000","-2.86625","-79.58218"
"132.75000","-2.87625","-79.89818"
"133.20002","-2.88594","-80.16663"
"133.65002","-2.89563","-80.40240"
"134.10000","-2.90547","-80.74386"
"134.55000","-2.91516","-81.01027"
"135.00000","-2.92516","-81.27766"
"135.45002","-2.93453","-81.51301"
"135.90002","-2.94438","-81.81726"
"136.35000","-2.95437","-82.11939"
"136.80000","-2.96391","-82.35668"
"137.25000","-2.97359","-82.61081"
"137.70002","-2.98359","-82.89832"
"138.15002","-2.99344","-83.14471"
"138.60000","-3.00281","-83.44522"
"139.05000","-3.01266","-83.72471"
"139.50000","-3.02266","-84.01845"
"139.95002","-3.03234","-84.25977"
"140.40002","-3.04188","-84.52941"
"140.85000","-3.05172","-84.83128"
"141.30000","-3.06156","-85.09851"
"141.75000","-3.07109","-85.34143"
"142.20002","-3.08078","-85.59433"
"142.65002","-3.09094","-85.86485"
"143.10000","-3.10063","-86.17950"
"143.55000","-3.11000","-86.43964"
"144.00000","-3.11984","-86.71259"
"144.45002","-3.12984","-86.96351"
"144.90002","-3.13922","-87.25456"
"145.35000","-3.14906","-87.50104"
"145.80000","-3.15906","-87.82521"
"146.25000","-3.16875","-88.04860"
"146.70002","-3.17828","-88.33158"
"147.15002","-3.18828","-88.61815"
"147.60000","-3.19812","-88.88950"
"148.05000","-3.20750","-89.14599"
"148.50000","-3.21734","-89.46758"
"148.95002","-3.22734","-89.70667"
"149.40002","-3.23703","-89.99701"
"149.85000","-3.24656","-90.20905"
"150.30000","-3.25656","-90.51917"
"150.75000","-3.26625","-90.77506"
"151.20002","-3.27594","-91.07739"
"151.65002","-3.28563","-91.30834"
"152.10000","-3.29547","-91.61930"
"152.55000","-3.30547","-91.86839"
"153.00000","-3.31484","-92.15049"
"153.45002","-3.32469","-92.38217"
"153.90002","-3.33469","-92.68399"
"154.35000","-3.34437","-92.88671"
"154.80000","-3.35391","-93.21510"
"155.25000","-3.36375","-93.49013"
"155.70002","-3.37359","-93.76397"
"156.15002","-3.38312","-94.02025"
"156.60000","-3.39281","-94.31344"
"157.05000","-3.40281","-94.59260"
"157.50000","-3.41250","-94.84825"
"157.95002","-3.42203","-95.13509"
"158.40002","-3.43203","-95.42362"
"158.85000","-3.44188","-95.68873"
"159.30000","-3.45125","-95.94494"
"159.75000","-3.46109","-96.23175"
"160.20002","-3.47109","-96.51959"
"160.65002","-3.48078","-96.76592"
"161.10000","-3.49031","-97.06054"
"161.55000","-3.50016","-97.35559"
"162.00002","-3.51000","-97.65051"
"162.45002","-3.51969","-97.89049"
"162.90002","-3.52937","-98.16841"
"163.35000","-3.53922","-98.43353"
"163.80000","-3.54906","-98.66124"
"164.25002","-3.55859","-98.96869"
"164.70002","-3.56844","-99.23660"
"165.15002","-3.57828","-99.53101"
"165.60000","-3.58797","-99.80162"
"166.05000","-3.59766","-100.06961"
"166.50002","-3.60750","-100.29137"
"166.95002","-3.61734","-100.58394"
"167.40002","-3.62672","-100.85162"
"167.85000","-3.63672","-101.15199"
"168.30000","-3.64656","-101.44300"
"168.75002","-3.65641","-101.71570"
"169.20002","-3.66578","-101.94935"
"169.65002","-3.67562","-102.27791"
"170.10000","-3.68563","-102.52190"
"170.55000","-3.69516","-102.79515"
"171.00002","-3.70484","-103.05434"
"171.45002","-3.71484","-103.31543"
"171.90002","-3.72453","-103.62053"
"172.35000","-3.73406","-103.83625"
"172.80000","-3.74375","-104.08894"
"173.25002","-3.75391","-104.34491"
"173.70002","-3.76344","-104.63998"
"174.15002","-3.77297","-104.87598"
"174.60000","-3.78312","-105.14496"
"175.05000","-3.79281","-105.40766"
"175.50002","-3.80219","-105.63502"
"175.95002","-3.81219","-105.95425"
"176.40002","-3.82203","-106.18496"
"176.85000","-3.83156","-106.43110"
"177.30000","-3.84141","-106.73221"
"177.75002","-3.85125","-107.00943"
"178.20002","-3.86094","-107.24627"
"178.65002","-3.87063","-107.57793"
"179.10000","-3.88047","-107.82549"
"179.55000","-3.89031","-108.04469"
"180.00002","-3.90000","-108.31478"
"180.45002","-3.90953","-108.58486"
"180.90002","-3.91953","-108.88705"
"181.35000","-3.92938","-109.13002"
"181.80000","-3.93891","-109.40221"
"182.25002","-3.94859","-109.65856"
"182.70002","-3.95844","-109.94825"
"183.15002","-3.96844","-110.23604"
"183.60000","-3.97781","-110.46625"
"184.05000","-3.98766","-110.71189"
"184.50002","-3.99766","-111.01465"
"184.95002","-4.00719","-111.26077"
"185.40002","-4.01688","-111.54452"
"185.85000","-4.02687","-111.82927"
"186.30000","-4.03656","-112.07457"
"186.75002","-4.04594","-112.25194"
"187.20002","-4.05594","-112.61333"
"187.65002","-4.06594","-112.82351"
"188.10000","-4.07547","-113.14156"
"188.55000","-4.08516","-113.35385"
"189.00002","-4.09500","-113.68299"
"189.45002","-4.10484","-113.87764"
"189.90002","-4.11437","-114.11622"
"190.35000","-4.12406","-114.35531"
"190.80000","-4.13406","-114.60811"
"191.25002","-4.14375","-114.80781"
"191.70002","-4.15328","-115.01403"
"192.15002","-4.16328","-115.29357"
"192.60000","-4.17313","-115.51636"
"193.05000","-4.18250","-115.75824"
"193.50002","-4.19250","-116.03897"
"193.95002","-4.20234","-116.29045"
"194.40002","-4.21188","-116.49665"
"194.85000","-4.22156","-116.72090"
"195.30000","-4.23156","-117.01286"
"195.75002","-4.24125","-117.21890"
"196.20002","-4.25078","-117.46578"
"196.65002","-4.26063","-117.74965"
"197.10000","-4.27047","-118.00585"
"197.55000","-4.28031","-118.17504"
"198.00002","-4.28984","-118.52749"
"198.45002","-4.29953","-118.73556"
"198.90002","-4.30953","-119.03637"
"199.35000","-4.31922","-119.26349"
"199.80000","-4.32891","-119.52867"
"200.25002","-4.33859","-119.74541"
"200.70002","-4.34859","-120.05841"
"201.15002","-4.35797","-120.28740"
"201.60000","-4.36766","-120.52789"
"202.05000","-4.37781","-120.82678"
"202.50002","-4.38750","-121.06911"
"202.95002","-4.39703","-121.30473"
"203.40002","-4.40703","-121.59693"
"203.85000","-4.41688","-121.84557"
"204.30000","-4.42625","-122.12842"
"204.75002","-4.43625","-122.37797"
"205.20002","-4.44609","-122.64990"
"205.65002","-4.45578","-122.89793"
"206.10000","-4.46531","-123.17811"
"206.55000","-4.47531","-123.39037"
"207.00002","-4.48516","-123.70096"
"207.45002","-4.49453","-123.92385"
"207.90002","-4.50453","-124.16050"
"208.35000","-4.51438","-124.42766"
"208.80000","-4.52406","-124.62919"
"209.25002","-4.53359","-124.80524"
"209.70002","-4.54344","-125.01267"
"210.15002","-4.55328","-125.17129"
"210.60000","-4.56297","-125.36141"
"211.05000","-4.57266","-125.59879"
"211.50002","-4.58234","-125.85675"
"211.95002","-4.59234","-126.08471"
"212.40002","-4.60188","-126.27803"
"212.85000","-4.61156","-126.52039"
"213.30000","-4.62156","-126.76803"
"213.75002","-4.63125","-126.94879"
"214.20002","-4.64078","-127.19376"
"214.65002","-4.65078","-127.44930"
"215.10000","-4.66063","-127.65001"
"215.55000","-4.67000","-127.89100"
"216.00002","-4.67984","-128.15712"
"216.45002","-4.68984","-128.39854"
"216.90002","-4.69953","-128.60880"
"217.35000","-4.70906","-128.89509"
"217.80000","-4.71891","-129.10196"
"218.25002","-4.72891","-129.32184"
"218.70002","-4.73844","-129.62246"
"219.15002","-4.74813","-129.83496"
"219.60000","-4.75797","-130.03776"
"220.05000","-4.76781","-130.34579"
"220.50002","-4.77719","-130.57932"
"220.95002","-4.78719","-130.87522"
"221.40002","-4.79719","-131.13578"
"221.85000","-4.80656","-131.36373"
"222.30000","-4.81641","-131.62819"
"222.75002","-4.82625","-131.83445"
"223.20002","-4.83594","-132.03304"
"223.65002","-4.84563","-132.28710"
"224.10000","-4.85547","-132.51916"
"224.55000","-4.86531","-132.68108"
"225.00002","-4.87484","-132.85235"
"225.45002","-4.88469","-133.05556"
"225.90002","-4.89453","-133.29010"
"226.35000","-4.90422","-133.43425"
"226.80002","-4.91375","-133.66576"
"227.25002","-4.92359","-133.84698"
"227.70002","-4.93344","-134.07505"
"228.15002","-4.94328","-134.27705"
"228.60000","-4.95281","-134.48433"
"229.05002","-4.96266","-134.74889"
"229.50002","-4.97266","-134.95600"
"229.95002","-4.98219","-135.15160"
"230.40002","-4.99188","-135.37369"
"230.85000","-5.00172","-135.60367"
"231.30002","-5.01156","-135.81926"
"231.75002","-5.02109","-136.00019"
"232.20002","-5.03094","-136.28605"
"232.65002","-5.04078","-136.46000"
"233.10000","-5.05047","-136.72651"
"233.55002","-5.06016","-136.94167"
"234.00002","-5.07016","-137.23037"
"234.45002","-5.07984","-137.42049"
"234.90002","-5.08938","-137.64165"
"235.35000","-5.09938","-137.89643"
"235.80002","-5.10906","-138.13474"
"236.25002","-5.11859","-138.33858"
"236.70002","-5.12844","-138.61649"
"237.15002","-5.13828","-138.87136"
"237.60000","-5.14797","-139.10338"
"238.05002","-5.15750","-139.32489"
"238.50002","-5.16750","-139.57111"
"238.95002","-5.17719","-139.79916"
"239.40002","-5.18687","-140.00658"
"239.85000","-5.19656","-140.22067"
"240.30002","-5.20641","-140.45487"
"240.75002","-5.21641","-140.61227"
"241.20002","-5.22578","-140.68904"
"241.65002","-5.23562","-140.89864"
"242.10000","-5.24547","-141.10207"
"242.55002","-5.25531","-141.31248"
"243.00002","-5.26484","-141.51522"
"243.45002","-5.27484","-141.66205"
"243.90002","-5.28469","-141.86298"
"244.35000","-5.29406","-142.07720"
"244.80002","-5.30391","-142.30866"
"245.25002","-5.31375","-142.46297"
"245.70002","-5.32359","-142.70183"
"246.15002","-5.33313","-142.93702"
"246.60000","-5.34297","-143.13722"
"247.05002","-5.35281","-143.30853"
"247.50002","-5.36250","-143.52740"
"247.95002","-5.37203","-143.73734"
"248.40002","-5.38203","-143.93291"
"248.85000","-5.39188","-144.17983"
"249.30002","-5.40125","-144.33096"
"249.75002","-5.41109","-144.57150"
"250.20002","-5.42109","-144.87640"
"250.65002","-5.43078","-145.08720"
"251.10000","-5.44031","-145.34005"
"251.55002","-5.45031","-145.53515"
"252.00002","-5.46000","-145.78615"
"252.45002","-5.46938","-145.97046"
"252.90002","-5.47953","-146.25508"
"253.35000","-5.48937","-146.45736"
"253.80002","-5.49891","-146.68500"
"254.25002","-5.50859","-146.88871"
"254.70002","-5.51859","-147.04430"
"255.15002","-5.52812","-147.10306"
"255.60000","-5.53781","-147.31258"
"256.05002","-5.54766","-147.47227"
"256.50000","-5.55734","-147.64451"
"256.95002","-5.56734","-147.84180"
"257.40003","-5.57688","-148.04730"
"257.85000","-5.58672","-148.20934"
"258.30002","-5.59656","-148.44120"
"258.75000","-5.60609","-148.60251"
"259.20002","-5.61578","-148.81562"
"259.65003","-5.62578","-148.97127"
"260.10000","-5.63563","-149.13786"
"260.55002","-5.64516","-149.31438"
"261.00000","-5.65500","-149.51595"
"261.45002","-5.66484","-149.65576"
"261.90003","-5.67438","-149.86230"
"262.35000","-5.68406","-150.08895"
"262.80003","-5.69406","-150.26412"
"263.25000","-5.70375","-150.46841"
"263.70000","-5.71328","-150.61414"
"264.15003","-5.72328","-150.84673"
"264.60000","-5.73312","-151.06337"
"265.05003","-5.74266","-151.25342"
"265.50000","-5.75234","-151.44886"
"265.95000","-5.76234","-151.65005"
"266.40003","-5.77203","-151.84234"
"266.85000","-5.78156","-152.03729"
"267.30003","-5.79141","-152.30753"
"267.75000","-5.80125","-152.50222"
"268.20000","-5.81109","-152.71037"
"268.65003","-5.82062","-152.95662"
"269.10000","-5.83047","-153.18139"
"269.55003","-5.84031","-153.38589"
"270.00000","-5.84984","-153.60765"
"270.45000","-5.85969","-153.80743"
"270.90003","-5.86953","-154.06255"
"271.35000","-5.87938","-154.24146"
"271.80003","-5.88891","-154.41815"
"272.25000","-5.89891","-154.54114"
"272.70000","-5.90859","-154.52696"
"273.15003","-5.91813","-154.65523"
"273.60000","-5.92797","-154.76136"
"274.05003","-5.93766","-154.95430"
"274.50000","-5.94750","-155.10666"
"274.95000","-5.95703","-155.28483"
"275.40003","-5.96688","-155.52716"
"275.85000","-5.97672","-155.66622"
"276.30003","-5.98656","-155.85410"
"276.75000","-5.99609","-155.94478"
"277.20000","-6.00594","-156.14731"
"277.65003","-6.01578","-156.31432"
"278.10000","-6.02531","-156.46731"
"278.55003","-6.03500","-156.64989"
"279.00000","-6.04516","-156.87793"
"279.45000","-6.05484","-157.02160"
"279.90003","-6.06422","-157.20520"
"280.35000","-6.07438","-157.40175"
"280.80003","-6.08406","-157.57179"
"281.25000","-6.09344","-157.69616"
"281.70000","-6.10344","-157.91854"
"282.15003","-6.11328","-158.06632"
"282.60000","-6.12297","-158.25419"
"283.05003","-6.13266","-158.45219"
"283.50000","-6.14250","-158.67747"
"283.95000","-6.15219","-158.87687"
"284.40003","-6.16188","-159.15697"
"284.85000","-6.17156","-159.35598"
"285.30003","-6.18156","-159.54584"
"285.75000","-6.19125","-159.69465"
"286.20000","-6.20078","-159.87722"
"286.65003","-6.21078","-160.11273"
"287.10000","-6.22063","-160.28866"
"287.55003","-6.23016","-160.45280"
"288.00000","-6.23984","-160.54356"
"288.45000","-6.24969","-160.60576"
"288.90003","-6.25953","-160.74669"
"289.35000","-6.26906","-160.81322"
"289.80003","-6.27891","-160.97892"
"290.25000","-6.28891","-161.03936"
"290.70000","-6.29844","-161.20544"
"291.15003","-6.30797","-161.35437"
"291.60000","-6.31812","-161.52574"
"292.05003","-6.32781","-161.64042"
"292.50000","-6.33719","-161.84239"
"292.95000","-6.34719","-161.99896"
"293.40003","-6.35719","-162.16919"
"293.85000","-6.36672","-162.27681"
"294.30003","-6.37641","-162.43856"
"294.75000","-6.38625","-162.55789"
"295.20000","-6.39609","-162.73929"
"295.65003","-6.40547","-162.87986"
"296.10000","-6.41547","-163.05098"
"296.55003","-6.42531","-163.20288"
"297.00000","-6.43516","-163.35040"
"297.45000","-6.44453","-163.46006"
"297.90003","-6.45438","-163.69948"
"298.35000","-6.46438","-163.88819"
"298.80003","-6.47375","-163.97333"
"299.25000","-6.48359","-164.17792"
"299.70000","-6.49359","-164.40360"
"300.15003","-6.50328","-164.57014"
"300.60000","-6.51281","-164.77549"
"301.05003","-6.52281","-165.01719"
"301.50000","-6.53266","-165.20144"
"301.95000","-6.54203","-165.36387"
"302.40003","-6.55188","-165.60461"
"302.85000","-6.56172","-165.75241"
"303.30003","-6.57141","-165.89712"
"303.75000","-6.58109","-165.98914"
"304.20000","-6.59094","-166.06724"
"304.65003","-6.60078","-166.08298"
"305.10000","-6.61047","-166.17401"
"305.55003","-6.62016","-166.31743"
"306.00000","-6.62984","-166.45858"
"306.45000","-6.63984","-166.59362"
"306.90003","-6.64937","-166.72565"
"307.35000","-6.65906","-166.80125"
"307.80003","-6.66922","-166.96408"
"308.25000","-6.67875","-167.07849"
"308.70000","-6.68828","-167.20513"
"309.15003","-6.69828","-167.38392"
"309.60000","-6.70813","-167.46564"
"310.05003","-6.71750","-167.59487"
"310.50000","-6.72734","-167.79354"
"310.95000","-6.73734","-167.89427"
"311.40003","-6.74703","-167.99508"
"311.85000","-6.75656","-168.11581"
"312.30003","-6.76656","-168.26876"
"312.75000","-6.77641","-168.38484"
"313.20000","-6.78578","-168.57142"
"313.65003","-6.79563","-168.75891"
"314.10000","-6.80547","-168.95248"
"314.55003","-6.81531","-169.11179"
"315.00000","-6.82484","-169.31919"
"315.45000","-6.83469","-169.46606"
"315.90003","-6.84453","-169.64376"
"316.35000","-6.85422","-169.79141"
"316.80003","-6.86391","-169.95074"
"317.25000","-6.87359","-170.10499"
"317.70000","-6.88359","-170.28796"
"318.15003","-6.89312","-170.44898"
"318.60000","-6.90297","-170.65538"
"319.05003","-6.91281","-170.75665"
"319.50000","-6.92250","-170.86001"
"319.95000","-6.93203","-170.91621"
"320.40003","-6.94203","-170.87670"
"320.85000","-6.95188","-170.84464"
"321.30003","-6.96125","-170.95963"
"321.75003","-6.97125","-171.06960"
"322.20000","-6.98109","-171.17573"
"322.65003","-6.99078","-171.32631"
"323.10000","-7.00031","-171.44535"
"323.55003","-7.01016","-171.54634"
"324.00003","-7.02016","-171.66469"
"324.45000","-7.02969","-171.77721"
"324.90003","-7.03938","-171.91350"
"325.35000","-7.04938","-172.02605"
"325.80003","-7.05906","-172.09345"
"326.25003","-7.06859","-172.20557"
"326.70000","-7.07844","-172.43091"
"327.15003","-7.08844","-172.48239"
"327.60000","-7.09781","-172.56513"
"328.05003","-7.10766","-172.70181"
"328.50003","-7.11766","-172.86424"
"328.95000","-7.12719","-173.01884"
"329.40003","-7.13672","-173.14658"
"329.85000","-7.14687","-173.37553"
"330.30003","-7.15656","-173.53902"
"330.75003","-7.16609","-173.64357"
"331.20000","-7.17594","-173.90536"
"331.65003","-7.18578","-174.03306"
"332.10000","-7.19547","-174.18480"
"332.55003","-7.20516","-174.31926"
"333.00003","-7.21500","-174.47079"
"333.45000","-7.22469","-174.58633"
"333.90003","-7.23453","-174.74972"
"334.35000","-7.24406","-174.85894"
"334.80003","-7.25391","-175.00935"
"335.25003","-7.26391","-175.02716"
"335.70000","-7.27328","-175.05273"
"336.15003","-7.28313","-175.04279"
"336.60000","-7.29313","-175.12385"
"337.05003","-7.30281","-175.10237"
"337.50003","-7.31234","-175.23101"
"337.95000","-7.32234","-175.29685"
"338.40003","-7.33203","-175.40049"
"338.85000","-7.34156","-175.43890"
"339.30003","-7.35141","-175.63514"
"339.75003","-7.36141","-175.72951"
"340.20000","-7.37109","-175.75623"
"340.65003","-7.38047","-175.71764"
"341.10000","-7.39047","-175.93110"
"341.55003","-7.40031","-176.02878"
"342.00003","-7.40984","-176.06175"
"342.45000","-7.41953","-176.20845"
"342.90003","-7.42953","-176.32766"
"343.35000","-7.43922","-176.44938"
"343.80003","-7.44891","-176.60379"
"344.25003","-7.45875","-176.74366"
"344.70000","-7.46844","-176.95183"
"345.15003","-7.47828","-177.01585"
"345.60000","-7.48781","-177.20550"
"346.05003","-7.49766","-177.29752"
"346.50003","-7.50750","-177.45093"
"346.95000","-7.51703","-177.56993"
"347.40003","-7.52688","-177.77188"
"347.85000","-7.53688","-177.81217"
"348.30003","-7.54641","-178.01618"
"348.75003","-7.55609","-178.13018"
"349.20000","-7.56609","-178.23670"
"349.65003","-7.57578","-178.30320"
"350.10000","-7.58531","-178.38025"
"350.55003","-7.59531","-178.47525"
"351.00003","-7.60516","-178.53228"
"351.45000","-7.61484","-178.50464"
"351.90003","-7.62438","-178.51014"
"352.35000","-7.63422","-178.58947"
"352.80003","-7.64406","-178.61884"
"353.25003","-7.65359","-178.66096"
"353.70000","-7.66328","-178.69802"
"354.15003","-7.67328","-178.74779"
"354.60000","-7.68312","-178.81123"
"355.05003","-7.69250","-178.91401"
"355.50003","-7.70234","-179.02719"
"355.95000","-7.71234","-179.11285"
"356.40003","-7.72187","-179.18516"
"356.85000","-7.73156","-179.25506"
"357.30003","-7.74156","-179.33929"
"357.75003","-7.75141","-179.37467"
"358.20000","-7.76062","-179.43772"
"358.65003","-7.77078","-179.59096"
"359.10000","-7.78063","-179.69379"
"359.55003","-7.79016","-179.86452"
"360.00003","-7.79984","-180.03551"
"360.45000","-7.80984","-180.13932"
"360.90003","-7.81953","-180.25987"
"361.35000","-7.82906","-180.42089"
"361.80003","-7.83891","-180.58468"
"362.25003","-7.84875","-180.72981"
"362.70000","-7.85859","-180.90704"
"363.15003","-7.86813","-180.97108"
"363.60000","-7.87797","-181.11017"
"364.05003","-7.88781","-181.16482"
"364.50003","-7.89734","-181.19352"
"364.95000","-7.90719","-181.28050"
"365.40003","-7.91703","-181.10359"
"365.85000","-7.92688","-181.04840"
"366.30003","-7.93625","-181.05233"
"366.75003","-7.94625","-181.04132"
"367.20000","-7.95609","-181.16422"
"367.65003","-7.96563","-181.20136"
"368.10000","-7.97531","-181.27715"
"368.55003","-7.98547","-181.32532"
"369.00003","-7.99516","-181.45580"
"369.45000","-8.00453","-181.45850"
"369.90003","-8.01438","-181.49864"
"370.35000","-8.02437","-181.61062"
"370.80003","-8.03391","-181.61895"
"371.25003","-8.04359","-181.62919"
"371.70000","-8.05344","-181.66427"
"372.15003","-8.06328","-181.75792"
"372.60000","-8.07281","-181.88827"
"373.05003","-8.08266","-182.00532"
"373.50003","-8.09266","-182.13283"
"373.95000","-8.10234","-182.22442"
"374.40003","-8.11188","-182.37175"
"374.85000","-8.12172","-182.49566"
"375.30003","-8.13156","-182.64635"
"375.75003","-8.14109","-182.65726"
"376.20000","-8.15094","-182.86129"
"376.65003","-8.16078","-182.93791"
"377.10000","-8.17047","-183.07533"
"377.55003","-8.18000","-183.17133"
"378.00003","-8.19000","-183.27441"
"378.45000","-8.19969","-183.25364"
"378.90003","-8.20938","-183.27767"
"379.35000","-8.21922","-183.33923"
"379.80003","-8.22906","-183.27519"
"380.25003","-8.23875","-183.30039"
"380.70000","-8.24828","-183.27262"
"381.15003","-8.25828","-183.27458"
"381.60000","-8.26797","-183.35693"
"382.05003","-8.27781","-183.44821"
"382.50003","-8.28734","-183.51141"
"382.95000","-8.29719","-183.55129"
"383.40003","-8.30719","-183.56368"
"383.85000","-8.31656","-183.55904"
"384.30003","-8.32625","-183.62880"
"384.75003","-8.33641","-183.64491"
"385.20000","-8.34594","-183.67110"
"385.65003","-8.35547","-183.73154"
"386.10000","-8.36547","-183.85274"
"386.55003","-8.37531","-183.92026"
"387.00003","-8.38469","-184.02332"
"387.45000","-8.39469","-184.13911"
"387.90003","-8.40453","-184.27564"
"388.35000","-8.41422","-184.35393"
"388.80003","-8.42391","-184.51696"
"389.25003","-8.43391","-184.60535"
"389.70000","-8.44359","-184.71837"
"390.15003","-8.45297","-184.78386"
"390.60000","-8.46297","-184.85917"
"391.05003","-8.47281","-184.87258"
"391.50003","-8.48250","-184.96588"
"391.95000","-8.49219","-184.95636"
"392.40003","-8.50203","-185.02947"
"392.85000","-8.51172","-184.95418"
"393.30003","-8.52141","-184.89420"
"393.75003","-8.53109","-184.93442"
"394.20000","-8.54094","-184.85712"
"394.65003","-8.55094","-184.95705"
"395.10000","-8.56031","-185.01861"
"395.55003","-8.57016","-185.07589"
"396.00003","-8.58016","-185.11644"
"396.45000","-8.58969","-185.11558"
"396.90003","-8.59922","-185.14508"
"397.35000","-8.60937","-185.15585"
"397.80003","-8.61906","-185.21100"
"398.25003","-8.62844","-185.26845"
"398.70000","-8.63844","-185.38747"
"399.15003","-8.64828","-185.49869"
"399.60000","-8.65797","-185.58837"
"400.05003","-8.66750","-185.67521"
"400.50003","-8.67750","-185.77619"
"400.95000","-8.68734","-185.84702"
"401.40003","-8.69688","-185.94610"
"401.85000","-8.70672","-186.04722"
"402.30003","-8.71656","-186.17079"
"402.75003","-8.72625","-186.17166"
"403.20000","-8.73578","-186.15222"
"403.65003","-8.74563","-186.23753"
"404.10000","-8.75563","-186.22726"
"404.55003","-8.76500","-186.16322"
"405.00003","-8.77484","-186.22588"
"405.45000","-8.78484","-186.08935"
"405.90003","-8.79453","-186.03213"
"406.35000","-8.80406","-186.00749"
"406.80003","-8.81406","-186.06720"
"407.25003","-8.82375","-186.01997"
"407.70000","-8.83328","-186.09114"
"408.15003","-8.84328","-186.14035"
"408.60000","-8.85313","-186.19750"
"409.05003","-8.86281","-186.19038"
"409.50003","-8.87234","-186.20299"
"409.95000","-8.88219","-186.23093"
"410.40003","-8.89203","-186.20830"
"410.85000","-8.90172","-186.26586"
"411.30003","-8.91141","-186.40896"
"411.75003","-8.92109","-186.40470"
"412.20000","-8.93125","-186.54320"
"412.65003","-8.94063","-186.65634"
"413.10000","-8.95031","-186.78529"
"413.55003","-8.96031","-186.87289"
"414.00003","-8.97016","-186.92551"
"414.45000","-8.97953","-187.02643"
"414.90003","-8.98953","-187.17250"
"415.35000","-8.99938","-187.23454"
"415.80003","-9.00891","-187.32557"
"416.25003","-9.01875","-187.34008"
"416.70000","-9.02859","-187.31058"
"417.15003","-9.03828","-187.23372"
"417.60000","-9.04781","-187.18630"
"418.05003","-9.05766","-187.07296"
"418.50003","-9.06766","-187.02194"
"418.95000","-9.07703","-187.00426"
"419.40003","-9.08688","-187.13027"
"419.85000","-9.09687","-187.11168"
"420.30003","-9.10656","-187.07754"
"420.75003","-9.11609","-187.10315"
"421.20000","-9.12594","-187.15668"
"421.65003","-9.13578","-187.15119"
"422.10000","-9.14547","-187.04174"
"422.55003","-9.15516","-187.07070"
"423.00003","-9.16500","-187.03492"
"423.45000","-9.17484","-187.09626"
"423.90003","-9.18438","-187.24330"
"424.35000","-9.19422","-187.40866"
"424.80003","-9.20406","-187.49215"
"425.25003","-9.21375","-187.55272"
"425.70000","-9.22328","-187.71579"
"426.15003","-9.23328","-187.77868"
"426.60000","-9.24313","-187.85881"
"427.05003","-9.25250","-187.89727"
"427.50003","-9.26250","-187.89236"
"427.95000","-9.27234","-187.82098"
"428.40003","-9.28203","-187.76029"
"428.85000","-9.29156","-187.60569"
"429.30003","-9.30141","-187.54411"
"429.75003","-9.31125","-187.53013"
"430.20000","-9.32094","-187.49055"
"430.65003","-9.33047","-187.51750"
"431.10000","-9.34047","-187.48725"
"431.55003","-9.35031","-187.51668"
"432.00003","-9.35969","-187.52191"
"432.45000","-9.36953","-187.53557"
"432.90003","-9.37969","-187.54445"
"433.35000","-9.38922","-187.41744"
"433.80003","-9.39891","-187.48827"
"434.25003","-9.40891","-187.56451"
"434.70000","-9.41859","-187.61734"
"435.15003","-9.42797","-187.64919"
"435.60000","-9.43797","-187.79518"
"436.05003","-9.44781","-187.87839"
"436.50003","-9.45734","-187.94652"
"436.95000","-9.46719","-188.09073"
"437.40003","-9.47703","-188.13012"
"437.85000","-9.48672","-188.18287"
"438.30003","-9.49641","-188.32197"
"438.75003","-9.50625","-188.33291"
"439.20000","-9.51594","-188.28426"
"439.65003","-9.52578","-188.15558"
"440.10000","-9.53547","-188.12487"
"440.55003","-9.54516","-188.01723"
"441.00003","-9.55516","-187.94438"
"441.45000","-9.56469","-187.83975"
"441.90003","-9.57438","-187.85624"
"442.35000","-9.58422","-187.83251"
"442.80003","-9.59406","-187.84609"
"443.25003","-9.60359","-187.79334"
"443.70000","-9.61344","-187.82564"
"444.15003","-9.62344","-187.79112"
"444.60000","-9.63297","-187.78862"
"445.05003","-9.64266","-187.69477"
"445.50003","-9.65266","-187.74534"
"445.95000","-9.66234","-187.76368"
"446.40003","-9.67172","-187.82103"
"446.85000","-9.68172","-187.88081"
"447.30003","-9.69172","-187.95384"
"447.75003","-9.70109","-187.98463"
"448.20000","-9.71094","-188.02974"
"448.65003","-9.72078","-188.09937"
"449.10000","-9.73047","-188.18144"
"449.55003","-9.74000","-188.22368"
"450.00003","-9.75000","-188.27796"
"450.45000","-9.75969","-188.26118"
"450.90003","-9.76953","-188.14074"
"451.35003","-9.77906","-188.05766"
"451.80003","-9.78891","-187.95989"
"452.25003","-9.79891","-187.80369"
"452.70000","-9.80828","-187.75400"
"453.15003","-9.81828","-187.81204"
"453.60003","-9.82813","-187.80997"
"454.05003","-9.83781","-187.79878"
"454.50003","-9.84734","-187.87881"
"454.95000","-9.85734","-187.88235"
"455.40003","-9.86703","-187.83743"
"455.85003","-9.87656","-187.79071"
"456.30003","-9.88656","-187.79887"
"456.75003","-9.89625","-187.71386"
"457.20000","-9.90594","-187.80801"
"457.65003","-9.91563","-187.84696"
"458.10003","-9.92531","-187.94179"
"458.55003","-9.93531","-188.04828"
"459.00003","-9.94500","-188.09550"
"459.45000","-9.95453","-188.21971"
"459.90003","-9.96437","-188.24296"
"460.35003","-9.97438","-188.14400"
"460.80003","-9.98375","-188.02464"
"461.25003","-9.99359","-187.86376"
"461.70000","-10.00359","-187.82333"
"462.15003","-10.01328","-187.75484"
"462.60003","-10.02266","-187.71946"
"463.05003","-10.03281","-187.72224"
"463.50003","-10.04266","-187.70995"
"463.95000","-10.05188","-187.70941"
"464.40003","-10.06203","-187.79524"
"464.85003","-10.07188","-187.71803"
"465.30003","-10.08141","-187.64434"
"465.75003","-10.09109","-187.74712"
"466.20000","-10.10109","-187.74346"
"466.65003","-10.11078","-187.74183"
"467.10003","-10.12031","-187.79904"
"467.55003","-10.13031","-187.93464"
"468.00003","-10.14000","-187.93724"
"468.45000","-10.14984","-187.93939"
"468.90003","-10.15938","-187.92562"
"469.35003","-10.16922","-187.84266"
"469.80003","-10.17906","-187.68944"
"470.25003","-10.18859","-187.55279"
"470.70000","-10.19844","-187.51586"
"471.15003","-10.20813","-187.43256"
"471.60003","-10.21812","-187.43664"
"472.05003","-10.22750","-187.46059"
"472.50003","-10.23734","-187.44431"
"472.95000","-10.24734","-187.37307"
"473.40003","-10.25703","-187.35928"
"473.85003","-10.26656","-187.36253"
"474.30003","-10.27656","-187.33405"
"474.75003","-10.28641","-187.29445"
"475.20000","-10.29562","-187.31652"
"475.65003","-10.30578","-187.37786"
"476.10003","-10.31562","-187.40637"
"476.55003","-10.32516","-187.46147"
"477.00003","-10.33484","-187.53801"
"477.45000","-10.34484","-187.56988"
"477.90003","-10.35453","-187.57695"
"478.35003","-10.36406","-187.50967"
"478.80003","-10.37391","-187.45683"
"479.25003","-10.38375","-187.25291"
"479.70000","-10.39359","-187.20206"
"480.15003","-10.40313","-187.14413"
"480.60003","-10.41297","-187.16525"
"481.05003","-10.42281","-187.11317"
"481.50003","-10.43234","-187.10835"
"481.95000","-10.44219","-187.21702"
"482.40003","-10.45219","-187.09613"
"482.85003","-10.46172","-187.03938"
"483.30003","-10.47141","-187.07125"
"483.75003","-10.48125","-187.06208"
"484.20000","-10.49094","-187.04681"
"484.65003","-10.50062","-187.01054"
"485.10003","-10.51047","-187.08149"
"485.55003","-10.52031","-187.09535"
"486.00003","-10.53000","-187.10401"
"486.45000","-10.53953","-187.15458"
"486.90003","-10.54937","-187.16749"
"487.35003","-10.55922","-187.05288"
"487.80003","-10.56906","-186.95105"
"488.25003","-10.57859","-186.85443"
"488.70000","-10.58844","-186.77784"
"489.15003","-10.59844","-186.69134"
"489.60003","-10.60781","-186.65319"
"490.05003","-10.61750","-186.70328"
"490.50003","-10.62766","-186.74122"
"490.95000","-10.63734","-186.66685"
"491.40003","-10.64672","-186.63272"
"491.85003","-10.65672","-186.55183"
"492.30003","-10.66656","-186.52784"
"492.75003","-10.67609","-186.50712"
"493.20000","-10.68594","-186.67746"
"493.65003","-10.69578","-186.62523"
"494.10003","-10.70563","-186.67841"
"494.55003","-10.71516","-186.75799"
"495.00003","-10.72516","-186.81193"
"495.45000","-10.73484","-186.69620"
"495.90003","-10.74438","-186.58981"
"496.35003","-10.75422","-186.51603"
"496.80003","-10.76406","-186.30793"
"497.25003","-10.77375","-186.19245"
"497.70000","-10.78328","-186.17006"
"498.15003","-10.79328","-186.12185"
"498.60003","-10.80297","-186.10815"
"499.05003","-10.81266","-186.06314"
"499.50003","-10.82234","-186.13523"
"499.95000","-10.83219","-186.05286"
"500.40003","-10.84203","-185.99715"
"500.85003","-10.85156","-185.93047"
"501.30003","-10.86125","-185.96197"
"501.75003","-10.87125","-186.00805"
"502.20000","-10.88094","-186.05929"
"502.65003","-10.89047","-186.11882"
"503.10003","-10.90063","-186.09133"
"503.55003","-10.91031","-186.07944"
"504.00003","-10.91969","-186.00574"
"504.45000","-10.92969","-185.94738"
"504.90003","-10.93953","-185.87114"
"505.35003","-10.94922","-185.70147"
"505.80003","-10.95891","-185.66165"
"506.25003","-10.96875","-185.61076"
"506.70000","-10.97859","-185.55855"
"507.15003","-10.98813","-185.49258"
"507.60003","-10.99781","-185.49509"
"508.05003","-11.00781","-185.49943"
"508.50003","-11.01766","-185.38384"
"508.95000","-11.02703","-185.33181"
"509.40003","-11.03703","-185.41031"
"509.85003","-11.04688","-185.45123"
"510.30003","-11.05625","-185.42338"
"510.75003","-11.06609","-185.47155"
"511.20000","-11.07609","-185.45624"
"511.65003","-11.08578","-185.40965"
"512.10003","-11.09531","-185.37767"
"512.55006","-11.10531","-185.30907"
"513.00000","-11.11516","-185.20880"
"513.45000","-11.12453","-185.09626"
"513.90003","-11.13437","-185.10172"
"514.35003","-11.14438","-185.08028"
"514.80006","-11.15391","-184.91596"
"515.25000","-11.16359","-184.84524"
"515.70000","-11.17344","-184.83087"
"516.15003","-11.18328","-184.70354"
"516.60003","-11.19313","-184.69343"
"517.05006","-11.20266","-184.68788"
"517.50000","-11.21234","-184.61134"
"517.95000","-11.22234","-184.56521"
"518.40003","-11.23172","-184.51883"
"518.85003","-11.24156","-184.47446"
"519.30006","-11.25156","-184.48142"
"519.75000","-11.26125","-184.42212"
"520.20000","-11.27078","-184.41362"
"520.65003","-11.28078","-184.49513"
"521.10003","-11.29062","-184.42964"
"521.55006","-11.30016","-184.33038"
"522.00000","-11.30984","-184.32613"
"522.45000","-11.31984","-184.22415"
"522.90003","-11.32953","-184.12597"
"523.35003","-11.33906","-184.05138"
"523.80006","-11.34906","-184.00507"
"524.25000","-11.35891","-183.92541"
"524.70000","-11.36828","-183.91004"
"525.15000","-11.37813","-183.86830"
"525.60006","-11.38812","-183.79580"
"526.05006","-11.39781","-183.72891"
"526.50000","-11.40719","-183.70708"
"526.95000","-11.41719","-183.71373"
"527.40000","-11.42703","-183.61015"
"527.85006","-11.43672","-183.54755"
"528.30006","-11.44641","-183.60177"
"528.75000","-11.45625","-183.52780"
"529.20000","-11.46609","-183.44829"
"529.65000","-11.47563","-183.42249"
"530.10006","-11.48547","-183.35331"
"530.55006","-11.49531","-183.30153"
"531.00000","-11.50500","-183.24915"
"531.45000","-11.51469","-183.23431"
"531.90000","-11.52453","-183.14125"
"532.35006","-11.53438","-183.08273"
"532.80006","-11.54375","-183.03299"
"533.25000","-11.55359","-182.95916"
"533.70000","-11.56359","-182.98853"
"534.15000","-11.57328","-182.91639"
"534.60006","-11.58281","-182.89568"
"535.05006","-11.59266","-182.82881"
"535.50000","-11.60266","-182.76555"
"535.95000","-11.61219","-182.74708"
"536.40000","-11.62187","-182.71359"
"536.85006","-11.63172","-182.65808"
"537.30006","-11.64156","-182.58819"
"537.75000","-11.65094","-182.42244"
"538.20000","-11.66094","-182.43140"
"538.65000","-11.67094","-182.30682"
"539.10006","-11.68047","-182.23314"
"539.55006","-11.69000","-182.23623"
"540.00000","-11.70016","-182.14438"
"540.45000","-11.70984","-182.10329"
"540.90000","-11.71922","-181.99043"
"541.35006","-11.72922","-182.00664"
"541.80006","-11.73906","-181.96246"
"542.25000","-11.74859","-181.84692"
"542.70000","-11.75844","-181.93655"
"543.15000","-11.76828","-181.89460"
"543.60006","-11.77797","-181.83427"
"544.05006","-11.78750","-181.77498"
"544.50000","-11.79734","-181.76202"
"544.95000","-11.80719","-181.65179"
"545.40000","-11.81703","-181.61142"
"545.85006","-11.82656","-181.39882"
"546.30006","-11.83656","-181.33214"
"546.75000","-11.84641","-181.25271"
"547.20000","-11.85578","-181.14729"
"547.65000","-11.86563","-181.14459"
"548.10006","-11.87547","-181.07053"
"548.55006","-11.88531","-180.90811"
"549.00000","-11.89484","-180.86363"
"549.45000","-11.90469","-180.75939"
"549.90000","-11.91469","-180.71231"
"550.35006","-11.92406","-180.63501"
"550.80006","-11.93375","-180.63275"
"551.25000","-11.94391","-180.56883"
"551.70000","-11.95359","-180.50445"
"552.15000","-11.96297","-180.42315"
"552.60006","-11.97297","-180.37347"
"553.05006","-11.98281","-180.35902"
"553.50000","-11.99234","-180.23882"
"553.95000","-12.00219","-180.18333"
"554.40000","-12.01219","-180.09607"
"554.85006","-12.02172","-179.94044"
"555.30006","-12.03125","-179.89667"
"555.75000","-12.04125","-179.88626"
"556.20000","-12.05109","-179.77782"
"556.65000","-12.06063","-179.68016"
"557.10006","-12.07031","-179.66866"
"557.55006","-12.08031","-179.60599"
"558.00000","-12.09016","-179.49415"
"558.45000","-12.09953","-179.44178"
"558.90000","-12.10938","-179.44040"
"559.35006","-12.11938","-179.28317"
"559.80006","-12.12906","-179.19807"
"560.25000","-12.13859","-179.18447"
"560.70000","-12.14859","-179.07497"
"561.15000","-12.15828","-178.92640"
"561.60006","-12.16781","-178.86747"
"562.05006","-12.17766","-178.78318"
"562.50000","-12.18750","-178.64341"
"562.95000","-12.19734","-178.52725"
"563.40000","-12.20687","-178.48456"
"563.85006","-12.21656","-178.37035"
"564.30006","-12.22656","-178.29524"
"564.75000","-12.23625","-178.20569"
"565.20000","-12.24578","-178.19110"
"565.65000","-12.25562","-177.99340"
"566.10006","-12.26563","-177.93721"
"566.55006","-12.27500","-177.82776"
"567.00000","-12.28484","-177.74634"
"567.45000","-12.29484","-177.74489"
"567.90000","-12.30453","-177.64656"
"568.35006","-12.31391","-177.58073"
"568.80006","-12.32406","-177.56026"
"569.25000","-12.33391","-177.40415"
"569.70000","-12.34313","-177.27502"
"570.15000","-12.35328","-177.25147"
"570.60006","-12.36313","-177.04612"
"571.05006","-12.37266","-176.94831"
"571.50000","-12.38234","-176.90826"
"571.95000","-12.39234","-176.77374"
"572.40000","-12.40203","-176.63427"
"572.85006","-12.41156","-176.45696"
"573.30006","-12.42141","-176.42314"
"573.75000","-12.43125","-176.30596"
"574.20000","-12.44109","-176.22972"
"574.65000","-12.45063","-176.02632"
"575.10006","-12.46047","-176.00017"
"575.55006","-12.47031","-175.87785"
"576.00000","-12.48000","-175.75530"
"576.45000","-12.48953","-175.71827"
"576.90000","-12.49938","-175.61205"
"577.35006","-12.50937","-175.48721"
"577.80006","-12.51875","-175.37260"
"578.25000","-12.52859","-175.19664"
"578.70000","-12.53859","-175.07257"
"579.15000","-12.54813","-174.87347"
"579.60006","-12.55781","-174.73543"
"580.05006","-12.56781","-174.51717"
"580.50000","-12.57750","-174.41103"
"580.95000","-12.58703","-174.21259"
"581.40000","-12.59703","-173.95759"
"581.85006","-12.60688","-173.72558"
"582.30006","-12.61641","-173.42573"
"582.75000","-12.62625","4.35979"
"583.20000","-12.63609","4.36515"
"583.65000","-12.64594","4.36404"
"584.10006","-12.65531","4.37543"
"584.55006","-12.66516","4.34522"
"585.00000","-12.67516","4.36712"
"585.45000","-12.68484","4.33982"
"585.90000","-12.69422","4.39835"
"586.35006","-12.70422","4.38160"
"586.80006","-12.71406","4.37420"
"587.25000","-12.72359","4.36706"
"587.70000","-12.73344","4.37876"
"588.15000","-12.74328","4.35758"
"588.60006","-12.75297","4.35700"
"589.05006","-12.76250","4.40670"
"589.50000","-12.77250","4.36853"
"589.95000","-12.78234","4.37853"
"590.40000","-12.79187","4.36545"
"590.85006","-12.80172","4.39060"
"591.30006","-12.81141","4.38550"
"591.75000","-12.82125","4.36485"
"592.20000","-12.83078","4.35258"
"592.65000","-12.84078","4.40752"
"593.10006","-12.85047","4.38331"
"593.55006","-12.86031","4.36801"
"594.00000","-12.86984","4.36031"
"594.45000","-12.87953","4.34809"
"594.90000","-12.88953","4.35539"
"595.35006","-12.89906","4.40872"
"595.80006","-12.90875","4.35925"
"596.25000","-12.91891","4.36582"
"596.70000","-12.92859","4.38624"
"597.15000","-12.93797","4.36622"
"597.60006","-12.94813","4.37166"
"598.05006","-12.95781","4.33204"
"598.50000","-12.96734","4.35465"
"598.95000","-12.97719","4.35448"
"599.40000","-12.98703","4.33030"
"599.85006","-12.99687","4.36243"
"600.30006","-13.00641","4.38688"
"600.75000","-13.01625","4.38958"
"601.20000","-13.02609","4.37412"
"601.65000","-13.03547","4.36718"
"602.10006","-13.04531","4.35128"
"602.55006","-13.05531","4.35551"
"603.00000","-13.06500","4.38061"
"603.45000","-13.07453","4.35165"
"603.90000","-13.08453","4.37433"
"604.35006","-13.09422","4.36772"
"604.80006","-13.10406","4.37616"
"605.25000","-13.11359","4.40175"
"605.70000","-13.12344","4.36904"
"606.15000","-13.13344","4.36167"
"606.60006","-13.14281","4.36910"
"607.05006","-13.15266","4.39001"
"607.50000","-13.16266","4.33871"
"607.95000","-13.17234","4.38054"
"608.40000","-13.18188","4.36910"
"608.85006","-13.19188","4.36246"
"609.30006","-13.20156","4.39482"
"609.75000","-13.21109","4.36351"
"610.20000","-13.22094","4.36627"
"610.65000","-13.23078","4.35697"
"611.10006","-13.24063","4.34514"
"611.55006","-13.25016","4.37009"
"612.00000","-13.26000","4.36302"
"612.45000","-13.26984","4.36999"
"612.90000","-13.27937","4.36525"
"613.35006","-13.28906","4.38025"
"613.80006","-13.29891","4.37255"
"614.25000","-13.30875","4.36219"
"614.70000","-13.31828","4.37968"
"615.15000","-13.32812","4.36700"
"615.60006","-13.33813","4.35405"
"616.05006","-13.34766","4.39004"
"616.50000","-13.35734","4.33821"
"616.95000","-13.36734","4.35021"
"617.15206","-13.37172","4.39895"