File: Lab 4 Data/G2CF_DRY.csv
Text Inputs : Specimen label,"G2CF_DRY"
Test : Rate 1,"0.70000",mm/min
Dimension : Support span,"25.60000",mm
Dimension : Thickness,"1.60200",mm
Dimension : Width,"13.37000",mm

Time,Extension,Load
(sec),(mm),(N)
"0.00000","-0.00016","0.05824"
"0.20000","-0.00094","-0.21864"
"0.40000","-0.00406","-1.14737"
"0.60000","-0.00688","-2.13053"
"0.80000","-0.00922","-2.94785"
"1.00000","-0.01172","-3.71513"
"1.20000","-0.01391","-4.46283"
"1.40000","-0.01641","-5.25307"
"1.60000","-0.01875","-6.07510"
"1.80000","-0.02109","-6.86944"
"2.00000","-0.02344","-7.52190"
"2.20000","-0.02578","-8.34924"
"2.40000","-0.02812","-9.12272"
"2.60000","-0.03047","-9.81409"
"2.80000","-0.03281","-10.56164"
"3.00000","-0.03516","-11.30810"
"3.20000","-0.03734","-11.99235"
"3.40000","-0.03969","-12.69741"
"3.60000","-0.04188","-13.46361"
"3.80000","-0.04422","-14.16587"
"4.00000","-0.04672","-14.87975"
"4.20000","-0.04906","-15.69897"
"4.40000","-0.05141","-16.39567"
"4.60000","-0.05375","-17.11702"
"4.80000","-0.05609","-17.84811"
"5.00000","-0.05844","-18.57515"
"5.20000","-0.06062","-19.31558"
"5.40000","-0.06313","-20.09089"
"5.60000","-0.06547","-20.82282"
"5.80000","-0.06766","-21.43720"
"6.00000","-0.07016","-22.19363"
"6.20000","-0.07250","-22.99011"
"6.40000","-0.07469","-23.59421"
"6.60000","-0.07688","-24.35190"
"6.80000","-0.07938","-25.09980"
"7.00000","-0.08156","-25.82639"
"7.20000","-0.08391","-26.48087"
"7.40000","-0.08641","-27.22651"
"7.60000","-0.08875","-27.94945"
"7.80000","-0.09094","-28.65188"
"8.00000","-0.09344","-29.39248"
"8.20000","-0.09578","-30.14910"
"8.40000","-0.09797","-30.81880"
"8.60000","-0.10047","-31.56299"
"8.80000","-0.10281","-32.28887"
"9.00000","-0.10516","-32.99052"
"9.20000","-0.10750","-33.77287"
"9.40000","-0.10984","-34.49877"
"9.60000","-0.11203","-35.16149"
"9.80000","-0.11437","-35.86478"
"10.00000","-0.11672","-36.64502"
"10.20000","-0.11891","-37.29032"
"10.40000","-0.12141","-38.04390"
"10.60000","-0.12375","-38.75797"
"10.80000","-0.12609","-39.47082"
"11.00000","-0.12828","-40.17697"
"11.20000","-0.13078","-40.90049"
"11.40000","-0.13313","-41.63544"
"11.60000","-0.13547","-42.36416"
"11.80000","-0.13781","-43.08647"
"12.00000","-0.14016","-43.79620"
"12.20000","-0.14234","-44.51821"
"12.40000","-0.14469","-45.17476"
"12.60000","-0.14687","-45.92665"
"12.80000","-0.14922","-46.70278"
"13.00000","-0.15172","-47.40825"
"13.20000","-0.15406","-48.12495"
"13.40000","-0.15625","-48.89193"
"13.60000","-0.15859","-49.60184"
"13.80000","-0.16109","-50.36347"
"14.00000","-0.16344","-51.12255"
"14.20000","-0.16578","-51.87212"
"14.40000","-0.16828","-52.58799"
"14.60000","-0.17047","-53.31509"
"14.80000","-0.17281","-54.02344"
"15.00000","-0.17516","-54.80742"
"15.20000","-0.17750","-55.43621"
"15.40000","-0.17953","-56.06898"
"15.60000","-0.18188","-56.82586"
"15.80000","-0.18438","-57.59473"
"16.00000","-0.18656","-58.32167"
"16.20000","-0.18906","-59.10657"
"16.40000","-0.19141","-59.86831"
"16.60000","-0.19375","-60.56100"
"16.80000","-0.19609","-61.34838"
"17.00000","-0.19859","-62.11857"
"17.20000","-0.20078","-62.80570"
"17.40000","-0.20313","-63.54205"
"17.60000","-0.20547","-64.29186"
"17.80000","-0.20781","-65.02031"
"18.00000","-0.21016","-65.69432"
"18.20000","-0.21234","-66.37714"
"18.40000","-0.21453","-67.07051"
"18.60000","-0.21688","-67.75182"
"18.80000","-0.21937","-68.62926"
"19.00000","-0.22172","-69.32435"
"19.20000","-0.22391","-70.02600"
"19.40000","-0.22641","-70.79441"
"19.60000","-0.22891","-71.56645"
"19.80000","-0.23125","-72.30215"
"20.00000","-0.23344","-72.98957"
"20.20000","-0.23578","-73.73322"
"20.40000","-0.23812","-74.45178"
"20.60000","-0.24047","-75.19553"
"20.80000","-0.24281","-75.97158"
"21.00000","-0.24516","-76.69649"
"21.20000","-0.24719","-77.36139"
"21.40000","-0.24969","-78.11834"
"21.60000","-0.25187","-78.81910"
"21.80000","-0.25438","-79.62431"
"22.00000","-0.25672","-80.37792"
"22.20000","-0.25906","-81.12866"
"22.40000","-0.26141","-81.88047"
"22.60000","-0.26375","-82.57583"
"22.80000","-0.26609","-83.30142"
"23.00000","-0.26844","-84.06110"
"23.20000","-0.27094","-84.84324"
"23.40000","-0.27328","-85.56277"
"23.60000","-0.27547","-86.29474"
"23.80000","-0.27781","-87.00400"
"24.00000","-0.28016","-87.73964"
"24.20000","-0.28234","-88.42936"
"24.40000","-0.28453","-89.12110"
"24.60000","-0.28688","-89.88626"
"24.80000","-0.28938","-90.64170"
"25.00000","-0.29172","-91.42676"
"25.20000","-0.29406","-92.13457"
"25.40000","-0.29641","-92.92839"
"25.60000","-0.29875","-93.63378"
"25.80000","-0.30109","-94.40760"
"26.00000","-0.30359","-95.14875"
"26.20000","-0.30578","-95.83253"
"26.40000","-0.30813","-96.66582"
"26.60000","-0.31047","-97.34169"
"26.80000","-0.31281","-98.06373"
"27.00000","-0.31516","-98.78532"
"27.20000","-0.31734","-99.54823"
"27.40000","-0.31969","-100.25037"
"27.60000","-0.32188","-100.92364"
"27.80000","-0.32437","-101.71852"
"28.00000","-0.32656","-102.46425"
"28.20000","-0.32891","-103.15013"
"28.40000","-0.33141","-103.97235"
"28.60000","-0.33375","-104.69649"
"28.80000","-0.33594","-105.41270"
"29.00000","-0.33844","-106.20304"
"29.20000","-0.34078","-106.91676"
"29.40000","-0.34312","-107.65743"
"29.60000","-0.34563","-108.42810"
"29.80000","-0.34781","-109.15032"
"30.00000","-0.35016","-109.87625"
"30.20000","-0.35234","-110.58514"
"30.40000","-0.35453","-111.31916"
"30.60000","-0.35688","-112.01696"
"30.80000","-0.35922","-112.79784"
"31.00000","-0.36172","-113.58582"
"31.20000","-0.36406","-114.31061"
"31.40000","-0.36625","-114.99754"
"31.60000","-0.36875","-115.82660"
"31.80000","-0.37109","-116.59769"
"32.00000","-0.37344","-117.32331"
"32.20000","-0.37594","-118.07798"
"32.40000","-0.37812","-118.81828"
"32.60000","-0.38047","-119.55472"
"32.80000","-0.38281","-120.30455"
"33.00000","-0.38516","-121.00942"
"33.20000","-0.38734","-121.72292"
"33.40000","-0.38953","-122.39302"
"33.60000","-0.39188","-123.19795"
"33.80000","-0.39422","-123.94894"
"34.00000","-0.39672","-124.73851"
"34.20000","-0.39906","-125.56168"
"34.40000","-0.40141","-126.25957"
"34.60000","-0.40375","-127.04246"
"34.80000","-0.40625","-127.81559"
"35.00000","-0.40859","-128.59895"
"35.20000","-0.41078","-129.31630"
"35.40000","-0.41328","-130.09135"
"35.60000","-0.41547","-130.76242"
"35.80000","-0.41781","-131.50528"
"36.00000","-0.42000","-132.21744"
"36.20000","-0.42234","-132.96262"
"36.40000","-0.42453","-133.62424"
"36.60000","-0.42703","-134.40961"
"36.80000","-0.42938","-135.15148"
"37.00000","-0.43156","-135.88770"
"37.20000","-0.43406","-136.71109"
"37.40000","-0.43656","-137.45559"
"37.60000","-0.43891","-138.19559"
"37.80000","-0.44109","-138.95098"
"38.00000","-0.44359","-139.70171"
"38.20000","-0.44578","-140.41521"
"38.40000","-0.44813","-141.19650"
"38.60000","-0.45047","-141.93854"
"38.80000","-0.45281","-142.68186"
"39.00000","-0.45484","-143.31050"
"39.20000","-0.45734","-144.05193"
"39.40000","-0.45953","-144.79410"
"39.60000","-0.46187","-145.53802"
"39.80000","-0.46438","-146.38279"
"40.00000","-0.46672","-147.15260"
"40.20000","-0.46922","-147.91070"
"40.40000","-0.47141","-148.64387"
"40.60000","-0.47391","-149.39936"
"40.80000","-0.47609","-150.10742"
"41.00000","-0.47844","-150.84528"
"41.20000","-0.48094","-151.65093"
"41.40000","-0.48313","-152.35277"
"41.60000","-0.48547","-153.07453"
"41.80000","-0.48781","-153.82558"
"42.00000","-0.49000","-154.53804"
"42.20000","-0.49219","-155.23585"
"42.40000","-0.49469","-156.05812"
"42.60000","-0.49688","-156.74122"
"42.80000","-0.49922","-157.55819"
"43.00000","-0.50172","-158.32212"
"43.20000","-0.50406","-159.10087"
"43.40000","-0.50641","-159.84412"
"43.60000","-0.50875","-160.58061"
"43.80000","-0.51125","-161.35065"
"44.00000","-0.51344","-162.09258"
"44.20000","-0.51578","-162.83324"
"44.40000","-0.51813","-163.63133"
"44.60000","-0.52047","-164.25980"
"44.80000","-0.52281","-165.06720"
"45.00000","-0.52516","-165.77423"
"45.20000","-0.52734","-166.51098"
"45.40000","-0.52953","-167.19548"
"45.60000","-0.53188","-167.97137"
"45.80000","-0.53438","-168.72901"
"46.00000","-0.53656","-169.49210"
"46.20000","-0.53906","-170.31187"
"46.40000","-0.54141","-171.08431"
"46.60000","-0.54375","-171.79536"
"46.80000","-0.54609","-172.61114"
"47.00000","-0.54859","-173.36342"
"47.20000","-0.55078","-174.06179"
"47.40000","-0.55312","-174.83819"
"47.60000","-0.55547","-175.57433"
"47.80000","-0.55781","-176.31395"
"48.00000","-0.56000","-177.03658"
"48.20000","-0.56219","-177.73215"
"48.40000","-0.56453","-178.48609"
"48.60000","-0.56688","-179.25270"
"48.80000","-0.56937","-180.04419"
"49.00000","-0.57172","-180.81166"
"49.20000","-0.57391","-181.50225"
"49.40000","-0.57641","-182.31668"
"49.60000","-0.57891","-183.01673"
"49.80000","-0.58109","-183.79958"
"50.00000","-0.58359","-184.56088"
"50.20000","-0.58594","-185.32462"
"50.40000","-0.58813","-186.09438"
"50.60000","-0.59047","-186.83966"
"50.80000","-0.59281","-187.55360"
"51.00000","-0.59500","-188.25240"
"51.20000","-0.59719","-188.99331"
"51.40000","-0.59969","-189.75800"
"51.60000","-0.60203","-190.54025"
"51.80000","-0.60422","-191.27283"
"52.00000","-0.60687","-192.08560"
"52.20000","-0.60906","-192.86560"
"52.40000","-0.61141","-193.55766"
"52.60000","-0.61391","-194.35059"
"52.80000","-0.61625","-195.05655"
"53.00000","-0.61859","-195.77570"
"53.20000","-0.62078","-196.52976"
"53.40000","-0.62313","-197.29605"
"53.60000","-0.62547","-198.03071"
"53.80000","-0.62781","-198.77175"
"54.00000","-0.63000","-199.43837"
"54.20000","-0.63219","-200.19757"
"54.40000","-0.63469","-200.96559"
"54.60000","-0.63703","-201.75995"
"54.80000","-0.63922","-202.43753"
"55.00000","-0.64172","-203.27233"
"55.20000","-0.64422","-204.06429"
"55.40000","-0.64656","-204.81702"
"55.60000","-0.64875","-205.57979"
"55.80000","-0.65125","-206.31384"
"56.00000","-0.65359","-207.03815"
"56.20000","-0.65578","-207.78947"
"56.40000","-0.65813","-208.54389"
"56.60000","-0.66047","-209.24356"
"56.80000","-0.66266","-209.97064"
"57.00000","-0.66500","-210.68113"
"57.20000","-0.66734","-211.44260"
"57.40000","-0.66953","-212.13260"
"57.60000","-0.67203","-212.91422"
"57.80000","-0.67437","-213.67505"
"58.00000","-0.67672","-214.45697"
"58.20000","-0.67906","-215.16895"
"58.40000","-0.68156","-215.96424"
"58.60000","-0.68391","-216.65497"
"58.80000","-0.68609","-217.39637"
"59.00000","-0.68859","-218.12903"
"59.20000","-0.69094","-218.84711"
"59.40000","-0.69297","-219.54477"
"59.60000","-0.69547","-220.31426"
"59.80000","-0.69781","-221.07841"
"60.00000","-0.70000","-221.70940"
"60.20000","-0.70234","-222.47775"
"60.40000","-0.70469","-223.19771"
"60.60000","-0.70687","-223.84796"
"60.80000","-0.70922","-224.60915"
"61.00000","-0.71172","-225.29516"
"61.20000","-0.71406","-226.07198"
"61.40000","-0.71641","-226.77094"
"61.60000","-0.71875","-227.49951"
"61.80000","-0.72109","-228.19458"
"62.00000","-0.72344","-228.83294"
"62.20000","-0.72594","-229.53322"
"62.40000","-0.72812","-230.19835"
"62.60000","-0.73047","-230.88930"
"62.80000","-0.73281","-231.58291"
"63.00000","-0.73500","-232.27513"
"63.20000","-0.73734","-232.98943"
"63.40000","-0.73953","-233.62095"
"63.60000","-0.74203","-234.30180"
"63.80000","-0.74422","-235.06982"
"64.00000","-0.74672","-235.76397"
"64.20000","-0.74906","-236.51110"
"64.40000","-0.75141","-237.22645"
"64.60001","-0.75375","-237.92507"
"64.80000","-0.75625","-238.65288"
"65.00000","-0.75844","-239.37685"
"65.20000","-0.76094","-240.13698"
"65.40000","-0.76313","-240.85343"
"65.60001","-0.76547","-241.53527"
"65.80000","-0.76781","-242.22896"
"66.00000","-0.77000","-242.89854"
"66.20001","-0.77219","-243.57773"
"66.40000","-0.77453","-244.31042"
"66.60001","-0.77703","-245.07068"
"66.80000","-0.77938","-245.85055"
"67.00000","-0.78156","-246.54679"
"67.20001","-0.78406","-247.28505"
"67.40000","-0.78641","-248.06330"
"67.60001","-0.78875","-248.71247"
"67.80000","-0.79125","-249.50836"
"68.00000","-0.79359","-250.21967"
"68.20001","-0.79578","-250.95267"
"68.40000","-0.79812","-251.66685"
"68.60001","-0.80047","-252.35331"
"68.80000","-0.80281","-253.09293"
"69.00000","-0.80500","-253.74269"
"69.20001","-0.80734","-254.47784"
"69.40000","-0.80953","-255.21012"
"69.60001","-0.81187","-255.81047"
"69.80000","-0.81438","-256.64890"
"70.00000","-0.81672","-257.28937"
"70.20001","-0.81906","-255.12114"
"70.40000","-0.82156","-255.22707"
"70.60001","-0.82391","-255.60416"
"70.80000","-0.82625","-256.09436"
"71.00000","-0.82859","-256.63139"
"71.20001","-0.83078","-257.23584"
"71.40000","-0.83313","-257.84656"
"71.60001","-0.83547","-258.46131"
"71.80000","-0.83766","-259.13531"
"72.00000","-0.83984","-259.74981"
"72.20001","-0.84219","-260.37142"
"72.40000","-0.84469","-261.11800"
"72.60001","-0.84688","-261.79478"
"72.80000","-0.84938","-262.51549"
"73.00000","-0.85172","-263.24464"
"73.20001","-0.85422","-263.95148"
"73.40000","-0.85656","-264.63276"
"73.60001","-0.85891","-265.33978"
"73.80000","-0.86125","-266.03671"
"74.00000","-0.86344","-266.70288"
"74.20001","-0.86578","-267.42214"
"74.40000","-0.86813","-268.09821"
"74.60001","-0.87047","-268.77686"
"74.80000","-0.87266","-263.21040"
"75.00000","-0.87500","-263.33109"
"75.20001","-0.87719","-263.85939"
"75.40000","-0.87969","-264.56708"
"75.60001","-0.88203","-262.17878"
"75.80000","-0.88453","-262.66538"
"76.00000","-0.88688","-263.29644"
"76.20001","-0.88922","-261.22598"
"76.40000","-0.89156","-261.66685"
"76.60001","-0.89375","-262.19381"
"76.80000","-0.89625","-262.56884"
"77.00000","-0.89859","-263.07348"
"77.20001","-0.90078","-263.61182"
"77.40000","-0.90312","-262.92631"
"77.60001","-0.90547","-262.39559"
"77.80000","-0.90766","-262.58714"
"78.00000","-0.91000","-262.97780"
"78.20001","-0.91234","-251.47090"
"78.40000","-0.91469","-247.45274"
"78.60001","-0.91703","-246.72920"
"78.80000","-0.91937","-246.70459"
"79.00000","-0.92172","-246.92519"
"79.20001","-0.92406","-247.21134"
"79.40000","-0.92656","-247.60924"
"79.60001","-0.92891","-247.88117"
"79.80000","-0.93109","-247.86310"
"80.00000","-0.93359","-248.17916"
"80.20001","-0.93578","-248.50711"
"80.40000","-0.93813","-248.90548"
"80.60001","-0.94047","-249.30213"
"80.80000","-0.94281","-234.21081"
"81.00001","-0.94500","-233.80751"
"81.20001","-0.94719","-233.34278"
"81.40000","-0.94969","-233.19826"
"81.60001","-0.95203","-233.09557"
"81.80000","-0.95438","-233.01762"
"82.00001","-0.95672","-227.52013"
"82.20001","-0.95922","-225.09474"
"82.40000","-0.96141","-220.75225"
"82.60001","-0.96391","-219.42640"
"82.80000","-0.96609","-218.81212"
"83.00001","-0.96844","-218.16911"
"83.20001","-0.97094","-217.62069"
"83.40000","-0.97312","-216.16939"
"83.60001","-0.97547","-212.18736"
"83.80000","-0.97766","-211.40991"
"84.00001","-0.98000","-210.70004"
"84.20001","-0.98219","-210.37571"
"84.40000","-0.98469","-210.32140"
"84.60001","-0.98703","-210.32346"
"84.80000","-0.98938","-210.47015"
"85.00001","-0.99172","-210.40266"
"85.20001","-0.99406","-210.59303"
"85.40000","-0.99641","-207.60033"
"85.60001","-0.99891","-205.07419"
"85.80000","-1.00125","-204.31221"
"86.00001","-1.00344","-203.66831"
"86.20001","-1.00578","-202.98868"
"86.40000","-1.00813","-202.78959"
"86.60001","-1.01047","-202.73665"
"86.80000","-1.01266","-202.79046"
"87.00001","-1.01500","-202.88998"
"87.20001","-1.01734","-203.11167"
"87.40000","-1.01953","-203.32968"
"87.60001","-1.02203","-203.64640"
"87.80000","-1.02438","-203.91136"
"88.00001","-1.02656","-203.72381"
"88.20001","-1.02906","-203.89929"
"88.40000","-1.03156","-204.25783"
"88.60001","-1.03391","-204.48882"
"88.80000","-1.03609","-204.74199"
"89.00001","-1.03859","-205.11318"
"89.20001","-1.04078","-205.36244"
"89.40000","-1.04313","-205.61356"
"89.60001","-1.04547","-205.95530"
"89.80000","-1.04766","-206.27830"
"90.00001","-1.04984","-206.55692"
"90.20001","-1.05234","-206.88294"
"90.40000","-1.05469","-207.27746"
"90.60001","-1.05703","-207.53337"
"90.80000","-1.05938","-207.90359"
"91.00001","-1.06188","-208.30784"
"91.20001","-1.06422","-208.58277"
"91.40000","-1.06656","-208.95056"
"91.60001","-1.06891","-209.25160"
"91.80000","-1.07109","-209.46776"
"92.00001","-1.07359","-209.75616"
"92.20001","-1.07594","-210.00935"
"92.40000","-1.07812","-210.40769"
"92.60001","-1.08031","-210.62851"
"92.80000","-1.08266","-210.96617"
"93.00001","-1.08484","-211.29793"
"93.20001","-1.08734","-211.65226"
"93.40000","-1.08969","-212.04531"
"93.60001","-1.09203","-212.40206"
"93.80000","-1.09453","-212.76897"
"94.00001","-1.09688","-213.07541"
"94.20001","-1.09922","-213.35864"
"94.40000","-1.10141","-213.35404"
"94.60001","-1.10391","-213.45178"
"94.80000","-1.10625","-213.61602"
"95.00001","-1.10844","-213.86102"
"95.20001","-1.11078","-213.91368"
"95.40000","-1.11313","-214.20605"
"95.60001","-1.11531","-214.33551"
"95.80000","-1.11766","-214.60406"
"96.00001","-1.12000","-214.85692"
"96.20001","-1.12234","-215.10942"
"96.40000","-1.12469","-215.35864"
"96.60001","-1.12703","-215.66657"
"96.80000","-1.12938","-215.92105"
"97.00001","-1.13172","-216.16450"
"97.20001","-1.13406","-216.35931"
"97.40000","-1.13656","-216.67570"
"97.60001","-1.13875","-215.67971"
"97.80000","-1.14109","-215.28102"
"98.00001","-1.14344","-214.98401"
"98.20001","-1.14578","-214.61820"
"98.40000","-1.14813","-214.34393"
"98.60001","-1.15031","-213.98494"
"98.80000","-1.15266","-213.67095"
"99.00001","-1.15484","-213.35263"
"99.20001","-1.15734","-212.94914"
"99.40000","-1.15969","-212.74207"
"99.60001","-1.16188","-212.25188"
"99.80000","-1.16437","-211.91457"
"100.00001","-1.16688","-211.65056"
"100.20001","-1.16906","-211.28196"
"100.40000","-1.17156","-211.21291"
"100.60001","-1.17375","-211.02887"
"100.80000","-1.17609","-210.85344"
"101.00001","-1.17859","-210.85395"
"101.20001","-1.18078","-210.75139"
"101.40000","-1.18313","-210.88980"
"101.60001","-1.18531","-210.82344"
"101.80000","-1.18766","-210.87307"
"102.00001","-1.19000","-210.92860"
"102.20001","-1.19234","-210.95503"
"102.40000","-1.19469","-211.10807"
"102.60001","-1.19703","-211.18632"
"102.80000","-1.19922","-211.25089"
"103.00001","-1.20172","-211.37122"
"103.20001","-1.20422","-211.42885"
"103.40000","-1.20656","-211.52440"
"103.60001","-1.20891","-211.45333"
"103.80000","-1.21125","-211.17158"
"104.00001","-1.21344","-210.88246"
"104.20001","-1.21578","-210.55711"
"104.40000","-1.21812","-210.39786"
"104.60001","-1.22031","-210.28323"
"104.80000","-1.22266","-210.23478"
"105.00001","-1.22500","-210.25132"
"105.20001","-1.22734","-210.23979"
"105.40000","-1.22969","-210.31478"
"105.60001","-1.23219","-210.45998"
"105.80000","-1.23438","-210.56382"
"106.00001","-1.23688","-210.61150"
"106.20001","-1.23922","-210.75096"
"106.40000","-1.24156","-210.83502"
"106.60001","-1.24391","-210.91685"
"106.80000","-1.24625","-211.06744"
"107.00001","-1.24859","-211.15785"
"107.20001","-1.25078","-211.25659"
"107.40000","-1.25297","-211.38215"
"107.60001","-1.25531","-211.44589"
"107.80000","-1.25750","-211.37878"
"108.00001","-1.26000","-211.46428"
"108.20001","-1.26234","-211.52988"
"108.40000","-1.26453","-211.56896"
"108.60001","-1.26703","-211.72570"
"108.80000","-1.26953","-211.89144"
"109.00001","-1.27187","-212.01396"
"109.20001","-1.27422","-212.11315"
"109.40000","-1.27656","-212.27539"
"109.60001","-1.27891","-212.40493"
"109.80000","-1.28109","-212.45405"
"110.00001","-1.28359","-212.50280"
"110.20001","-1.28578","-212.57725"
"110.40000","-1.28797","-212.58097"
"110.60001","-1.29031","-212.64257"
"110.80000","-1.29266","-212.79546"
"111.00001","-1.29484","-212.83867"
"111.20001","-1.29734","-212.99003"
"111.40000","-1.29969","-213.13587"
"111.60001","-1.30203","-213.22209"
"111.80000","-1.30438","-213.32204"
"112.00001","-1.30688","-213.42173"
"112.20001","-1.30922","-213.56260"
"112.40000","-1.31141","-213.60509"
"112.60001","-1.31391","-213.76064"
"112.80000","-1.31625","-213.90129"
"113.00001","-1.31828","-213.96032"
"113.20001","-1.32078","-214.15958"
"113.40001","-1.32312","-214.26938"
"113.60001","-1.32531","-214.34957"
"113.80000","-1.32766","-214.52779"
"114.00001","-1.33000","-214.65395"
"114.20001","-1.33234","-214.79487"
"114.40001","-1.33469","-214.96374"
"114.60001","-1.33703","-215.11950"
"114.80000","-1.33922","-215.28566"
"115.00001","-1.34172","-215.43134"
"115.20001","-1.34422","-215.57990"
"115.40001","-1.34656","-215.74682"
"115.60001","-1.34875","-215.79079"
"115.80000","-1.35125","-215.92112"
"116.00001","-1.35344","-215.96387"
"116.20001","-1.35578","-215.99373"
"116.40001","-1.35813","-215.78865"
"116.60001","-1.36031","-215.57160"
"116.80000","-1.36266","-215.42059"
"117.00001","-1.36500","-215.38589"
"117.20001","-1.36734","-215.29011"
"117.40001","-1.36953","-215.20028"
"117.60001","-1.37203","-215.06570"
"117.80000","-1.37453","-215.05147"
"118.00001","-1.37672","-214.48616"
"118.20001","-1.37906","-214.19596"
"118.40001","-1.38156","-214.07839"
"118.60001","-1.38375","-213.90788"
"118.80000","-1.38625","-213.77016"
"119.00001","-1.38859","-212.77348"
"119.20001","-1.39078","-210.96695"
"119.40001","-1.39313","-209.89444"
"119.60001","-1.39531","-209.09503"
"119.80000","-1.39766","-208.55442"
"120.00001","-1.39984","-208.08039"
"120.20001","-1.40234","-207.81213"
"120.40001","-1.40469","-207.53423"
"120.60001","-1.40687","-207.28158"
"120.80000","-1.40937","-207.14160"
"121.00001","-1.41188","-207.03109"
"121.20001","-1.41406","-206.92894"
"121.40001","-1.41656","-206.89510"
"121.60001","-1.41891","-206.84471"
"121.80000","-1.42125","-206.83007"
"122.00001","-1.42344","-206.85753"
"122.20001","-1.42578","-206.85863"
"122.40001","-1.42797","-206.85077"
"122.60001","-1.43016","-206.90979"
"122.80000","-1.43266","-207.03482"
"123.00001","-1.43500","-207.12217"
"123.20001","-1.43719","-207.22318"
"123.40001","-1.43969","-207.43085"
"123.60001","-1.44219","-207.52111"
"123.80000","-1.44453","-207.65895"
"124.00001","-1.44688","-207.83700"
"124.20001","-1.44922","-207.86196"
"124.40001","-1.45156","-207.97078"
"124.60001","-1.45391","-208.07201"
"124.80000","-1.45625","-208.29683"
"125.00001","-1.45844","-208.35264"
"125.20001","-1.46078","-208.46875"
"125.40001","-1.46297","-208.53771"
"125.60001","-1.46531","-208.51618"
"125.80000","-1.46750","-208.54883"
"126.00001","-1.47000","-208.21212"
"126.20001","-1.47219","-207.23358"
"126.40001","-1.47469","-206.22829"
"126.60001","-1.47719","-205.34545"
"126.80000","-1.47953","-204.53084"
"127.00001","-1.48188","-203.69707"
"127.20001","-1.48422","-203.22418"
"127.40001","-1.48656","-202.58954"
"127.60001","-1.48875","-201.88630"
"127.80000","-1.49109","-201.45509"
"128.00000","-1.49344","-201.04095"
"128.20002","-1.49563","-200.48320"
"128.40001","-1.49797","-200.13355"
"128.60001","-1.50031","-199.83690"
"128.80000","-1.50250","-199.50310"
"129.00000","-1.50500","-199.24982"
"129.20002","-1.50734","-199.11557"
"129.40001","-1.50984","-198.93382"
"129.60001","-1.51219","-198.82247"
"129.80000","-1.51453","-198.73587"
"130.00000","-1.51687","-198.68128"
"130.20002","-1.51906","-198.60419"
"130.40001","-1.52156","-197.10189"
"130.60001","-1.52391","-196.49314"
"130.80000","-1.52609","-196.13111"
"131.00000","-1.52844","-195.93639"
"131.20002","-1.53078","-195.85751"
"131.40002","-1.53297","-195.74488"
"131.60000","-1.53531","-195.77315"
"131.80000","-1.53766","-195.71200"
"132.00000","-1.54000","-195.81156"
"132.20002","-1.54234","-195.91441"
"132.40002","-1.54469","-196.02908"
"132.60000","-1.54719","-196.10809"
"132.80000","-1.54953","-196.21687"
"133.00000","-1.55188","-196.34560"
"133.20002","-1.55422","-196.45154"
"133.40002","-1.55641","-196.56954"
"133.60000","-1.55891","-196.72323"
"133.80000","-1.56109","-196.84749"
"134.00000","-1.56344","-196.96480"
"134.20002","-1.56578","-197.14158"
"134.40002","-1.56797","-197.27070"
"134.60000","-1.57031","-197.40514"
"134.80000","-1.57266","-197.61387"
"135.00000","-1.57500","-197.82439"
"135.20002","-1.57734","-198.03226"
"135.40002","-1.57969","-198.24583"
"135.60000","-1.58219","-198.45420"
"135.80000","-1.58453","-198.68776"
"136.00000","-1.58672","-198.84927"
"136.20002","-1.58922","-199.15981"
"136.40002","-1.59141","-199.31214"
"136.60000","-1.59391","-199.54579"
"136.80000","-1.59625","-199.62640"
"137.00000","-1.59844","-199.49900"
"137.20002","-1.60062","-199.25090"
"137.40002","-1.60297","-199.08242"
"137.60000","-1.60531","-198.95775"
"137.80000","-1.60750","-198.95470"
"138.00000","-1.61000","-198.98305"
"138.20002","-1.61234","-199.07668"
"138.40002","-1.61469","-197.84514"
"138.60000","-1.61703","-197.84495"
"138.80000","-1.61953","-197.94317"
"139.00000","-1.62172","-198.02675"
"139.20002","-1.62422","-198.16283"
"139.40002","-1.62656","-198.30108"
"139.60000","-1.62891","-198.50403"
"139.80000","-1.63125","-198.62421"
"140.00000","-1.63344","-198.84156"
"140.20002","-1.63578","-199.02192"
"140.40002","-1.63797","-199.13768"
"140.60000","-1.64031","-199.28563"
"140.80000","-1.64266","-199.57479"
"141.00000","-1.64484","-199.73749"
"141.20002","-1.64734","-199.99718"
"141.40002","-1.64984","-200.24404"
"141.60000","-1.65203","-200.42764"
"141.80000","-1.65453","-200.66611"
"142.00000","-1.65688","-200.87058"
"142.20002","-1.65922","-201.03374"
"142.40002","-1.66156","-200.97770"
"142.60000","-1.66391","-201.33600"
"142.80000","-1.66609","-201.64687"
"143.00000","-1.66844","-201.86268"
"143.20002","-1.67063","-202.05889"
"143.40002","-1.67297","-202.27533"
"143.60000","-1.67516","-202.52302"
"143.80000","-1.67766","-202.82473"
"144.00000","-1.68000","-203.04710"
"144.20002","-1.68234","-203.28782"
"144.40002","-1.68484","-203.54392"
"144.60000","-1.68719","-203.83218"
"144.80000","-1.68953","-204.08818"
"145.00000","-1.69188","-204.26370"
"145.20002","-1.69422","-204.55427"
"145.40002","-1.69656","-204.80677"
"145.60000","-1.69891","-205.07457"
"145.80000","-1.70125","-205.28903"
"146.00000","-1.70344","-205.47600"
"146.20002","-1.70562","-205.67667"
"146.40002","-1.70797","-205.96005"
"146.60000","-1.71016","-206.19178"
"146.80000","-1.71266","-206.49130"
"147.00000","-1.71516","-206.75758"
"147.20002","-1.71750","-207.03223"
"147.40002","-1.71984","-207.26606"
"147.60000","-1.72219","-207.51618"
"147.80000","-1.72453","-207.73435"
"148.00000","-1.72687","-207.93121"
"148.20002","-1.72922","-208.24183"
"148.40002","-1.73156","-208.40134"
"148.60000","-1.73375","-208.55725"
"148.80000","-1.73609","-208.76620"
"149.00000","-1.73844","-208.96774"
"149.20002","-1.74047","-209.08965"
"149.40002","-1.74297","-209.29823"
"149.60000","-1.74531","-209.50468"
"149.80000","-1.74766","-209.71246"
"150.00000","-1.75000","-209.90489"
"150.20002","-1.75234","-210.13983"
"150.40002","-1.75469","-210.36191"
"150.60000","-1.75703","-210.49837"
"150.80000","-1.75937","-210.75066"
"151.00000","-1.76187","-210.97779"
"151.20002","-1.76406","-211.07275"
"151.40002","-1.76641","-211.31072"
"151.60000","-1.76891","-211.56298"
"151.80000","-1.77109","-211.72248"
"152.00000","-1.77344","-211.88764"
"152.20002","-1.77578","-212.07519"
"152.40002","-1.77797","-211.97475"
"152.60000","-1.78031","-212.07226"
"152.80000","-1.78266","-212.29189"
"153.00000","-1.78500","-212.44956"
"153.20002","-1.78734","-212.66347"
"153.40002","-1.78969","-212.86866"
"153.60000","-1.79219","-213.08383"
"153.80000","-1.79438","-213.19484"
"154.00000","-1.79688","-213.42523"
"154.20002","-1.79906","-213.59907"
"154.40002","-1.80141","-213.73469"
"154.60000","-1.80391","-213.89155"
"154.80000","-1.80625","-214.03918"
"155.00000","-1.80844","-214.14895"
"155.20002","-1.81062","-214.27879"
"155.40002","-1.81297","-214.44960"
"155.60000","-1.81531","-214.55660"
"155.80000","-1.81766","-214.73894"
"156.00000","-1.82000","-214.88650"
"156.20002","-1.82234","-215.08932"
"156.40002","-1.82469","-215.18113"
"156.60000","-1.82719","-215.27950"
"156.80000","-1.82953","-215.32634"
"157.00000","-1.83188","-215.34346"
"157.20002","-1.83422","-215.43214"
"157.40002","-1.83656","-215.43073"
"157.60000","-1.83891","-215.45947"
"157.80000","-1.84125","-215.53058"
"158.00000","-1.84344","-215.58367"
"158.20002","-1.84562","-215.59738"
"158.40002","-1.84797","-215.65130"
"158.60000","-1.85031","-215.67039"
"158.80000","-1.85250","-215.64044"
"159.00000","-1.85500","-215.67663"
"159.20002","-1.85750","-215.76503"
"159.40002","-1.85984","-215.74033"
"159.60000","-1.86219","-215.79880"
"159.80000","-1.86453","-215.86096"
"160.00000","-1.86687","-215.83727"
"160.20002","-1.86922","-215.87174"
"160.40002","-1.87156","-215.92936"
"160.60000","-1.87391","-215.94187"
"160.80000","-1.87609","-215.99911"
"161.00002","-1.87844","-216.02755"
"161.20002","-1.88063","-216.09781"
"161.40002","-1.88281","-216.12782"
"161.60000","-1.88531","-216.29011"
"161.80000","-1.88766","-216.40042"
"162.00002","-1.89000","-216.51102"
"162.20002","-1.89234","-216.63837"
"162.40002","-1.89484","-216.78928"
"162.60000","-1.89719","-216.90540"
"162.80000","-1.89953","-216.99658"
"163.00002","-1.90188","-217.13138"
"163.20002","-1.90422","-217.18506"
"163.40002","-1.90641","-217.22585"
"163.60000","-1.90891","-217.29818"
"163.80000","-1.91125","-217.38037"
"164.00002","-1.91328","-217.42715"
"164.20002","-1.91563","-217.55533"
"164.40002","-1.91797","-217.62572"
"164.60000","-1.92031","-217.73385"
"164.80000","-1.92266","-217.93533"
"165.00002","-1.92500","-218.05383"
"165.20002","-1.92734","-218.21771"
"165.40002","-1.92969","-218.31483"
"165.60000","-1.93219","-218.46650"
"165.80000","-1.93453","-218.63554"
"166.00002","-1.93688","-218.75918"
"166.20002","-1.93922","-218.92171"
"166.40002","-1.94156","-219.09039"
"166.60000","-1.94375","-219.15419"
"166.80000","-1.94625","-219.34176"
"167.00002","-1.94844","-219.44931"
"167.20002","-1.95062","-219.53067"
"167.40002","-1.95297","-219.74893"
"167.60000","-1.95531","-219.87915"
"167.80000","-1.95766","-220.04126"
"168.00002","-1.96000","-220.20105"
"168.20002","-1.96234","-220.35701"
"168.40002","-1.96469","-220.47464"
"168.60000","-1.96703","-220.56641"
"168.80000","-1.96953","-220.66886"
"169.00002","-1.97172","-220.82919"
"169.20002","-1.97406","-220.90092"
"169.40002","-1.97656","-221.13582"
"169.60000","-1.97875","-221.17032"
"169.80000","-1.98125","-221.37983"
"170.00002","-1.98344","-221.45441"
"170.20002","-1.98578","-221.52891"
"170.40002","-1.98797","-221.61972"
"170.60000","-1.99031","-221.79235"
"170.80000","-1.99266","-221.95075"
"171.00002","-1.99500","-222.08013"
"171.20002","-1.99734","-222.27749"
"171.40002","-1.99984","-222.42432"
"171.60000","-2.00203","-222.50479"
"171.80000","-2.00437","-222.68005"
"172.00002","-2.00688","-222.87209"
"172.20002","-2.00922","-222.85677"
"172.40002","-2.01156","-223.06833"
"172.60000","-2.01391","-223.17529"
"172.80000","-2.01625","-223.28189"
"173.00002","-2.01844","-223.40545"
"173.20002","-2.02063","-223.47197"
"173.40002","-2.02297","-223.63389"
"173.60000","-2.02531","-223.73119"
"173.80000","-2.02766","-223.92932"
"174.00002","-2.03000","-223.98725"
"174.20002","-2.03219","-224.00647"
"174.40002","-2.03469","-223.96054"
"174.60000","-2.03703","-224.02164"
"174.80000","-2.03938","-224.07211"
"175.00002","-2.04188","-224.26555"
"175.20002","-2.04422","-224.36304"
"175.40002","-2.04641","-224.41138"
"175.60000","-2.04891","-224.53915"
"175.80000","-2.05109","-224.68859"
"176.00002","-2.05344","-224.79268"
"176.20002","-2.05562","-224.86396"
"176.40002","-2.05797","-224.26944"
"176.60000","-2.06031","-224.32117"
"176.80000","-2.06266","-224.41283"
"177.00002","-2.06516","-224.60338"
"177.20002","-2.06750","-224.69856"
"177.40002","-2.06984","-224.78949"
"177.60000","-2.07219","-224.90907"
"177.80000","-2.07453","-225.00172"
"178.00002","-2.07687","-225.13695"
"178.20002","-2.07922","-225.27367"
"178.40002","-2.08156","-225.37399"
"178.60000","-2.08375","-225.43466"
"178.80000","-2.08609","-225.55269"
"179.00002","-2.08828","-225.72741"
"179.20002","-2.09062","-225.82361"
"179.40002","-2.09297","-225.97676"
"179.60000","-2.09531","-226.17152"
"179.80000","-2.09750","-226.31682"
"180.00002","-2.10000","-226.49877"
"180.20002","-2.10250","-226.60950"
"180.40002","-2.10484","-226.74473"
"180.60000","-2.10719","-226.83488"
"180.80000","-2.10953","-226.96357"
"181.00002","-2.11187","-227.13259"
"181.20002","-2.11406","-227.29497"
"181.40002","-2.11656","-227.43756"
"181.60000","-2.11891","-227.59575"
"181.80000","-2.12094","-227.65931"
"182.00002","-2.12328","-227.75277"
"182.20002","-2.12563","-227.89180"
"182.40002","-2.12781","-228.07175"
"182.60000","-2.13031","-228.26388"
"182.80000","-2.13266","-228.49057"
"183.00002","-2.13516","-228.66022"
"183.20002","-2.13750","-228.80008"
"183.40002","-2.13984","-228.95837"
"183.60000","-2.14219","-229.04318"
"183.80000","-2.14453","-229.22337"
"184.00002","-2.14688","-229.44501"
"184.20002","-2.14922","-229.57629"
"184.40002","-2.15141","-229.57336"
"184.60000","-2.15391","-229.58186"
"184.80000","-2.15609","-229.35431"
"185.00002","-2.15828","-225.51056"
"185.20002","-2.16063","-224.99647"
"185.40002","-2.16297","-224.12781"
"185.60000","-2.16531","-223.23780"
"185.80000","-2.16766","-222.83133"
"186.00002","-2.17016","-222.56752"
"186.20002","-2.17250","-222.38115"
"186.40002","-2.17484","-222.23465"
"186.60000","-2.17719","-222.16288"
"186.80000","-2.17953","-222.14808"
"187.00002","-2.18172","-222.04146"
"187.20002","-2.18422","-222.10332"
"187.40002","-2.18641","-222.04926"
"187.60000","-2.18875","-222.05396"
"187.80000","-2.19109","-222.10469"
"188.00002","-2.19344","-222.13848"
"188.20002","-2.19563","-222.22662"
"188.40002","-2.19797","-222.25589"
"188.60000","-2.20031","-222.36072"
"188.80000","-2.20266","-222.38068"
"189.00002","-2.20500","-222.43351"
"189.20002","-2.20750","-222.55430"
"189.40002","-2.20969","-222.44358"
"189.60000","-2.21203","-222.50991"
"189.80000","-2.21453","-222.62365"
"190.00002","-2.21672","-222.67969"
"190.20002","-2.21922","-222.82213"
"190.40002","-2.22156","-222.83586"
"190.60000","-2.22391","-222.60511"
"190.80000","-2.22609","-222.36599"
"191.00002","-2.22828","-222.15614"
"191.20002","-2.23063","-222.12528"
"191.40002","-2.23297","-222.06122"
"191.60000","-2.23531","-222.06290"
"191.80000","-2.23781","-222.05375"
"192.00002","-2.24000","-222.01801"
"192.20002","-2.24234","-222.04131"
"192.40002","-2.24484","-222.01721"
"192.60000","-2.24703","-222.02514"
"192.80000","-2.24953","-222.04494"
"193.00002","-2.25188","-220.75223"
"193.20002","-2.25422","-220.45325"
"193.40002","-2.25656","-220.22892"
"193.60000","-2.25891","-220.08542"
"193.80000","-2.26109","-219.92097"
"194.00002","-2.26328","-219.70728"
"194.20002","-2.26563","-219.65725"
"194.40002","-2.26797","-219.51463"
"194.60000","-2.27016","-219.43456"
"194.80000","-2.27266","-219.47192"
"195.00002","-2.27500","-219.43884"
"195.20002","-2.27734","-219.36201"
"195.40002","-2.27984","-219.33515"
"195.60000","-2.28219","-219.40427"
"195.80000","-2.28453","-219.39257"
"196.00002","-2.28688","-219.34835"
"196.20002","-2.28922","-219.38542"
"196.40002","-2.29156","-219.30885"
"196.60000","-2.29375","-219.39136"
"196.80000","-2.29609","-219.35966"
"197.00002","-2.29828","-219.31889"
"197.20002","-2.30047","-219.32893"
"197.40002","-2.30313","-219.39665"
"197.60000","-2.30531","-219.44227"
"197.80000","-2.30766","-219.46333"
"198.00002","-2.31016","-219.55578"
"198.20002","-2.31250","-219.53076"
"198.40002","-2.31484","-219.58459"
"198.60000","-2.31719","-219.66048"
"198.80000","-2.31953","-219.68134"
"199.00002","-2.32187","-219.73344"
"199.20002","-2.32422","-219.80861"
"199.40002","-2.32656","-219.83318"
"199.60000","-2.32875","-220.01840"
"199.80000","-2.33094","-219.96744"
"200.00002","-2.33328","-220.14752"
"200.20002","-2.33547","-220.24421"
"200.40002","-2.33797","-220.40583"
"200.60000","-2.34031","-220.55445"
"200.80000","-2.34281","-220.59690"
"201.00002","-2.34516","-220.79436"
"201.20002","-2.34750","-220.87581"
"201.40002","-2.34984","-221.02086"
"201.60000","-2.35219","-221.16510"
"201.80000","-2.35453","-220.34558"
"202.00002","-2.35687","-220.35344"
"202.20002","-2.35906","-220.41880"
"202.40002","-2.36141","-220.45303"
"202.60000","-2.36375","-220.62086"
"202.80000","-2.36594","-220.68711"
"203.00002","-2.36828","-220.78346"
"203.20002","-2.37063","-220.97113"
"203.40002","-2.37297","-221.09205"
"203.60000","-2.37531","-221.24371"
"203.80000","-2.37766","-221.45420"
"204.00002","-2.38000","-221.63376"
"204.20002","-2.38234","-221.79203"
"204.40002","-2.38469","-221.95736"
"204.60000","-2.38719","-222.15851"
"204.80000","-2.38938","-222.29675"
"205.00002","-2.39188","-222.55961"
"205.20002","-2.39422","-222.72594"
"205.40002","-2.39641","-222.77666"
"205.60000","-2.39891","-222.96185"
"205.80000","-2.40109","-223.09540"
"206.00002","-2.40328","-222.96192"
"206.20002","-2.40563","-223.01801"
"206.40002","-2.40797","-223.14081"
"206.60000","-2.41031","-223.32216"
"206.80000","-2.41266","-223.47897"
"207.00002","-2.41500","-223.74474"
"207.20002","-2.41750","-223.84126"
"207.40002","-2.41969","-223.73488"
"207.60000","-2.42219","-223.85778"
"207.80000","-2.42438","-223.97671"
"208.00002","-2.42672","-224.04412"
"208.20002","-2.42922","-224.15385"
"208.40002","-2.43156","-224.34520"
"208.60000","-2.43375","-224.42477"
"208.80000","-2.43609","-224.46331"
"209.00002","-2.43828","-224.52503"
"209.20002","-2.44047","-224.65570"
"209.40002","-2.44297","-224.94128"
"209.60000","-2.44531","-225.09867"
"209.80000","-2.44766","-225.26527"
"210.00002","-2.45000","-225.38522"
"210.20002","-2.45250","-225.53809"
"210.40002","-2.45484","-225.70016"
"210.60000","-2.45719","-225.84934"
"210.80000","-2.45953","-225.94463"
"211.00002","-2.46188","-225.88786"
"211.20002","-2.46422","-225.98851"
"211.40002","-2.46656","-226.12527"
"211.60000","-2.46875","-226.17988"
"211.80000","-2.47094","-226.25467"
"212.00002","-2.47328","-226.38269"
"212.20002","-2.47563","-226.54340"
"212.40002","-2.47781","-226.65072"
"212.60000","-2.48031","-226.86401"
"212.80000","-2.48281","-227.05231"
"213.00002","-2.48516","-227.11229"
"213.20002","-2.48750","-227.26512"
"213.40002","-2.48984","-227.37563"
"213.60000","-2.49219","-227.12948"
"213.80000","-2.49453","-225.90004"
"214.00002","-2.49688","-225.47765"
"214.20002","-2.49922","-225.37436"
"214.40002","-2.50141","-225.31845"
"214.60000","-2.50375","-225.37667"
"214.80000","-2.50594","-225.39783"
"215.00002","-2.50813","-225.43535"
"215.20002","-2.51062","-225.58982"
"215.40002","-2.51297","-225.63590"
"215.60000","-2.51531","-224.79396"
"215.80000","-2.51781","-224.73253"
"216.00002","-2.52016","-224.74080"
"216.20002","-2.52250","-224.72484"
"216.40002","-2.52484","-224.78117"
"216.60000","-2.52719","-224.76576"
"216.80000","-2.52953","-224.79083"
"217.00002","-2.53188","-224.78934"
"217.20002","-2.53422","-224.79128"
"217.40002","-2.53656","-224.74771"
"217.60000","-2.53859","-224.66941"
"217.80000","-2.54094","-224.70515"
"218.00002","-2.54328","-224.78648"
"218.20002","-2.54562","-224.87119"
"218.40002","-2.54813","-224.99518"
"218.60000","-2.55047","-225.06962"
"218.80000","-2.55281","-225.15809"
"219.00002","-2.55516","-225.19927"
"219.20002","-2.55750","-225.23977"
"219.40002","-2.55984","-225.27101"
"219.60000","-2.56219","-223.32462"
"219.80000","-2.56453","-223.27177"
"220.00002","-2.56672","-223.05876"
"220.20002","-2.56906","-222.89772"
"220.40002","-2.57156","-222.96838"
"220.60000","-2.57375","-222.85070"
"220.80000","-2.57594","-222.81088"
"221.00002","-2.57828","-222.74839"
"221.20002","-2.58063","-222.73298"
"221.40002","-2.58297","-222.75543"
"221.60000","-2.58531","-222.70722"
"221.80000","-2.58766","-222.63959"
"222.00002","-2.59000","-222.55193"
"222.20002","-2.59234","-218.76691"
"222.40002","-2.59484","-218.02627"
"222.60000","-2.59703","-217.08932"
"222.80000","-2.59953","-215.23632"
"223.00002","-2.60187","-214.86154"
"223.20002","-2.60406","-214.59615"
"223.40002","-2.60656","-203.21533"
"223.60000","-2.60875","-202.22930"
"223.80000","-2.61109","-201.29757"
"224.00002","-2.61328","-200.73526"
"224.20002","-2.61563","-191.24327"
"224.40002","-2.61797","-189.77478"
"224.60000","-2.62031","-188.55546"
"224.80000","-2.62266","-188.05400"
"225.00002","-2.62516","-187.75228"
"225.20002","-2.62734","-187.52001"
"225.40002","-2.62969","-187.45635"
"225.60000","-2.63219","-187.20847"
"225.80002","-2.63453","-186.91575"
"226.00002","-2.63688","-186.82145"
"226.20002","-2.63922","-186.37175"
"226.40002","-2.64156","-185.56409"
"226.60000","-2.64375","-185.49100"
"226.80002","-2.64594","-185.27392"
"227.00002","-2.64828","-185.27608"
"227.20002","-2.65063","-185.13680"
"227.40002","-2.65297","-185.19057"
"227.60000","-2.65531","-185.21532"
"227.80002","-2.65750","-185.25938"
"228.00002","-2.66016","-185.37302"
"228.20002","-2.66234","-185.48617"
"228.40002","-2.66469","-185.54790"
"228.60000","-2.66719","-185.64356"
"228.80002","-2.66953","-185.70580"
"229.00002","-2.67188","-185.80217"
"229.20002","-2.67422","-185.91860"
"229.40002","-2.67656","-185.95157"
"229.60000","-2.67859","-183.89544"
"229.80002","-2.68094","-183.79882"
"230.00002","-2.68328","-183.94718"
"230.20002","-2.68563","-183.98063"
"230.40002","-2.68797","-183.90061"
"230.60000","-2.69047","-184.02422"
"230.80002","-2.69266","-184.07136"
"231.00002","-2.69516","-184.12460"
"231.20002","-2.69750","-182.44544"
"231.40002","-2.69984","-170.03417"
"231.60000","-2.70219","-169.54448"
"231.80002","-2.70453","-168.86527"
"232.00002","-2.70688","-166.85244"
"232.20002","-2.70906","-166.46978"
"232.40002","-2.71156","-166.33760"
"232.60000","-2.71375","-166.25343"
"232.80002","-2.71594","-166.21253"
"233.00002","-2.71828","-166.25099"
"233.20002","-2.72063","-166.30527"
"233.40002","-2.72297","-166.30489"
"233.60000","-2.72547","-166.37903"
"233.80002","-2.72781","-166.45785"
"234.00002","-2.73016","-166.35584"
"234.20002","-2.73250","-166.33680"
"234.40002","-2.73484","-166.41755"
"234.60000","-2.73719","-166.43360"
"234.80002","-2.73937","-166.51360"
"235.00002","-2.74188","-166.56520"
"235.20002","-2.74422","-166.59619"
"235.40002","-2.74625","-166.58869"
"235.60000","-2.74859","-166.66971"
"235.80002","-2.75094","-166.73671"
"236.00002","-2.75328","-166.81174"
"236.20002","-2.75562","-166.96284"
"236.40002","-2.75813","-166.46761"
"236.60000","-2.76047","-166.52020"
"236.80002","-2.76281","-166.58196"
"237.00002","-2.76516","-166.64473"
"237.20002","-2.76750","-166.67357"
"237.40002","-2.76984","-166.65004"
"237.60000","-2.77219","-166.73129"
"237.80002","-2.77453","-166.82288"
"238.00002","-2.77672","-162.26565"
"238.20002","-2.77922","-161.73597"
"238.40002","-2.78141","-161.62079"
"238.60000","-2.78359","-161.07263"
"238.80002","-2.78594","-160.18247"
"239.00002","-2.78828","-159.45364"
"239.20002","-2.79062","-159.28483"
"239.40002","-2.79297","-159.12578"
"239.60000","-2.79547","-159.10704"
"239.80002","-2.79781","-158.37334"
"240.00002","-2.80016","-156.64622"
"240.20002","-2.80250","-154.25986"
"240.40002","-2.80484","-153.56608"
"240.60000","-2.80703","-153.42865"
"240.80002","-2.80953","-153.46353"
"241.00002","-2.81172","-153.49979"
"241.20002","-2.81406","-153.61207"
"241.40002","-2.81641","-153.73080"
"241.60000","-2.81875","-153.69498"
"241.80002","-2.82094","-153.78577"
"242.00002","-2.82328","-153.97033"
"242.20002","-2.82563","-153.76410"
"242.40002","-2.82797","-153.88561"
"242.60000","-2.83047","-152.06962"
"242.80002","-2.83281","-152.15387"
"243.00002","-2.83500","-150.71976"
"243.20002","-2.83734","-150.57229"
"243.40002","-2.83984","-150.52967"
"243.60000","-2.84203","-150.46861"
"243.80002","-2.84453","-150.33744"
"244.00002","-2.84687","-150.34927"
"244.20002","-2.84922","-150.42424"
"244.40002","-2.85141","-150.47145"
"244.60000","-2.85375","-150.60921"
"244.80002","-2.85594","-147.39450"
"245.00002","-2.85828","-145.37614"
"245.20002","-2.86063","-145.41880"
"245.40002","-2.86297","-145.41728"
"245.60000","-2.86516","-145.42988"
"245.80002","-2.86766","-145.67419"
"246.00002","-2.87016","-145.85854"
"246.20002","-2.87250","-145.96405"
"246.40002","-2.87484","-146.24605"
"246.60000","-2.87719","-146.34552"
"246.80002","-2.87953","-146.53061"
"247.00002","-2.88188","-146.69529"
"247.20002","-2.88422","-146.64182"
"247.40002","-2.88641","-146.69193"
"247.60000","-2.88859","-146.71691"
"247.80002","-2.89094","-146.89559"
"248.00002","-2.89328","-147.03929"
"248.20002","-2.89578","-108.57270"
"248.40002","-2.89812","-105.92972"
"248.60000","-2.90047","-104.92144"
"248.80002","-2.90281","-105.05507"
"249.00002","-2.90516","-105.27539"
"249.20002","-2.90750","-105.59092"
"249.40002","-2.90984","-105.87154"
"249.60000","-2.91219","-106.21035"
"249.80002","-2.91453","-106.47006"
"250.00002","-2.91688","-106.74405"
"250.20002","-2.91922","-107.03329"
"250.40002","-2.92141","-107.31135"
"250.60000","-2.92375","-107.58634"
"250.80002","-2.92594","-107.81907"
"251.00002","-2.92844","-108.18133"
"251.20002","-2.93063","-108.41718"
"251.40002","-2.93297","-108.73606"
"251.60000","-2.93547","-109.01980"
"251.80002","-2.93781","-109.26919"
"252.00002","-2.94016","-109.51693"
"252.20002","-2.94250","-109.76267"
"252.40002","-2.94484","-110.04280"
"252.60000","-2.94719","-110.27336"
"252.80002","-2.94953","-110.42228"
"253.00002","-2.95188","-110.47033"
"253.20002","-2.95406","-110.61975"
"253.40002","-2.95625","-110.82969"
"253.60000","-2.95859","-111.00898"
"253.80002","-2.96094","-111.22892"
"254.00002","-2.96328","-111.49655"
"254.20002","-2.96578","-111.61905"
"254.40002","-2.96813","-111.76595"
"254.60000","-2.97047","-111.68691"
"254.80002","-2.97281","-111.79351"
"255.00002","-2.97516","-111.94277"
"255.20002","-2.97750","-112.14863"
"255.40002","-2.97984","-112.39499"
"255.60000","-2.98219","-112.56452"
"255.80002","-2.98437","-112.71889"
"256.00000","-2.98672","-112.88865"
"256.20002","-2.98906","-113.01861"
"256.40003","-2.99125","-113.19106"
"256.60000","-2.99359","-113.37340"
"256.80002","-2.99594","-113.54228"
"257.00000","-2.99828","-113.73969"
"257.20002","-3.00062","-113.93651"
"257.40003","-3.00297","-114.06454"
"257.60000","-3.00547","-114.23837"
"257.80002","-3.00766","-114.37773"
"258.00000","-3.01016","-114.56734"
"258.20002","-3.01250","-114.78901"
"258.40003","-3.01469","-114.92408"
"258.60000","-3.01719","-115.13235"
"258.80002","-3.01953","-115.29090"
"259.00000","-3.02172","-115.43426"
"259.20002","-3.02422","-115.65307"
"259.40003","-3.02641","-115.84739"
"259.60000","-3.02859","-115.93377"
"259.80002","-3.03094","-116.10456"
"260.00000","-3.03328","-116.29030"
"260.20002","-3.03562","-116.44126"
"260.40003","-3.03797","-116.58380"
"260.60000","-3.04047","-116.79922"
"260.80002","-3.04281","-116.91756"
"261.00000","-3.04500","-116.94591"
"261.20002","-3.04750","-117.13220"
"261.40003","-3.04984","-117.23771"
"261.60000","-3.05219","-117.36038"
"261.80002","-3.05453","-117.54856"
"262.00000","-3.05687","-117.64009"
"262.20000","-3.05922","-117.73985"
"262.40003","-3.06141","-117.85223"
"262.60000","-3.06359","-117.98376"
"262.80003","-3.06594","-118.12549"
"263.00000","-3.06828","-118.32152"
"263.20000","-3.07063","-118.47265"
"263.40003","-3.07297","-117.92044"
"263.60000","-3.07531","-117.87492"
"263.80003","-3.07781","-117.98859"
"264.00000","-3.08000","-118.05212"
"264.20000","-3.08250","-118.22876"
"264.40003","-3.08484","-118.34534"
"264.60000","-3.08719","-118.43824"
"264.80003","-3.08953","-118.54056"
"265.00000","-3.09187","-117.95841"
"265.20000","-3.09406","-117.37750"
"265.40003","-3.09625","-117.30657"
"265.60000","-3.09859","-117.38417"
"265.80003","-3.10094","-117.50847"
"266.00000","-3.10328","-117.50511"
"266.20000","-3.10578","-117.61875"
"266.40003","-3.10812","-117.74533"
"266.60000","-3.11031","-117.78733"
"266.80003","-3.11281","-117.93034"
"267.00000","-3.11516","-118.07654"
"267.20000","-3.11750","-118.17918"
"267.40003","-3.11984","-118.29187"
"267.60000","-3.12219","-118.39514"
"267.80003","-3.12453","-118.52428"
"268.00000","-3.12672","-118.61235"
"268.20000","-3.12922","-118.74946"
"268.40003","-3.13141","-118.83180"
"268.60000","-3.13359","-118.90545"
"268.80003","-3.13609","-119.05435"
"269.00000","-3.13828","-119.14057"
"269.20000","-3.14063","-119.27421"
"269.40003","-3.14312","-119.45710"
"269.60000","-3.14547","-119.56604"
"269.80003","-3.14781","-119.31029"
"270.00000","-3.15016","-119.29079"
"270.20000","-3.15250","-119.02253"
"270.40003","-3.15484","-118.95096"
"270.60000","-3.15719","-119.03420"
"270.80003","-3.15953","-119.16910"
"271.00000","-3.16188","-119.18735"
"271.20000","-3.16406","-119.20255"
"271.40003","-3.16625","-119.20974"
"271.60000","-3.16859","-118.92251"
"271.80003","-3.17094","-118.28844"
"272.00000","-3.17344","-118.21250"
"272.20000","-3.17578","-118.30523"
"272.40003","-3.17813","-118.34420"
"272.60000","-3.18047","-116.58875"
"272.80003","-3.18281","-116.39846"
"273.00000","-3.18516","-116.23346"
"273.20000","-3.18750","-116.14531"
"273.40003","-3.18984","-116.17112"
"273.60000","-3.19203","-116.13007"
"273.80003","-3.19437","-116.18970"
"274.00000","-3.19688","-111.61138"
"274.20000","-3.19906","-105.22463"
"274.40003","-3.20125","-105.16186"
"274.60000","-3.20359","-105.09521"
"274.80003","-3.20594","-105.09728"
"275.00000","-3.20828","-105.20962"
"275.20000","-3.21063","-105.23655"
"275.40003","-3.21297","-105.40032"
"275.60000","-3.21531","-105.38495"
"275.80003","-3.21781","-105.49475"
"276.00000","-3.22016","-105.68511"
"276.20000","-3.22234","-105.78607"
"276.40003","-3.22484","-105.93673"
"276.60000","-3.22719","-105.90191"
"276.80003","-3.22953","-105.98520"
"277.00000","-3.23188","-106.14723"
"277.20000","-3.23406","-106.23486"
"277.40003","-3.23641","-106.32291"
"277.60000","-3.23859","-106.42447"
"277.80003","-3.24094","-106.57371"
"278.00000","-3.24328","-106.69663"
"278.20000","-3.24562","-105.99690"
"278.40003","-3.24813","-105.98819"
"278.60000","-3.25047","-106.06038"
"278.80003","-3.25266","-106.09619"
"279.00000","-3.25516","-106.24092"
"279.20000","-3.25750","-106.27093"
"279.40003","-3.25984","-106.41999"
"279.60000","-3.26219","-106.48935"
"279.80003","-3.26453","-106.55640"
"279.81200","-3.26469","-106.58676"