File: Lab 4 Data/G2NC_0.5_DRY.csv
Text Inputs : Specimen label,"G2NC_0.5"
Test : Rate 1,"15.77685",mm/min
Dimension : Support span,"50.00000",mm
Dimension : Thickness,"2.64100",mm
Dimension : Width,"13.37000",mm

Time,Extension,Load
(sec),(mm),(N)
"0.00000","0.00000","-0.00620"
"0.05000","-0.00891","-0.06038"
"0.10000","-0.02344","-0.35804"
"0.15000","-0.03781","-0.62121"
"0.20000","-0.05188","-0.90531"
"0.25000","-0.06516","-1.15754"
"0.30000","-0.07859","-1.38966"
"0.35000","-0.09188","-1.59989"
"0.40000","-0.10516","-1.86885"
"0.45000","-0.11844","-2.10309"
"0.50000","-0.13141","-2.31486"
"0.55000","-0.14469","-2.55004"
"0.60000","-0.15781","-2.79065"
"0.65000","-0.17094","-3.00677"
"0.70000","-0.18406","-3.28852"
"0.75000","-0.19719","-3.47564"
"0.80000","-0.21016","-3.74201"
"0.85000","-0.22344","-3.97751"
"0.90000","-0.23641","-4.23012"
"0.95000","-0.24984","-4.46800"
"1.00000","-0.26312","-4.69166"
"1.05000","-0.27609","-4.92389"
"1.10000","-0.28938","-5.16319"
"1.15000","-0.30219","-5.38681"
"1.20000","-0.31547","-5.64441"
"1.25000","-0.32875","-5.89224"
"1.30000","-0.34172","-6.15541"
"1.35000","-0.35484","-6.35500"
"1.40000","-0.36797","-6.59301"
"1.45000","-0.38094","-6.84385"
"1.50000","-0.39422","-7.06742"
"1.55000","-0.40750","-7.32509"
"1.60000","-0.42063","-7.54530"
"1.65000","-0.43406","-7.80709"
"1.70000","-0.44687","-8.03345"
"1.75000","-0.46016","-8.28303"
"1.80000","-0.47328","-8.54087"
"1.85000","-0.48625","-8.78232"
"1.90000","-0.49969","-9.04183"
"1.95000","-0.51250","-9.28551"
"2.00000","-0.52594","-9.52415"
"2.05000","-0.53906","-9.77390"
"2.10000","-0.55203","-10.00068"
"2.15000","-0.56547","-10.25086"
"2.20000","-0.57844","-10.53122"
"2.25000","-0.59172","-10.73754"
"2.30000","-0.60500","-10.99715"
"2.35000","-0.61781","-11.25178"
"2.40000","-0.63109","-11.50698"
"2.45000","-0.64437","-11.72734"
"2.50000","-0.65734","-11.95426"
"2.55000","-0.67078","-12.21098"
"2.60000","-0.68359","-12.50388"
"2.65000","-0.69672","-12.69498"
"2.70000","-0.71000","-12.97596"
"2.75000","-0.72297","-13.20071"
"2.80000","-0.73641","-13.49550"
"2.85000","-0.74938","-13.76527"
"2.90000","-0.76250","-13.96302"
"2.95000","-0.77578","-14.23705"
"3.00000","-0.78891","-14.48146"
"3.05000","-0.80203","-14.71941"
"3.10000","-0.81516","-14.97958"
"3.15000","-0.82812","-15.20108"
"3.20000","-0.84141","-15.43224"
"3.25000","-0.85453","-15.69394"
"3.30000","-0.86750","-15.95607"
"3.35000","-0.88109","-16.20243"
"3.40000","-0.89391","-16.44069"
"3.45000","-0.90719","-16.65476"
"3.50000","-0.92047","-16.93090"
"3.55000","-0.93328","-17.17097"
"3.60000","-0.94672","-17.45137"
"3.65000","-0.95969","-17.64444"
"3.70000","-0.97281","-17.92495"
"3.75000","-0.98609","-18.16547"
"3.80000","-0.99891","-18.42033"
"3.85000","-1.01219","-18.68698"
"3.90000","-1.02547","-18.96422"
"3.95000","-1.03859","-19.18570"
"4.00000","-1.05188","-19.43430"
"4.05000","-1.06484","-19.70612"
"4.10000","-1.07797","-19.92392"
"4.15000","-1.09141","-20.21852"
"4.20000","-1.10422","-20.46502"
"4.25000","-1.11766","-20.68895"
"4.30000","-1.13063","-20.95387"
"4.35000","-1.14359","-21.23083"
"4.40000","-1.15703","-21.46196"
"4.45000","-1.16984","-21.71289"
"4.50000","-1.18328","-21.96604"
"4.55000","-1.19656","-22.23151"
"4.60000","-1.20953","-22.48011"
"4.65000","-1.22281","-22.71999"
"4.70000","-1.23594","-22.99582"
"4.75000","-1.24891","-23.24856"
"4.80000","-1.26234","-23.51196"
"4.85000","-1.27531","-23.72958"
"4.90000","-1.28828","-23.97896"
"4.95000","-1.30172","-24.25666"
"5.00000","-1.31453","-24.50784"
"5.05000","-1.32797","-24.76939"
"5.10000","-1.34094","-25.04168"
"5.15000","-1.35406","-25.29388"
"5.20000","-1.36750","-25.53805"
"5.25000","-1.38031","-25.80359"
"5.30000","-1.39359","-26.03356"
"5.35000","-1.40672","-26.28047"
"5.40000","-1.41984","-26.58670"
"5.45000","-1.43297","-26.81608"
"5.50000","-1.44609","-27.10890"
"5.55000","-1.45922","-27.34104"
"5.60000","-1.47250","-27.61934"
"5.65000","-1.48547","-27.86472"
"5.70000","-1.49875","-28.11888"
"5.75000","-1.51203","-28.39695"
"5.80000","-1.52500","-28.62398"
"5.85000","-1.53844","-28.85812"
"5.90000","-1.55109","-29.13354"
"5.95000","-1.56438","-29.40917"
"6.00000","-1.57781","-29.65325"
"6.05000","-1.59078","-29.95079"
"6.10000","-1.60406","-30.20138"
"6.15000","-1.61703","-30.43503"
"6.20000","-1.63016","-30.68380"
"6.25000","-1.64344","-30.94726"
"6.30000","-1.65656","-31.23096"
"6.35000","-1.66969","-31.48226"
"6.40000","-1.68313","-31.75644"
"6.45000","-1.69578","-31.99242"
"6.50000","-1.70922","-32.30888"
"6.55000","-1.72219","-32.53409"
"6.60000","-1.73516","-32.77426"
"6.65000","-1.74891","-33.05329"
"6.70000","-1.76141","-33.29222"
"6.75000","-1.77484","-33.55435"
"6.80000","-1.78797","-33.79895"
"6.85000","-1.80094","-34.07076"
"6.90000","-1.81453","-34.35704"
"6.95000","-1.82750","-34.58153"
"7.00000","-1.84062","-34.82683"
"7.05000","-1.85406","-35.12517"
"7.10000","-1.86687","-35.36640"
"7.15000","-1.88000","-35.59823"
"7.20000","-1.89344","-35.88800"
"7.25000","-1.90625","-36.17462"
"7.30000","-1.91969","-36.40002"
"7.35000","-1.93250","-36.64557"
"7.40000","-1.94563","-36.91844"
"7.45000","-1.95922","-37.18821"
"7.50000","-1.97188","-37.46678"
"7.55000","-1.98547","-37.70592"
"7.60000","-1.99844","-37.94711"
"7.65000","-2.01141","-38.22200"
"7.70000","-2.02484","-38.45465"
"7.75000","-2.03766","-38.74171"
"7.80000","-2.05094","-39.02811"
"7.85000","-2.06422","-39.29044"
"7.90000","-2.07719","-39.55425"
"7.95000","-2.09047","-39.80274"
"8.00000","-2.10344","-40.07652"
"8.05000","-2.11656","-40.34430"
"8.10000","-2.13016","-40.57475"
"8.15000","-2.14281","-40.84034"
"8.20000","-2.15625","-41.13327"
"8.25000","-2.16938","-41.41033"
"8.30000","-2.18203","-41.62929"
"8.35000","-2.19563","-41.90553"
"8.40000","-2.20859","-42.19111"
"8.45000","-2.22172","-42.39409"
"8.50000","-2.23516","-42.68152"
"8.55000","-2.24797","-42.97612"
"8.60000","-2.26125","-43.24413"
"8.65000","-2.27453","-43.49394"
"8.70000","-2.28750","-43.76306"
"8.75000","-2.30094","-43.98578"
"8.80000","-2.31391","-44.28175"
"8.85000","-2.32687","-44.50039"
"8.90000","-2.34047","-44.78884"
"8.95000","-2.35328","-45.00868"
"9.00000","-2.36656","-45.29775"
"9.05000","-2.37969","-45.52952"
"9.10000","-2.39266","-45.77294"
"9.15000","-2.40609","-46.02288"
"9.20000","-2.41891","-46.27799"
"9.25000","-2.43219","-46.50197"
"9.30000","-2.44547","-46.78682"
"9.35000","-2.45859","-47.04081"
"9.40000","-2.47188","-47.29209"
"9.45000","-2.48484","-47.55414"
"9.50000","-2.49781","-47.77009"
"9.55000","-2.51125","-48.06155"
"9.60000","-2.52422","-48.28876"
"9.65000","-2.53734","-48.54650"
"9.70000","-2.55063","-48.80193"
"9.75000","-2.56344","-49.05070"
"9.80000","-2.57688","-49.35804"
"9.85000","-2.59000","-49.58121"
"9.90000","-2.60313","-49.83349"
"9.95000","-2.61656","-50.09667"
"10.00000","-2.62938","-50.33359"
"10.05000","-2.64266","-50.60201"
"10.10000","-2.65578","-50.85585"
"10.15000","-2.66891","-51.12870"
"10.20000","-2.68219","-51.36013"
"10.25000","-2.69516","-51.61705"
"10.30000","-2.70813","-51.87296"
"10.35000","-2.72156","-52.14484"
"10.40000","-2.73437","-52.39256"
"10.45000","-2.74766","-52.64740"
"10.50000","-2.76109","-52.91136"
"10.55000","-2.77391","-53.13392"
"10.60000","-2.78734","-53.40031"
"10.65000","-2.80031","-53.61940"
"10.70000","-2.81344","-53.86263"
"10.75000","-2.82688","-54.13536"
"10.80000","-2.83969","-54.36782"
"10.85000","-2.85297","-54.61093"
"10.90000","-2.86609","-54.86294"
"10.95000","-2.87906","-55.10397"
"11.00000","-2.89250","-55.36348"
"11.05000","-2.90563","-55.59040"
"11.10000","-2.91875","-55.82363"
"11.15000","-2.93219","-56.07244"
"11.20000","-2.94500","-56.31172"
"11.25000","-2.95812","-56.54500"
"11.30000","-2.97125","-56.81445"
"11.35000","-2.98422","-57.05971"
"11.40000","-2.99781","-57.26052"
"11.45000","-3.01047","-57.49295"
"11.50000","-3.02375","-57.73743"
"11.55000","-3.03703","-57.98066"
"11.60000","-3.05000","-58.23505"
"11.65000","-3.06344","-58.49265"
"11.70000","-3.07656","-58.73512"
"11.75000","-3.08969","-58.94896"
"11.80000","-3.10313","-59.20743"
"11.85000","-3.11578","-59.44566"
"11.90000","-3.12891","-59.66976"
"11.95000","-3.14219","-59.88296"
"12.00000","-3.15516","-60.13915"
"12.05000","-3.16859","-60.43287"
"12.10000","-3.18156","-60.63637"
"12.15000","-3.19453","-60.89451"
"12.20000","-3.20813","-61.19066"
"12.25000","-3.22078","-61.41807"
"12.30000","-3.23438","-61.66244"
"12.35000","-3.24750","-61.88858"
"12.40000","-3.26047","-62.18085"
"12.45000","-3.27391","-62.40685"
"12.50000","-3.28672","-62.63322"
"12.55000","-3.30000","-62.90053"
"12.60000","-3.31328","-63.14928"
"12.65000","-3.32609","-63.40517"
"12.70000","-3.33938","-63.62930"
"12.75000","-3.35250","-63.86985"
"12.80000","-3.36547","-64.13812"
"12.85000","-3.37922","-64.38619"
"12.90000","-3.39187","-64.63148"
"12.95000","-3.40516","-64.87679"
"13.00000","-3.41844","-65.13950"
"13.05000","-3.43125","-65.39484"
"13.10000","-3.44469","-65.61031"
"13.15000","-3.45766","-65.85140"
"13.20000","-3.47078","-66.10062"
"13.25000","-3.48406","-66.37244"
"13.30000","-3.49688","-66.61683"
"13.35000","-3.51016","-66.83981"
"13.40000","-3.52359","-67.10032"
"13.45000","-3.53656","-67.34476"
"13.50000","-3.54984","-67.59694"
"13.55000","-3.56297","-67.82632"
"13.60000","-3.57594","-68.08358"
"13.65000","-3.58937","-68.30196"
"13.70000","-3.60219","-68.54581"
"13.75000","-3.61562","-68.79200"
"13.80000","-3.62875","-69.06675"
"13.85000","-3.64156","-69.25828"
"13.90000","-3.65500","-69.49698"
"13.95000","-3.66781","-69.78929"
"14.00000","-3.68125","-70.02291"
"14.05000","-3.69469","-70.25558"
"14.10000","-3.70750","-70.52628"
"14.15000","-3.72078","-70.77006"
"14.20000","-3.73391","-71.01082"
"14.25000","-3.74688","-71.25960"
"14.30000","-3.76016","-71.49639"
"14.35000","-3.77328","-71.76421"
"14.40000","-3.78641","-72.00825"
"14.45000","-3.79984","-72.24126"
"14.50000","-3.81234","-72.47013"
"14.55000","-3.82578","-72.73365"
"14.60000","-3.83906","-72.99451"
"14.65000","-3.85219","-73.19289"
"14.70000","-3.86563","-73.46822"
"14.75000","-3.87844","-73.75180"
"14.80000","-3.89172","-73.97585"
"14.85000","-3.90484","-74.19607"
"14.90000","-3.91781","-74.45322"
"14.95000","-3.93109","-74.73537"
"15.00000","-3.94422","-74.95252"
"15.05000","-3.95719","-75.17592"
"15.10000","-3.97047","-75.43330"
"15.15000","-3.98344","-75.67854"
"15.20000","-3.99672","-75.92358"
"15.25000","-4.01016","-76.16899"
"15.30000","-4.02297","-76.39757"
"15.35000","-4.03641","-76.64538"
"15.40000","-4.04922","-76.92970"
"15.45000","-4.06234","-77.13045"
"15.50000","-4.07578","-77.37096"
"15.55000","-4.08859","-77.64296"
"15.60000","-4.10188","-77.90648"
"15.65000","-4.11516","-78.13262"
"15.70000","-4.12797","-78.39134"
"15.75000","-4.14141","-78.63238"
"15.80000","-4.15453","-78.91544"
"15.85000","-4.16766","-79.11918"
"15.90000","-4.18109","-79.41647"
"15.95000","-4.19391","-79.63127"
"16.00000","-4.20703","-79.88431"
"16.05000","-4.22031","-80.12165"
"16.10000","-4.23328","-80.36364"
"16.15000","-4.24672","-80.60913"
"16.20000","-4.25953","-80.86223"
"16.25000","-4.27281","-81.08112"
"16.30000","-4.28594","-81.34428"
"16.35000","-4.29891","-81.56048"
"16.40000","-4.31234","-81.83496"
"16.45000","-4.32547","-82.10332"
"16.50000","-4.33875","-82.34994"
"16.55000","-4.35188","-82.59034"
"16.60000","-4.36484","-82.85117"
"16.65000","-4.37797","-83.09202"
"16.70000","-4.39125","-83.32272"
"16.75000","-4.40422","-83.55409"
"16.80000","-4.41750","-83.79165"
"16.85000","-4.43078","-84.04630"
"16.90000","-4.44359","-84.27043"
"16.95000","-4.45719","-84.50078"
"17.00000","-4.47000","-84.77774"
"17.05000","-4.48344","-84.99008"
"17.10000","-4.49656","-85.25144"
"17.15000","-4.50953","-85.43547"
"17.20000","-4.52266","-85.68530"
"17.25000","-4.53578","-85.89611"
"17.30000","-4.54891","-86.15474"
"17.35000","-4.56219","-86.35976"
"17.40000","-4.57516","-86.61338"
"17.45000","-4.58828","-86.81881"
"17.50000","-4.60156","-87.02031"
"17.55000","-4.61453","-87.23537"
"17.60000","-4.62797","-87.47665"
"17.65000","-4.64094","-87.70179"
"17.70000","-4.65406","-87.95904"
"17.75000","-4.66750","-88.16165"
"17.80000","-4.68016","-88.37839"
"17.85000","-4.69359","-88.58426"
"17.90000","-4.70672","-88.84312"
"17.95000","-4.71984","-89.04457"
"18.00000","-4.73297","-89.26960"
"18.05000","-4.74594","-89.51768"
"18.10000","-4.75922","-89.72352"
"18.15000","-4.77250","-89.91770"
"18.20000","-4.78563","-90.18139"
"18.25000","-4.79875","-90.41235"
"18.30000","-4.81203","-90.64453"
"18.35000","-4.82484","-90.84783"
"18.40000","-4.83844","-91.09798"
"18.45000","-4.85125","-91.35419"
"18.50000","-4.86453","-91.58667"
"18.55000","-4.87781","-91.80824"
"18.60000","-4.89062","-92.01196"
"18.65000","-4.90391","-92.24466"
"18.70000","-4.91688","-92.48341"
"18.75000","-4.93016","-92.68532"
"18.80000","-4.94359","-92.90633"
"18.85000","-4.95656","-93.13645"
"18.90000","-4.96984","-93.34772"
"18.95000","-4.98297","-93.57456"
"19.00000","-4.99594","-93.80641"
"19.05000","-5.00922","-93.98099"
"19.10000","-5.02234","-94.18370"
"19.15000","-5.03531","-94.42450"
"19.20000","-5.04875","-94.63950"
"19.25000","-5.06156","-94.87690"
"19.30000","-5.07484","-95.06704"
"19.35000","-5.08797","-95.30523"
"19.40000","-5.10109","-95.50683"
"19.45000","-5.11453","-95.74728"
"19.50000","-5.12750","-95.94859"
"19.55000","-5.14062","-96.19570"
"19.60000","-5.15375","-96.40475"
"19.65000","-5.16688","-96.61767"
"19.70000","-5.18016","-96.83711"
"19.75000","-5.19328","-97.03585"
"19.80000","-5.20625","-97.24261"
"19.85000","-5.21938","-97.41491"
"19.90000","-5.23250","-97.62872"
"19.95000","-5.24563","-97.81965"
"20.00000","-5.25922","-98.00239"
"20.05000","-5.27203","-98.21597"
"20.10000","-5.28531","-98.42604"
"20.15000","-5.29828","-98.62555"
"20.20000","-5.31141","-98.80858"
"20.25000","-5.32484","-99.00191"
"20.30000","-5.33766","-99.20754"
"20.35000","-5.35094","-99.38754"
"20.40000","-5.36406","-99.60600"
"20.45000","-5.37703","-99.80835"
"20.50000","-5.39031","-100.01326"
"20.55000","-5.40344","-100.26098"
"20.60000","-5.41656","-100.46563"
"20.65000","-5.43016","-100.68239"
"20.70000","-5.44297","-100.90442"
"20.75000","-5.45609","-101.10238"
"20.80000","-5.46938","-101.32032"
"20.85000","-5.48219","-101.55505"
"20.90000","-5.49563","-101.76237"
"20.95000","-5.50859","-101.94157"
"21.00000","-5.52172","-102.14052"
"21.05000","-5.53500","-102.32043"
"21.10000","-5.54797","-102.52508"
"21.15000","-5.56141","-102.73480"
"21.20000","-5.57453","-102.91252"
"21.25000","-5.58766","-103.11594"
"21.30000","-5.60094","-103.34508"
"21.35000","-5.61391","-103.56392"
"21.40000","-5.62703","-103.74205"
"21.45000","-5.64047","-103.97197"
"21.50000","-5.65328","-104.18978"
"21.55000","-5.66656","-104.40258"
"21.60000","-5.67969","-104.59185"
"21.65000","-5.69266","-104.79318"
"21.70000","-5.70609","-105.03358"
"21.75000","-5.71891","-105.21433"
"21.80000","-5.73234","-105.42456"
"21.85000","-5.74578","-105.63070"
"21.90000","-5.75844","-105.77030"
"21.95000","-5.77172","-105.98580"
"22.00000","-5.78484","-106.17242"
"22.05000","-5.79797","-106.35193"
"22.10000","-5.81125","-106.57877"
"22.15000","-5.82422","-106.75565"
"22.20000","-5.83734","-106.92410"
"22.25000","-5.85063","-107.12960"
"22.30000","-5.86359","-107.31743"
"22.35000","-5.87703","-107.51370"
"22.40000","-5.89016","-107.71300"
"22.45000","-5.90328","-107.87840"
"22.50000","-5.91656","-108.08204"
"22.55000","-5.92922","-108.27716"
"22.60000","-5.94250","-108.45048"
"22.65000","-5.95578","-108.58851"
"22.70000","-5.96891","-108.80326"
"22.75000","-5.98203","-108.94201"
"22.80000","-5.99500","-109.12152"
"22.85000","-6.00812","-109.29272"
"22.90000","-6.02156","-109.42732"
"22.95000","-6.03453","-109.64443"
"23.00000","-6.04766","-109.81231"
"23.05000","-6.06109","-109.99931"
"23.10000","-6.07391","-110.14696"
"23.15000","-6.08734","-110.36264"
"23.20000","-6.10031","-110.54367"
"23.25000","-6.11344","-110.74087"
"23.30000","-6.12672","-110.92423"
"23.35000","-6.13953","-111.10349"
"23.40000","-6.15297","-111.26383"
"23.45000","-6.16594","-111.47659"
"23.50000","-6.17922","-111.67360"
"23.55000","-6.19250","-111.87430"
"23.60000","-6.20562","-112.03409"
"23.65000","-6.21891","-112.20788"
"23.70000","-6.23203","-112.39170"
"23.75000","-6.24484","-112.56700"
"23.80000","-6.25812","-112.73148"
"23.85000","-6.27141","-112.92181"
"23.90000","-6.28438","-113.07461"
"23.95000","-6.29781","-113.25375"
"24.00000","-6.31047","-113.39129"
"24.05000","-6.32375","-113.57637"
"24.10000","-6.33703","-113.74609"
"24.15000","-6.35016","-113.87526"
"24.20000","-6.36359","-114.05257"
"24.25000","-6.37625","-114.20796"
"24.30000","-6.38953","-114.38222"
"24.35000","-6.40281","-114.58495"
"24.40000","-6.41578","-114.76248"
"24.45000","-6.42922","-114.96793"
"24.50000","-6.44234","-115.09416"
"24.55000","-6.45531","-115.26384"
"24.60000","-6.46844","-115.43409"
"24.65000","-6.48156","-115.60508"
"24.70000","-6.49469","-115.76775"
"24.75000","-6.50812","-115.98407"
"24.80000","-6.52094","-116.15036"
"24.85000","-6.53438","-116.33038"
"24.90000","-6.54734","-116.51429"
"24.95000","-6.56031","-116.68474"
"25.00000","-6.57391","-116.90759"
"25.05000","-6.58672","-117.06421"
"25.10000","-6.60000","-117.23384"
"25.15000","-6.61328","-117.42083"
"25.20000","-6.62609","-117.60759"
"25.25000","-6.63937","-117.76287"
"25.30000","-6.65250","-117.89835"
"25.35000","-6.66563","-118.04286"
"25.40000","-6.67906","-118.18085"
"25.45000","-6.69187","-118.30137"
"25.50000","-6.70500","-118.39177"
"25.55000","-6.71828","-118.55108"
"25.60000","-6.73125","-118.66482"
"25.65000","-6.74469","-118.82319"
"25.70000","-6.75766","-118.95336"
"25.75000","-6.77078","-119.13470"
"25.80000","-6.78406","-119.27589"
"25.85000","-6.79688","-119.41711"
"25.90000","-6.81047","-119.55212"
"25.95000","-6.82359","-119.71678"
"26.00000","-6.83672","-119.85805"
"26.05000","-6.85000","-119.98514"
"26.10000","-6.86281","-120.15902"
"26.15000","-6.87594","-120.28620"
"26.20000","-6.88937","-120.42223"
"26.25000","-6.90219","-120.61175"
"26.30000","-6.91563","-120.74498"
"26.35000","-6.92875","-120.90939"
"26.40000","-6.94141","-121.05869"
"26.45000","-6.95516","-121.22348"
"26.50000","-6.96797","-121.39280"
"26.55000","-6.98125","-121.52855"
"26.60000","-6.99469","-121.72719"
"26.65000","-7.00750","-121.83058"
"26.70000","-7.02078","-121.98114"
"26.75000","-7.03375","-122.15684"
"26.80000","-7.04688","-122.31613"
"26.85000","-7.06016","-122.47342"
"26.90000","-7.07312","-122.66709"
"26.95000","-7.08625","-122.79913"
"27.00000","-7.09953","-122.99898"
"27.05000","-7.11234","-123.12497"
"27.10000","-7.12656","-81.64929"
"27.15000","-7.13953","6.82279"
"27.20000","-7.15234","2.03831"
"27.25000","-7.16563","1.71738"
"27.30000","-7.17828","1.81638"
"27.35000","-7.19172","1.81572"
"27.40000","-7.20484","1.85901"
"27.45000","-7.21781","1.81301"
"27.50000","-7.23109","1.81819"
"27.55000","-7.24406","1.82787"
"27.60000","-7.25703","1.82435"
"27.65000","-7.27062","1.82613"
"27.70000","-7.28344","1.80684"
"27.75000","-7.29672","1.86151"
"27.80000","-7.31016","1.84482"
"27.85000","-7.32297","1.80813"
"27.90000","-7.33641","1.81627"
"27.95000","-7.34938","1.81746"
"28.00000","-7.36250","1.83676"
"28.05000","-7.37594","1.83345"
"28.10000","-7.38859","1.82673"
"28.15000","-7.40203","1.84742"
"28.20000","-7.41500","1.88321"
"28.25000","-7.42813","1.87025"
"28.30000","-7.44156","1.88214"
"28.35000","-7.45453","1.87882"
"28.40000","-7.46781","1.83272"
"28.45000","-7.48109","1.85766"
"28.50000","-7.49375","1.85147"
"28.55000","-7.50719","1.85702"
"28.60000","-7.52031","1.84234"
"28.65000","-7.53328","1.86689"
"28.70000","-7.54672","1.83199"
"28.75000","-7.55953","1.84421"
"28.80000","-7.57281","1.84222"
"28.85000","-7.58609","1.83366"
"28.90000","-7.59906","1.83832"
"28.95000","-7.61266","1.85673"
"29.00000","-7.62547","1.85169"
"29.05000","-7.63859","1.84373"
"29.10000","-7.65188","1.85144"
"29.15000","-7.66484","1.84472"
"29.20000","-7.67813","1.83937"
"29.25000","-7.69141","1.87985"
"29.30000","-7.70422","1.83465"
"29.35000","-7.71750","1.85542"
"29.40000","-7.73047","1.86703"
"29.45000","-7.74359","1.86847"
"29.50000","-7.75719","1.84063"
"29.55000","-7.77000","1.87070"
"29.60000","-7.78328","1.85921"
"29.65000","-7.79641","1.84286"
"29.70000","-7.80937","1.86588"
"29.75000","-7.82297","1.85555"
"29.80000","-7.83578","1.84617"
"29.85000","-7.84891","1.84134"
"29.87000","-7.85438","1.84026"