File: Lab 4 Data/G2NE_DRY.csv
Text Inputs : Specimen label,"G2NE_DRY"
Test : Rate 1,"1.30000",mm/min
Dimension : Support span,"50.00000",mm
Dimension : Thickness,"3.48000",mm
Dimension : Width,"13.81000",mm

Time,Extension,Load
(sec),(mm),(N)
"0.00000","0.00000","0.03773"
"0.30000","-0.00469","-0.19548"
"0.60000","-0.01297","-0.61704"
"0.90000","-0.01938","-0.89641"
"1.20000","-0.02594","-1.15613"
"1.50000","-0.03234","-1.43256"
"1.80000","-0.03891","-1.61748"
"2.10000","-0.04547","-1.87243"
"2.40000","-0.05203","-2.11342"
"2.70000","-0.05875","-2.37251"
"3.00000","-0.06516","-2.54994"
"3.30000","-0.07141","-2.84224"
"3.60000","-0.07781","-3.00885"
"3.90000","-0.08438","-3.35321"
"4.20000","-0.09109","-3.56931"
"4.50000","-0.09766","-3.82972"
"4.80000","-0.10391","-4.06019"
"5.10000","-0.11047","-4.40381"
"5.40000","-0.11703","-4.62513"
"5.70000","-0.12359","-4.87553"
"6.00000","-0.13016","-5.17149"
"6.30000","-0.13656","-5.40783"
"6.60000","-0.14297","-5.48995"
"6.90000","-0.14953","-5.39290"
"7.20000","-0.15625","-5.64493"
"7.50000","-0.16266","-5.95456"
"7.80000","-0.16891","-6.19487"
"8.10000","-0.17531","-6.44651"
"8.40000","-0.18203","-6.75469"
"8.70000","-0.18859","-7.02699"
"9.00000","-0.19516","-7.32491"
"9.30000","-0.20156","-7.57406"
"9.60000","-0.20797","-7.84435"
"9.90000","-0.21438","-8.08476"
"10.20000","-0.22094","-8.34677"
"10.50000","-0.22750","-8.59606"
"10.80000","-0.23406","-8.91684"
"11.10000","-0.24047","-9.12057"
"11.40000","-0.24688","-9.41914"
"11.70000","-0.25359","-9.62059"
"12.00000","-0.26000","-9.93017"
"12.30000","-0.26656","-10.15706"
"12.60000","-0.27313","-10.44773"
"12.90000","-0.27938","-10.64199"
"13.20000","-0.28594","-10.94454"
"13.50000","-0.29250","-11.18085"
"13.80000","-0.29922","-11.43245"
"14.10000","-0.30578","-11.73870"
"14.40000","-0.31188","-11.95401"
"14.70000","-0.31844","-12.21864"
"15.00000","-0.32500","-12.50507"
"15.30000","-0.33156","-12.71583"
"15.60000","-0.33813","-12.99261"
"15.90000","-0.34453","-13.22284"
"16.20000","-0.35094","-13.48718"
"16.50000","-0.35750","-13.74967"
"16.80000","-0.36422","-13.99158"
"17.10000","-0.37062","-14.25030"
"17.40000","-0.37688","-14.52627"
"17.70000","-0.38328","-14.77104"
"18.00000","-0.39000","-15.05783"
"18.30000","-0.39656","-15.28418"
"18.60000","-0.40313","-15.54079"
"18.90000","-0.40969","-15.77685"
"19.20000","-0.41594","-15.99089"
"19.50000","-0.42234","-16.25316"
"19.80000","-0.42891","-16.51559"
"20.10000","-0.43547","-16.70487"
"20.40000","-0.44219","-16.96889"
"20.70000","-0.44859","-17.26396"
"21.00000","-0.45500","-17.51428"
"21.30000","-0.46156","-17.77496"
"21.60000","-0.46797","-18.03867"
"21.90000","-0.47469","-18.25288"
"22.20000","-0.48109","-18.55315"
"22.50000","-0.48734","-18.80691"
"22.80000","-0.49391","-19.09401"
"23.10000","-0.50047","-19.35731"
"23.40000","-0.50719","-19.61576"
"23.70000","-0.51359","-19.88351"
"24.00000","-0.51984","-20.10268"
"24.30000","-0.52641","-20.38054"
"24.60000","-0.53297","-20.62318"
"24.90000","-0.53969","-20.90080"
"25.20000","-0.54609","-21.16253"
"25.50000","-0.55250","-21.42563"
"25.80000","-0.55891","-21.70345"
"26.10000","-0.56547","-21.95031"
"26.40000","-0.57219","-22.16688"
"26.70000","-0.57859","-22.43971"
"27.00000","-0.58500","-22.68233"
"27.30000","-0.59125","-22.94634"
"27.60000","-0.59797","-23.20422"
"27.90000","-0.60469","-23.45911"
"28.20000","-0.61125","-23.69211"
"28.50000","-0.61766","-23.95262"
"28.80000","-0.62391","-24.19447"
"29.10000","-0.63047","-24.42859"
"29.40000","-0.63703","-24.67444"
"29.70000","-0.64359","-24.95701"
"30.00000","-0.65016","-25.21912"
"30.30000","-0.65656","-25.46316"
"30.60000","-0.66297","-25.73706"
"30.90000","-0.66953","-25.96466"
"31.20000","-0.67594","-26.28383"
"31.50000","-0.68266","-26.54519"
"31.80000","-0.68906","-26.80151"
"32.10000","-0.69531","-27.03584"
"32.40000","-0.70188","-27.31279"
"32.70000","-0.70844","-27.58602"
"33.00000","-0.71516","-27.86839"
"33.30000","-0.72172","-28.11895"
"33.60000","-0.72797","-28.37464"
"33.90000","-0.73438","-28.62138"
"34.20000","-0.74094","-28.92086"
"34.50000","-0.74766","-29.18109"
"34.80000","-0.75422","-29.47018"
"35.10000","-0.76063","-29.70375"
"35.40000","-0.76703","-29.93440"
"35.70000","-0.77359","-30.24425"
"36.00000","-0.78016","-30.47917"
"36.30000","-0.78672","-30.74813"
"36.60000","-0.79297","-30.99068"
"36.90000","-0.79922","-31.19457"
"37.20000","-0.80609","-31.51825"
"37.50000","-0.81266","-31.76479"
"37.80000","-0.81922","-32.04707"
"38.10000","-0.82563","-32.26667"
"38.40000","-0.83188","-32.51302"
"38.70000","-0.83844","-32.75612"
"39.00000","-0.84500","-33.04285"
"39.30000","-0.85156","-33.28393"
"39.60000","-0.85812","-33.56546"
"39.90000","-0.86453","-33.76422"
"40.20000","-0.87094","-34.03118"
"40.50000","-0.87750","-34.29039"
"40.80000","-0.88406","-34.53440"
"41.10000","-0.89047","-34.78664"
"41.40000","-0.89719","-35.02496"
"41.70000","-0.90344","-35.27814"
"42.00000","-0.91000","-35.52738"
"42.30000","-0.91656","-35.79541"
"42.60000","-0.92313","-36.12126"
"42.90000","-0.92969","-36.32840"
"43.20000","-0.93594","-36.59006"
"43.50000","-0.94234","-36.84302"
"43.80000","-0.94906","-37.12502"
"44.10000","-0.95563","-37.40150"
"44.40000","-0.96219","-37.68246"
"44.70000","-0.96859","-37.90339"
"45.00000","-0.97500","-38.15929"
"45.30000","-0.98156","-38.39245"
"45.60000","-0.98812","-38.70170"
"45.90000","-0.99453","-38.94108"
"46.20000","-1.00094","-39.22977"
"46.50000","-1.00734","-39.48184"
"46.80000","-1.01406","-39.76763"
"47.10000","-1.02063","-40.07098"
"47.40000","-1.02719","-40.32673"
"47.70000","-1.03359","-40.58331"
"48.00000","-1.04000","-40.86819"
"48.30000","-1.04641","-41.09905"
"48.60000","-1.05281","-41.36146"
"48.90000","-1.05953","-41.62234"
"49.20000","-1.06609","-41.91532"
"49.50000","-1.07266","-42.20680"
"49.80000","-1.07891","-42.37396"
"50.10000","-1.08547","-42.66220"
"50.40000","-1.09203","-42.94101"
"50.70000","-1.09859","-43.18890"
"51.00000","-1.10516","-43.46821"
"51.30000","-1.11141","-43.76232"
"51.60000","-1.11797","-44.00644"
"51.90000","-1.12453","-44.22865"
"52.20000","-1.13109","-44.52038"
"52.50000","-1.13766","-44.73196"
"52.80000","-1.14391","-45.02803"
"53.10000","-1.15031","-45.29553"
"53.40000","-1.15688","-45.54335"
"53.70000","-1.16359","-45.78845"
"54.00000","-1.17016","-46.04535"
"54.30000","-1.17656","-46.29443"
"54.60000","-1.18297","-46.57028"
"54.90000","-1.18953","-46.82173"
"55.20000","-1.19609","-47.13770"
"55.50000","-1.20250","-47.37291"
"55.80000","-1.20906","-47.67706"
"56.10000","-1.21531","-47.87907"
"56.40000","-1.22203","-48.14257"
"56.70000","-1.22859","-48.43062"
"57.00000","-1.23516","-48.68667"
"57.30000","-1.24156","-48.94250"
"57.60000","-1.24797","-49.22080"
"57.90000","-1.25437","-49.46105"
"58.20000","-1.26109","-49.72364"
"58.50000","-1.26766","-49.98813"
"58.80000","-1.27422","-50.24985"
"59.10000","-1.28063","-50.52995"
"59.40000","-1.28687","-50.80158"
"59.70000","-1.29344","-51.09396"
"60.00000","-1.30000","-51.33246"
"60.30000","-1.30656","-51.59457"
"60.60000","-1.31313","-51.85017"
"60.90000","-1.31938","-52.11028"
"61.20000","-1.32594","-52.40605"
"61.50000","-1.33250","-52.61619"
"61.80000","-1.33922","-52.91122"
"62.10000","-1.34563","-53.13384"
"62.40000","-1.35188","-53.40281"
"62.70000","-1.35828","-53.64900"
"63.00000","-1.36484","-53.93360"
"63.30000","-1.37172","-54.19140"
"63.60000","-1.37828","-54.46146"
"63.90000","-1.38453","-54.72686"
"64.20000","-1.39094","-54.99865"
"64.50000","-1.39750","-55.25517"
"64.80000","-1.40422","-55.52938"
"65.10001","-1.41063","-55.80207"
"65.40000","-1.41719","-56.07639"
"65.70001","-1.42328","-56.33009"
"66.00000","-1.43000","-56.59686"
"66.30000","-1.43656","-56.84076"
"66.60001","-1.44313","-57.08611"
"66.90000","-1.44969","-57.34506"
"67.20001","-1.45594","-57.61977"
"67.50000","-1.46234","-57.87099"
"67.80000","-1.46906","-58.19279"
"68.10001","-1.47562","-58.46092"
"68.40000","-1.48219","-58.73651"
"68.70001","-1.48859","-59.01202"
"69.00000","-1.49484","-59.24713"
"69.30000","-1.50141","-59.48277"
"69.60001","-1.50797","-59.77275"
"69.90000","-1.51453","-60.04018"
"70.20001","-1.52109","-60.28586"
"70.50000","-1.52734","-60.53191"
"70.80000","-1.53391","-60.82701"
"71.10001","-1.54063","-61.08040"
"71.40000","-1.54719","-61.34615"
"71.70001","-1.55359","-61.63395"
"72.00000","-1.55984","-61.90083"
"72.30000","-1.56625","-62.13359"
"72.60001","-1.57297","-62.43686"
"72.90000","-1.57969","-62.74057"
"73.20001","-1.58609","-62.99860"
"73.50000","-1.59266","-63.25931"
"73.80000","-1.59891","-63.50560"
"74.10001","-1.60547","-63.75950"
"74.40000","-1.61203","-64.02206"
"74.70001","-1.61859","-64.26492"
"75.00000","-1.62516","-64.53761"
"75.30000","-1.63141","-64.79242"
"75.60001","-1.63797","-65.05122"
"75.90000","-1.64453","-65.35619"
"76.20001","-1.65109","-65.58636"
"76.50000","-1.65750","-65.87313"
"76.80000","-1.66391","-66.12642"
"77.10001","-1.67031","-66.37530"
"77.40000","-1.67703","-66.66411"
"77.70001","-1.68359","-66.89715"
"78.00000","-1.69016","-67.15817"
"78.30000","-1.69656","-67.43775"
"78.60001","-1.70281","-67.68105"
"78.90000","-1.70938","-67.99527"
"79.20001","-1.71594","-68.19980"
"79.50000","-1.72250","-68.46659"
"79.80000","-1.72922","-68.75905"
"80.10001","-1.73547","-69.02236"
"80.40000","-1.74203","-69.27595"
"80.70001","-1.74844","-69.59393"
"81.00001","-1.75516","-69.82940"
"81.30000","-1.76172","-70.10896"
"81.60001","-1.76781","-70.38280"
"81.90000","-1.77437","-70.63680"
"82.20001","-1.78094","-70.91734"
"82.50001","-1.78766","-71.16583"
"82.80000","-1.79422","-71.42755"
"83.10001","-1.80063","-71.68862"
"83.40000","-1.80687","-71.88850"
"83.70001","-1.81344","-72.20294"
"84.00001","-1.82016","-72.42216"
"84.30000","-1.82656","-72.71327"
"84.60001","-1.83313","-72.98840"
"84.90000","-1.83938","-73.26909"
"85.20001","-1.84609","-73.55618"
"85.50001","-1.85266","-73.81896"
"85.80000","-1.85922","-74.06438"
"86.10001","-1.86563","-74.31630"
"86.40000","-1.87203","-74.56554"
"86.70001","-1.87844","-74.80963"
"87.00001","-1.88500","-75.08222"
"87.30000","-1.89172","-75.35535"
"87.60001","-1.89813","-75.61136"
"87.90000","-1.90469","-75.88556"
"88.20001","-1.91094","-76.12236"
"88.50001","-1.91750","-76.39667"
"88.80000","-1.92391","-76.69918"
"89.10001","-1.93063","-76.95025"
"89.40000","-1.93719","-77.23224"
"89.70001","-1.94344","-77.51257"
"90.00001","-1.95000","-77.73569"
"90.30000","-1.95656","-78.05212"
"90.60001","-1.96313","-78.29494"
"90.90000","-1.96969","-78.56136"
"91.20001","-1.97594","-78.80566"
"91.50001","-1.98234","-79.04297"
"91.80000","-1.98891","-79.36081"
"92.10001","-1.99562","-79.62611"
"92.40000","-2.00219","-79.87779"
"92.70001","-2.00859","-80.09664"
"93.00001","-2.01484","-80.32778"
"93.30000","-2.02156","-80.69901"
"93.60001","-2.02813","-80.94550"
"93.90000","-2.03469","-81.20961"
"94.20001","-2.04109","-81.47834"
"94.50001","-2.04734","-81.72748"
"94.80000","-2.05406","-82.01505"
"95.10001","-2.06063","-82.26552"
"95.40000","-2.06719","-82.53173"
"95.70001","-2.07344","-82.78091"
"96.00001","-2.07984","-82.97053"
"96.30000","-2.08641","-83.26383"
"96.60001","-2.09313","-83.56517"
"96.90000","-2.09969","-83.83057"
"97.20001","-2.10609","-84.09656"
"97.50001","-2.11266","-84.34690"
"97.80000","-2.11891","-84.61095"
"98.10001","-2.12531","-84.86922"
"98.40000","-2.13188","-85.16806"
"98.70001","-2.13859","-85.39229"
"99.00001","-2.14516","-85.67900"
"99.30000","-2.15141","-85.94767"
"99.60001","-2.15797","-86.21106"
"99.90000","-2.16453","-86.46551"
"100.20001","-2.17125","-86.72263"
"100.50001","-2.17766","-86.97414"
"100.80000","-2.18391","-87.25333"
"101.10001","-2.19047","-87.50650"
"101.40000","-2.19703","-87.78607"
"101.70001","-2.20375","-88.02411"
"102.00001","-2.21016","-88.29948"
"102.30000","-2.21656","-88.60149"
"102.60001","-2.22281","-88.82005"
"102.90000","-2.22938","-89.09040"
"103.20001","-2.23609","-89.37703"
"103.50001","-2.24266","-89.59825"
"103.80000","-2.24906","-89.87988"
"104.10001","-2.25531","-90.15435"
"104.40000","-2.26203","-90.40084"
"104.70001","-2.26859","-90.66661"
"105.00001","-2.27516","-90.95815"
"105.30000","-2.28141","-91.19204"
"105.60001","-2.28797","-91.47247"
"105.90000","-2.29438","-91.70623"
"106.20001","-2.30094","-92.00594"
"106.50001","-2.30766","-92.26224"
"106.80000","-2.31406","-92.48969"
"107.10001","-2.32063","-92.76940"
"107.40000","-2.32703","-93.05897"
"107.70001","-2.33344","-93.26688"
"108.00001","-2.34000","-93.54236"
"108.30000","-2.34656","-93.80207"
"108.60001","-2.35313","-94.07253"
"108.90000","-2.35938","-94.32849"
"109.20001","-2.36594","-94.58359"
"109.50001","-2.37250","-94.86835"
"109.80000","-2.37906","-95.13891"
"110.10001","-2.38563","-95.39034"
"110.40000","-2.39188","-95.67565"
"110.70001","-2.39844","-95.92597"
"111.00001","-2.40500","-96.21002"
"111.30000","-2.41172","-96.45256"
"111.60001","-2.41828","-96.68716"
"111.90000","-2.42453","-96.95102"
"112.20001","-2.43078","-97.19169"
"112.50001","-2.43734","-97.47932"
"112.80000","-2.44422","-97.73770"
"113.10001","-2.45062","-98.00560"
"113.40001","-2.45719","-98.24590"
"113.70001","-2.46344","-98.51879"
"114.00001","-2.47000","-98.82318"
"114.30000","-2.47672","-99.06121"
"114.60001","-2.48313","-99.35411"
"114.90001","-2.48953","-99.59456"
"115.20001","-2.49594","-99.86044"
"115.50001","-2.50234","-100.10242"
"115.80000","-2.50906","-100.38154"
"116.10001","-2.51562","-100.67279"
"116.40001","-2.52219","-100.93505"
"116.70001","-2.52859","-101.14475"
"117.00001","-2.53484","-101.41959"
"117.30000","-2.54141","-101.65122"
"117.60001","-2.54797","-101.93327"
"117.90001","-2.55453","-102.23177"
"118.20001","-2.56125","-102.49863"
"118.50001","-2.56734","-102.71941"
"118.80000","-2.57391","-102.98727"
"119.10001","-2.58047","-103.24669"
"119.40001","-2.58719","-103.55450"
"119.70001","-2.59359","-103.79626"
"120.00001","-2.60000","-104.05708"
"120.30000","-2.60641","-104.27454"
"120.60001","-2.61297","-104.59043"
"120.90001","-2.61969","-104.82699"
"121.20001","-2.62625","-105.10365"
"121.50001","-2.63266","-105.33545"
"121.80000","-2.63875","-105.58788"
"122.10001","-2.64547","-105.80300"
"122.40001","-2.65219","-106.15412"
"122.70001","-2.65875","-106.39039"
"123.00001","-2.66516","-106.64658"
"123.30000","-2.67141","-106.89385"
"123.60001","-2.67797","-107.18547"
"123.90001","-2.68453","-107.41431"
"124.20001","-2.69109","-107.66123"
"124.50001","-2.69750","-107.95423"
"124.80000","-2.70391","-108.19688"
"125.10001","-2.71047","-108.44727"
"125.40001","-2.71703","-108.72453"
"125.70001","-2.72359","-108.98372"
"126.00001","-2.73016","-109.24486"
"126.30000","-2.73672","-109.51275"
"126.60001","-2.74281","-109.77586"
"126.90001","-2.74938","-110.05010"
"127.20001","-2.75609","-110.29700"
"127.50001","-2.76266","-110.55751"
"127.80000","-2.76922","-110.83389"
"128.10001","-2.77531","-111.09364"
"128.40001","-2.78187","-111.34515"
"128.70002","-2.78844","-111.60970"
"129.00000","-2.79516","-111.89454"
"129.30000","-2.80172","-112.11338"
"129.60001","-2.80812","-112.38853"
"129.90001","-2.81438","-112.64375"
"130.20002","-2.82109","-112.88762"
"130.50000","-2.82766","-113.15195"
"130.80000","-2.83422","-113.41143"
"131.10000","-2.84063","-113.68948"
"131.40002","-2.84672","-113.93026"
"131.70002","-2.85344","-114.22966"
"132.00000","-2.86016","-114.49397"
"132.30000","-2.86672","-114.71493"
"132.60000","-2.87313","-114.99668"
"132.90002","-2.87938","-115.23369"
"133.20002","-2.88594","-115.47663"
"133.50000","-2.89250","-115.74988"
"133.80000","-2.89906","-116.00646"
"134.10000","-2.90563","-116.22752"
"134.40002","-2.91188","-116.54275"
"134.70002","-2.91844","-116.77682"
"135.00000","-2.92500","-117.04107"
"135.30000","-2.93156","-117.30691"
"135.60000","-2.93828","-117.57188"
"135.90002","-2.94469","-117.82965"
"136.20002","-2.95094","-118.10230"
"136.50000","-2.95734","-118.36392"
"136.80000","-2.96406","-118.64276"
"137.10000","-2.97062","-118.83125"
"137.40002","-2.97719","-119.17249"
"137.70002","-2.98344","-119.39616"
"138.00000","-2.98984","-119.65347"
"138.30000","-2.99641","-119.89804"
"138.60000","-3.00313","-120.16246"
"138.90002","-3.00969","-120.43698"
"139.20002","-3.01609","-120.71297"
"139.50000","-3.02234","-120.97904"
"139.80000","-3.02906","-121.22170"
"140.10000","-3.03562","-121.48511"
"140.40002","-3.04219","-121.75377"
"140.70002","-3.04844","-122.01462"
"141.00000","-3.05469","-122.28243"
"141.30000","-3.06141","-122.50328"
"141.60000","-3.06813","-122.75897"
"141.90002","-3.07469","-123.05595"
"142.20002","-3.08109","-123.30367"
"142.50000","-3.08734","-123.52000"
"142.80000","-3.09391","-123.78735"
"143.10000","-3.10063","-124.03873"
"143.40002","-3.10703","-124.35344"
"143.70002","-3.11359","-124.59390"
"144.00000","-3.12000","-124.85684"
"144.30000","-3.12641","-125.11351"
"144.60000","-3.13297","-125.37814"
"144.90002","-3.13969","-125.60082"
"145.20002","-3.14609","-125.89235"
"145.50000","-3.15266","-126.11941"
"145.80000","-3.15891","-126.37327"
"146.10000","-3.16547","-126.60804"
"146.40002","-3.17203","-126.89425"
"146.70002","-3.17875","-127.13575"
"147.00000","-3.18516","-127.39073"
"147.30000","-3.19156","-127.63098"
"147.60000","-3.19797","-127.90436"
"147.90002","-3.20438","-128.13284"
"148.20002","-3.21109","-128.36442"
"148.50000","-3.21766","-128.63742"
"148.80000","-3.22406","-128.89289"
"149.10000","-3.23031","-129.13724"
"149.40002","-3.23687","-129.37454"
"149.70002","-3.24359","-129.64219"
"150.00000","-3.25016","-129.88986"
"150.30000","-3.25656","-130.11513"
"150.60000","-3.26281","-130.34760"
"150.90002","-3.26938","-130.58519"
"151.20002","-3.27609","-130.82254"
"151.50000","-3.28266","-131.11410"
"151.80000","-3.28922","-131.37639"
"152.10000","-3.29531","-131.58462"
"152.40002","-3.30203","-131.84298"
"152.70002","-3.30859","-132.10036"
"153.00000","-3.31516","-132.33645"
"153.30000","-3.32156","-132.61945"
"153.60000","-3.32797","-132.81093"
"153.90002","-3.33438","-133.05587"
"154.20002","-3.34094","-133.31878"
"154.50000","-3.34750","-133.53927"
"154.80000","-3.35406","-133.77034"
"155.10000","-3.36063","-134.00532"
"155.40002","-3.36687","-134.20236"
"155.70002","-3.37344","-134.45784"
"156.00000","-3.38000","-134.72133"
"156.30000","-3.38656","-134.93493"
"156.60000","-3.39313","-135.21827"
"156.90002","-3.39953","-135.43672"
"157.20002","-3.40594","-135.67838"
"157.50000","-3.41234","-135.90989"
"157.80000","-3.41906","-136.16266"
"158.10000","-3.42562","-136.39130"
"158.40002","-3.43203","-136.60434"
"158.70002","-3.43844","-136.83735"
"159.00000","-3.44500","-137.09239"
"159.30000","-3.45156","-137.28300"
"159.60000","-3.45828","-137.53488"
"159.90002","-3.46453","-137.78140"
"160.20002","-3.47078","-137.98892"
"160.50000","-3.47734","-138.23537"
"160.80000","-3.48422","-138.48074"
"161.10000","-3.49062","-138.73829"
"161.40002","-3.49719","-138.96559"
"161.70002","-3.50344","-139.18891"
"162.00002","-3.51000","-139.42635"
"162.30000","-3.51656","-139.64664"
"162.60000","-3.52313","-139.87415"
"162.90002","-3.52969","-140.14518"
"163.20002","-3.53609","-140.35840"
"163.50002","-3.54234","-140.56932"
"163.80000","-3.54891","-140.77672"
"164.10000","-3.55547","-140.99026"
"164.40002","-3.56203","-141.25153"
"164.70002","-3.56859","-141.47056"
"165.00002","-3.57484","-141.74143"
"165.30000","-3.58141","-141.94181"
"165.60000","-3.58813","-142.21280"
"165.90002","-3.59469","-142.46779"
"166.20002","-3.60125","-142.64449"
"166.50002","-3.60750","-142.87887"
"166.80000","-3.61391","-143.08278"
"167.10000","-3.62031","-143.37634"
"167.40002","-3.62703","-143.55903"
"167.70002","-3.63375","-143.80246"
"168.00002","-3.64000","-144.02970"
"168.30000","-3.64641","-144.21140"
"168.60000","-3.65297","-144.45988"
"168.90002","-3.65969","-144.68415"
"169.20002","-3.66625","-144.93653"
"169.50002","-3.67250","-145.13251"
"169.80000","-3.67891","-145.35377"
"170.10000","-3.68531","-145.64586"
"170.40002","-3.69219","-145.82086"
"170.70002","-3.69875","-146.05604"
"171.00002","-3.70516","-146.27357"
"171.30000","-3.71141","-146.48255"
"171.60000","-3.71797","-146.71413"
"171.90002","-3.72453","-146.92899"
"172.20002","-3.73109","-147.11143"
"172.50002","-3.73766","-147.38210"
"172.80000","-3.74406","-147.58377"
"173.10000","-3.75031","-147.77786"
"173.40002","-3.75703","-148.03690"
"173.70002","-3.76375","-148.25610"
"174.00002","-3.77016","-148.47396"
"174.30000","-3.77656","-148.69376"
"174.60000","-3.78297","-148.92163"
"174.90002","-3.78938","-149.09940"
"175.20002","-3.79609","-149.32885"
"175.50002","-3.80266","-149.54100"
"175.80000","-3.80922","-149.76502"
"176.10000","-3.81547","-149.96609"
"176.40002","-3.82187","-150.16334"
"176.70002","-3.82844","-150.36671"
"177.00002","-3.83500","-150.64357"
"177.30000","-3.84172","-150.84798"
"177.60000","-3.84812","-151.05057"
"177.90002","-3.85438","-151.26880"
"178.20002","-3.86094","-151.47779"
"178.50002","-3.86750","-151.76795"
"178.80000","-3.87422","-151.94165"
"179.10000","-3.88063","-152.22483"
"179.40002","-3.88687","-152.38338"
"179.70002","-3.89344","-152.58513"
"180.00002","-3.90016","-152.81738"
"180.30000","-3.90672","-153.01106"
"180.60000","-3.91328","-153.20939"
"180.90002","-3.91938","-153.40663"
"181.20002","-3.92594","-153.63071"
"181.50002","-3.93250","-153.85479"
"181.80000","-3.93922","-154.10210"
"182.10000","-3.94562","-154.32141"
"182.40002","-3.95203","-154.56794"
"182.70002","-3.95844","-154.72428"
"183.00002","-3.96484","-154.95272"
"183.30000","-3.97156","-155.15125"
"183.60000","-3.97797","-155.39780"
"183.90002","-3.98469","-155.58403"
"184.20002","-3.99094","-155.81290"
"184.50002","-3.99734","-156.01827"
"184.80000","-4.00406","-156.25160"
"185.10000","-4.01063","-156.44096"
"185.40002","-4.01719","-156.67049"
"185.70002","-4.02359","-156.90444"
"186.00002","-4.02984","-157.05893"
"186.30000","-4.03641","-157.28632"
"186.60000","-4.04313","-157.53465"
"186.90002","-4.04969","-157.74036"
"187.20002","-4.05609","-157.91440"
"187.50002","-4.06234","-158.16007"
"187.80000","-4.06906","-158.40983"
"188.10000","-4.07562","-158.58909"
"188.40002","-4.08219","-158.86126"
"188.70002","-4.08859","-159.01741"
"189.00002","-4.09484","-159.22632"
"189.30000","-4.10141","-159.41689"
"189.60000","-4.10813","-159.65687"
"189.90002","-4.11469","-159.89808"
"190.20002","-4.12125","-160.02784"
"190.50002","-4.12734","-160.27369"
"190.80000","-4.13391","-160.48456"
"191.10000","-4.14063","-160.73672"
"191.40002","-4.14719","-160.97108"
"191.70002","-4.15359","-161.14419"
"192.00002","-4.16016","-161.35944"
"192.30000","-4.16641","-161.57756"
"192.60000","-4.17297","-161.78174"
"192.90002","-4.17938","-162.00641"
"193.20002","-4.18594","-162.18243"
"193.50002","-4.19266","-162.38803"
"193.80000","-4.19891","-162.60337"
"194.10000","-4.20547","-162.84073"
"194.40002","-4.21203","-163.03238"
"194.70002","-4.21859","-163.25999"
"195.00002","-4.22531","-163.45549"
"195.30000","-4.23156","-163.67216"
"195.60000","-4.23781","-163.86710"
"195.90002","-4.24453","-164.08060"
"196.20002","-4.25094","-164.26237"
"196.50002","-4.25766","-164.49673"
"196.80000","-4.26406","-164.67623"
"197.10000","-4.27031","-164.85756"
"197.40002","-4.27687","-165.09557"
"197.70002","-4.28359","-165.30270"
"198.00002","-4.29016","-165.49688"
"198.30000","-4.29656","-165.70795"
"198.60000","-4.30281","-165.90970"
"198.90002","-4.30938","-166.12053"
"199.20002","-4.31609","-166.33378"
"199.50002","-4.32266","-166.54564"
"199.80000","-4.32906","-166.76812"
"200.10000","-4.33531","-166.92977"
"200.40002","-4.34188","-167.16408"
"200.70002","-4.34859","-167.39177"
"201.00002","-4.35516","-167.60193"
"201.30000","-4.36172","-167.79367"
"201.60000","-4.36812","-167.94557"
"201.90002","-4.37438","-168.14215"
"202.20002","-4.38094","-168.39929"
"202.50002","-4.38766","-168.59299"
"202.80000","-4.39406","-168.79853"
"203.10000","-4.40062","-169.00465"
"203.40002","-4.40703","-169.20296"
"203.70002","-4.41344","-169.40737"
"204.00002","-4.42000","-169.65754"
"204.30000","-4.42656","-169.88287"
"204.60000","-4.43328","-170.05539"
"204.90002","-4.43953","-170.26938"
"205.20002","-4.44578","-170.42993"
"205.50002","-4.45250","-170.66631"
"205.80000","-4.45906","-170.89270"
"206.10000","-4.46563","-171.07245"
"206.40002","-4.47219","-171.27695"
"206.70002","-4.47828","-171.46647"
"207.00002","-4.48484","-171.67259"
"207.30000","-4.49156","-171.88998"
"207.60000","-4.49813","-172.06023"
"207.90002","-4.50469","-172.32792"
"208.20002","-4.51094","-172.50298"
"208.50002","-4.51750","-172.68118"
"208.80000","-4.52406","-172.90428"
"209.10000","-4.53062","-173.12214"
"209.40002","-4.53719","-173.30481"
"209.70002","-4.54344","-173.50512"
"210.00002","-4.54984","-173.66584"
"210.30000","-4.55656","-173.91915"
"210.60000","-4.56313","-174.07265"
"210.90002","-4.56969","-174.30518"
"211.20002","-4.57609","-174.48679"
"211.50002","-4.58234","-174.67745"
"211.80000","-4.58891","-174.89366"
"212.10000","-4.59547","-175.08535"
"212.40002","-4.60203","-175.31155"
"212.70002","-4.60859","-175.51159"
"213.00002","-4.61500","-175.68626"
"213.30000","-4.62141","-175.86894"
"213.60000","-4.62797","-176.10233"
"213.90002","-4.63453","-176.29221"
"214.20002","-4.64109","-176.48740"
"214.50002","-4.64766","-176.65932"
"214.80000","-4.65375","-176.85212"
"215.10000","-4.66047","-177.05163"
"215.40002","-4.66703","-177.26144"
"215.70002","-4.67375","-177.49852"
"216.00002","-4.68016","-177.62642"
"216.30000","-4.68641","-177.84307"
"216.60000","-4.69297","-178.04863"
"216.90002","-4.69953","-178.23614"
"217.20002","-4.70625","-178.43861"
"217.50002","-4.71266","-178.61389"
"217.80000","-4.71891","-178.79857"
"218.10000","-4.72531","-178.98371"
"218.40002","-4.73203","-179.19417"
"218.70002","-4.73875","-179.36083"
"219.00002","-4.74516","-179.52716"
"219.30000","-4.75141","-179.72395"
"219.60000","-4.75781","-179.88492"
"219.90002","-4.76453","-180.09273"
"220.20002","-4.77109","-180.28796"
"220.50002","-4.77766","-180.47333"
"220.80000","-4.78406","-180.64594"
"221.10000","-4.79047","-180.78757"
"221.40002","-4.79688","-180.93616"
"221.70002","-4.80344","-181.09445"
"222.00002","-4.81016","-181.28226"
"222.30000","-4.81656","-181.41776"
"222.60000","-4.82312","-181.60181"
"222.90002","-4.82938","-181.73827"
"223.20002","-4.83594","-181.90131"
"223.50002","-4.84250","-182.06442"
"223.80000","-4.84922","-182.24658"
"224.10000","-4.85563","-182.40467"
"224.40002","-4.86187","-182.53732"
"224.70002","-4.86844","-182.75579"
"225.00002","-4.87500","-182.91643"
"225.30002","-4.88172","-183.10927"
"225.60000","-4.88813","-183.26659"
"225.90002","-4.89438","-183.42420"
"226.20002","-4.90078","-183.59296"
"226.50002","-4.90750","-183.76932"
"226.80002","-4.91422","-183.94172"
"227.10000","-4.92063","-184.09062"
"227.40002","-4.92703","-184.24513"
"227.70002","-4.93344","-184.38794"
"228.00002","-4.94000","-184.60140"
"228.30002","-4.94672","-184.74691"
"228.60000","-4.95313","-184.96685"
"228.90002","-4.95938","-185.07728"
"229.20002","-4.96578","-185.23157"
"229.50002","-4.97250","-185.43627"
"229.80002","-4.97906","-185.58906"
"230.10000","-4.98562","-185.80681"
"230.40002","-4.99219","-185.93557"
"230.70002","-4.99844","-186.09880"
"231.00002","-5.00484","-186.29568"
"231.30002","-5.01156","-186.42345"
"231.60000","-5.01813","-186.55580"
"231.90002","-5.02453","-186.70034"
"232.20002","-5.03109","-186.86911"
"232.50002","-5.03734","-187.01203"
"232.80002","-5.04406","-187.17473"
"233.10000","-5.05063","-187.34159"
"233.40002","-5.05719","-187.54043"
"233.70002","-5.06359","-187.68879"
"234.00002","-5.06984","-187.88818"
"234.30002","-5.07641","-188.03934"
"234.60000","-5.08313","-188.29217"
"234.90002","-5.08969","-188.45804"
"235.20002","-5.09609","-188.63881"
"235.50002","-5.10234","-188.79957"
"235.80002","-5.10891","-188.92275"
"236.10000","-5.11547","-189.16368"
"236.40002","-5.12219","-189.34712"
"236.70002","-5.12875","-189.52822"
"237.00002","-5.13516","-189.70795"
"237.30002","-5.14141","-189.83841"
"237.60000","-5.14812","-190.11958"
"237.90002","-5.15469","-190.27304"
"238.20002","-5.16109","-190.43649"
"238.50002","-5.16750","-190.64222"
"238.80002","-5.17375","-190.82977"
"239.10000","-5.18047","-191.04894"
"239.40002","-5.18703","-191.22966"
"239.70002","-5.19359","-191.35382"
"240.00002","-5.20016","-191.54400"
"240.30002","-5.20641","-191.67481"
"240.60000","-5.21297","-191.88676"
"240.90002","-5.21953","-192.06528"
"241.20002","-5.22609","-192.28280"
"241.50002","-5.23266","-192.47403"
"241.80002","-5.23906","-192.63957"
"242.10000","-5.24547","-192.84919"
"242.40002","-5.25203","-193.02856"
"242.70002","-5.25844","-193.21799"
"243.00002","-5.26516","-193.37351"
"243.30002","-5.27156","-193.50780"
"243.60000","-5.27781","-193.72109"
"243.90002","-5.28453","-193.88655"
"244.20002","-5.29109","-194.08803"
"244.50002","-5.29766","-194.26968"
"244.80002","-5.30422","-194.43132"
"245.10000","-5.31031","-194.57951"
"245.40002","-5.31687","-194.76943"
"245.70002","-5.32344","-194.96409"
"246.00002","-5.33016","-195.12590"
"246.30002","-5.33672","-195.24276"
"246.60000","-5.34313","-195.42713"
"246.90002","-5.34938","-195.59501"
"247.20002","-5.35609","-195.76866"
"247.50002","-5.36266","-195.86276"
"247.80002","-5.36906","-195.93619"
"248.10000","-5.37563","-195.98324"
"248.40002","-5.38188","-196.07743"
"248.70002","-5.38844","-196.22888"
"249.00002","-5.39516","-196.34087"
"249.30002","-5.40172","-196.43473"
"249.60000","-5.40797","-196.61572"
"249.90002","-5.41438","-196.72701"
"250.20002","-5.42078","-196.92572"
"250.50002","-5.42750","-197.04374"
"250.80002","-5.43406","-197.22231"
"251.10000","-5.44062","-197.35875"
"251.40002","-5.44719","-197.53296"
"251.70002","-5.45344","-197.63639"
"252.00002","-5.46000","-197.76937"
"252.30002","-5.46641","-197.91344"
"252.60000","-5.47313","-198.07346"
"252.90002","-5.47969","-198.22760"
"253.20002","-5.48594","-198.33978"
"253.50002","-5.49234","-198.50513"
"253.80002","-5.49906","-198.63917"
"254.10000","-5.50563","-198.75998"
"254.40002","-5.51219","-198.85968"
"254.70002","-5.51844","-199.04193"
"255.00002","-5.52484","-199.16356"
"255.30002","-5.53141","-199.33261"
"255.60000","-5.53813","-199.45757"
"255.90002","-5.54469","-199.57995"
"256.20002","-5.55109","-199.72686"
"256.50000","-5.55750","-199.82340"
"256.80002","-5.56406","-200.00705"
"257.10000","-5.57062","-200.08733"
"257.40003","-5.57703","-200.20533"
"257.70002","-5.58359","-200.38161"
"258.00000","-5.58984","-200.51964"
"258.30002","-5.59656","-200.70685"
"258.60000","-5.60313","-200.83830"
"258.90003","-5.60969","-200.97423"
"259.20002","-5.61609","-201.14599"
"259.50000","-5.62234","-201.20054"
"259.80002","-5.62891","-201.41590"
"260.10000","-5.63563","-201.54014"
"260.40003","-5.64219","-201.69014"
"260.70002","-5.64859","-201.80868"
"261.00000","-5.65500","-201.93134"
"261.30002","-5.66141","-201.98606"
"261.60000","-5.66797","-202.08441"
"261.90003","-5.67438","-202.13921"
"262.20000","-5.68109","-202.29572"
"262.50000","-5.68766","-202.47690"
"262.80003","-5.69391","-202.57888"
"263.10000","-5.70047","-202.82090"
"263.40003","-5.70703","-203.00195"
"263.70000","-5.71359","-203.19043"
"264.00000","-5.72016","-203.38304"
"264.30003","-5.72641","-203.50892"
"264.60000","-5.73281","-203.69306"
"264.90003","-5.73938","-203.86206"
"265.20000","-5.74625","-204.07638"
"265.50000","-5.75266","-204.17480"
"265.80003","-5.75906","-204.36840"
"266.10000","-5.76547","-204.55044"
"266.40003","-5.77203","-204.72985"
"266.70000","-5.77859","-204.89601"
"267.00000","-5.78516","-205.06633"
"267.30003","-5.79172","-205.20326"
"267.60000","-5.79781","-205.40755"
"267.90003","-5.80453","-205.60253"
"268.20000","-5.81109","-205.73191"
"268.50000","-5.81766","-205.86921"
"268.80003","-5.82406","-206.03184"
"269.10000","-5.83047","-206.17403"
"269.40003","-5.83688","-206.39904"
"269.70000","-5.84344","-206.57133"
"270.00000","-5.85016","-206.72463"
"270.30003","-5.85672","-206.86416"
"270.60000","-5.86312","-207.01688"
"270.90003","-5.86938","-207.15313"
"271.20000","-5.87594","-207.32062"
"271.50000","-5.88250","-207.49729"
"271.80003","-5.88906","-207.67050"
"272.10000","-5.89562","-207.79179"
"272.40003","-5.90187","-207.96591"
"272.70000","-5.90844","-208.09954"
"273.00000","-5.91500","-208.25509"
"273.30003","-5.92172","-208.32747"
"273.60000","-5.92813","-208.44590"
"273.90003","-5.93437","-208.44968"
"274.20000","-5.94078","-208.46926"
"274.50000","-5.94750","-208.54771"
"274.80003","-5.95422","-208.59532"
"275.10000","-5.96063","-208.71596"
"275.40003","-5.96703","-208.81429"
"275.70000","-5.97344","-208.90042"
"276.00000","-5.98000","-209.08825"
"276.30003","-5.98672","-209.19088"
"276.60000","-5.99313","-209.31188"
"276.90003","-5.99969","-209.38462"
"277.20000","-6.00578","-209.51593"
"277.50000","-6.01250","-209.66446"
"277.80003","-6.01906","-209.74847"
"278.10000","-6.02562","-209.82623"
"278.40003","-6.03203","-209.91521"
"278.70000","-6.03844","-210.04450"
"279.00000","-6.04484","-210.18831"
"279.30003","-6.05141","-210.33337"
"279.60000","-6.05813","-210.44085"
"279.90003","-6.06469","-210.56419"
"280.20000","-6.07109","-210.69547"
"280.50000","-6.07750","-210.81042"
"280.80003","-6.08391","-210.93171"
"281.10000","-6.09047","-211.09365"
"281.40003","-6.09719","-211.12390"
"281.70000","-6.10359","-211.28826"
"282.00000","-6.11000","-211.38942"
"282.30003","-6.11641","-211.51310"
"282.60000","-6.12297","-211.62968"
"282.90003","-6.12969","-211.74785"
"283.20000","-6.13609","-211.87231"
"283.50000","-6.14234","-211.95844"
"283.80003","-6.14891","-212.07701"
"284.10000","-6.15547","-212.21755"
"284.40003","-6.16219","-212.32489"
"284.70000","-6.16859","-212.42343"
"285.00000","-6.17500","-212.50827"
"285.30003","-6.18141","-212.63976"
"285.60000","-6.18797","-212.79085"
"285.90003","-6.19469","-212.90850"
"286.20000","-6.20109","-212.97343"
"286.50000","-6.20766","-213.12138"
"286.80003","-6.21391","-213.23549"
"287.10000","-6.22047","-213.37161"
"287.40003","-6.22719","-213.46804"
"287.70000","-6.23359","-213.59580"
"288.00000","-6.24000","-213.70323"
"288.30003","-6.24641","-213.79801"
"288.60000","-6.25297","-213.90209"
"288.90003","-6.25953","-213.94173"
"289.20000","-6.26625","-213.96196"
"289.50000","-6.27281","-214.08632"
"289.80003","-6.27906","-214.15209"
"290.10000","-6.28531","-214.26963"
"290.40003","-6.29188","-214.34894"
"290.70000","-6.29844","-214.55042"
"291.00000","-6.30500","-214.70841"
"291.30003","-6.31172","-214.83140"
"291.60000","-6.31797","-214.99457"
"291.90003","-6.32453","-215.14913"
"292.20000","-6.33094","-215.31586"
"292.50000","-6.33766","-215.50180"
"292.80003","-6.34406","-215.60708"
"293.10000","-6.35047","-215.76352"
"293.40003","-6.35687","-215.90794"
"293.70000","-6.36344","-216.11357"
"294.00000","-6.37016","-216.26858"
"294.30003","-6.37672","-216.39764"
"294.60000","-6.38313","-216.52712"
"294.90003","-6.38937","-216.65312"
"295.20000","-6.39594","-216.86109"
"295.50000","-6.40266","-217.00529"
"295.80003","-6.40922","-217.13145"
"296.10000","-6.41563","-217.27148"
"296.40003","-6.42188","-217.41459"
"296.70000","-6.42859","-217.62287"
"297.00000","-6.43500","-217.72448"
"297.30003","-6.44156","-217.83901"
"297.60000","-6.44797","-217.98488"
"297.90003","-6.45438","-218.07496"
"298.20000","-6.46094","-218.23788"
"298.50000","-6.46750","-218.43396"
"298.80003","-6.47422","-218.50444"
"299.10000","-6.48062","-218.65027"
"299.40003","-6.48703","-218.77542"
"299.70000","-6.49344","-218.88839"
"300.00000","-6.49984","-219.04463"
"300.30003","-6.50656","-219.20519"
"300.60000","-6.51313","-219.31982"
"300.90003","-6.51969","-219.25801"
"301.20000","-6.52594","-219.11483"
"301.50000","-6.53250","-219.08315"
"301.80003","-6.53906","-219.12271"
"302.10000","-6.54563","-219.20430"
"302.40003","-6.55219","-219.28288"
"302.70000","-6.55859","-219.33630"
"303.00000","-6.56484","-219.43077"
"303.30003","-6.57156","-219.54512"
"303.60000","-6.57828","-219.61458"
"303.90003","-6.58469","-219.71585"
"304.20000","-6.59094","-219.78226"
"304.50000","-6.59719","-219.84668"
"304.80003","-6.60391","-219.97876"
"305.10000","-6.61062","-220.02142"
"305.40003","-6.61719","-220.17822"
"305.70000","-6.62359","-220.26170"
"306.00000","-6.63000","-220.34980"
"306.30003","-6.63641","-220.47795"
"306.60000","-6.64312","-220.57511"
"306.90003","-6.64953","-220.64216"
"307.20000","-6.65594","-220.77017"
"307.50000","-6.66234","-220.83342"
"307.80003","-6.66891","-220.93643"
"308.10000","-6.67547","-221.03818"
"308.40003","-6.68203","-221.11656"
"308.70000","-6.68859","-221.19442"
"309.00000","-6.69516","-221.31532"
"309.30003","-6.70141","-221.40875"
"309.60000","-6.70781","-221.53303"
"309.90003","-6.71453","-221.65421"
"310.20000","-6.72109","-221.76769"
"310.50000","-6.72766","-221.85855"
"310.80003","-6.73391","-221.92065"
"311.10000","-6.74047","-222.02021"
"311.40003","-6.74688","-222.13984"
"311.70000","-6.75359","-222.24467"
"312.00000","-6.76016","-222.32467"
"312.30003","-6.76656","-222.40842"
"312.60000","-6.77281","-222.54657"
"312.90003","-6.77953","-222.65678"
"313.20000","-6.78609","-222.79860"
"313.50000","-6.79266","-222.84793"
"313.80003","-6.79906","-222.91405"
"314.10000","-6.80531","-222.97420"
"314.40003","-6.81187","-223.11999"
"314.70000","-6.81859","-223.21539"
"315.00000","-6.82516","-223.20492"
"315.30003","-6.83172","-223.20149"
"315.60000","-6.83781","-223.21872"
"315.90003","-6.84453","-223.33411"
"316.20000","-6.85109","-223.46741"
"316.50000","-6.85766","-223.53806"
"316.80003","-6.86406","-223.67382"
"317.10000","-6.87047","-223.76820"
"317.40003","-6.87703","-223.92210"
"317.70000","-6.88359","-224.09918"
"318.00000","-6.89016","-224.25737"
"318.30003","-6.89672","-224.39614"
"318.60000","-6.90312","-224.50853"
"318.90003","-6.90938","-224.64944"
"319.20000","-6.91594","-224.80117"
"319.50000","-6.92250","-224.96788"
"319.80003","-6.92906","-225.07913"
"320.10000","-6.93562","-225.18024"
"320.40003","-6.94203","-225.27210"
"320.70000","-6.94844","-225.42564"
"321.00000","-6.95484","-225.56784"
"321.30003","-6.96156","-225.67207"
"321.60000","-6.96813","-225.77699"
"321.90003","-6.97453","-225.90568"
"322.20000","-6.98078","-226.05382"
"322.50003","-6.98750","-226.25837"
"322.80003","-6.99406","-226.35894"
"323.10000","-7.00063","-226.46064"
"323.40003","-7.00703","-226.57849"
"323.70000","-7.01328","-226.69476"
"324.00003","-7.01984","-226.88387"
"324.30003","-7.02672","-227.00243"
"324.60000","-7.03313","-227.12290"
"324.90003","-7.03969","-227.21063"
"325.20000","-7.04594","-227.21982"
"325.50003","-7.05250","-227.29862"
"325.80003","-7.05891","-227.15686"
"326.10000","-7.06547","-226.96165"
"326.40003","-7.07203","-226.90795"
"326.70000","-7.07844","-226.95281"
"327.00003","-7.08500","-227.04301"
"327.30003","-7.09156","-227.10292"
"327.60000","-7.09812","-227.15976"
"327.90003","-7.10469","-227.19335"
"328.20000","-7.11109","-227.23770"
"328.50003","-7.11734","-227.30047"
"328.80003","-7.12391","-227.39096"
"329.10000","-7.13063","-227.46855"
"329.40003","-7.13719","-227.53239"
"329.70000","-7.14359","-227.54636"
"330.00003","-7.15000","-227.64532"
"330.30003","-7.15641","-227.70785"
"330.60000","-7.16281","-227.85529"
"330.90003","-7.16953","-227.93310"
"331.20000","-7.17625","-228.03413"
"331.50003","-7.18250","-228.04363"
"331.80003","-7.18891","-228.13033"
"332.10000","-7.19547","-228.21605"
"332.40003","-7.20219","-228.27923"
"332.70000","-7.20875","-228.31056"
"333.00003","-7.21500","-228.41549"
"333.30003","-7.22125","-228.45624"
"333.60000","-7.22781","-228.57049"
"333.90003","-7.23469","-228.67111"
"334.20000","-7.24125","-228.72427"
"334.50003","-7.24766","-228.80372"
"334.80003","-7.25391","-228.87763"
"335.10000","-7.26047","-229.04998"
"335.40003","-7.26703","-229.11586"
"335.70000","-7.27359","-229.18105"
"336.00003","-7.28016","-229.25047"
"336.30003","-7.28656","-229.30194"
"336.60000","-7.29297","-229.30516"
"336.90003","-7.29938","-229.30164"
"337.20000","-7.30609","-229.20873"
"337.50003","-7.31266","-229.11705"
"337.80003","-7.31922","-229.17613"
"338.10000","-7.32547","-229.24036"
"338.40003","-7.33203","-229.36743"
"338.70000","-7.33859","-229.54090"
"339.00003","-7.34516","-229.64604"
"339.30003","-7.35172","-229.76896"
"339.60000","-7.35797","-229.83987"
"339.90003","-7.36438","-229.97310"
"340.20000","-7.37078","-230.10803"
"340.50003","-7.37750","-230.20200"
"340.80003","-7.38422","-230.36176"
"341.10000","-7.39062","-230.48470"
"341.40003","-7.39687","-230.62797"
"341.70000","-7.40344","-230.73325"
"342.00003","-7.41016","-230.89299"
"342.30003","-7.41672","-230.96681"
"342.60000","-7.42313","-231.03403"
"342.90003","-7.42922","-231.17689"
"343.20000","-7.43578","-231.30149"
"343.50003","-7.44266","-231.45968"
"343.80003","-7.44922","-231.60668"
"344.10000","-7.45563","-231.69929"
"344.40003","-7.46188","-231.78499"
"344.70000","-7.46844","-231.93197"
"345.00003","-7.47516","-232.06828"
"345.30003","-7.48156","-232.16229"
"345.60000","-7.48813","-232.29387"
"345.90003","-7.49453","-232.34392"
"346.20000","-7.50094","-232.42868"
"346.50003","-7.50750","-232.46551"
"346.80003","-7.51406","-232.38907"
"347.10000","-7.52062","-232.06981"
"347.40003","-7.52703","-231.84780"
"347.70000","-7.53344","-231.83597"
"348.00003","-7.54000","-231.83981"
"348.30003","-7.54656","-231.89658"
"348.60000","-7.55313","-231.87555"
"348.90003","-7.55969","-231.87522"
"349.20000","-7.56594","-231.95468"
"349.50003","-7.57234","-232.04561"
"349.80003","-7.57875","-232.05919"
"350.10000","-7.58547","-232.15920"
"350.40003","-7.59219","-232.18213"
"350.70000","-7.59859","-232.19934"
"351.00003","-7.60484","-232.21094"
"351.30003","-7.61141","-232.32603"
"351.60000","-7.61813","-232.36273"
"351.90003","-7.62469","-232.36958"
"352.20000","-7.63109","-232.42885"
"352.50003","-7.63734","-232.49006"
"352.80003","-7.64391","-232.55266"
"353.10000","-7.65062","-232.64967"
"353.40003","-7.65719","-232.72127"
"353.70000","-7.66375","-232.82396"
"354.00003","-7.66984","-232.84940"
"354.30003","-7.67641","-232.96431"
"354.60000","-7.68297","-233.04537"
"354.90003","-7.68953","-233.07174"
"355.20000","-7.69609","-233.08329"
"355.50003","-7.70250","-233.15802"
"355.80003","-7.70891","-233.24447"
"356.10000","-7.71547","-233.31447"
"356.40003","-7.72203","-233.30761"
"356.70000","-7.72859","-233.38923"
"357.00003","-7.73516","-233.44973"
"357.30003","-7.74141","-233.44319"
"357.60000","-7.74797","-233.38189"
"357.90003","-7.75453","-233.25589"
"358.20000","-7.76109","-233.07487"
"358.50003","-7.76766","-233.01113"
"358.80003","-7.77391","-233.03336"
"359.10000","-7.78031","-233.14424"
"359.40003","-7.78688","-233.27036"
"359.70000","-7.79359","-233.32378"
"360.00003","-7.80016","-233.43153"
"360.30003","-7.80672","-233.56371"
"360.60000","-7.81281","-233.67787"
"360.90003","-7.81953","-233.85487"
"361.20000","-7.82609","-233.96894"
"361.50003","-7.83266","-234.01370"
"361.80003","-7.83906","-234.11483"
"362.10000","-7.84531","-234.22036"
"362.40003","-7.85188","-234.33585"
"362.70000","-7.85859","-234.43423"
"363.00003","-7.86516","-234.52017"
"363.30003","-7.87172","-234.61118"
"363.60000","-7.87781","-234.70864"
"363.90003","-7.88437","-234.86529"
"364.20000","-7.89094","-234.98576"
"364.50003","-7.89766","-235.11264"
"364.80003","-7.90422","-235.24011"
"365.10000","-7.91063","-235.39105"
"365.40003","-7.91688","-235.48706"
"365.70000","-7.92344","-235.61111"
"366.00003","-7.93000","-235.67215"
"366.30003","-7.93656","-235.79823"
"366.60000","-7.94313","-235.84319"
"366.90003","-7.94953","-235.77040"
"367.20000","-7.95594","-235.53381"
"367.50003","-7.96250","-235.10925"
"367.80003","-7.96906","-234.92889"
"368.10000","-7.97578","-234.88354"
"368.40003","-7.98203","-234.90380"
"368.70000","-7.98828","-234.94406"
"369.00003","-7.99484","-235.06200"
"369.30003","-8.00156","-235.03777"
"369.60000","-8.00813","-235.09638"
"369.90003","-8.01453","-235.12922"
"370.20000","-8.02094","-235.18387"
"370.50003","-8.02750","-235.22349"
"370.80003","-8.03422","-235.27876"
"371.10000","-8.04078","-235.21930"
"371.40003","-8.04703","-235.28108"
"371.70000","-8.05328","-235.31556"
"372.00003","-8.05984","-235.43784"
"372.30003","-8.06672","-235.48942"
"372.60000","-8.07313","-235.48169"
"372.90003","-8.07969","-235.54642"
"373.20000","-8.08578","-235.54413"
"373.50003","-8.09234","-235.66145"
"373.80003","-8.09906","-235.69627"
"374.10000","-8.10563","-235.68509"
"374.40003","-8.11219","-235.76308"
"374.70000","-8.11859","-235.78279"
"375.00003","-8.12484","-235.82311"
"375.30003","-8.13141","-235.89298"
"375.60000","-8.13812","-235.92021"
"375.90003","-8.14453","-235.91101"
"376.20000","-8.15109","-235.97894"
"376.50003","-8.15734","-235.99925"
"376.80003","-8.16391","-235.98932"
"377.10000","-8.17063","-235.81756"
"377.40003","-8.17719","-235.60293"
"377.70000","-8.18375","-235.53787"
"378.00003","-8.19000","-235.55469"
"378.30003","-8.19625","-235.61900"
"378.60000","-8.20297","-235.70960"
"378.90003","-8.20953","-235.73464"
"379.20000","-8.21625","-235.80549"
"379.50003","-8.22266","-235.84031"
"379.80003","-8.22891","-235.92141"
"380.10000","-8.23547","-236.05425"
"380.40003","-8.24203","-236.15152"
"380.70000","-8.24859","-236.16996"
"381.00003","-8.25516","-236.29742"
"381.30003","-8.26141","-236.36471"
"381.60000","-8.26797","-236.49361"
"381.90003","-8.27469","-236.57667"
"382.20000","-8.28109","-236.62683"
"382.50003","-8.28781","-236.72391"
"382.80003","-8.29391","-236.74792"
"383.10000","-8.30031","-236.88560"
"383.40003","-8.30703","-237.03748"
"383.70000","-8.31359","-237.03920"
"384.00003","-8.32016","-237.11275"
"384.30003","-8.32656","-237.19400"
"384.60000","-8.33297","-237.29172"
"384.90003","-8.33953","-237.42547"
"385.20000","-8.34609","-237.53302"
"385.50003","-8.35250","-237.53121"
"385.80003","-8.35906","-237.65273"
"386.10000","-8.36547","-237.71957"
"386.40003","-8.37188","-237.89845"
"386.70000","-8.37844","-237.97842"
"387.00003","-8.38516","-238.03392"
"387.30003","-8.39172","-238.11765"
"387.60000","-8.39797","-238.08913"
"387.90003","-8.40422","-238.11640"
"388.20000","-8.41109","-238.09347"
"388.50003","-8.41766","-237.72245"
"388.80003","-8.42422","-237.26193"
"389.10000","-8.43063","-237.05555"
"389.40003","-8.43688","-237.02210"
"389.70000","-8.44344","-237.02035"
"390.00003","-8.45016","-236.93159"
"390.30003","-8.45672","-236.91444"
"390.60000","-8.46313","-236.87523"
"390.90003","-8.46937","-236.92520"
"391.20000","-8.47594","-237.03266"
"391.50003","-8.48266","-237.03787"
"391.80003","-8.48922","-237.05447"
"392.10000","-8.49563","-237.08398"
"392.40003","-8.50188","-237.14140"
"392.70000","-8.50828","-237.23787"
"393.00003","-8.51500","-237.34929"
"393.30003","-8.52172","-237.32424"
"393.60000","-8.52813","-237.30947"
"393.90003","-8.53453","-237.44937"
"394.20000","-8.54094","-237.46051"
"394.50003","-8.54734","-237.48415"
"394.80003","-8.55391","-237.53732"
"395.10000","-8.56047","-237.54837"
"395.40003","-8.56703","-237.61457"
"395.70000","-8.57359","-237.68201"
"396.00003","-8.57984","-237.67112"
"396.30003","-8.58656","-237.72949"
"396.60000","-8.59313","-237.62109"
"396.90003","-8.59984","-237.43451"
"397.20000","-8.60609","-237.10182"
"397.50003","-8.61234","-236.99975"
"397.80003","-8.61891","-237.05952"
"398.10000","-8.62547","-237.13402"
"398.40003","-8.63219","-237.21680"
"398.70000","-8.63859","-237.20386"
"399.00003","-8.64484","-237.28702"
"399.30003","-8.65141","-237.37568"
"399.60000","-8.65813","-237.49281"
"399.90003","-8.66469","-237.52222"
"400.20000","-8.67109","-237.55999"
"400.50003","-8.67750","-237.58037"
"400.80003","-8.68391","-237.70461"
"401.10000","-8.69063","-237.77207"
"401.40003","-8.69719","-237.78467"
"401.70000","-8.70359","-237.84159"
"402.00003","-8.70984","-237.95430"
"402.30003","-8.71625","-238.04136"
"402.60000","-8.72312","-238.18498"
"402.90003","-8.72969","-238.14421"
"403.20000","-8.73625","-238.22695"
"403.50003","-8.74266","-238.31883"
"403.80003","-8.74891","-238.35473"
"404.10000","-8.75547","-238.47949"
"404.40003","-8.76203","-238.51395"
"404.70000","-8.76859","-238.62857"
"405.00003","-8.77500","-238.66469"
"405.30003","-8.78156","-238.73692"
"405.60000","-8.78797","-238.79647"
"405.90003","-8.79453","-238.86297"
"406.20000","-8.80109","-238.88990"
"406.50003","-8.80906","8.30193"
"406.80003","-8.81391","9.13201"
"407.10000","-8.82031","9.12718"
"407.40003","-8.82703","9.16211"
"407.70000","-8.83359","9.16104"
"408.00003","-8.84016","9.15737"
"408.30003","-8.84672","9.20959"
"408.60000","-8.85281","9.18517"
"408.90003","-8.85938","9.16984"
"409.20000","-8.86594","9.20085"
"409.50003","-8.87266","9.21266"
"409.80003","-8.87922","9.16293"
"410.10000","-8.88547","9.21171"
"410.40003","-8.89203","9.20478"
"410.70000","-8.89859","9.21795"
"411.00003","-8.90516","9.18501"
"411.30003","-8.91172","9.17346"
"411.60000","-8.91797","9.18830"
"411.90003","-8.92438","9.16025"
"412.20000","-8.93094","9.18003"
"412.50003","-8.93766","9.18929"
"412.80003","-8.94422","9.16183"
"413.10000","-8.95063","9.19331"
"413.40003","-8.95688","9.18699"
"413.70000","-8.96344","9.21103"
"414.00003","-8.97000","9.22409"
"414.30003","-8.97656","9.18016"
"414.60000","-8.98312","9.21278"
"414.71003","-8.98547","9.24028"