File: Lab 4 Data/G3CF_DRY.csv
Text Inputs : Specimen label,"G3CF_DRY"
Test : Rate 1,"0.70000",mm/min
Dimension : Support span,"25.60000",mm
Dimension : Thickness,"1.52500",mm
Dimension : Width,"12.70000",mm

Time,Extension,Load
(sec),(mm),(N)
"0.00000","0.00000","0.09615"
"0.30000","-0.00156","-0.17779"
"0.60000","-0.00703","-1.55668"
"0.90000","-0.01062","-2.48684"
"1.20000","-0.01406","-3.40668"
"1.50000","-0.01766","-4.28500"
"1.80000","-0.02109","-5.13312"
"2.10000","-0.02453","-6.00287"
"2.40000","-0.02797","-6.73806"
"2.70000","-0.03156","-7.68175"
"3.00000","-0.03500","-8.37801"
"3.30000","-0.03875","-9.33710"
"3.60000","-0.04219","-10.07703"
"3.90000","-0.04578","-10.93023"
"4.20000","-0.04922","-11.74535"
"4.50000","-0.05281","-12.55264"
"4.80000","-0.05625","-13.35583"
"5.10000","-0.05969","-14.17825"
"5.40000","-0.06313","-15.01665"
"5.70000","-0.06656","-15.79248"
"6.00000","-0.07000","-16.65953"
"6.30000","-0.07359","-17.48330"
"6.60000","-0.07719","-18.31583"
"6.90000","-0.08078","-19.14722"
"7.20000","-0.08422","-19.92585"
"7.50000","-0.08766","-20.73474"
"7.80000","-0.09125","-21.58249"
"8.10000","-0.09453","-22.30521"
"8.40000","-0.09797","-23.16258"
"8.70000","-0.10156","-23.99030"
"9.00000","-0.10516","-24.85882"
"9.30000","-0.10859","-25.71649"
"9.60000","-0.11219","-26.53148"
"9.90000","-0.11578","-27.43082"
"10.20000","-0.11922","-28.27581"
"10.50000","-0.12281","-29.07855"
"10.80000","-0.12625","-29.92131"
"11.10000","-0.12969","-30.76256"
"11.40000","-0.13297","-31.58466"
"11.70000","-0.13656","-32.44455"
"12.00000","-0.14000","-33.25539"
"12.30000","-0.14359","-34.08144"
"12.60000","-0.14703","-34.94761"
"12.90000","-0.15062","-35.82891"
"13.20000","-0.15406","-36.68319"
"13.50000","-0.15766","-37.55556"
"13.80000","-0.16125","-38.44796"
"14.10000","-0.16469","-39.30018"
"14.40000","-0.16812","-40.10090"
"14.70000","-0.17156","-41.02127"
"15.00000","-0.17500","-41.86636"
"15.30000","-0.17859","-42.78558"
"15.60000","-0.18219","-43.67262"
"15.90000","-0.18563","-44.49908"
"16.20000","-0.18922","-45.43152"
"16.50000","-0.19281","-46.29983"
"16.80000","-0.19625","-47.16952"
"17.10000","-0.19969","-47.96956"
"17.40000","-0.20297","-48.85766"
"17.70000","-0.20656","-49.79399"
"18.00000","-0.21000","-50.73832"
"18.30000","-0.21344","-51.53805"
"18.60000","-0.21719","-52.47355"
"18.90000","-0.22063","-53.35452"
"19.20000","-0.22422","-54.29064"
"19.50000","-0.22781","-55.10747"
"19.80000","-0.23125","-56.08442"
"20.10000","-0.23469","-56.91645"
"20.40000","-0.23797","-57.79399"
"20.70000","-0.24156","-58.65243"
"21.00000","-0.24500","-59.61643"
"21.30000","-0.24859","-60.49208"
"21.60000","-0.25219","-61.41499"
"21.90000","-0.25578","-62.30980"
"22.20000","-0.25922","-63.20375"
"22.50000","-0.26281","-64.07022"
"22.80000","-0.26609","-64.99001"
"23.10000","-0.26953","-65.85895"
"23.40000","-0.27297","-66.69960"
"23.70000","-0.27656","-67.69297"
"24.00000","-0.28000","-68.59272"
"24.30000","-0.28375","-69.51669"
"24.60000","-0.28719","-70.40653"
"24.90000","-0.29078","-71.31679"
"25.20000","-0.29422","-72.17226"
"25.50000","-0.29781","-73.10008"
"25.80000","-0.30125","-74.02095"
"26.10000","-0.30453","-74.79078"
"26.40000","-0.30797","-75.79166"
"26.70000","-0.31156","-76.65443"
"27.00000","-0.31516","-77.63678"
"27.30000","-0.31859","-78.55525"
"27.60000","-0.32219","-79.55329"
"27.90000","-0.32578","-80.34544"
"28.20000","-0.32922","-81.35642"
"28.50000","-0.33266","-82.15331"
"28.80000","-0.33625","-83.13240"
"29.10000","-0.33953","-83.95893"
"29.40000","-0.34297","-84.92976"
"29.70000","-0.34656","-85.85051"
"30.00000","-0.35016","-86.77417"
"30.30000","-0.35375","-87.68925"
"30.60000","-0.35719","-88.62656"
"30.90000","-0.36078","-89.58356"
"31.20000","-0.36422","-90.49529"
"31.50000","-0.36766","-91.42336"
"31.80000","-0.37109","-92.31155"
"32.10000","-0.37453","-93.18426"
"32.40000","-0.37797","-94.09251"
"32.70000","-0.38156","-95.09826"
"33.00000","-0.38500","-95.97875"
"33.30000","-0.38859","-96.92233"
"33.60000","-0.39203","-97.86757"
"33.90000","-0.39578","-98.84116"
"34.20000","-0.39922","-99.74914"
"34.50000","-0.40281","-100.71428"
"34.80000","-0.40625","-101.59427"
"35.10000","-0.40953","-102.44879"
"35.40000","-0.41297","-103.39187"
"35.70000","-0.41656","-104.38750"
"36.00000","-0.42016","-105.34703"
"36.30000","-0.42359","-106.27390"
"36.60000","-0.42719","-107.19185"
"36.90000","-0.43078","-108.11276"
"37.20000","-0.43422","-109.05207"
"37.50000","-0.43781","-109.92670"
"37.80000","-0.44125","-110.91911"
"38.10000","-0.44453","-111.76622"
"38.40000","-0.44797","-112.70813"
"38.70000","-0.45141","-113.62882"
"39.00000","-0.45516","-114.69935"
"39.30000","-0.45859","-115.58995"
"39.60000","-0.46234","-116.58045"
"39.90000","-0.46578","-117.53062"
"40.20000","-0.46922","-118.46062"
"40.50000","-0.47281","-119.40083"
"40.80000","-0.47609","-120.33915"
"41.10000","-0.47953","-121.22686"
"41.40000","-0.48297","-122.21335"
"41.70000","-0.48656","-123.16565"
"42.00000","-0.49016","-124.13363"
"42.30000","-0.49375","-125.10449"
"42.60000","-0.49719","-126.06208"
"42.90000","-0.50078","-127.03446"
"43.20000","-0.50422","-127.93580"
"43.50000","-0.50781","-128.88642"
"43.80000","-0.51094","-129.80090"
"44.10000","-0.51453","-130.74353"
"44.40000","-0.51797","-131.69101"
"44.70000","-0.52172","-132.75432"
"45.00000","-0.52516","-133.68356"
"45.30000","-0.52875","-134.67485"
"45.60000","-0.53219","-135.56200"
"45.90000","-0.53578","-136.57958"
"46.20000","-0.53922","-137.52125"
"46.50000","-0.54266","-138.45611"
"46.80000","-0.54609","-139.39396"
"47.10000","-0.54953","-140.30785"
"47.40000","-0.55297","-141.31692"
"47.70000","-0.55656","-142.26029"
"48.00000","-0.56000","-143.30655"
"48.30000","-0.56359","-144.21998"
"48.60000","-0.56719","-145.24940"
"48.90000","-0.57063","-146.17146"
"49.20000","-0.57422","-147.15477"
"49.50000","-0.57766","-148.06204"
"49.80000","-0.58125","-149.06292"
"50.10000","-0.58453","-149.96122"
"50.40000","-0.58797","-150.89181"
"50.70000","-0.59156","-151.88178"
"51.00000","-0.59516","-152.87913"
"51.30000","-0.59875","-153.88669"
"51.60000","-0.60219","-154.82352"
"51.90000","-0.60563","-155.77810"
"52.20000","-0.60922","-156.77668"
"52.50000","-0.61281","-157.71950"
"52.80000","-0.61609","-158.66939"
"53.10000","-0.61953","-159.56286"
"53.40000","-0.62297","-160.55914"
"53.70000","-0.62656","-161.58933"
"54.00000","-0.63000","-162.49763"
"54.30000","-0.63375","-163.52005"
"54.60000","-0.63719","-164.46667"
"54.90000","-0.64078","-165.47589"
"55.20000","-0.64422","-166.38886"
"55.50000","-0.64781","-167.34406"
"55.80000","-0.65109","-168.30878"
"56.10000","-0.65453","-169.19727"
"56.40000","-0.65797","-170.19007"
"56.70000","-0.66156","-171.19393"
"57.00000","-0.66516","-172.21222"
"57.30000","-0.66875","-173.14583"
"57.60000","-0.67234","-174.09330"
"57.90000","-0.67578","-175.10476"
"58.20000","-0.67922","-176.06027"
"58.50000","-0.68266","-176.96839"
"58.80000","-0.68609","-177.87786"
"59.10000","-0.68938","-178.77396"
"59.40000","-0.69313","-179.83461"
"59.70000","-0.69656","-180.72782"
"60.00000","-0.70016","-181.78182"
"60.30000","-0.70375","-182.76203"
"60.60000","-0.70719","-183.64452"
"60.90000","-0.71078","-184.68508"
"61.20000","-0.71422","-185.55544"
"61.50000","-0.71766","-186.56155"
"61.80000","-0.72094","-187.46078"
"62.10000","-0.72453","-188.42716"
"62.40000","-0.72812","-189.39944"
"62.70000","-0.73156","-190.37291"
"63.00000","-0.73516","-191.35717"
"63.30000","-0.73875","-192.31642"
"63.60000","-0.74219","-193.18501"
"63.90000","-0.74578","-194.17716"
"64.20000","-0.74906","-195.07920"
"64.50000","-0.75281","-196.06853"
"64.80000","-0.75594","-196.93539"
"65.10001","-0.75953","-197.86686"
"65.40000","-0.76297","-198.84279"
"65.70001","-0.76656","-199.79134"
"66.00000","-0.77000","-200.75032"
"66.30000","-0.77359","-201.70894"
"66.60001","-0.77719","-202.64527"
"66.90000","-0.78063","-203.58218"
"67.20001","-0.78422","-204.49629"
"67.50000","-0.78781","-205.46244"
"67.80000","-0.79109","-206.40407"
"68.10001","-0.79453","-207.21514"
"68.40000","-0.79812","-208.18209"
"68.70001","-0.80156","-209.05761"
"69.00000","-0.80516","-210.09458"
"69.30000","-0.80859","-211.02378"
"69.60001","-0.81219","-211.96524"
"69.90000","-0.81578","-212.93014"
"70.20001","-0.81922","-213.65846"
"70.50000","-0.82266","-214.73527"
"70.80000","-0.82609","-215.69576"
"71.10001","-0.82953","-216.43694"
"71.40000","-0.83313","-217.56394"
"71.70001","-0.83656","-218.33563"
"72.00000","-0.84000","-219.34407"
"72.30000","-0.84359","-220.20299"
"72.60001","-0.84734","-221.12213"
"72.90000","-0.85078","-222.05703"
"73.20001","-0.85422","-222.94233"
"73.50000","-0.85781","-223.83442"
"73.80000","-0.86109","-224.69480"
"74.10001","-0.86453","-225.54601"
"74.40000","-0.86797","-226.44393"
"74.70001","-0.87172","-227.42100"
"75.00000","-0.87516","-223.12120"
"75.30000","-0.87891","-209.35021"
"75.60001","-0.88234","-208.93576"
"75.90000","-0.88578","-209.35785"
"76.20001","-0.88922","-209.88978"
"76.50000","-0.89266","-210.58805"
"76.80000","-0.89594","-211.27708"
"77.10001","-0.89953","-212.05772"
"77.40000","-0.90297","-212.79342"
"77.70001","-0.90656","-205.04678"
"78.00000","-0.91031","-205.57502"
"78.30000","-0.91375","-206.18003"
"78.60001","-0.91719","-206.85643"
"78.90000","-0.92062","-207.48990"
"79.20001","-0.92422","-208.15797"
"79.50000","-0.92750","-208.82322"
"79.80000","-0.93109","-209.44426"
"80.10001","-0.93453","-208.20959"
"80.40000","-0.93813","-207.59817"
"80.70001","-0.94172","-207.81055"
"81.00001","-0.94531","-208.02980"
"81.30000","-0.94875","-208.29121"
"81.60001","-0.95234","-208.54194"
"81.90000","-0.95578","-208.87649"
"82.20001","-0.95922","-209.21728"
"82.50001","-0.96266","-209.66876"
"82.80000","-0.96609","-210.10589"
"83.10001","-0.96953","-210.59578"
"83.40000","-0.97312","-211.16167"
"83.70001","-0.97656","-211.76765"
"84.00001","-0.98016","-212.27170"
"84.30000","-0.98375","-212.82636"
"84.60001","-0.98719","-213.29917"
"84.90000","-0.99078","-213.85176"
"85.20001","-0.99406","-214.36270"
"85.50001","-0.99766","-214.81505"
"85.80000","-1.00094","-215.21393"
"86.10001","-1.00453","-215.40442"
"86.40000","-1.00797","-215.75075"
"86.70001","-1.01156","-215.85353"
"87.00001","-1.01531","-208.46816"
"87.30000","-1.01859","-208.35701"
"87.60001","-1.02219","-208.64489"
"87.90000","-1.02578","-209.03718"
"88.20001","-1.02922","-209.38797"
"88.50001","-1.03266","-209.76685"
"88.80000","-1.03609","-210.21096"
"89.10001","-1.03953","-210.70363"
"89.40000","-1.04313","-211.29400"
"89.70001","-1.04656","-211.76664"
"90.00001","-1.05016","-212.40249"
"90.30000","-1.05375","-212.91604"
"90.60001","-1.05734","-213.52243"
"90.90000","-1.06078","-214.06282"
"91.20001","-1.06422","-214.65119"
"91.50001","-1.06766","-215.15207"
"91.80000","-1.07094","-215.70744"
"92.10001","-1.07453","-216.31503"
"92.40000","-1.07812","-216.89359"
"92.70001","-1.08156","-217.49990"
"93.00001","-1.08516","-218.06518"
"93.30000","-1.08875","-218.66802"
"93.60001","-1.09219","-219.24574"
"93.90000","-1.09578","-219.78946"
"94.20001","-1.09922","-220.36929"
"94.50001","-1.10266","-220.88785"
"94.80000","-1.10594","-221.37444"
"95.10001","-1.10969","-221.64430"
"95.40000","-1.11297","-222.05736"
"95.70001","-1.11672","-222.67520"
"96.00001","-1.12031","-223.15171"
"96.30000","-1.12375","-223.70547"
"96.60001","-1.12719","-224.19896"
"96.90000","-1.13078","-224.73367"
"97.20001","-1.13422","-225.19426"
"97.50001","-1.13750","-225.35844"
"97.80000","-1.14094","-225.84658"
"98.10001","-1.14453","-226.45174"
"98.40000","-1.14813","-226.99222"
"98.70001","-1.15172","-227.43355"
"99.00001","-1.15531","-225.01783"
"99.30000","-1.15875","-224.51822"
"99.60001","-1.16234","-224.77962"
"99.90000","-1.16563","-225.04499"
"100.20001","-1.16922","-225.44051"
"100.50001","-1.17250","-225.61707"
"100.80000","-1.17609","-225.88382"
"101.10001","-1.17953","-226.08493"
"101.40000","-1.18313","-226.52544"
"101.70001","-1.18656","-226.84433"
"102.00001","-1.19016","-227.28033"
"102.30000","-1.19375","-227.67115"
"102.60001","-1.19719","-227.98989"
"102.90000","-1.20078","-228.40431"
"103.20001","-1.20422","-228.22447"
"103.50001","-1.20766","-228.43516"
"103.80000","-1.21094","-228.64452"
"104.10001","-1.21453","-228.93118"
"104.40000","-1.21797","-229.22033"
"104.70001","-1.22172","-229.59361"
"105.00001","-1.22516","-229.93317"
"105.30000","-1.22875","-230.13812"
"105.60001","-1.23219","-230.44808"
"105.90000","-1.23578","-230.75713"
"106.20001","-1.23922","-231.01704"
"106.50001","-1.24250","-231.33336"
"106.80000","-1.24594","-229.70611"
"107.10001","-1.24953","-218.99873"
"107.40000","-1.25313","-217.89685"
"107.70001","-1.25656","-217.46790"
"108.00001","-1.26016","-217.28635"
"108.30000","-1.26375","-217.18686"
"108.60001","-1.26734","-216.39245"
"108.90000","-1.27078","-209.37582"
"109.20001","-1.27422","-208.33021"
"109.50001","-1.27750","-202.41406"
"109.80000","-1.28109","-199.21133"
"110.10001","-1.28453","-197.92685"
"110.40000","-1.28813","-196.16248"
"110.70001","-1.29172","-188.62413"
"111.00001","-1.29531","-183.31308"
"111.30000","-1.29875","-178.34384"
"111.60001","-1.30219","-175.37437"
"111.90000","-1.30578","-173.53330"
"112.20001","-1.30906","-172.27847"
"112.50001","-1.31250","-171.19477"
"112.80000","-1.31609","-170.48052"
"113.10001","-1.31953","-169.97591"
"113.40001","-1.32312","-169.60425"
"113.70001","-1.32672","-169.36358"
"114.00001","-1.33031","-169.15759"
"114.30000","-1.33375","-168.98861"
"114.60001","-1.33719","-168.80561"
"114.90001","-1.34078","-168.70312"
"115.20001","-1.34406","-168.53649"
"115.50001","-1.34750","-168.48331"
"115.80000","-1.35094","-168.34376"
"116.10001","-1.35469","-168.30696"
"116.40001","-1.35813","-168.26170"
"116.70001","-1.36172","-168.12878"
"117.00001","-1.36531","-168.02233"
"117.30000","-1.36875","-167.89762"
"117.60001","-1.37234","-158.01203"
"117.90001","-1.37563","-156.29210"
"118.20001","-1.37906","-155.54543"
"118.50001","-1.38250","-155.07005"
"118.80000","-1.38609","-154.80216"
"119.10001","-1.38953","-154.58075"
"119.40001","-1.39313","-154.43224"
"119.70001","-1.39656","-154.30219"
"120.00001","-1.40016","-154.20963"
"120.30000","-1.40359","-153.89367"
"120.60001","-1.40734","-153.70951"
"120.90001","-1.41063","-153.53906"
"121.20001","-1.41422","-153.38100"
"121.50001","-1.41766","-153.16299"
"121.80000","-1.42094","-152.86881"
"122.10001","-1.42453","-152.73600"
"122.40001","-1.42813","-152.71771"
"122.70001","-1.43172","-152.61381"
"123.00001","-1.43516","-152.69010"
"123.30000","-1.43875","-152.70593"
"123.60001","-1.44234","-152.80577"
"123.90001","-1.44578","-152.86942"
"124.20001","-1.44922","-152.97015"
"124.50001","-1.45250","-153.07269"
"124.80000","-1.45594","-153.16669"
"125.10001","-1.45953","-153.33844"
"125.40001","-1.46297","-153.46644"
"125.70001","-1.46672","-153.65218"
"126.00001","-1.47016","-153.80151"
"126.30000","-1.47375","-154.04585"
"126.60001","-1.47719","-154.12292"
"126.90001","-1.48078","-154.33704"
"127.20001","-1.48406","-154.47467"
"127.50001","-1.48750","-154.66043"
"127.80000","-1.49109","-154.87378"
"128.10001","-1.49453","-155.09621"
"128.40001","-1.49813","-155.31395"
"128.70002","-1.50172","-155.53830"
"129.00000","-1.50531","-155.75374"
"129.30000","-1.50875","-155.92003"
"129.60001","-1.51234","-156.11248"
"129.90001","-1.51563","-156.30150"
"130.20002","-1.51906","-156.50973"
"130.50000","-1.52234","-156.61713"
"130.80000","-1.52609","-156.88868"
"131.10000","-1.52953","-157.04667"
"131.40002","-1.53313","-157.28211"
"131.70002","-1.53672","-157.45837"
"132.00000","-1.54031","-157.65630"
"132.30000","-1.54375","-157.82394"
"132.60000","-1.54719","-157.97962"
"132.90002","-1.55078","-158.15824"
"133.20002","-1.55406","-158.29032"
"133.50000","-1.55750","-158.47310"
"133.80000","-1.56109","-158.72803"
"134.10000","-1.56469","-158.91623"
"134.40002","-1.56828","-159.08195"
"134.70002","-1.57172","-159.18961"
"135.00000","-1.57516","-159.33348"
"135.30000","-1.57875","-159.50305"
"135.60000","-1.58219","-159.62690"
"135.90002","-1.58578","-159.79996"
"136.20002","-1.58906","-159.88795"
"136.50000","-1.59250","-160.05918"
"136.80000","-1.59609","-160.27199"
"137.10000","-1.59953","-160.45731"
"137.40002","-1.60328","-160.65335"
"137.70002","-1.60672","-160.80126"
"138.00000","-1.61031","-160.93243"
"138.30000","-1.61375","-161.10010"
"138.60000","-1.61719","-161.22529"
"138.90002","-1.62063","-161.41525"
"139.20002","-1.62406","-161.57774"
"139.50000","-1.62750","-161.68613"
"139.80000","-1.63109","-161.94969"
"140.10000","-1.63453","-162.09278"
"140.40002","-1.63813","-162.34042"
"140.70002","-1.64156","-162.49338"
"141.00000","-1.64531","-162.72351"
"141.30000","-1.64875","-162.85215"
"141.60000","-1.65234","-163.05866"
"141.90002","-1.65578","-163.22944"
"142.20002","-1.65906","-163.38604"
"142.50000","-1.66250","-163.57167"
"142.80000","-1.66609","-163.83421"
"143.10000","-1.66969","-164.05310"
"143.40002","-1.67312","-164.21817"
"143.70002","-1.67672","-164.46644"
"144.00000","-1.68031","-164.67750"
"144.30000","-1.68375","-164.85842"
"144.60000","-1.68719","-165.06495"
"144.90002","-1.69062","-165.22722"
"145.20002","-1.69391","-165.34612"
"145.50000","-1.69750","-165.52383"
"145.80000","-1.70094","-165.71868"
"146.10000","-1.70469","-165.99083"
"146.40002","-1.70812","-166.18915"
"146.70002","-1.71172","-166.40177"
"147.00000","-1.71531","-166.61612"
"147.30000","-1.71875","-166.77484"
"147.60000","-1.72219","-166.93093"
"147.90002","-1.72563","-167.14873"
"148.20002","-1.72906","-167.29971"
"148.50000","-1.73250","-167.46134"
"148.80000","-1.73609","-167.72751"
"149.10000","-1.73969","-167.92212"
"149.40002","-1.74328","-168.17082"
"149.70002","-1.74672","-168.32286"
"150.00000","-1.75031","-168.56113"
"150.30000","-1.75375","-168.71933"
"150.60000","-1.75734","-168.87004"
"150.90002","-1.76063","-169.00368"
"151.20002","-1.76406","-169.14248"
"151.50000","-1.76750","-169.36598"
"151.80000","-1.77109","-169.61273"
"152.10000","-1.77469","-169.82742"
"152.40002","-1.77828","-170.05732"
"152.70002","-1.78172","-170.19819"
"153.00000","-1.78531","-170.43250"
"153.30000","-1.78875","-170.61334"
"153.60000","-1.79219","-170.77498"
"153.90002","-1.79562","-170.97469"
"154.20002","-1.79906","-171.17547"
"154.50000","-1.80250","-171.39284"
"154.80000","-1.80609","-171.57739"
"155.10000","-1.80953","-171.75956"
"155.40002","-1.81312","-171.91805"
"155.70002","-1.81672","-172.08604"
"156.00000","-1.82016","-172.19000"
"156.30000","-1.82375","-172.27871"
"156.60000","-1.82719","-172.29490"
"156.90002","-1.83062","-172.42072"
"157.20002","-1.83406","-172.51300"
"157.50000","-1.83750","-172.66065"
"157.80000","-1.84109","-172.82534"
"158.10000","-1.84453","-173.00900"
"158.40002","-1.84828","-173.20881"
"158.70002","-1.85172","-173.37106"
"159.00000","-1.85516","-173.57914"
"159.30000","-1.85875","-173.73746"
"159.60000","-1.86234","-173.92311"
"159.90002","-1.86563","-174.04744"
"160.20002","-1.86906","-174.18986"
"160.50000","-1.87250","-174.40375"
"160.80000","-1.87609","-174.64232"
"161.10000","-1.87953","-174.82525"
"161.40002","-1.88313","-175.08138"
"161.70002","-1.88672","-175.23294"
"162.00002","-1.89031","-175.47216"
"162.30000","-1.89375","-175.63077"
"162.60000","-1.89719","-175.76253"
"162.90002","-1.90063","-175.91745"
"163.20002","-1.90406","-176.07503"
"163.50002","-1.90750","-176.28720"
"163.80000","-1.91109","-176.39898"
"164.10000","-1.91469","-176.68672"
"164.40002","-1.91828","-176.85646"
"164.70002","-1.92172","-177.00385"
"165.00002","-1.92531","-177.19045"
"165.30000","-1.92875","-177.36726"
"165.60000","-1.93219","-177.48982"
"165.90002","-1.93562","-177.66939"
"166.20002","-1.93891","-177.76756"
"166.50002","-1.94266","-178.07055"
"166.80000","-1.94594","-178.21059"
"167.10000","-1.94969","-178.37744"
"167.40002","-1.95328","-178.58796"
"167.70002","-1.95672","-178.64624"
"168.00002","-1.96031","-178.75170"
"168.30000","-1.96375","-178.83886"
"168.60000","-1.96719","-178.93946"
"168.90002","-1.97047","-179.00437"
"169.20002","-1.97406","-179.17173"
"169.50002","-1.97750","-179.33480"
"169.80000","-1.98109","-179.46115"
"170.10000","-1.98469","-179.67088"
"170.40002","-1.98828","-179.85698"
"170.70002","-1.99172","-180.01296"
"171.00002","-1.99531","-180.20710"
"171.30000","-1.99859","-180.32458"
"171.60000","-2.00234","-180.57324"
"171.90002","-2.00547","-180.64795"
"172.20002","-2.00906","-180.78981"
"172.50002","-2.01250","-181.00718"
"172.80000","-2.01609","-181.13639"
"173.10000","-2.01953","-181.34449"
"173.40002","-2.02313","-181.51600"
"173.70002","-2.02672","-181.73316"
"174.00002","-2.03016","-181.88061"
"174.30000","-2.03375","-181.98628"
"174.60000","-2.03719","-182.18379"
"174.90002","-2.04063","-182.32122"
"175.20002","-2.04406","-182.44099"
"175.50002","-2.04750","-182.60915"
"175.80000","-2.05109","-182.76991"
"176.10000","-2.05469","-183.01951"
"176.40002","-2.05813","-183.17411"
"176.70002","-2.06172","-183.36218"
"177.00002","-2.06516","-183.50551"
"177.30000","-2.06875","-183.70019"
"177.60000","-2.07219","-183.86303"
"177.90002","-2.07563","-183.99496"
"178.20002","-2.07891","-184.15298"
"178.50002","-2.08250","-184.42225"
"178.80000","-2.08609","-184.63681"
"179.10000","-2.08953","-184.77151"
"179.40002","-2.09313","-185.02312"
"179.70002","-2.09672","-185.20709"
"180.00002","-2.10031","-185.40062"
"180.30000","-2.10375","-185.55781"
"180.60000","-2.10719","-185.75398"
"180.90002","-2.11047","-185.49277"
"181.20002","-2.11406","-185.60376"
"181.50002","-2.11750","-185.71129"
"181.80000","-2.12125","-185.97992"
"182.10000","-2.12469","-186.11971"
"182.40002","-2.12828","-186.41498"
"182.70002","-2.13172","-186.57543"
"183.00002","-2.13531","-186.80133"
"183.30000","-2.13875","-186.96304"
"183.60000","-2.14219","-187.10792"
"183.90002","-2.14547","-187.32119"
"184.20002","-2.14906","-187.51947"
"184.50002","-2.15250","-187.74930"
"184.80000","-2.15609","-188.01684"
"185.10000","-2.15969","-188.26006"
"185.40002","-2.16328","-188.50604"
"185.70002","-2.16672","-188.74317"
"186.00002","-2.17016","-188.88695"
"186.30000","-2.17375","-189.13854"
"186.60000","-2.17703","-189.30065"
"186.90002","-2.18062","-189.54402"
"187.20002","-2.18391","-189.73246"
"187.50002","-2.18766","-190.00877"
"187.80000","-2.19109","-190.25110"
"188.10000","-2.19469","-190.49296"
"188.40002","-2.19828","-190.73738"
"188.70002","-2.20172","-190.92631"
"189.00002","-2.20531","-191.17987"
"189.30000","-2.20875","-191.31646"
"189.60000","-2.21219","-191.54884"
"189.90002","-2.21547","-191.67701"
"190.20002","-2.21906","-191.91196"
"190.50002","-2.22250","-192.14518"
"190.80000","-2.22609","-192.41259"
"191.10000","-2.22969","-192.60978"
"191.40002","-2.23328","-192.86990"
"191.70002","-2.23656","-193.02038"
"192.00002","-2.24031","-193.30736"
"192.30000","-2.24375","-193.42110"
"192.60000","-2.24719","-193.65029"
"192.90002","-2.25063","-193.82864"
"193.20002","-2.25406","-193.95702"
"193.50002","-2.25750","-194.14317"
"193.80000","-2.26109","-194.34955"
"194.10000","-2.26469","-194.55403"
"194.40002","-2.26813","-194.71582"
"194.70002","-2.27172","-194.82533"
"195.00002","-2.27531","-194.94301"
"195.30000","-2.27875","-194.97702"
"195.60000","-2.28219","-195.05160"
"195.90002","-2.28547","-195.13257"
"196.20002","-2.28891","-195.21507"
"196.50002","-2.29266","-195.51713"
"196.80000","-2.29594","-195.35333"
"197.10000","-2.29969","-195.62814"
"197.40002","-2.30313","-195.63504"
"197.70002","-2.30688","-195.85302"
"198.00002","-2.31031","-195.91615"
"198.30000","-2.31375","-195.99549"
"198.60000","-2.31719","-196.04582"
"198.90002","-2.32047","-196.10438"
"199.20002","-2.32406","-196.21678"
"199.50002","-2.32750","-196.38700"
"199.80000","-2.33109","-196.58936"
"200.10000","-2.33453","-196.67968"
"200.40002","-2.33828","-196.91249"
"200.70002","-2.34172","-197.00410"
"201.00002","-2.34531","-197.15412"
"201.30000","-2.34875","-197.18487"
"201.60000","-2.35219","-197.38594"
"201.90002","-2.35547","-197.33751"
"202.20002","-2.35906","-197.59405"
"202.50002","-2.36250","-197.59851"
"202.80000","-2.36625","-197.82662"
"203.10000","-2.36984","-197.91562"
"203.40002","-2.37328","-198.05031"
"203.70002","-2.37672","-198.14953"
"204.00002","-2.38031","-198.30886"
"204.30000","-2.38375","-198.43165"
"204.60000","-2.38703","-198.46965"
"204.90002","-2.39047","-198.69203"
"205.20002","-2.39406","-198.87406"
"205.50002","-2.39766","-199.04662"
"205.80000","-2.40125","-199.17320"
"206.10000","-2.40469","-199.25090"
"206.40002","-2.40828","-199.39814"
"206.70002","-2.41172","-199.51902"
"207.00002","-2.41516","-199.54231"
"207.30000","-2.41875","-199.61849"
"207.60000","-2.42203","-199.53040"
"207.90002","-2.42562","-199.62149"
"208.20002","-2.42906","-199.69197"
"208.50002","-2.43266","-199.83076"
"208.80000","-2.43609","-199.92484"
"209.10000","-2.43969","-200.00719"
"209.40002","-2.44328","-200.11226"
"209.70002","-2.44672","-200.14271"
"210.00002","-2.45031","-200.26812"
"210.30000","-2.45375","-200.43861"
"210.60000","-2.45719","-200.47542"
"210.90002","-2.46047","-200.51159"
"211.20002","-2.46406","-200.68882"
"211.50002","-2.46750","-200.76042"
"211.80000","-2.47109","-200.88164"
"212.10000","-2.47469","-200.95350"
"212.40002","-2.47828","-201.05453"
"212.70002","-2.48172","-201.09178"
"213.00002","-2.48531","-201.28539"
"213.30000","-2.48875","-201.34786"
"213.60000","-2.49219","-201.46526"
"213.90002","-2.49547","-201.49523"
"214.20002","-2.49906","-201.69267"
"214.50002","-2.50266","-201.84522"
"214.80000","-2.50609","-201.91610"
"215.10000","-2.50969","-202.07901"
"215.40002","-2.51328","-202.27572"
"215.70002","-2.51672","-202.26598"
"216.00002","-2.52031","-202.43764"
"216.30000","-2.52375","-202.61360"
"216.60000","-2.52703","-202.62299"
"216.90002","-2.53047","-202.74054"
"217.20002","-2.53391","-202.11378"
"217.50002","-2.53766","-202.04891"
"217.80000","-2.54125","-201.86102"
"218.10000","-2.54484","-201.73388"
"218.40002","-2.54828","-201.75364"
"218.70002","-2.55172","-201.88345"
"219.00002","-2.55531","-201.93184"
"219.30000","-2.55875","-201.90962"
"219.60000","-2.56219","-201.81518"
"219.90002","-2.56547","-201.84925"
"220.20002","-2.56906","-202.05326"
"220.50002","-2.57266","-202.18493"
"220.80000","-2.57625","-202.32549"
"221.10000","-2.57969","-202.42179"
"221.40002","-2.58328","-202.60081"
"221.70002","-2.58672","-202.74360"
"222.00002","-2.59031","-202.89311"
"222.30000","-2.59359","-203.10981"
"222.60000","-2.59703","-203.28986"
"222.90002","-2.60047","-203.26769"
"223.20002","-2.60422","-203.77027"
"223.50002","-2.60781","-203.97183"
"223.80000","-2.61125","-204.11644"
"224.10000","-2.61469","-204.23032"
"224.40002","-2.61812","-204.54073"
"224.70002","-2.62172","-204.70409"
"225.00002","-2.62516","-204.85800"
"225.30002","-2.62875","-205.22349"
"225.60000","-2.63203","-205.31511"
"225.90002","-2.63547","-205.53026"
"226.20002","-2.63906","-205.80223"
"226.50002","-2.64250","-206.07920"
"226.80002","-2.64609","-206.28136"
"227.10000","-2.64969","-206.54034"
"227.40002","-2.65312","-206.79461"
"227.70002","-2.65672","-207.02330"
"228.00002","-2.66016","-207.04776"
"228.30002","-2.66375","-207.36745"
"228.60000","-2.66719","-207.44132"
"228.90002","-2.67047","-207.58281"
"229.20002","-2.67406","-207.83773"
"229.50002","-2.67750","-207.94630"
"229.80002","-2.68125","-208.30411"
"230.10000","-2.68453","-208.18882"
"230.40002","-2.68828","-208.50977"
"230.70002","-2.69187","-208.52046"
"231.00002","-2.69531","-208.78088"
"231.30002","-2.69875","-208.79040"
"231.60000","-2.70203","-208.88284"
"231.90002","-2.70547","-208.94652"
"232.20002","-2.70906","-208.96230"
"232.50002","-2.71250","-208.83316"
"232.80002","-2.71609","-208.67091"
"233.10000","-2.71953","-208.50703"
"233.40002","-2.72328","-208.48919"
"233.70002","-2.72672","-208.41368"
"234.00002","-2.73031","-208.32185"
"234.30002","-2.73375","-208.24809"
"234.60000","-2.73703","-208.15378"
"234.90002","-2.74047","-208.17811"
"235.20002","-2.74406","-208.17446"
"235.50002","-2.74766","-208.18861"
"235.80002","-2.75109","-208.19802"
"236.10000","-2.75484","-208.18688"
"236.40002","-2.75828","-208.10718"
"236.70002","-2.76172","-208.08514"
"237.00002","-2.76516","-208.11548"
"237.30002","-2.76875","-208.13925"
"237.60000","-2.77203","-208.09252"
"237.90002","-2.77563","-208.12256"
"238.20002","-2.77891","-208.17701"
"238.50002","-2.78266","-208.27644"
"238.80002","-2.78625","-208.35465"
"239.10000","-2.78969","-208.31846"
"239.40002","-2.79328","-208.38352"
"239.70002","-2.79672","-208.39280"
"240.00002","-2.80031","-208.47589"
"240.30002","-2.80344","-208.46501"
"240.60000","-2.80703","-208.53369"
"240.90002","-2.81063","-208.59659"
"241.20002","-2.81422","-208.78484"
"241.50002","-2.81781","-208.89202"
"241.80002","-2.82125","-208.98359"
"242.10000","-2.82469","-208.92696"
"242.40002","-2.82828","-209.08467"
"242.70002","-2.83172","-209.14899"
"243.00002","-2.83531","-209.34368"
"243.30002","-2.83859","-209.29325"
"243.60000","-2.84203","-209.49017"
"243.90002","-2.84563","-209.58079"
"244.20002","-2.84906","-209.79160"
"244.50002","-2.85266","-209.86542"
"244.80002","-2.85625","-209.96984"
"245.10000","-2.85969","-210.02144"
"245.40002","-2.86312","-210.11457"
"245.70002","-2.86672","-210.22735"
"246.00002","-2.87016","-210.32339"
"246.30002","-2.87375","-210.41570"
"246.60000","-2.87703","-210.48762"
"246.90002","-2.88062","-210.67850"
"247.20002","-2.88406","-210.77847"
"247.50002","-2.88766","-210.95352"
"247.80002","-2.89109","-211.03919"
"248.10000","-2.89469","-211.14726"
"248.40002","-2.89812","-211.25488"
"248.70002","-2.90187","-211.37977"
"249.00002","-2.90531","-211.47901"
"249.30002","-2.90859","-211.55858"
"249.60000","-2.91203","-211.59559"
"249.90002","-2.91562","-211.89503"
"250.20002","-2.91906","-211.89623"
"250.50002","-2.92250","-211.99975"
"250.80002","-2.92625","-212.24741"
"251.10000","-2.92969","-212.32558"
"251.40002","-2.93328","-212.31154"
"251.70002","-2.93672","-212.43760"
"252.00002","-2.94031","-212.58092"
"252.30002","-2.94359","-212.59055"
"252.60000","-2.94703","-212.73609"
"252.90002","-2.95047","-212.89462"
"253.20002","-2.95422","-213.03350"
"253.50002","-2.95766","-213.06390"
"253.80002","-2.96125","-213.19965"
"254.10000","-2.96469","-213.28149"
"254.40002","-2.96828","-213.35945"
"254.70002","-2.97172","-213.45910"
"255.00002","-2.97516","-213.51501"
"255.30002","-2.97875","-213.57294"
"255.60000","-2.98203","-213.59831"
"255.90002","-2.98563","-213.77094"
"256.20002","-2.98906","-213.86644"
"256.50000","-2.99281","-213.92707"
"256.80002","-2.99625","-214.07031"
"257.10000","-2.99969","-214.11004"
"257.40003","-3.00328","-214.15794"
"257.70002","-3.00672","-214.17413"
"258.00000","-3.01016","-214.26884"
"258.30002","-3.01359","-214.26860"
"258.60000","-3.01688","-214.42119"
"258.90003","-3.02063","-214.55009"
"259.20002","-3.02422","-214.65667"
"259.50000","-3.02766","-214.77671"
"259.80002","-3.03125","-214.92349"
"260.10000","-3.03469","-214.94268"
"260.40003","-3.03828","-215.08303"
"260.70002","-3.04156","-215.08822"
"261.00000","-3.04516","-215.14731"
"261.30002","-3.04844","-215.20259"
"261.60000","-3.05203","-215.41042"
"261.90003","-3.05563","-215.35736"
"262.20000","-3.05906","-215.50812"
"262.50000","-3.06266","-215.54936"
"262.80003","-3.06625","-215.78934"
"263.10000","-3.06969","-215.87081"
"263.40003","-3.07328","-216.02817"
"263.70000","-3.07672","-216.19273"
"264.00000","-3.08031","-216.30127"
"264.30003","-3.08359","-216.34867"
"264.60000","-3.08703","-216.50238"
"264.90003","-3.09062","-216.69917"
"265.20000","-3.09406","-216.87493"
"265.50000","-3.09766","-216.94278"
"265.80003","-3.10109","-217.13715"
"266.10000","-3.10469","-217.14484"
"266.40003","-3.10828","-217.29738"
"266.70000","-3.11172","-217.23401"
"267.00000","-3.11516","-217.22704"
"267.30003","-3.11859","-217.36991"
"267.60000","-3.12203","-217.39274"
"267.90003","-3.12562","-217.42959"
"268.20000","-3.12906","-217.47114"
"268.50000","-3.13266","-217.73089"
"268.80003","-3.13625","-217.95806"
"269.10000","-3.13984","-218.00041"
"269.40003","-3.14328","-218.08429"
"269.70000","-3.14672","-218.34329"
"270.00000","-3.15016","-218.16835"
"270.30003","-3.15359","-218.37557"
"270.60000","-3.15703","-218.48587"
"270.90003","-3.16047","-218.59443"
"271.20000","-3.16422","-218.86157"
"271.50000","-3.16766","-218.89221"
"271.80003","-3.17125","-219.07149"
"272.10000","-3.17469","-219.13752"
"272.40003","-3.17828","-219.32283"
"272.70000","-3.18172","-219.44892"
"273.00000","-3.18516","-219.41535"
"273.30003","-3.18844","-219.54477"
"273.60000","-3.19203","-219.54598"
"273.90003","-3.19547","-219.67774"
"274.20000","-3.19922","-219.82070"
"274.50000","-3.20281","-219.97852"
"274.80003","-3.20625","-220.00965"
"275.10000","-3.20969","-220.14499"
"275.40003","-3.21328","-219.82588"
"275.70000","-3.21672","-219.67284"
"276.00000","-3.22000","-219.47822"
"276.30003","-3.22344","-219.66523"
"276.60000","-3.22703","-219.80178"
"276.90003","-3.23063","-219.89886"
"277.20000","-3.23422","-220.00095"
"277.50000","-3.23766","-220.08739"
"277.80003","-3.24125","-220.15601"
"278.10000","-3.24469","-220.21981"
"278.40003","-3.24813","-220.26306"
"278.70000","-3.25172","-220.41727"
"279.00000","-3.25516","-220.50634"
"279.30003","-3.25859","-220.53555"
"279.60000","-3.26203","-220.64900"
"279.90003","-3.26547","-220.73809"
"280.20000","-3.26906","-220.90310"
"280.50000","-3.27266","-220.97625"
"280.80003","-3.27625","-220.90366"
"281.10000","-3.27969","-220.03077"
"281.40003","-3.28328","-220.03666"
"281.70000","-3.28672","-219.96349"
"282.00000","-3.29016","-220.06026"
"282.30003","-3.29359","-220.04861"
"282.60000","-3.29703","-220.03382"
"282.90003","-3.30047","-220.13554"
"283.20000","-3.30422","-220.19053"
"283.50000","-3.30766","-220.36131"
"283.80003","-3.31109","-220.44184"
"284.10000","-3.31469","-220.47579"
"284.40003","-3.31828","-220.68605"
"284.70000","-3.32172","-220.72628"
"285.00000","-3.32516","-220.83122"
"285.30003","-3.32844","-220.89303"
"285.60000","-3.33203","-220.85488"
"285.90003","-3.33562","-220.99473"
"286.20000","-3.33906","-220.80462"
"286.50000","-3.34266","-221.19025"
"286.80003","-3.34609","-220.81964"
"287.10000","-3.34984","-220.61143"
"287.40003","-3.35328","-220.67215"
"287.70000","-3.35672","-220.76404"
"288.00000","-3.36016","-220.79356"
"288.30003","-3.36359","-220.88289"
"288.60000","-3.36703","-220.99435"
"288.90003","-3.37062","-221.13713"
"289.20000","-3.37406","-221.31613"
"289.50000","-3.37766","-221.45752"
"289.80003","-3.38125","-221.57015"
"290.10000","-3.38469","-221.67319"
"290.40003","-3.38828","-221.85702"
"290.70000","-3.39172","-221.89258"
"291.00000","-3.39516","-222.11635"
"291.30003","-3.39844","-222.02747"
"291.60000","-3.40203","-222.27580"
"291.90003","-3.40563","-222.36617"
"292.20000","-3.40922","-222.51349"
"292.50000","-3.41266","-222.62417"
"292.80003","-3.41625","-222.60724"
"293.10000","-3.41969","-222.84351"
"293.40003","-3.42313","-222.89323"
"293.70000","-3.42672","-223.12393"
"294.00000","-3.43000","-223.09845"
"294.30003","-3.43344","-223.20407"
"294.60000","-3.43719","-223.45355"
"294.90003","-3.44078","-223.57959"
"295.20000","-3.44422","-223.69934"
"295.50000","-3.44781","-223.78964"
"295.80003","-3.45125","-223.92714"
"296.10000","-3.45484","-224.03527"
"296.40003","-3.45813","-224.08862"
"296.70000","-3.46172","-224.22230"
"297.00000","-3.46500","-224.03844"
"297.30003","-3.46859","-223.85824"
"297.60000","-3.47203","-223.88518"
"297.90003","-3.47563","-223.90641"
"298.20000","-3.47922","-223.76612"
"298.50000","-3.48281","-222.35291"
"298.80003","-3.48625","-222.26207"
"299.10000","-3.48969","-222.34373"
"299.40003","-3.49313","-222.34961"
"299.70000","-3.49672","-222.46873"
"300.00000","-3.50016","-222.39937"
"300.30003","-3.50344","-222.41089"
"300.60000","-3.50703","-222.56089"
"300.90003","-3.51063","-222.58081"
"301.20000","-3.51422","-222.71469"
"301.50000","-3.51766","-222.63220"
"301.80003","-3.52125","-222.95091"
"302.10000","-3.52469","-223.02421"
"302.40003","-3.52828","-223.12900"
"302.70000","-3.53172","-223.24903"
"303.00000","-3.53500","-223.34903"
"303.30003","-3.53844","-223.43876"
"303.60000","-3.54219","-223.63426"
"303.90003","-3.54563","-223.69746"
"304.20000","-3.54922","-223.74194"
"304.50000","-3.55266","-223.73585"
"304.80003","-3.55625","-224.03941"
"305.10000","-3.55969","-223.96579"
"305.40003","-3.56328","-224.15234"
"305.70000","-3.56672","-224.17994"
"306.00000","-3.57000","-224.25883"
"306.30003","-3.57359","-224.38174"
"306.60000","-3.57703","-224.51315"
"306.90003","-3.58062","-224.69260"
"307.20000","-3.58406","-224.60731"
"307.50000","-3.58781","-224.72205"
"307.80003","-3.59125","-224.84180"
"308.10000","-3.59484","-224.92973"
"308.40003","-3.59828","-225.03627"
"308.70000","-3.60172","-225.18240"
"309.00000","-3.60516","-225.25733"
"309.30003","-3.60859","-225.22589"
"309.60000","-3.61203","-225.36054"
"309.90003","-3.61562","-225.47044"
"310.20000","-3.61922","-225.57659"
"310.50000","-3.62281","-225.59848"
"310.80003","-3.62625","-225.61247"
"311.10000","-3.62984","-225.62066"
"311.40003","-3.63328","-225.68932"
"311.70000","-3.63656","-225.86148"
"312.00000","-3.64000","-225.43767"
"312.30003","-3.64359","-225.57942"
"312.60000","-3.64719","-225.92526"
"312.90003","-3.65063","-226.12637"
"313.20000","-3.65422","-225.80886"
"313.50000","-3.65766","-225.90959"
"313.80003","-3.66125","-226.05058"
"314.10000","-3.66469","-225.96220"
"314.40003","-3.66813","-226.10391"
"314.70000","-3.67156","-226.17275"
"315.00000","-3.67500","-226.39893"
"315.30003","-3.67859","-226.47263"
"315.60000","-3.68203","-226.55280"
"315.90003","-3.68563","-226.72910"
"316.20000","-3.68906","-226.77330"
"316.50000","-3.69281","-226.91721"
"316.80003","-3.69609","-227.01306"
"317.10000","-3.69984","-227.10767"
"317.40003","-3.70328","-226.71601"
"317.70000","-3.70672","-203.54891"
"318.00000","-3.71016","-203.60455"
"318.30003","-3.71359","-203.81708"
"318.60000","-3.71703","-203.90887"
"318.90003","-3.72063","-204.18731"
"319.20000","-3.72422","-204.44337"
"319.50000","-3.72766","-204.63455"
"319.80003","-3.73125","-204.84438"
"320.10000","-3.73484","-205.05670"
"320.40003","-3.73828","-205.34122"
"320.70000","-3.74172","-205.52445"
"321.00000","-3.74500","-205.69123"
"321.30003","-3.74859","-205.96357"
"321.60000","-3.75219","-175.48766"
"321.90003","-3.75563","-175.45318"
"322.20000","-3.75922","-175.68657"
"322.50003","-3.76266","-175.86783"
"322.80003","-3.76625","-176.20251"
"323.10000","-3.76969","-176.33947"
"323.40003","-3.77328","-176.68275"
"323.70000","-3.77656","-176.87080"
"324.00003","-3.78000","-177.16506"
"324.30003","-3.78359","-177.48600"
"324.60000","-3.78719","-177.78754"
"324.90003","-3.79062","-177.99597"
"325.20000","-3.79422","-178.25270"
"325.50003","-3.79781","-178.55508"
"325.80003","-3.80125","-178.82699"
"326.10000","-3.80469","-179.00253"
"326.40003","-3.80812","-179.29628"
"326.70000","-3.81156","-179.57957"
"327.00003","-3.81500","-179.78182"
"327.30003","-3.81859","-180.18218"
"327.60000","-3.82203","-180.40111"
"327.90003","-3.82578","-180.74507"
"328.20000","-3.82922","-180.98325"
"328.50003","-3.83281","-181.30099"
"328.80003","-3.83625","-181.50415"
"329.10000","-3.83984","-181.75533"
"329.40003","-3.84328","-181.99131"
"329.70000","-3.84656","-182.12322"
"330.00003","-3.85000","-182.38464"
"330.30003","-3.85359","-182.66970"
"330.60000","-3.85719","-182.88625"
"330.90003","-3.86062","-182.94631"
"331.20000","-3.86422","-183.17573"
"331.50003","-3.86766","-183.29935"
"331.80003","-3.87125","-183.53524"
"332.10000","-3.87453","-183.67633"
"332.40003","-3.87828","-183.92937"
"332.70000","-3.88156","-184.01293"
"333.00003","-3.88500","-184.13814"
"333.30003","-3.88859","-184.15688"
"333.60000","-3.89203","-184.21784"
"333.90003","-3.89563","-184.40589"
"334.20000","-3.89922","-184.58122"
"334.50003","-3.90266","-184.74445"
"334.80003","-3.90625","-184.93192"
"335.10000","-3.90969","-185.05760"
"335.40003","-3.91328","-185.19586"
"335.70000","-3.91672","-185.36119"
"336.00003","-3.92000","-185.50603"
"336.30003","-3.92359","-185.57096"
"336.60000","-3.92703","-185.65739"
"336.90003","-3.93063","-185.86775"
"337.20000","-3.93406","-185.96834"
"337.50003","-3.93781","-186.09442"
"337.80003","-3.94125","-186.24600"
"338.10000","-3.94484","-186.36776"
"338.40003","-3.94828","-186.53926"
"338.70000","-3.95156","-186.63270"
"339.00003","-3.95500","-186.80364"
"339.30003","-3.95859","-187.01132"
"339.60000","-3.96203","-187.17613"
"339.90003","-3.96563","-187.41675"
"340.20000","-3.96906","-187.02632"
"340.50003","-3.97281","-187.24119"
"340.80003","-3.97625","-187.25865"
"341.10000","-3.97969","-187.33492"
"341.40003","-3.98328","-187.30892"
"341.70000","-3.98656","-187.28219"
"342.00003","-3.99000","-186.80459"
"342.30003","-3.99344","-186.60871"
"342.60000","-3.99719","-186.65256"
"342.90003","-4.00078","-177.12466"
"343.20000","-4.00422","-177.43921"
"343.50003","-4.00781","-177.73956"
"343.80003","-4.01125","-178.05567"
"344.10000","-4.01469","-178.29781"
"344.40003","-4.01813","-178.59355"
"344.70000","-4.02156","-178.83867"
"345.00003","-4.02500","-179.14847"
"345.30003","-4.02844","-179.35963"
"345.60000","-4.03219","-179.69573"
"345.90003","-4.03578","-179.93763"
"346.20000","-4.03922","-180.08545"
"346.50003","-4.04281","-180.32072"
"346.80003","-4.04625","-180.47549"
"347.10000","-4.04969","-180.70908"
"347.40003","-4.05297","-180.76716"
"347.70000","-4.05656","-180.98958"
"348.00003","-4.06000","-181.28522"
"348.30003","-4.06375","-181.33895"
"348.60000","-4.06719","-181.64532"
"348.90003","-4.07078","-181.77247"
"349.20000","-4.07422","-181.80603"
"349.50003","-4.07781","-182.07729"
"349.80003","-4.08125","-182.17942"
"350.10000","-4.08484","-182.32949"
"350.40003","-4.08813","-182.45183"
"350.70000","-4.09156","-182.56124"
"351.00003","-4.09500","-182.72676"
"351.30003","-4.09859","-182.89225"
"351.60000","-4.10219","-182.99691"
"351.90003","-4.10563","-182.95793"
"352.20000","-4.10922","-183.12866"
"352.50003","-4.11266","-183.25172"
"352.80003","-4.11625","-183.46587"
"353.10000","-4.11969","-183.45103"
"353.40003","-4.12313","-183.47993"
"353.70000","-4.12656","-180.95143"
"354.00003","-4.13000","-180.75181"
"354.30003","-4.13359","-180.67852"
"354.60000","-4.13719","-180.70390"
"354.90003","-4.14063","-180.84250"
"355.20000","-4.14422","-180.89419"
"355.50003","-4.14766","-180.94705"
"355.80003","-4.15125","-181.07375"
"356.10000","-4.15469","-181.01137"
"356.40003","-4.15813","-181.06874"
"356.70000","-4.16156","-181.09305"
"357.00003","-4.16500","-181.03439"
"357.30003","-4.16859","-181.00891"
"357.60000","-4.17203","-180.89928"
"357.90003","-4.17563","-181.01024"
"358.20000","-4.17922","-181.05300"
"358.50003","-4.18281","-181.21129"
"358.80003","-4.18625","-181.25288"
"359.10000","-4.18969","-181.31675"
"359.40003","-4.19313","-181.02130"
"359.70000","-4.19656","-180.44828"
"360.00003","-4.20000","-180.49555"
"360.30003","-4.20359","-180.61554"
"360.60000","-4.20703","-180.62320"
"360.90003","-4.21063","-180.62580"
"361.20000","-4.21422","-180.66518"
"361.50003","-4.21781","-180.78920"
"361.80003","-4.22125","-180.82086"
"362.10000","-4.22469","-180.95413"
"362.40003","-4.22813","-180.96732"
"362.70000","-4.23141","-180.96570"
"363.00003","-4.23516","-181.18115"
"363.30003","-4.23859","-181.19171"
"363.60000","-4.24219","-181.28900"
"363.90003","-4.24578","-181.42669"
"364.20000","-4.24922","-181.53366"
"364.50003","-4.25266","-181.61787"
"364.80003","-4.25625","-181.75080"
"365.10000","-4.25969","-181.84971"
"365.40003","-4.26297","-181.96741"
"365.70000","-4.26641","-181.90289"
"366.00003","-4.27016","-182.01279"
"366.30003","-4.27375","-181.94385"
"366.60000","-4.27719","-136.68782"
"366.90003","-4.28078","-136.81469"
"367.20000","-4.28422","-137.13659"
"367.50003","-4.28781","-137.37348"
"367.80003","-4.29109","-137.61240"
"368.10000","-4.29469","-137.88843"
"368.40003","-4.29797","-138.03274"
"368.70000","-4.30156","-138.20673"
"369.00003","-4.30500","-138.41730"
"369.30003","-4.30859","-138.69243"
"369.60000","-4.31203","-138.83031"
"369.90003","-4.31562","-139.17906"
"370.20000","-4.31922","-139.33671"
"370.50003","-4.32266","-139.64374"
"370.80003","-4.32625","-139.73426"
"371.10000","-4.32969","-140.01268"
"371.40003","-4.33312","-140.12176"
"371.70000","-4.33656","-140.33301"
"372.00003","-4.34000","-140.19990"
"372.15403","-4.34188","-140.15904"