File: Lab 4 Data/G3NE_DRY.csv
Text Inputs : Specimen label,"G3NE_DRY"
Test : Rate 1,"14.93964",mm/min
Dimension : Support span,"50.00000",mm
Dimension : Thickness,"2.78900",mm
Dimension : Width,"13.44000",mm

Time,Extension,Load
(sec),(mm),(N)
"0.00000","0.00000","-0.00552"
"0.05000","-0.00578","-0.06558"
"0.10000","-0.01984","-0.35838"
"0.15000","-0.03437","-0.69293"
"0.20000","-0.04828","-1.05270"
"0.25000","-0.06156","-1.39877"
"0.30000","-0.07437","-1.72275"
"0.35000","-0.08703","-2.01660"
"0.40000","-0.09937","-2.31357"
"0.45000","-0.11188","-2.63564"
"0.50000","-0.12438","-2.93981"
"0.55000","-0.13688","-3.20193"
"0.60000","-0.14922","-3.49724"
"0.65000","-0.16188","-3.80000"
"0.70000","-0.17406","-4.13453"
"0.75000","-0.18656","-4.42757"
"0.80000","-0.19922","-4.73862"
"0.85000","-0.21156","-5.04427"
"0.90000","-0.22422","-5.33499"
"0.95000","-0.23656","-5.62694"
"1.00000","-0.24891","-5.93615"
"1.05000","-0.26156","-6.24922"
"1.10000","-0.27391","-6.53447"
"1.15000","-0.28641","-6.85618"
"1.20000","-0.29891","-7.16218"
"1.25000","-0.31125","-7.51971"
"1.30000","-0.32359","-7.81921"
"1.35000","-0.33609","-8.11718"
"1.40000","-0.34844","-8.45143"
"1.45000","-0.36094","-8.77707"
"1.50000","-0.37359","-9.10765"
"1.55000","-0.38594","-9.40015"
"1.60000","-0.39859","-9.75031"
"1.65000","-0.41078","-10.10308"
"1.70000","-0.42312","-10.39255"
"1.75000","-0.43578","-10.71793"
"1.80000","-0.44813","-11.05231"
"1.85000","-0.46047","-11.36694"
"1.90000","-0.47297","-11.70825"
"1.95000","-0.48531","-12.03289"
"2.00000","-0.49766","-12.37717"
"2.05000","-0.51031","-12.68742"
"2.10000","-0.52281","-13.06734"
"2.15000","-0.53516","-13.36362"
"2.20000","-0.54781","-13.72351"
"2.25000","-0.56000","-14.05705"
"2.30000","-0.57266","-14.34578"
"2.35000","-0.58500","-14.73079"
"2.40000","-0.59734","-15.03163"
"2.45000","-0.61016","-15.37003"
"2.50000","-0.62234","-15.71390"
"2.55000","-0.63484","-16.04436"
"2.60000","-0.64734","-16.35356"
"2.65000","-0.65953","-16.69421"
"2.70000","-0.67219","-16.96463"
"2.75000","-0.68469","-17.33260"
"2.80000","-0.69719","-17.64693"
"2.85000","-0.70969","-17.98488"
"2.90000","-0.72219","-18.30711"
"2.95000","-0.73453","-18.68030"
"3.00000","-0.74703","-19.00540"
"3.05000","-0.75953","-19.34592"
"3.10000","-0.77188","-19.63905"
"3.15000","-0.78453","-19.96443"
"3.20000","-0.79656","-20.28923"
"3.25000","-0.80906","-20.58733"
"3.30000","-0.82172","-20.96823"
"3.35000","-0.83391","-21.27361"
"3.40000","-0.84656","-21.62718"
"3.45000","-0.85906","-22.00395"
"3.50000","-0.87141","-22.30085"
"3.55000","-0.88391","-22.68485"
"3.60000","-0.89625","-22.98150"
"3.65000","-0.90875","-23.32372"
"3.70000","-0.92125","-23.64082"
"3.75000","-0.93359","-23.99802"
"3.80000","-0.94594","-24.29113"
"3.85000","-0.95859","-24.67458"
"3.90000","-0.97078","-24.98698"
"3.95000","-0.98328","-25.29714"
"4.00000","-0.99609","-25.63019"
"4.05000","-1.00844","-26.03152"
"4.10000","-1.02094","-26.34262"
"4.15000","-1.03328","-26.67047"
"4.20000","-1.04563","-26.97667"
"4.25000","-1.05828","-27.31717"
"4.30000","-1.07047","-27.63771"
"4.35000","-1.08297","-27.97564"
"4.40000","-1.09547","-28.29542"
"4.45000","-1.10781","-28.69553"
"4.50000","-1.12016","-29.00042"
"4.55000","-1.13297","-29.36546"
"4.60000","-1.14516","-29.70360"
"4.65000","-1.15766","-30.03548"
"4.70000","-1.17047","-30.36447"
"4.75000","-1.18250","-30.69705"
"4.80000","-1.19500","-31.05696"
"4.85000","-1.20750","-31.36804"
"4.90000","-1.21969","-31.74108"
"4.95000","-1.23250","-32.07516"
"5.00000","-1.24484","-32.41354"
"5.05000","-1.25719","-32.72917"
"5.10000","-1.26984","-33.05740"
"5.15000","-1.28203","-33.39670"
"5.20000","-1.29469","-33.74496"
"5.25000","-1.30734","-34.07391"
"5.30000","-1.31953","-34.36408"
"5.35000","-1.33219","-34.73007"
"5.40000","-1.34469","-35.07681"
"5.45000","-1.35688","-35.40416"
"5.50000","-1.36938","-35.72198"
"5.55000","-1.38203","-36.08893"
"5.60000","-1.39422","-36.43912"
"5.65000","-1.40672","-36.74017"
"5.70000","-1.41922","-37.07331"
"5.75000","-1.43141","-37.42485"
"5.80000","-1.44422","-37.76404"
"5.85000","-1.45641","-38.10721"
"5.90000","-1.46906","-38.40731"
"5.95000","-1.48172","-38.77010"
"6.00000","-1.49375","-39.11338"
"6.05000","-1.50641","-39.45660"
"6.10000","-1.51875","-39.79226"
"6.15000","-1.53109","-40.15333"
"6.20000","-1.54375","-40.49472"
"6.25000","-1.55609","-40.82490"
"6.30000","-1.56844","-41.18348"
"6.35000","-1.58094","-41.53217"
"6.40000","-1.59344","-41.84817"
"6.45000","-1.60578","-42.22128"
"6.50000","-1.61859","-42.54729"
"6.55000","-1.63062","-42.87654"
"6.60000","-1.64328","-43.25414"
"6.65000","-1.65594","-43.56457"
"6.70000","-1.66797","-43.91589"
"6.75000","-1.68078","-44.23229"
"6.80000","-1.69328","-44.58333"
"6.85000","-1.70547","-44.91131"
"6.90000","-1.71812","-45.23121"
"6.95000","-1.73047","-45.59884"
"7.00000","-1.74266","-45.93975"
"7.05000","-1.75531","-46.24813"
"7.10000","-1.76766","-46.56953"
"7.15000","-1.78016","-46.91453"
"7.20000","-1.79313","-47.27717"
"7.25000","-1.80516","-47.62843"
"7.30000","-1.81750","-47.95322"
"7.35000","-1.83016","-48.30413"
"7.40000","-1.84219","-48.66001"
"7.45000","-1.85500","-48.98796"
"7.50000","-1.86734","-49.35188"
"7.55000","-1.87953","-49.70918"
"7.60000","-1.89234","-50.02165"
"7.65000","-1.90453","-50.36638"
"7.70000","-1.91719","-50.69373"
"7.75000","-1.92984","-51.05805"
"7.80000","-1.94203","-51.41815"
"7.85000","-1.95453","-51.77192"
"7.90000","-1.96719","-52.09804"
"7.95000","-1.97938","-52.44900"
"8.00000","-1.99188","-52.80861"
"8.05000","-2.00453","-53.15837"
"8.10000","-2.01656","-53.47852"
"8.15000","-2.02938","-53.86756"
"8.20000","-2.04172","-54.18500"
"8.25000","-2.05391","-54.48539"
"8.30000","-2.06672","-54.81953"
"8.35000","-2.07891","-55.16273"
"8.40000","-2.09156","-55.49420"
"8.45000","-2.10438","-55.87426"
"8.50000","-2.11625","-56.16268"
"8.55000","-2.12891","-56.50846"
"8.60000","-2.14141","-56.85288"
"8.65000","-2.15359","-57.21000"
"8.70000","-2.16625","-57.54726"
"8.75000","-2.17859","-57.87099"
"8.80000","-2.19094","-58.22534"
"8.85000","-2.20359","-58.57018"
"8.90000","-2.21594","-58.88593"
"8.95000","-2.22812","-59.23727"
"9.00000","-2.24109","-59.56815"
"9.05000","-2.25344","-59.92431"
"9.10000","-2.26578","-60.24153"
"9.15000","-2.27859","-60.63761"
"9.20000","-2.29031","-60.93270"
"9.25000","-2.30297","-61.24796"
"9.30000","-2.31563","-61.65376"
"9.35000","-2.32797","-61.97712"
"9.40000","-2.34047","-62.35394"
"9.45000","-2.35297","-62.69208"
"9.50000","-2.36516","-63.02565"
"9.55000","-2.37781","-63.35302"
"9.60000","-2.39031","-63.68986"
"9.65000","-2.40266","-64.05242"
"9.70000","-2.41547","-64.33536"
"9.75000","-2.42766","-64.67410"
"9.80000","-2.43984","-64.97150"
"9.85000","-2.45281","-65.33226"
"9.90000","-2.46484","-65.63339"
"9.95000","-2.47750","-65.95490"
"10.00000","-2.49016","-66.30108"
"10.05000","-2.50203","-66.61947"
"10.10000","-2.51484","-66.97144"
"10.15000","-2.52703","-67.28211"
"10.20000","-2.53953","-67.57830"
"10.25000","-2.55219","-67.92724"
"10.30000","-2.56469","-68.24331"
"10.35000","-2.57719","-68.55564"
"10.40000","-2.58969","-68.87190"
"10.45000","-2.60187","-69.19698"
"10.50000","-2.61437","-69.50659"
"10.55000","-2.62703","-69.84919"
"10.60000","-2.63922","-70.18097"
"10.65000","-2.65172","-70.49145"
"10.70000","-2.66438","-70.83485"
"10.75000","-2.67625","-71.17247"
"10.80000","-2.68906","-71.44805"
"10.85000","-2.70156","-71.79999"
"10.90000","-2.71391","-72.10204"
"10.95000","-2.72672","-72.42788"
"11.00000","-2.73891","-72.74302"
"11.05000","-2.75125","-73.05732"
"11.10000","-2.76391","-73.39933"
"11.15000","-2.77625","-73.72735"
"11.20000","-2.78875","-74.04488"
"11.25000","-2.80125","-74.35263"
"11.30000","-2.81344","-74.68797"
"11.35000","-2.82594","-74.95178"
"11.40000","-2.83844","-75.28787"
"11.45000","-2.85062","-75.62619"
"11.50000","-2.86344","-75.93657"
"11.55000","-2.87578","-76.26340"
"11.60000","-2.88813","-76.57797"
"11.65000","-2.90094","-76.88550"
"11.70000","-2.91297","-77.19129"
"11.75000","-2.92547","-77.52474"
"11.80000","-2.93828","-77.83732"
"11.85000","-2.95047","-78.15960"
"11.90000","-2.96297","-78.44611"
"11.95000","-2.97547","-78.73309"
"12.00000","-2.98766","-79.08319"
"12.05000","-3.00031","-79.41887"
"12.10000","-3.01297","-79.73144"
"12.15000","-3.02516","-80.05424"
"12.20000","-3.03781","-80.37284"
"12.25000","-3.05016","-80.69811"
"12.30000","-3.06234","-81.00798"
"12.35000","-3.07531","-81.35099"
"12.40000","-3.08734","-81.68734"
"12.45000","-3.09984","-81.95194"
"12.50000","-3.11266","-82.32424"
"12.55000","-3.12453","-82.59845"
"12.60000","-3.13719","-82.93509"
"12.65000","-3.14969","-83.27579"
"12.70000","-3.16203","-83.54787"
"12.75000","-3.17484","-83.91749"
"12.80000","-3.18719","-84.25790"
"12.85000","-3.19953","-84.61195"
"12.90000","-3.21219","-84.92544"
"12.95000","-3.22437","-85.22699"
"13.00000","-3.23656","-85.51291"
"13.05000","-3.24938","-85.86464"
"13.10000","-3.26172","-86.17733"
"13.15000","-3.27406","-86.49262"
"13.20000","-3.28688","-86.77551"
"13.25000","-3.29891","-87.10532"
"13.30000","-3.31156","-87.40660"
"13.35000","-3.32406","-87.73373"
"13.40000","-3.33625","-88.07174"
"13.45000","-3.34922","-88.36288"
"13.50000","-3.36156","-88.67273"
"13.55000","-3.37391","-88.97681"
"13.60000","-3.38641","-89.32838"
"13.65000","-3.39859","-89.64118"
"13.70000","-3.41109","-89.92520"
"13.75000","-3.42375","-90.25563"
"13.80000","-3.43594","-90.59165"
"13.85000","-3.44844","-90.90633"
"13.90000","-3.46094","-91.25577"
"13.95000","-3.47312","-91.53550"
"14.00000","-3.48594","-91.87253"
"14.05000","-3.49844","-92.16455"
"14.10000","-3.51063","-92.49894"
"14.15000","-3.52344","-92.82466"
"14.20000","-3.53563","-93.12662"
"14.25000","-3.54797","-93.42533"
"14.30000","-3.56078","-93.77263"
"14.35000","-3.57297","-94.06990"
"14.40000","-3.58547","-94.40851"
"14.45000","-3.59797","-94.72728"
"14.50000","-3.61016","-95.01756"
"14.55000","-3.62266","-95.32272"
"14.60000","-3.63547","-95.63575"
"14.65000","-3.64766","-95.94552"
"14.70000","-3.66016","-96.26994"
"14.75000","-3.67281","-96.58244"
"14.80000","-3.68484","-96.87722"
"14.85000","-3.69750","-97.17031"
"14.90000","-3.71000","-97.51300"
"14.95000","-3.72234","-97.79374"
"15.00000","-3.73516","-98.11559"
"15.05000","-3.74703","-98.39877"
"15.10000","-3.75969","-98.67811"
"15.15000","-3.77234","-98.99254"
"15.20000","-3.78438","-99.28496"
"15.25000","-3.79703","-99.62353"
"15.30000","-3.80969","-99.96427"
"15.35000","-3.82203","-100.25613"
"15.40000","-3.83469","-100.57020"
"15.45000","-3.84687","-100.89116"
"15.50000","-3.85922","-101.13182"
"15.55000","-3.87188","-101.48314"
"15.60000","-3.88422","-101.81973"
"15.65000","-3.89656","-102.11959"
"15.70000","-3.90938","-102.40888"
"15.75000","-3.92141","-102.70583"
"15.80000","-3.93391","-103.00927"
"15.85000","-3.94672","-103.33406"
"15.90000","-3.95875","-103.63884"
"15.95000","-3.97156","-103.93438"
"16.00000","-3.98406","-104.23993"
"16.05000","-3.99625","-104.53077"
"16.10000","-4.00891","-104.85080"
"16.15000","-4.02125","-105.15182"
"16.20000","-4.03359","-105.44474"
"16.25000","-4.04625","-105.79314"
"16.30000","-4.05844","-106.06888"
"16.35000","-4.07078","-106.36277"
"16.40000","-4.08344","-106.69794"
"16.45000","-4.09578","-106.94760"
"16.50000","-4.10828","-107.24653"
"16.55000","-4.12109","-107.55331"
"16.60000","-4.13313","-107.85817"
"16.65000","-4.14578","-108.15591"
"16.70000","-4.15813","-108.44210"
"16.75000","-4.17047","-108.70663"
"16.80000","-4.18313","-109.03059"
"16.85000","-4.19531","-109.33175"
"16.90000","-4.20781","-109.61066"
"16.95000","-4.22031","-109.91499"
"17.00000","-4.23266","-110.20842"
"17.05000","-4.24516","-110.48239"
"17.10000","-4.25781","-110.77166"
"17.15000","-4.27016","-111.06597"
"17.20000","-4.28266","-111.38728"
"17.25000","-4.29531","-111.67757"
"17.30000","-4.30750","-111.99975"
"17.35000","-4.31984","-112.24795"
"17.40000","-4.33250","-112.58777"
"17.45000","-4.34469","-112.84886"
"17.50000","-4.35750","-113.14053"
"17.55000","-4.36969","-113.43504"
"17.60000","-4.38203","-113.71494"
"17.65000","-4.39469","-114.02940"
"17.70000","-4.40687","-114.28895"
"17.75000","-4.41953","-114.61878"
"17.80000","-4.43219","-114.90377"
"17.85000","-4.44453","-115.19139"
"17.90000","-4.45703","-115.48181"
"17.95000","-4.46953","-115.79342"
"18.00000","-4.48172","-116.06014"
"18.05000","-4.49422","-116.34380"
"18.10000","-4.50688","-116.64226"
"18.15000","-4.51906","-116.91860"
"18.20000","-4.53172","-117.20742"
"18.25000","-4.54406","-117.49454"
"18.30000","-4.55625","-117.75467"
"18.35000","-4.56906","-118.02894"
"18.40000","-4.58141","-118.32749"
"18.45000","-4.59391","-118.59852"
"18.50000","-4.60656","-118.88147"
"18.55000","-4.61875","-119.13095"
"18.60000","-4.63125","-119.44391"
"18.65000","-4.64359","-119.72341"
"18.70000","-4.65609","-119.96511"
"18.75000","-4.66859","-120.24892"
"18.80000","-4.68109","-120.48326"
"18.85000","-4.69344","-120.77344"
"18.90000","-4.70594","-121.03599"
"18.95000","-4.71828","-121.34305"
"19.00000","-4.73063","-121.57649"
"19.05000","-4.74344","-121.86683"
"19.10000","-4.75563","-122.15513"
"19.15000","-4.76813","-122.47195"
"19.20000","-4.78078","-122.74642"
"19.25000","-4.79281","-123.00453"
"19.30000","-4.80547","-123.30024"
"19.35000","-4.81797","-123.56730"
"19.40000","-4.83031","-123.81500"
"19.45000","-4.84281","-124.12215"
"19.50000","-4.85516","-124.39130"
"19.55000","-4.86750","-124.64081"
"19.60000","-4.88016","-124.91610"
"19.65000","-4.89266","-125.20023"
"19.70000","-4.90516","-125.44510"
"19.75000","-4.91781","-125.74838"
"19.80000","-4.93000","-125.97973"
"19.85000","-4.94234","-126.23679"
"19.90000","-4.95500","-126.50259"
"19.95000","-4.96719","-126.76992"
"20.00000","-4.97984","-127.02093"
"20.05000","-4.99219","-127.32129"
"20.10000","-5.00453","-127.51297"
"20.15000","-5.01719","-127.83051"
"20.20000","-5.02938","-128.04814"
"20.25000","-5.04203","-128.34830"
"20.30000","-5.05469","-128.60105"
"20.35000","-5.06703","-128.87227"
"20.40000","-5.07969","-129.09932"
"20.45000","-5.09203","-129.35830"
"20.50000","-5.10422","-129.61878"
"20.55000","-5.11672","-129.86721"
"20.60000","-5.12938","-130.15320"
"20.65000","-5.14156","-130.40207"
"20.70000","-5.15406","-130.63455"
"20.75000","-5.16672","-130.87129"
"20.80000","-5.17875","-131.12152"
"20.85000","-5.19156","-131.39172"
"20.90000","-5.20391","-131.61537"
"20.95000","-5.21641","-131.85178"
"21.00000","-5.22922","-132.16480"
"21.05000","-5.24125","-132.43196"
"21.10000","-5.25375","-132.66807"
"21.15000","-5.26625","-132.92555"
"21.20000","-5.27859","-133.16741"
"21.25000","-5.29109","-133.43257"
"21.30000","-5.30359","-133.66522"
"21.35000","-5.31594","-133.90610"
"21.40000","-5.32828","-134.13399"
"21.45000","-5.34078","-134.36174"
"21.50000","-5.35313","-134.60651"
"21.55000","-5.36594","-134.85651"
"21.60000","-5.37813","-135.12986"
"21.65000","-5.39062","-135.36762"
"21.70000","-5.40328","-135.61486"
"21.75000","-5.41531","-135.88101"
"21.80000","-5.42797","-136.08490"
"21.85000","-5.44062","-136.35024"
"21.90000","-5.45281","-136.60253"
"21.95000","-5.46547","-136.82842"
"22.00000","-5.47781","-137.08130"
"22.05000","-5.49000","-137.28620"
"22.10000","-5.50266","-137.53062"
"22.15000","-5.51516","-137.81442"
"22.20000","-5.52750","-138.03155"
"22.25000","-5.54031","-138.24175"
"22.30000","-5.55250","-138.49476"
"22.35000","-5.56484","-138.69734"
"22.40000","-5.57766","-138.94480"
"22.45000","-5.58969","-139.16275"
"22.50000","-5.60234","-139.36634"
"22.55000","-5.61484","-139.61967"
"22.60000","-5.62687","-139.82804"
"22.65000","-5.63969","-140.04248"
"22.70000","-5.65187","-140.26972"
"22.75000","-5.66438","-140.49763"
"22.80000","-5.67703","-140.72604"
"22.85000","-5.68953","-140.93806"
"22.90000","-5.70203","-141.20055"
"22.95000","-5.71453","-141.42104"
"23.00000","-5.72688","-141.65260"
"23.05000","-5.73922","-141.85378"
"23.10000","-5.75188","-142.06246"
"23.15000","-5.76406","-142.29741"
"23.20000","-5.77656","-142.52650"
"23.25000","-5.78922","-142.79812"
"23.30000","-5.80125","-143.03567"
"23.35000","-5.81391","-143.27665"
"23.40000","-5.82641","-143.52754"
"23.45000","-5.83875","-143.73913"
"23.50000","-5.85172","-144.01089"
"23.55000","-5.86375","-144.21308"
"23.60000","-5.87609","-144.41266"
"23.65000","-5.88875","-144.64250"
"23.70000","-5.90109","-144.83378"
"23.75000","-5.91359","-145.06192"
"23.80000","-5.92609","-145.29851"
"23.85000","-5.93844","-145.50623"
"23.90000","-5.95078","-145.70577"
"23.95000","-5.96344","-145.93901"
"24.00000","-5.97563","-146.12753"
"24.05000","-5.98828","-146.34202"
"24.10000","-6.00078","-146.55298"
"24.15000","-6.01313","-146.74495"
"24.20000","-6.02578","-146.97864"
"24.25000","-6.03797","-147.17773"
"24.30000","-6.05031","-147.35282"
"24.35000","-6.06297","-147.58929"
"24.40000","-6.07531","-147.78743"
"24.45000","-6.08781","-147.96034"
"24.50000","-6.10031","-148.18120"
"24.55000","-6.11250","-148.39415"
"24.60000","-6.12500","-148.59398"
"24.65000","-6.13766","-148.78943"
"24.70000","-6.15000","-148.99375"
"24.75000","-6.16250","-149.20882"
"24.80000","-6.17500","-149.42459"
"24.85000","-6.18734","-149.63362"
"24.90000","-6.20000","-149.82210"
"24.95000","-6.21219","-150.02482"
"25.00000","-6.22469","-150.24820"
"25.05000","-6.23750","-150.44557"
"25.10000","-6.24938","-150.59822"
"25.15000","-6.26203","-150.82449"
"25.20000","-6.27469","-151.02769"
"25.25000","-6.28687","-151.20766"
"25.30000","-6.29953","-151.42404"
"25.35000","-6.31188","-151.62083"
"25.40000","-6.32438","-151.79359"
"25.45000","-6.33703","-151.98709"
"25.50000","-6.34922","-152.16466"
"25.55000","-6.36172","-152.35244"
"25.60000","-6.37437","-152.57555"
"25.65000","-6.38672","-152.78432"
"25.70000","-6.39906","-152.96349"
"25.75000","-6.41172","-153.19671"
"25.80000","-6.42375","-153.35076"
"25.85000","-6.43641","-153.57079"
"25.90000","-6.44906","-153.79642"
"25.95000","-6.46109","-153.95775"
"26.00000","-6.47406","-154.18475"
"26.05000","-6.48625","-154.37406"
"26.10000","-6.49859","-154.53720"
"26.15000","-6.51125","-154.74549"
"26.20000","-6.52344","-154.90827"
"26.25000","-6.53609","-155.09452"
"26.30000","-6.54859","-155.31295"
"26.35000","-6.56078","-155.45995"
"26.40000","-6.57328","-155.65589"
"26.45000","-6.58594","-155.82253"
"26.50000","-6.59813","-156.03169"
"26.55000","-6.61078","-156.24538"
"26.60000","-6.62344","-156.41944"
"26.65000","-6.63562","-156.62270"
"26.70000","-6.64828","-156.78549"
"26.75000","-6.66047","-156.97967"
"26.80000","-6.67266","-157.13511"
"26.85000","-6.68563","-157.36826"
"26.90000","-6.69766","-157.51097"
"26.95000","-6.71031","-157.70894"
"27.00000","-6.72297","-157.88637"
"27.05000","-6.73500","-158.04807"
"27.10000","-6.74750","-158.23953"
"27.15000","-6.76016","-158.39478"
"27.20000","-6.77250","-158.58920"
"27.25000","-6.78500","-158.76601"
"27.30000","-6.79766","-158.96522"
"27.35000","-6.80969","-159.11989"
"27.40000","-6.82234","-159.27555"
"27.45000","-6.83469","-159.48026"
"27.50000","-6.84703","-159.62163"
"27.55000","-6.86000","-159.81313"
"27.60000","-6.87187","-159.99721"
"27.65000","-6.88453","-160.12602"
"27.70000","-6.89719","-160.30572"
"27.75000","-6.90922","-160.46954"
"27.80000","-6.92203","-160.63631"
"27.85000","-6.93469","-160.84822"
"27.90000","-6.94688","-160.96264"
"27.95000","-6.95953","-161.12566"
"28.00000","-6.97188","-161.29231"
"28.05000","-6.98406","-161.43054"
"28.10000","-6.99672","-161.60002"
"28.15000","-7.00922","-161.75143"
"28.20000","-7.02141","-161.88538"
"28.25000","-7.03422","-162.09144"
"28.30000","-7.04625","-162.25325"
"28.35000","-7.05875","-162.42621"
"28.40000","-7.07156","-162.59432"
"28.45000","-7.08359","-162.71485"
"28.50000","-7.09641","-162.91793"
"28.55000","-7.10891","-163.07320"
"28.60000","-7.12109","-163.18668"
"28.65000","-7.13375","-163.39289"
"28.70000","-7.14609","-163.53043"
"28.75000","-7.15844","-163.71068"
"28.80000","-7.17109","-163.86619"
"28.85000","-7.18328","-164.04767"
"28.90000","-7.19562","-164.16039"
"28.95000","-7.20828","-164.34681"
"29.00000","-7.22047","-164.50943"
"29.05000","-7.23297","-164.67042"
"29.10000","-7.24594","-164.81381"
"29.15000","-7.25797","-164.92490"
"29.20000","-7.27078","-165.07246"
"29.25000","-7.28313","-165.22642"
"29.30000","-7.29516","-165.29467"
"29.35000","-7.30797","-165.47333"
"29.40000","-7.32031","-165.58504"
"29.45000","-7.33266","-165.70738"
"29.50000","-7.34531","-165.87960"
"29.55000","-7.35750","-165.97748"
"29.60000","-7.37000","-166.14370"
"29.65000","-7.38266","-166.29416"
"29.70000","-7.39500","-166.43448"
"29.75000","-7.40766","-166.54801"
"29.80000","-7.42031","-166.70438"
"29.85000","-7.43234","-166.82643"
"29.90000","-7.44484","-166.97923"
"29.95000","-7.45734","-167.12053"
"30.00000","-7.46953","-167.24443"
"30.05000","-7.48234","-167.38513"
"30.10000","-7.49453","-167.52889"
"30.15000","-7.50687","-167.62925"
"30.20000","-7.51969","-167.79447"
"30.25000","-7.53172","-167.90377"
"30.30000","-7.54438","-168.03544"
"30.35000","-7.55719","-168.16553"
"30.40000","-7.56922","-168.27792"
"30.45000","-7.58188","-168.42052"
"30.50000","-7.59453","-168.54789"
"30.55000","-7.60656","-168.63028"
"30.60000","-7.61922","-168.77649"
"30.65000","-7.63172","-168.90716"
"30.70000","-7.64391","-169.01856"
"30.75000","-7.65656","-169.13675"
"30.80000","-7.66891","-169.27879"
"30.85000","-7.68125","-169.35235"
"30.90000","-7.69406","-169.50615"
"30.95000","-7.70609","-169.61571"
"31.00000","-7.71875","-169.75207"
"31.05000","-7.73156","-169.83323"
"31.10000","-7.74359","-169.90867"
"31.15000","-7.75625","-170.04551"
"31.20000","-7.76859","-170.14923"
"31.25000","-7.78094","-170.24130"
"31.30000","-7.79359","-170.39131"
"31.35000","-7.80594","-170.51123"
"31.40000","-7.81813","-170.58492"
"31.45000","-7.83078","-170.72562"
"31.50000","-7.84313","-170.81387"
"31.55000","-7.85547","-170.94402"
"31.60000","-7.86844","-171.05894"
"31.65000","-7.88031","-171.17398"
"31.70000","-7.89313","-171.26590"
"31.75000","-7.90578","-171.36950"
"31.80000","-7.91766","-171.45347"
"31.85000","-7.93047","-171.56329"
"31.90000","-7.94281","-171.68308"
"31.95000","-7.95516","-171.81059"
"32.00000","-7.96781","-171.91466"
"32.05000","-7.98016","-172.00585"
"32.10000","-7.99234","-172.15518"
"32.15000","-8.00500","-172.27676"
"32.20000","-8.01750","-172.40152"
"32.25000","-8.03000","-172.53656"
"32.30000","-8.04281","-172.64223"
"32.35000","-8.05484","-172.76496"
"32.40000","-8.06719","-172.86668"
"32.45000","-8.07984","-172.98909"
"32.50000","-8.09219","-173.04143"
"32.55000","-8.10484","-173.12115"
"32.60000","-8.11719","-173.22209"
"32.65000","-8.12938","-173.21562"
"32.70000","-8.14203","-173.37533"
"32.75000","-8.15422","-173.46371"
"32.80000","-8.16688","-173.53624"
"32.85000","-8.17969","-173.65957"
"32.90000","-8.19172","-173.74326"
"32.95000","-8.20438","-173.86548"
"33.00000","-8.21703","-173.96236"
"33.05000","-8.22906","-174.07263"
"33.10000","-8.24156","-174.15259"
"33.15000","-8.25422","-174.29028"
"33.20000","-8.26641","-174.37160"
"33.25000","-8.27906","-174.47008"
"33.30000","-8.29156","-174.57914"
"33.35000","-8.30359","-174.65146"
"33.40000","-8.31641","-174.76054"
"33.45000","-8.32875","-174.84823"
"33.50000","-8.34109","-174.92451"
"33.55000","-8.35391","-175.00401"
"33.60000","-8.36609","-175.06590"
"33.65000","-8.37875","-175.18647"
"33.70000","-8.39125","-175.26759"
"33.75000","-8.40344","-175.33142"
"33.80000","-8.41594","-175.48246"
"33.85000","-8.42844","-175.53484"
"33.90000","-8.44078","-175.61354"
"33.95000","-8.45328","-175.68756"
"34.00000","-8.46563","-175.78635"
"34.05000","-8.47797","-175.85294"
"34.10000","-8.49078","-175.95539"
"34.15000","-8.50297","-176.03496"
"34.20000","-8.51547","-176.08862"
"34.25000","-8.52828","-176.21106"
"34.30000","-8.54016","-176.25364"
"34.35000","-8.55281","-176.32226"
"34.40000","-8.56547","-176.45162"
"34.45000","-8.57766","-176.50330"
"34.50000","-8.59031","-176.59269"
"34.55000","-8.60266","-176.66433"
"34.60000","-8.61484","-176.70212"
"34.65000","-8.62750","-176.82012"
"34.70000","-8.64000","-176.88602"
"34.75000","-8.65250","-176.93095"
"34.80000","-8.66500","-177.03209"
"34.85000","-8.67734","-177.08572"
"34.90000","-8.68953","-177.13005"
"34.95000","-8.70250","-177.26758"
"35.00000","-8.71469","-177.34833"
"35.05000","-8.72719","-177.46976"
"35.10000","-8.73984","-177.53445"
"35.15000","-8.75187","-177.55602"
"35.20000","-8.76453","-177.69821"
"35.25000","-8.77688","-177.75491"
"35.30000","-8.78938","-177.80358"
"35.35000","-8.80203","-177.93190"
"35.40000","-8.81437","-177.97804"
"35.45000","-8.82688","-178.08206"
"35.50000","-8.83938","-178.15465"
"35.55000","-8.85172","-178.19291"
"35.60000","-8.86406","-178.25434"
"35.65000","-8.87688","-178.30838"
"35.70000","-8.88906","-178.34874"
"35.75000","-8.90141","-178.41375"
"35.80000","-8.91406","-178.48171"
"35.85000","-8.92609","-178.48391"
"35.90000","-8.93891","-178.58844"
"35.95000","-8.95125","-178.63926"
"36.00000","-8.96359","-178.67748"
"36.05000","-8.97641","-178.78314"
"36.10000","-8.98859","-178.83563"
"36.15000","-9.00094","-178.87957"
"36.20000","-9.01359","-178.96155"
"36.25000","-9.02594","-179.02771"
"36.30000","-9.03844","-179.06509"
"36.35000","-9.05094","-179.16413"
"36.40000","-9.06328","-179.18883"
"36.45000","-9.07562","-179.24290"
"36.50000","-9.08813","-179.32495"
"36.55000","-9.10047","-179.34382"
"36.60000","-9.11313","-179.41769"
"36.65000","-9.12578","-179.47830"
"36.70000","-9.13797","-179.51123"
"36.75000","-9.15078","-179.56456"
"36.80000","-9.16281","-179.62605"
"36.85000","-9.17531","-179.67518"
"36.90000","-9.18797","-179.76232"
"36.95000","-9.20016","-179.79147"
"37.00000","-9.21281","-179.84981"
"37.05000","-9.22516","-179.91310"
"37.10000","-9.23750","-179.95277"
"37.15000","-9.24984","-180.00521"
"37.20000","-9.26250","-180.04084"
"37.25000","-9.27484","-180.09814"
"37.30000","-9.28734","-180.13259"
"37.35000","-9.30000","-180.18750"
"37.40000","-9.31219","-180.22850"
"37.45000","-9.32484","-180.31871"
"37.50000","-9.33719","-180.38403"
"37.55000","-9.34953","-180.41691"
"37.60000","-9.36219","-180.47426"
"37.65000","-9.37438","-180.51500"
"37.70000","-9.38703","-180.61083"
"37.75000","-9.39937","-180.66613"
"37.80000","-9.41172","-180.66479"
"37.85000","-9.42438","-180.71121"
"37.90000","-9.43688","-180.77310"
"37.95000","-9.44937","-180.81998"
"38.00000","-9.46188","-180.85280"
"38.05000","-9.47422","-180.86432"
"38.10000","-9.48656","-180.88870"
"38.15000","-9.49906","-180.98842"
"38.20000","-9.51141","-180.97127"
"38.25000","-9.52391","-181.02594"
"38.30000","-9.53656","-181.06865"
"38.35000","-9.54859","-181.08917"
"38.40000","-9.56125","-181.11233"
"38.45000","-9.57391","-181.13481"
"38.50000","-9.58609","-181.13296"
"38.55000","-9.59891","-181.19626"
"38.60000","-9.61125","-181.23174"
"38.65000","-9.62359","-181.22798"
"38.70000","-9.63609","-181.30504"
"38.75000","-9.64844","-181.33888"
"38.80000","-9.66094","-181.41458"
"38.85000","-9.67359","-181.45522"
"38.90000","-9.68594","-181.47653"
"38.95000","-9.69828","-181.49065"
"39.00000","-9.71078","-181.56480"
"39.05000","-9.72313","-181.54783"
"39.10000","-9.73563","-181.58771"
"39.15000","-9.74828","-181.63573"
"39.20000","-9.76047","-181.60909"
"39.25000","-9.77312","-181.67237"
"39.30000","-9.78531","-181.63394"
"39.35000","-9.79781","-181.65696"
"39.40000","-9.81047","-181.72929"
"39.45000","-9.82266","-181.73907"
"39.50000","-9.83516","-181.74207"
"39.55000","-9.84766","-181.75408"
"39.60000","-9.86000","-181.78022"
"39.65000","-9.87234","-181.83745"
"39.70000","-9.88500","-181.83324"
"39.75000","-9.89719","-181.84673"
"39.80000","-9.90969","-181.86746"
"39.85000","-9.92250","-181.91110"
"39.90000","-9.93469","-181.87970"
"39.95000","-9.94719","-181.94063"
"40.00000","-9.95969","-181.95752"
"40.05000","-9.97203","-181.93439"
"40.10000","-9.98469","-182.00621"
"40.15000","-9.99688","-182.00044"
"40.20000","-10.00938","-182.02519"
"40.25000","-10.02203","-182.05741"
"40.30000","-10.03422","-182.04374"
"40.35000","-10.04688","-182.12983"
"40.40000","-10.05938","-182.10802"
"40.45000","-10.07188","-182.09692"
"40.50000","-10.08437","-182.15280"
"40.55000","-10.09672","-182.11665"
"40.60000","-10.10906","-182.15071"
"40.65000","-10.12156","-182.19333"
"40.70000","-10.13406","-182.17657"
"40.75000","-10.14641","-182.18318"
"40.80000","-10.15906","-182.26936"
"40.85000","-10.17125","-182.25376"
"40.90000","-10.18359","-182.25178"
"40.95000","-10.19641","-182.27637"
"41.00000","-10.20859","-182.29218"
"41.05000","-10.22125","-182.28251"
"41.10000","-10.23375","-182.29673"
"41.15000","-10.24594","-182.27465"
"41.20000","-10.25859","-182.29151"
"41.25000","-10.27094","-182.30388"
"41.30000","-10.28344","-182.30818"
"41.35000","-10.29594","-182.32590"
"41.40000","-10.30828","-182.32832"
"41.45000","-10.32063","-182.33158"
"41.50000","-10.33313","-182.35385"
"41.55000","-10.34547","-182.33992"
"41.60000","-10.35797","-182.35339"
"41.65000","-10.37078","-182.37757"
"41.70000","-10.38281","-182.30874"
"41.75000","-10.39547","-182.32899"
"41.80000","-10.40797","-182.33551"
"41.85000","-10.42016","-182.32666"
"41.90000","-10.43281","-182.36419"
"41.95000","-10.44516","-182.34737"
"42.00000","-10.45750","-182.33316"
"42.05000","-10.47016","-182.34627"
"42.10000","-10.48250","-182.36592"
"42.15000","-10.49484","-182.32970"
"42.20000","-10.50750","-182.32083"
"42.25000","-10.51984","-182.31273"
"42.30000","-10.53234","-182.34197"
"42.35000","-10.54516","-182.33711"
"42.40000","-10.55719","-182.28207"
"42.45000","-10.56969","-182.30490"
"42.50000","-10.58219","-182.32465"
"42.55000","-10.59438","-182.32439"
"42.60000","-10.60719","-182.34152"
"42.65000","-10.61937","-182.32068"
"42.70000","-10.63188","-182.32431"
"42.75000","-10.64469","-182.32523"
"42.80000","-10.65672","-182.27506"
"42.85000","-10.66937","-182.31232"
"42.90000","-10.68203","-182.31887"
"42.95000","-10.69422","-182.27132"
"43.00000","-10.70672","-182.29295"
"43.05000","-10.71937","-182.28333"
"43.10000","-10.73141","-182.23485"
"43.15000","-10.74406","-182.26704"
"43.20000","-10.75656","-182.29965"
"43.25000","-10.76875","-182.29123"
"43.30000","-10.78156","-182.27495"
"43.35000","-10.79375","-182.23854"
"43.40000","-10.80609","-182.18834"
"43.45000","-10.81891","-182.22515"
"43.50000","-10.83109","-182.20469"
"43.55000","-10.84375","-182.18003"
"43.60000","-10.85625","-182.21419"
"43.65000","-10.86844","-182.14520"
"43.70000","-10.88094","-182.14762"
"43.75000","-10.89344","-182.12911"
"43.80000","-10.90594","-182.13509"
"43.85000","-10.91844","-182.10018"
"43.90000","-10.93078","-182.05134"
"43.95000","-10.94313","-182.03883"
"44.00000","-10.95563","-182.05866"
"44.05000","-10.96797","-182.04035"
"44.10000","-10.98047","-182.04905"
"44.15000","-10.99328","-182.07554"
"44.20000","-11.00531","-181.97807"
"44.25000","-11.01797","-181.95191"
"44.30000","-11.03063","-181.94502"
"44.35000","-11.04250","-181.87268"
"44.40000","-11.05531","-181.92798"
"44.45000","-11.06781","-181.88024"
"44.50000","-11.08000","-181.91660"
"44.55000","-11.09266","-181.89142"
"44.60000","-11.10484","-181.89289"
"44.65000","-11.11719","-181.86741"
"44.70000","-11.12984","-181.86674"
"44.75000","-11.14234","-181.84429"
"44.80000","-11.15484","-181.79601"
"44.85000","-11.16766","-181.78498"
"44.90000","-11.17969","-181.71584"
"44.95000","-11.19203","-181.68574"
"45.00000","-11.20484","-181.66998"
"45.05000","-11.21688","-181.58607"
"45.10000","-11.22969","-181.64545"
"45.15000","-11.24203","-181.59170"
"45.20000","-11.25422","-181.51762"
"45.25000","-11.26703","-181.55621"
"45.30000","-11.27906","-181.46366"
"45.35000","-11.29172","-181.47392"
"45.40000","-11.30453","-181.45621"
"45.45000","-11.31672","-181.37116"
"45.50000","-11.32922","-181.35324"
"45.55000","-11.34188","-181.31819"
"45.60000","-11.35406","-181.28484"
"45.65000","-11.36656","-181.29595"
"45.70000","-11.37922","-181.24035"
"45.75000","-11.39125","-181.17381"
"45.80000","-11.40391","-181.17433"
"45.85000","-11.41641","-181.13757"
"45.90000","-11.42828","-181.05326"
"45.95000","-11.44125","-181.11942"
"46.00000","-11.45359","-181.06394"
"46.05000","-11.46609","-181.04170"
"46.10000","-11.47891","-180.99962"
"46.15000","-11.49094","-180.89937"
"46.20000","-11.50344","-180.88290"
"46.25000","-11.51609","-180.87661"
"46.30000","-11.52828","-180.80682"
"46.35000","-11.54094","-180.76552"
"46.40000","-11.55344","-180.72309"
"46.45000","-11.56562","-180.66455"
"46.50000","-11.57812","-180.65540"
"46.55000","-11.59047","-180.59490"
"46.60000","-11.60281","-180.53722"
"46.65000","-11.61578","-180.50291"
"46.70000","-11.62797","-180.42430"
"46.75000","-11.64031","-180.40933"
"46.80000","-11.65313","-180.41702"
"46.85000","-11.66500","-180.32080"
"46.90000","-11.67766","-180.30595"
"46.95000","-11.69031","-180.32774"
"47.00000","-11.70250","-180.22897"
"47.05000","-11.71516","-180.23724"
"47.10000","-11.72750","-180.16718"
"47.15000","-11.73969","-180.11395"
"47.20000","-11.75250","-180.06867"
"47.25000","-11.76484","-180.02704"
"47.30000","-11.77719","-179.93683"
"47.35000","-11.79000","-179.94558"
"47.40000","-11.80219","-179.83966"
"47.45000","-11.81453","-179.82725"
"47.50000","-11.82734","-179.82414"
"47.55000","-11.83937","-179.76500"
"47.60000","-11.85203","-179.73838"
"47.65000","-11.86469","-179.70840"
"47.70000","-11.87656","-179.57734"
"47.75000","-11.88937","-179.59820"
"47.80000","-11.90172","-179.52733"
"47.85000","-11.91406","-179.50989"
"47.90000","-11.92688","-179.43971"
"47.95000","-11.93922","-179.35261"
"48.00000","-11.95172","-179.34093"
"48.05000","-11.96438","-179.31610"
"48.10000","-11.97641","-179.23394"
"48.15000","-11.98891","-179.18963"
"48.20000","-12.00172","-179.17207"
"48.25000","-12.01375","-179.07606"
"48.30000","-12.02625","-179.04632"
"48.35000","-12.03891","-178.99312"
"48.40000","-12.05094","-178.89231"
"48.45000","-12.06375","-178.89306"
"48.50000","-12.07609","-178.80695"
"48.55000","-12.08844","-178.73516"
"48.60000","-12.10141","-178.73397"
"48.65000","-12.11344","-178.61666"
"48.70000","-12.12594","-178.57930"
"48.75000","-12.13859","-178.49013"
"48.80000","-12.15078","-178.41348"
"48.85000","-12.16328","-178.43995"
"48.90000","-12.17594","-178.39883"
"48.95000","-12.18797","-178.32153"
"49.00000","-12.20063","-178.25436"
"49.05000","-12.21312","-178.20571"
"49.10000","-12.22531","-178.16773"
"49.15000","-12.23813","-178.09035"
"49.20000","-12.25063","-177.98340"
"49.25000","-12.26266","-177.95393"
"49.30000","-12.27563","-177.94250"
"49.35000","-12.28750","-177.84482"
"49.40000","-12.30000","-177.77154"
"49.45000","-12.31297","-177.71490"
"49.50000","-12.32500","-177.58740"
"49.55000","-12.33750","-177.57755"
"49.60000","-12.35016","-177.53901"
"49.65000","-12.36219","-177.46605"
"49.70000","-12.37484","-177.43468"
"49.75000","-12.38750","-177.40136"
"49.80000","-12.39969","-177.33084"
"49.85000","-12.41234","-177.30223"
"49.90000","-12.42484","-177.24216"
"49.95000","-12.43703","-177.20770"
"50.00000","-12.44984","-177.18077"
"50.05000","-12.46188","-177.05865"
"50.10000","-12.47453","-177.03798"
"50.15000","-12.48734","-177.01888"
"50.20000","-12.49922","-176.90983"
"50.25000","-12.51188","-176.93304"
"50.30000","-12.52437","-176.85385"
"50.35000","-12.53656","-176.79412"
"50.40000","-12.54938","-176.77164"
"50.45000","-12.56188","-176.73720"
"50.50000","-12.57422","-176.67433"
"50.55000","-12.58687","-176.70138"
"50.60000","-12.59906","-176.59839"
"50.65000","-12.61141","-176.55887"
"50.70000","-12.62422","-176.53668"
"50.75000","-12.63641","-176.47222"
"50.80000","-12.64875","-176.44936"
"50.85000","-12.66156","-176.42859"
"50.90000","-12.67359","-176.32641"
"50.95000","-12.68609","-176.29186"
"51.00000","-12.69875","-176.26705"
"51.05000","-12.71094","-176.14592"
"51.10000","-12.72375","-176.15523"
"51.15000","-12.73594","-176.05230"
"51.20000","-12.74844","-176.02067"
"51.25000","-12.76094","-176.00294"
"51.30000","-12.77328","-175.90873"
"51.35000","-12.78562","-175.89502"
"51.40000","-12.79828","-175.79587"
"51.45000","-12.81063","-175.77562"
"51.50000","-12.82297","-175.76087"
"51.55000","-12.83563","-175.73157"
"51.60000","-12.84781","-175.63408"
"51.65000","-12.86047","-175.51981"
"51.70000","-12.87313","-175.45169"
"51.75000","-12.88516","-175.33118"
"51.80000","-12.89797","-175.32883"
"51.85000","-12.91016","-175.23734"
"51.90000","-12.92344","-53.68446"
"51.95000","-12.93594","7.91881"
"52.00000","-12.94781","1.28617"
"52.05000","-12.96016","1.52638"
"52.10000","-12.97266","1.56347"
"52.15000","-12.98484","1.59583"
"52.20000","-12.99734","1.61170"
"52.25000","-13.00984","1.57228"
"52.30000","-13.02219","1.53982"
"52.35000","-13.03484","1.55642"
"52.40000","-13.04750","1.59483"
"52.45000","-13.05953","1.56616"
"52.50000","-13.07219","1.57730"
"52.55000","-13.08453","1.58278"
"52.60000","-13.09688","1.58137"
"52.65000","-13.10969","1.57391"
"52.70000","-13.12172","1.59808"
"52.75000","-13.13422","1.58148"
"52.80000","-13.14703","1.56757"
"52.85000","-13.15906","1.56416"
"52.90000","-13.17172","1.57052"
"52.95000","-13.18438","1.56827"
"53.00000","-13.19672","1.57650"
"53.05000","-13.20938","1.57606"
"53.10000","-13.22172","1.56612"
"53.15000","-13.23391","1.58130"
"53.20000","-13.24656","1.59792"
"53.25000","-13.25891","1.57332"
"53.30000","-13.27125","1.57397"
"53.35000","-13.28391","1.58447"
"53.40000","-13.29609","1.58974"
"53.45000","-13.30844","1.60584"
"53.50000","-13.32125","1.62717"
"53.55000","-13.33328","1.61927"
"53.60000","-13.34609","1.57964"
"53.65000","-13.35859","1.59215"
"53.70000","-13.37094","1.61106"
"53.75000","-13.38359","1.58328"
"53.80000","-13.39578","1.59844"
"53.85000","-13.40828","1.62043"
"53.90000","-13.42078","1.62398"
"53.95000","-13.43312","1.62597"
"54.00000","-13.44547","1.60252"
"54.05000","-13.45813","1.60727"
"54.10000","-13.47031","1.60840"
"54.15000","-13.48281","1.59612"
"54.20000","-13.49562","1.62335"
"54.25000","-13.50781","1.62099"
"54.30000","-13.52047","1.60842"
"54.35000","-13.53281","1.60860"
"54.40000","-13.54500","1.59141"
"54.45000","-13.55766","1.59219"
"54.50000","-13.57000","1.62317"
"54.55000","-13.58250","1.60961"
"54.60000","-13.59500","1.60214"
"54.65000","-13.60734","1.60891"
"54.70000","-13.61984","1.60570"
"54.75000","-13.63234","1.61609"
"54.80000","-13.64484","1.60732"
"54.85000","-13.65719","1.61020"
"54.90000","-13.66984","1.58154"
"54.95000","-13.68203","1.60213"
"55.00000","-13.69453","1.61430"
"55.05000","-13.70719","1.58575"
"55.10000","-13.71938","1.58416"
"55.15000","-13.73219","1.60913"
"55.20000","-13.74437","1.61502"
"55.25000","-13.75672","1.60219"
"55.30000","-13.76922","1.59420"
"55.35000","-13.78141","1.59827"
"55.40000","-13.79422","1.62288"
"55.45000","-13.80687","1.62200"
"55.50000","-13.81922","1.59088"
"55.55000","-13.83172","1.58910"
"55.60000","-13.84422","1.60760"
"55.65000","-13.85641","1.62951"
"55.70000","-13.86891","1.60920"
"55.75000","-13.88141","1.58683"
"55.80000","-13.89359","1.61851"
"55.85000","-13.90625","1.62558"
"55.90000","-13.91875","1.59445"
"55.95000","-13.93094","1.58489"
"56.00000","-13.94359","1.61076"
"56.05000","-13.95594","1.59837"
"56.10000","-13.96859","1.61785"
"56.15000","-13.98125","1.59922"
"56.20000","-13.99344","1.58427"
"56.25000","-14.00594","1.57515"
"56.30000","-14.01828","1.61717"
"56.35000","-14.03078","1.59411"
"56.40000","-14.04328","1.62401"
"56.45000","-14.05578","1.59792"
"56.50000","-14.06812","1.58778"
"56.55000","-14.08047","1.59811"
"56.60000","-14.09297","1.59100"
"56.65000","-14.10531","1.59222"
"56.70000","-14.11812","1.62730"
"56.75000","-14.13031","1.60477"
"56.80000","-14.14281","1.63166"
"56.85000","-14.15547","1.58641"
"56.90000","-14.16750","1.63054"
"56.95000","-14.18016","1.61711"
"57.00000","-14.19266","1.58548"
"57.05000","-14.20500","1.59223"
"57.10000","-14.21750","1.61422"
"57.15000","-14.22984","1.59689"
"57.20000","-14.24219","1.61605"
"57.25000","-14.25469","1.59049"
"57.30000","-14.26719","1.62736"
"57.35000","-14.27969","1.62162"
"57.40000","-14.29234","1.60067"
"57.45000","-14.30469","1.58396"
"57.45600","-14.30609","1.58760"